Workbook

Sheet 阅读指南
A1: 伯克希尔的账本
A3: 2021—2025 年度 · 2025H1 同期基准 · 2026H1｜金额默认：百万美元；股数：股；每股：美元
A6: 先看什么 | B6: 「变化」是一页分析；「变化明细」列出同比、期末变化和占比。各输入格均有来源批注，亦可在「取数索引」集中检索。
A7: 颜色说明 | B7: 浅蓝＝披露事实输入；浅绿＝公式；浅橙＝可修改的假设。原始输入也可编辑，但将偏离披露事实。数字格式“–”表示0。
A8: 利润口径 | B8: 主表使用MD&A归属股东的税后分项；「法定分部」另列税前分部利润，保留制造、服务零售、McLane、Pilot。税前与税后不可直接混加。
A9: 历史重述与归类 | B9: 2021–2022采用2023年报ASU 2018-12重述数据。原Non-controlled businesses并入其他，2023 Pilot并入制造服务零售，与2025口径衔接；桥接见「对账」。
A10: 时间口径 | B10: 利润、回购和现金流为期间数；浮存金、现金、组合、权益和每股账面价值为期末数。2026H1同比只对2025H1；不年化。
A11: 现金口径 | B11: 主表＝合并现金及现金等价物＋资产负债表单列短期国债，含铁路能源，未扣未结算国债应付款，不含受限现金。不重复加入现金等价物中的国债。
A12: 组合与浮存金 | B12: 组合按Note 4的公允价值行业分类，包含权益证券中的优先股及认股权证，不含权益法投资。浮存金是约数负债资金，不是额外现金或股东权益。
A13: 每股账面价值 | B13: 归属伯克希尔股东权益÷期末等值A股数；等值A＝A股＋B股/1500。采用期末数量而非EPS加权平均股数，不等于内在价值。
A14: 资料优先级 | B14: 用户提供材料优先。其未覆盖的2021–2022明细、2023部分期末数和2025H1期末数，补充官方2022/2023年报及2025二季报，访问日2026-10-22。
A15: 边界 | B15: 只研究账本与历史决策；不提供投资建议。2025股东信署名Gregory E. Abel，小游戏巴菲特原文均取自更早股东信。

Sheet 变化
A1: 交班后的半年：增长从哪里来？
A3: 2026H1 对 2025H1；存量另看较2025年末变化｜所有展示数与下表公式联动，不将半年业绩年化
A5: 经营分项合计同比 | D5: 现金＋国债 / 十亿美元 | G5: 税后敏感性 / 百万美元
A6: ='利润'!H12/'利润'!G12-1 -> 0.16960723 | D6: ='资本'!H12/1000 -> 365.514 | G6: ='假设'!B13 -> -1155.0242
A8: 2026H1：24,329 百万美元 | D8: 合并口径；较2025年末下降约2.1% | G8: 假设利率−100bp；详见假设页
A10: 业务 | B10: 2025H1 | C10: 2026H1 | D10: 变化 | E10: 同比 | F10: H1占比 | G10: 增量贡献
A11: 保险承保 | B11: ='利润'!G6 -> 3328 | C11: ='利润'!H6 -> 3448 | D11: =C11-B11 -> 120 | E11: =C11/B11-1 -> 0.036057692 | F11: =C11/'利润'!H12 -> 0.14172387 | G11: =D11/('利润'!H12-'利润'!G12) -> 0.034013605 | H11: 其他增长含汇兑反转；其增量贡献不代表业务自然增长。
A12: 保险投资收益 | B12: ='利润'!G7 -> 6260 | C12: ='利润'!H7 -> 5738 | D12: =C12-B12 -> -522 | E12: =C12/B12-1 -> -0.083386581 | F12: =C12/'利润'!H12 -> 0.23585022 | G12: =D12/('利润'!H12-'利润'!G12) -> -0.14795918
A13: BNSF | B13: ='利润'!G8 -> 2680 | C13: ='利润'!H8 -> 2935 | D13: =C13-B13 -> 255 | E13: =C13/B13-1 -> 0.095149254 | F13: =C13/'利润'!H12 -> 0.12063792 | G13: =D13/('利润'!H12-'利润'!G12) -> 0.072278912
A14: BHE | B14: ='利润'!G9 -> 1799 | C14: ='利润'!H9 -> 2005 | D14: =C14-B14 -> 206 | E14: =C14/B14-1 -> 0.11450806 | F14: =C14/'利润'!H12 -> 0.082411936 | G14: =D14/('利润'!H12-'利润'!G12) -> 0.058390023
A15: 制造服务零售 | B15: ='利润'!G10 -> 6661 | C15: ='利润'!H10 -> 7669 | D15: =C15-B15 -> 1008 | E15: =C15/B15-1 -> 0.15132863 | F15: =C15/'利润'!H12 -> 0.31522052 | G15: =D15/('利润'!H12-'利润'!G12) -> 0.28571429
A16: 其他 | B16: ='利润'!G11 -> 73 | C16: ='利润'!H11 -> 2534 | D16: =C16-B16 -> 2461 | E16: =C16/B16-1 -> 33.712329 | F16: =C16/'利润'!H12 -> 0.10415553 | G16: =D16/('利润'!H12-'利润'!G12) -> 0.69756236
A18: 读法：汇兑变化贡献经营增量约61.4%；仅剔除该汇兑影响后经营分项增幅约6.1%。现金口径、浮存金约数与回购差额见资本/对账；完整同比及组合占比见变化明细。
A49: 事实：股票净买入11,625，较2025H1净卖出4,500发生方向变化；企业收购净支付9,704。OxyChem协议签于2025年、交割于2026年，不宜全部归因于新任CEO。研究截至所给2026Q2报告；不构成投资建议。

Sheet 利润
A1: 经营利润与归母净利润
A3: 税后、归属伯克希尔股东；百万美元。主表按2025年报MD&A聚合口径。
A5: 指标 | B5: 2021 | C5: 2022 | D5: 2023 | E5: 2024 | F5: 2025 | G5: 2025H1 | H5: 2026H1 | I5: 口径与来源提示
A6: 保险承保 | B6: 870 | C6: -30 | D6: 5428 | E6: 9020 | F6: 7258 | G6: 3328 | H6: 3448 | I6: 详见本格批注 / 取数索引
A7: 保险投资收益 | B7: 4807 | C7: 6484 | D7: 9567 | E7: 13670 | F7: 12513 | G7: 6260 | H7: 5738 | I7: 详见本格批注 / 取数索引
A8: 铁路 BNSF | B8: 5990 | C8: 5946 | D8: 5087 | E8: 5031 | F8: 5476 | G8: 2680 | H8: 2935 | I8: 详见本格批注 / 取数索引
A9: 能源 BHE | B9: 3572 | C9: 3904 | D9: 2331 | E9: 3730 | F9: 3979 | G9: 1799 | H9: 2005 | I9: 详见本格批注 / 取数索引
A10: 制造、服务和零售（含Pilot、McLane） | B10: 11120 | C10: 12512 | D10: 13362 | E10: 13072 | F10: 13647 | G10: 6661 | H10: 7669 | I10: 详见本格批注 / 取数索引
A11: 其他（含权益法收益及汇兑） | B11: ='对账'!B8 -> 1238 | C11: ='对账'!C8 -> 2037 | D11: 1575 | E11: 2914 | F11: 1613 | G11: 73 | H11: 2534 | I11: 2021–22其他已作分类桥接，详见对账。
A12: 经营分项合计 | B12: =SUM(B6:B11) -> 27597 | C12: =SUM(C6:C11) -> 30853 | D12: =SUM(D6:D11) -> 37350 | E12: =SUM(E6:E11) -> 47437 | F12: =SUM(F6:F11) -> 44486 | G12: =SUM(G6:G11) -> 20801 | H12: =SUM(H6:H11) -> 24329
A14: 投资损益（含早年衍生合约） | B14: 62340 | C14: -53612 | D14: 58873 | E14: 41558 | F14: 30737 | G14: -68 | H14: 11444
A15: 权益法投资减值（税后） | B15: 0 | C15: 0 | D15: 0 | E15: 0 | F15: -8255 | G15: -3760 | H15: 0
A16: 公式归母净利润 | B16: =B12+B14+B15 -> 89937 | C16: =C12+C14+C15 -> -22759 | D16: =D12+D14+D15 -> 96223 | E16: =E12+E14+E15 -> 88995 | F16: =F12+F14+F15 -> 66968 | G16: =G12+G14+G15 -> 16973 | H16: =H12+H14+H15 -> 35773
A17: 披露归母净利润 | B17: 89937 | C17: -22759 | D17: 96223 | E17: 88995 | F17: 66968 | G17: 16973 | H17: 35773
A18: 净利润对账差（应为0） | B18: =B16-B17 -> 0 | C18: =C16-C17 -> 0 | D18: =D16-D17 -> 0 | E18: =E16-E17 -> 0 | F18: =F16-F17 -> 0 | G18: =G16-G17 -> 0 | H18: =H16-H17 -> 0
A20: 注：此处经营分项合计为MD&A六项合计。其他中仍可能包含商誉等经营层面的减值；不把它误称为剔除所有一次性因素的“核心利润”。2023年报将Pilot及Non-controlled businesses单列，桥接见对账。

Sheet 资本
A1: 浮存金、现金与每股账面价值
A3: 期末存量与期间回购分区列示；合并现金口径含铁路能源，不扣国债未结算应付款。
A5: 指标 | B5: 2021 | C5: 2022 | D5: 2023 | E5: 2024 | F5: 2025 | G5: 2025H1 | H5: 2026H1 | I5: 口径与来源提示
A6: 保险浮存金（约数） | B6: 147000 | C6: 164000 | D6: 169000 | E6: 171000 | F6: 176000 | G6: 174000 | H6: 177500
A8: 现金及等价物：保险及其他 | B8: 85319 | C8: 32260 | D8: 33672 | E8: 44333 | F8: 47719 | G8: 96193 | H8: 35096
A9: 现金及等价物：铁路能源 | B9: 2865 | C9: 3551 | D9: 4350 | E9: 3396 | F9: 4158 | G9: 4293 | H9: 5513
A10: 合并现金及现金等价物 | B10: =B8+B9 -> 88184 | C10: =C8+C9 -> 35811 | D10: =D8+D9 -> 38022 | E10: =E8+E9 -> 47729 | F10: =F8+F9 -> 51877 | G10: =G8+G9 -> 100486 | H10: =H8+H9 -> 40609
A11: 单列短期美国国债 | B11: 58535 | C11: 92774 | D11: 129619 | E11: 286472 | F11: 321434 | G11: 243605 | H11: 324905
A12: 现金＋单列短期国债 | B12: =B10+B11 -> 146719 | C12: =C10+C11 -> 128585 | D12: =D10+D11 -> 167641 | E12: =E10+E11 -> 334201 | F12: =F10+F11 -> 373311 | G12: =G10+G11 -> 344091 | H12: =H10+H11 -> 365514
A15: 归属伯克希尔股东权益 | B15: 501568 | C15: 473424 | D15: 561273 | E15: 649368 | F15: 717419 | G15: 667989 | H15: 747910
A16: 期末A股数量 | B16: 617113 | C16: 591564 | D16: 567775 | E16: 547562 | F16: 515835 | G16: 531469 | H16: 501101
A17: 期末B股数量 | B17: 1290474503 | C17: 1302254076 | D17: 1310561508 | E17: 1335992139 | F17: 1383582639 | G17: 1360131639 | H17: 1395887484
A18: 期末等值A股数量（精确换算） | B18: =B16+B17/1500 -> 1477429.3 | C18: =C16+C17/1500 -> 1459733.4 | D18: =D16+D17/1500 -> 1441482.7 | E18: =E16+E17/1500 -> 1438223.4 | F18: =F16+F17/1500 -> 1438223.4 | G18: =G16+G17/1500 -> 1438223.4 | H18: =H16+H17/1500 -> 1431692.7
A19: 每股账面价值 A（美元） | B19: =B15*1000000/B18 -> 339486.96 | C19: =C15*1000000/C18 -> 324322.24 | D19: =D15*1000000/D18 -> 389372.01 | E19: =E15*1000000/E18 -> 451507.04 | F19: =F15*1000000/F18 -> 498823.05 | G19: =G15*1000000/G18 -> 464454.26 | H19: =H15*1000000/H18 -> 522395.64
A20: 每股账面价值 B（美元） | B20: =B19/1500 -> 226.32464 | C20: =C19/1500 -> 216.21483 | D20: =D19/1500 -> 259.58134 | E20: =E19/1500 -> 301.00469 | F20: =F19/1500 -> 332.5487 | G20: =G19/1500 -> 309.63617 | H20: =H19/1500 -> 348.26376
A23: 回购入账金额（期间数） | B23: 26942 | C23: 8031 | D23: 8976 | E23: 2918 | F23: 0 | G23: 0 | H23: 4762
A24: 回购现金支付（期间数） | B24: 27061 | C24: 7854 | D24: 9171 | E24: 2918 | F24: 0 | G24: 0 | H24: 4444
A25: 回购入账减现金支付 | B25: =B23-B24 -> -119 | C25: =C23-C24 -> 177 | D25: =D23-D24 -> -195 | E25: =E23-E24 -> 0 | F25: =F23-F24 -> 0 | G25: =G23-G24 -> 0 | H25: =H23-H24 -> 318
A27: 2026H1回购：权益变动表4,762；现金流量表4,444，差318。两表记录基础不同，本模型保留差额，不在没有明细时把它全部断言为某一种结算差异。期末等值A股由两类股精确换算，与公告四舍五入后的1,431,693股略有差别。

Sheet 股票组合
A1: 股票组合：从消费品转向更广的行业
A3: Note 4 权益证券公允价值；百万美元。行业分类不是各只股票的交易归因，市值变化同时受交易与估值影响。
A5: 指标 | B5: 2021 | C5: 2022 | D5: 2023 | E5: 2024 | F5: 2025 | G5: 2025H1 | H5: 2026H1 | I5: 口径与来源提示
A6: 银行、保险与金融 | B6: 89058 | C6: 69556 | D6: 78312 | E6: 91643 | F6: 104129 | G6: 93424 | H6: 94477
A7: 消费品 | B7: 191021 | C7: 152892 | D7: 201143 | E7: 104749 | F7: 94954 | G7: 91475 | H7: 100486
A8: 商业、工业及其他 | B8: 70640 | C8: 86345 | D8: 74387 | E8: 75196 | F8: 98695 | G8: 83024 | H8: 128816
A9: 三类公允价值合计 | B9: =SUM(B6:B8) -> 350719 | C9: =SUM(C6:C8) -> 308793 | D9: =SUM(D6:D8) -> 353842 | E9: =SUM(E6:E8) -> 271588 | F9: =SUM(F6:F8) -> 297778 | G9: =SUM(G6:G8) -> 267923 | H9: =SUM(H6:H8) -> 323779
A10: 披露权益证券总额 | B10: 350719 | C10: 308793 | D10: 353842 | E10: 271588 | F10: 297778 | G10: 267923 | H10: 323779
A11: 分类对账差（应为0） | B11: =B9-B10 -> 0 | C11: =C9-C10 -> 0 | D11: =D9-D10 -> 0 | E11: =E9-E10 -> 0 | F11: =F9-F10 -> 0 | G11: =G9-G10 -> 0 | H11: =H9-H10 -> 0
A14: 银行、保险与金融占比 | B14: =B6/B9 -> 0.25392978 | C14: =C6/C9 -> 0.22525122 | D14: =D6/D9 -> 0.22131912 | E14: =E6/E9 -> 0.33743391 | F14: =F6/F9 -> 0.34968668 | G14: =G6/G9 -> 0.3486972 | H14: =H6/H9 -> 0.29179471
A15: 消费品占比 | B15: =B7/B9 -> 0.54465541 | C15: =C7/C9 -> 0.4951278 | D15: =D7/D9 -> 0.56845428 | E15: =E7/E9 -> 0.38569083 | F15: =F7/F9 -> 0.31887514 | G15: =G7/G9 -> 0.34142272 | H15: =H7/H9 -> 0.31035367
A16: 商业、工业及其他占比 | B16: =B8/B9 -> 0.20141481 | C16: =C8/C9 -> 0.27962098 | D16: =D8/D9 -> 0.2102266 | E16: =E8/E9 -> 0.27687527 | F16: =F8/F9 -> 0.33143819 | G16: =G8/G9 -> 0.30988008 | H16: =H8/H9 -> 0.39785162
A18: 排除权益法：Kraft Heinz、Occidental普通股等权益法投资不在本行业表内。2022年Occidental普通股转入权益法，使行业组合跨年可比性受到影响。2026H1商业工业类市值增加不等同于全部来自新买入，不能用市值变化代替现金流。

Sheet 法定分部
A1: 法定分部利润：保留业务颗粒度
A3: 税前利润、百万美元；2021–22来自2023年报Note 26，2023–25来自2025年报Note 26，半年来自2026Q2 Note 24。
A5: 指标 | B5: 2021 | C5: 2022 | D5: 2023 | E5: 2024 | F5: 2025 | G5: 2025H1 | H5: 2026H1 | I5: 口径与来源提示
A6: 保险承保 | B6: 1111 | C6: -22 | D6: 6913 | E6: 11405 | F6: 9460 | G6: 4256 | H6: 4445
A7: 保险投资收益 | B7: 5649 | C7: 7724 | D7: 11581 | E7: 16748 | F7: 15261 | G7: 7564 | H7: 6989
A8: BNSF | B8: 7861 | C8: 7708 | D8: 6614 | E8: 6648 | F8: 7175 | G8: 3412 | H8: 3881
A9: BHE | B9: 3293 | C9: 3146 | D9: 940 | E9: 2292 | F9: 2342 | G9: 1108 | H9: 1348
A10: 制造 | B10: 9841 | C10: 11177 | D10: 11445 | E10: 11895 | F10: 12571 | G10: 5963 | H10: 7176
A11: 服务和零售 | B11: 4481 | C11: 4771 | D11: 4721 | E11: 3700 | F11: 4039 | G11: 2046 | H11: 2347
A12: McLane | B12: 230 | C12: 271 | D12: 455 | E12: 634 | F12: 676 | G12: 357 | H12: 317
A13: Pilot | B13: 0 | C13: 0 | D13: 968 | E13: 614 | F13: 190 | G13: 287 | H13: 240
A14: 经营分部税前合计 | B14: =SUM(B6:B13) -> 32466 | C14: =SUM(C6:C13) -> 34775 | D14: =SUM(D6:D13) -> 43637 | E14: =SUM(E6:E13) -> 53936 | F14: =SUM(F6:F13) -> 51714 | G14: =SUM(G6:G13) -> 24993 | H14: =SUM(H6:H13) -> 26743
A16: BHE税前利润不能直接与主表税后归属股东利润比较：生产税收抵免可形成所得税收益，且存在少数股东权益。制造服务零售主表聚合了制造、服务零售、McLane及Pilot，并作税项和归属处理。

Sheet 现金流
A1: 资金用途：把交易与市值变化分开
A3: 期间现金流；购入、资本支出、收购和回购使用正数表示资金用途。百万美元。
A5: 指标 | B5: 2021 | C5: 2022 | D5: 2023 | E5: 2024 | F5: 2025 | G5: 2025H1 | H5: 2026H1 | I5: 口径与来源提示
A6: 经营现金净流入 | B6: 39427 | C6: 37350 | D6: 49196 | E6: 30592 | F6: 45969 | G6: 20988 | H6: 21653
A7: 资本支出（含租赁设备） | B7: 13276 | C7: 15464 | D7: 19409 | E7: 18976 | F7: 20927 | G7: 9139 | H7: 10631
A8: 经营现金流减资本支出 | B8: =B6-B7 -> 26151 | C8: =C6-C7 -> 21886 | D8: =D6-D7 -> 29787 | E8: =E6-E7 -> 11616 | F8: =F6-F7 -> 25042 | G8: =G6-G7 -> 11849 | H8: =H6-H7 -> 11022
A9: 购入权益证券 | B9: 8448 | C9: 67930 | D9: 16462 | E9: 9237 | F9: 16923 | G9: 7092 | H9: 39405
A10: 出售权益证券所得 | B10: 15849 | C10: 33664 | D10: 40631 | E10: 143359 | F10: 30686 | G10: 11592 | H10: 27780
A11: 权益证券净买入（负数为净卖出） | B11: =B9-B10 -> -7401 | C11: =C9-C10 -> 34266 | D11: =D9-D10 -> -24169 | E11: =E9-E10 -> -134122 | F11: =F9-F10 -> -13763 | G11: =G9-G10 -> -4500 | H11: =H9-H10 -> 11625
A12: 企业收购净支付 | B12: 456 | C12: 10594 | D12: 8604 | E12: 396 | F12: 1074 | G12: 101 | H12: 9704
A13: 回购现金支付 | B13: ='资本'!B24 -> 27061 | C13: ='资本'!C24 -> 7854 | D13: ='资本'!D24 -> 9171 | E13: ='资本'!E24 -> 2918 | F13: ='资本'!F24 -> 0 | G13: ='资本'!G24 -> 0 | H13: ='资本'!H24 -> 4444
A15: 经营现金流减资本支出只是简化的现金余量，不等于可全部分配的自由现金流；尚有保险赔付准备、债务和监管约束。权益证券净买入不含权益法投资与企业收购，亦不能解释全部股票公允价值变化。

Sheet 对账
A1: 口径桥接与增长归因
A3: 所有相加、扣除和贡献度均用公式；观察性调整不是预测，也不是公司披露的新经营指标。
A5: 2023年报旧口径 / 百万美元 | B5: 2021 | C5: 2022
A6: 原其他 | B6: 434 | C6: 509
A7: 原非控制业务 | B7: 804 | C7: 1528
A8: 重分类后其他 | B8: =SUM(B6:B7) -> 1238 | C8: =SUM(C6:C7) -> 2037
A10: 2023原制造服务零售 | B10: 12759
A11: 2023原Pilot | B11: 603
A12: 合并后制造服务零售 | B12: =B10+B11 -> 13362
A15: 2026H1增长拆解 | B15: 2025H1 | C15: 2026H1 | D15: 差额 / 贡献
A16: 经营分项合计 | B16: ='利润'!G12 -> 20801 | C16: ='利润'!H12 -> 24329 | D16: =C16-B16 -> 3528
A17: 其中：债务汇兑损益 | B17: -1590 | C17: 575 | D17: =(C17-B17)/D16 -> 0.61366213
A18: 扣除上述汇兑后的经营分项 | B18: =B16-B17 -> 22391 | C18: =C16-C17 -> 23754 | D18: =C18/B18-1 -> 0.060872672
A20: 披露承保利润 | B20: ='利润'!G6 -> 3328 | C20: ='利润'!H6 -> 3448
A21: 加回当期重大灾害损失 | B21: 850 | C21: 0
A22: 仅剔除重大灾害的观察数 | B22: =B20+B21 -> 4178 | C22: =C20+C21 -> 3448 | D22: =C22-B22 -> -730
A24: 汇兑贡献＝汇兑损益变化÷经营分项增量。只剔除汇兑后的增幅约6.1%，不代表有机增长率；灾害观察数未调整准备金变化、业务组合或其他影响，不能当成正常化利润。
A28: 2025年末保险及其他净现金口径 | B28: 369000
A29: 2026H1保险及其他净现金口径 | B29: 359200
A30: 2026H1浮存金披露增量 | B30: 1100
A32: 主表2025浮存金176,000为粗粒度披露。177,500−176,000＝1,500仅是两期约数差；季报披露实际增量约1,100。由177,500−1,100反推176,400只是近似推导，模型不把它替换为披露年末数。

Sheet 假设
A1: 一个可调的假设：短期利率敏感性
A3: 浅橙格可修改；这里只展示静态机械敏感性，所有披露事实保持独立。不是盈利预测。
A6: 假设：短期收益率变动 | B6: -0.01
A7: 假设：适用现金与国债比例 | B7: 0.8
A8: 假设：边际税率 | B8: 0.21
A9: 假设：年内作用时间比例 | B9: 0.5
A11: 2026H1现金＋国债（百万美元） | B11: ='资本'!H12 -> 365514
A12: 假设：税前利息变化 | B12: =B11*B6*B7*B9 -> -1462.056
A13: 假设：税后利息变化 | B13: =B12*(1-B8) -> -1155.0242
A14: 占披露2026H1经营分项合计 | B14: =B13/'利润'!H12 -> -0.047475204
A17: 假设将6月末余额视作固定基数，80%资金同步重定价，利率下降100基点，持续半年，税率21%。忽略资金流、资产负债期限结构、海外税差、收入归属变化与管理层应对。调整B6–B9后，B12–B14与「变化」的敏感性显示自动更新。

Sheet 变化明细
A1: 同比、期末变化、占比：完整公式清单
A3: 同比基数≤0时显示“不适用”，另给绝对变动；2021缺2020可比基期，不强行填0%。2026H1与2025H1同口径比较。
A5: 指标 | B5: 2022同比 | C5: 2023同比 | D5: 2024同比 | E5: 2025同比 | F5: 2026H1同比 | G5: H1同比绝对变化 | H5: 较2025年末变化 | I5: 2026H1占比 / 分母 | J5: 占比分母 / 说明
A6: 保险承保 | B6: =IF('利润'!B6>0,'利润'!C6/'利润'!B6-1,"不适用") -> -1.0344828 | C6: =IF('利润'!C6>0,'利润'!D6/'利润'!C6-1,"不适用") -> 不适用 | D6: =IF('利润'!D6>0,'利润'!E6/'利润'!D6-1,"不适用") -> 0.66175387 | E6: =IF('利润'!E6>0,'利润'!F6/'利润'!E6-1,"不适用") -> -0.19534368 | F6: =IF('利润'!G6>0,'利润'!H6/'利润'!G6-1,"不适用") -> 0.036057692 | G6: ='利润'!H6-'利润'!G6 -> 120 | H6: 期间数不比较 | I6: ='利润'!H6/'利润'!H12 -> 0.14172387 | J6: 经营分项合计
A7: 保险投资收益 | B7: =IF('利润'!B7>0,'利润'!C7/'利润'!B7-1,"不适用") -> 0.34886624 | C7: =IF('利润'!C7>0,'利润'!D7/'利润'!C7-1,"不适用") -> 0.4754781 | D7: =IF('利润'!D7>0,'利润'!E7/'利润'!D7-1,"不适用") -> 0.42887007 | E7: =IF('利润'!E7>0,'利润'!F7/'利润'!E7-1,"不适用") -> -0.084637893 | F7: =IF('利润'!G7>0,'利润'!H7/'利润'!G7-1,"不适用") -> -0.083386581 | G7: ='利润'!H7-'利润'!G7 -> -522 | H7: 期间数不比较 | I7: ='利润'!H7/'利润'!H12 -> 0.23585022 | J7: 经营分项合计
A8: 铁路 BNSF | B8: =IF('利润'!B8>0,'利润'!C8/'利润'!B8-1,"不适用") -> -0.007345576 | C8: =IF('利润'!C8>0,'利润'!D8/'利润'!C8-1,"不适用") -> -0.14446687 | D8: =IF('利润'!D8>0,'利润'!E8/'利润'!D8-1,"不适用") -> -0.011008453 | E8: =IF('利润'!E8>0,'利润'!F8/'利润'!E8-1,"不适用") -> 0.0884516 | F8: =IF('利润'!G8>0,'利润'!H8/'利润'!G8-1,"不适用") -> 0.095149254 | G8: ='利润'!H8-'利润'!G8 -> 255 | H8: 期间数不比较 | I8: ='利润'!H8/'利润'!H12 -> 0.12063792 | J8: 经营分项合计
A9: 能源 BHE | B9: =IF('利润'!B9>0,'利润'!C9/'利润'!B9-1,"不适用") -> 0.092945129 | C9: =IF('利润'!C9>0,'利润'!D9/'利润'!C9-1,"不适用") -> -0.40292008 | D9: =IF('利润'!D9>0,'利润'!E9/'利润'!D9-1,"不适用") -> 0.6001716 | E9: =IF('利润'!E9>0,'利润'!F9/'利润'!E9-1,"不适用") -> 0.066756032 | F9: =IF('利润'!G9>0,'利润'!H9/'利润'!G9-1,"不适用") -> 0.11450806 | G9: ='利润'!H9-'利润'!G9 -> 206 | H9: 期间数不比较 | I9: ='利润'!H9/'利润'!H12 -> 0.082411936 | J9: 经营分项合计
A10: 制造、服务和零售（含Pilot、McLane） | B10: =IF('利润'!B10>0,'利润'!C10/'利润'!B10-1,"不适用") -> 0.12517986 | C10: =IF('利润'!C10>0,'利润'!D10/'利润'!C10-1,"不适用") -> 0.067934783 | D10: =IF('利润'!D10>0,'利润'!E10/'利润'!D10-1,"不适用") -> -0.021703338 | E10: =IF('利润'!E10>0,'利润'!F10/'利润'!E10-1,"不适用") -> 0.043987148 | F10: =IF('利润'!G10>0,'利润'!H10/'利润'!G10-1,"不适用") -> 0.15132863 | G10: ='利润'!H10-'利润'!G10 -> 1008 | H10: 期间数不比较 | I10: ='利润'!H10/'利润'!H12 -> 0.31522052 | J10: 经营分项合计
A11: 其他（含权益法收益及汇兑） | B11: =IF('利润'!B11>0,'利润'!C11/'利润'!B11-1,"不适用") -> 0.6453958 | C11: =IF('利润'!C11>0,'利润'!D11/'利润'!C11-1,"不适用") -> -0.22680412 | D11: =IF('利润'!D11>0,'利润'!E11/'利润'!D11-1,"不适用") -> 0.85015873 | E11: =IF('利润'!E11>0,'利润'!F11/'利润'!E11-1,"不适用") -> -0.44646534 | F11: =IF('利润'!G11>0,'利润'!H11/'利润'!G11-1,"不适用") -> 33.712329 | G11: ='利润'!H11-'利润'!G11 -> 2461 | H11: 期间数不比较 | I11: ='利润'!H11/'利润'!H12 -> 0.10415553 | J11: 经营分项合计
A12: 经营分项合计 | B12: =IF('利润'!B12>0,'利润'!C12/'利润'!B12-1,"不适用") -> 0.11798384 | C12: =IF('利润'!C12>0,'利润'!D12/'利润'!C12-1,"不适用") -> 0.2105792 | D12: =IF('利润'!D12>0,'利润'!E12/'利润'!D12-1,"不适用") -> 0.27006693 | E12: =IF('利润'!E12>0,'利润'!F12/'利润'!E12-1,"不适用") -> -0.062208824 | F12: =IF('利润'!G12>0,'利润'!H12/'利润'!G12-1,"不适用") -> 0.16960723 | G12: ='利润'!H12-'利润'!G12 -> 3528 | H12: 期间数不比较 | I12: —
A13: 归母净利润 | B13: =IF('利润'!B17>0,'利润'!C17/'利润'!B17-1,"不适用") -> -1.2530549 | C13: =IF('利润'!C17>0,'利润'!D17/'利润'!C17-1,"不适用") -> 不适用 | D13: =IF('利润'!D17>0,'利润'!E17/'利润'!D17-1,"不适用") -> -0.075117176 | E13: =IF('利润'!E17>0,'利润'!F17/'利润'!E17-1,"不适用") -> -0.24750829 | F13: =IF('利润'!G17>0,'利润'!H17/'利润'!G17-1,"不适用") -> 1.1076415 | G13: ='利润'!H17-'利润'!G17 -> 18800 | H13: 期间数不比较 | I13: —
A14: 浮存金（约数） | B14: =IF('资本'!B6>0,'资本'!C6/'资本'!B6-1,"不适用") -> 0.11564626 | C14: =IF('资本'!C6>0,'资本'!D6/'资本'!C6-1,"不适用") -> 0.030487805 | D14: =IF('资本'!D6>0,'资本'!E6/'资本'!D6-1,"不适用") -> 0.01183432 | E14: =IF('资本'!E6>0,'资本'!F6/'资本'!E6-1,"不适用") -> 0.029239766 | F14: =IF('资本'!G6>0,'资本'!H6/'资本'!G6-1,"不适用") -> 0.020114943 | G14: ='资本'!H6-'资本'!G6 -> 3500 | H14: ='资本'!H6/'资本'!F6-1 -> 0.0085227273 | I14: —
A15: 保险及其他现金 | B15: =IF('资本'!B8>0,'资本'!C8/'资本'!B8-1,"不适用") -> -0.62188961 | C15: =IF('资本'!C8>0,'资本'!D8/'资本'!C8-1,"不适用") -> 0.043769374 | D15: =IF('资本'!D8>0,'资本'!E8/'资本'!D8-1,"不适用") -> 0.31661321 | E15: =IF('资本'!E8>0,'资本'!F8/'资本'!E8-1,"不适用") -> 0.076376514 | F15: =IF('资本'!G8>0,'资本'!H8/'资本'!G8-1,"不适用") -> -0.63515017 | G15: ='资本'!H8-'资本'!G8 -> -61097 | H15: ='资本'!H8/'资本'!F8-1 -> -0.26452776 | I15: ='资本'!H8/'资本'!H12 -> 0.09601821 | J15: 现金＋国债
A16: 铁路能源现金 | B16: =IF('资本'!B9>0,'资本'!C9/'资本'!B9-1,"不适用") -> 0.23944154 | C16: =IF('资本'!C9>0,'资本'!D9/'资本'!C9-1,"不适用") -> 0.22500704 | D16: =IF('资本'!D9>0,'资本'!E9/'资本'!D9-1,"不适用") -> -0.21931034 | E16: =IF('资本'!E9>0,'资本'!F9/'资本'!E9-1,"不适用") -> 0.22438163 | F16: =IF('资本'!G9>0,'资本'!H9/'资本'!G9-1,"不适用") -> 0.28418355 | G16: ='资本'!H9-'资本'!G9 -> 1220 | H16: ='资本'!H9/'资本'!F9-1 -> 0.32587783 | I16: ='资本'!H9/'资本'!H12 -> 0.01508287 | J16: 现金＋国债
A17: 合并现金及等价物 | B17: =IF('资本'!B10>0,'资本'!C10/'资本'!B10-1,"不适用") -> -0.59390592 | C17: =IF('资本'!C10>0,'资本'!D10/'资本'!C10-1,"不适用") -> 0.061740806 | D17: =IF('资本'!D10>0,'资本'!E10/'资本'!D10-1,"不适用") -> 0.25529956 | E17: =IF('资本'!E10>0,'资本'!F10/'资本'!E10-1,"不适用") -> 0.086907331 | F17: =IF('资本'!G10>0,'资本'!H10/'资本'!G10-1,"不适用") -> -0.59587405 | G17: ='资本'!H10-'资本'!G10 -> -59877 | H17: ='资本'!H10/'资本'!F10-1 -> -0.21720608 | I17: ='资本'!H10/'资本'!H12 -> 0.11110108 | J17: 现金＋国债
A18: 单列短期国债 | B18: =IF('资本'!B11>0,'资本'!C11/'资本'!B11-1,"不适用") -> 0.58493209 | C18: =IF('资本'!C11>0,'资本'!D11/'资本'!C11-1,"不适用") -> 0.39714791 | D18: =IF('资本'!D11>0,'资本'!E11/'资本'!D11-1,"不适用") -> 1.2101081 | E18: =IF('资本'!E11>0,'资本'!F11/'资本'!E11-1,"不适用") -> 0.12204334 | F18: =IF('资本'!G11>0,'资本'!H11/'资本'!G11-1,"不适用") -> 0.33373699 | G18: ='资本'!H11-'资本'!G11 -> 81300 | H18: ='资本'!H11/'资本'!F11-1 -> 0.010798484 | I18: ='资本'!H11/'资本'!H12 -> 0.88889892 | J18: 现金＋国债
A19: 现金＋国债 | B19: =IF('资本'!B12>0,'资本'!C12/'资本'!B12-1,"不适用") -> -0.12359681 | C19: =IF('资本'!C12>0,'资本'!D12/'资本'!C12-1,"不适用") -> 0.30373683 | D19: =IF('资本'!D12>0,'资本'!E12/'资本'!D12-1,"不适用") -> 0.9935517 | E19: =IF('资本'!E12>0,'资本'!F12/'资本'!E12-1,"不适用") -> 0.11702538 | F19: =IF('资本'!G12>0,'资本'!H12/'资本'!G12-1,"不适用") -> 0.062259693 | G19: ='资本'!H12-'资本'!G12 -> 21423 | H19: ='资本'!H12/'资本'!F12-1 -> -0.020886071 | I19: —
A20: 股东权益 | B20: =IF('资本'!B15>0,'资本'!C15/'资本'!B15-1,"不适用") -> -0.056112033 | C20: =IF('资本'!C15>0,'资本'!D15/'资本'!C15-1,"不适用") -> 0.18556093 | D20: =IF('资本'!D15>0,'资本'!E15/'资本'!D15-1,"不适用") -> 0.15695571 | E20: =IF('资本'!E15>0,'资本'!F15/'资本'!E15-1,"不适用") -> 0.10479574 | F20: =IF('资本'!G15>0,'资本'!H15/'资本'!G15-1,"不适用") -> 0.11964419 | G20: ='资本'!H15-'资本'!G15 -> 79921 | H20: ='资本'!H15/'资本'!F15-1 -> 0.042500965 | I20: —
A21: 期末等值A股数 | B21: =IF('资本'!B18>0,'资本'!C18/'资本'!B18-1,"不适用") -> -0.011977528 | C21: =IF('资本'!C18>0,'资本'!D18/'资本'!C18-1,"不适用") -> -0.012502771 | D21: =IF('资本'!D18>0,'资本'!E18/'资本'!D18-1,"不适用") -> -0.0022610372 | E21: =IF('资本'!E18>0,'资本'!F18/'资本'!E18-1,"不适用") -> 0 | F21: =IF('资本'!G18>0,'资本'!H18/'资本'!G18-1,"不适用") -> -0.0045408591 | G21: ='资本'!H18-'资本'!G18 -> -6530.77 | H21: ='资本'!H18/'资本'!F18-1 -> -0.0045408591 | I21: —
A22: 每股账面价值A | B22: =IF('资本'!B19>0,'资本'!C19/'资本'!B19-1,"不适用") -> -0.044669535 | C22: =IF('资本'!C19>0,'资本'!D19/'资本'!C19-1,"不适用") -> 0.2005714 | D22: =IF('资本'!D19>0,'资本'!E19/'资本'!D19-1,"不适用") -> 0.15957755 | E22: =IF('资本'!E19>0,'资本'!F19/'资本'!E19-1,"不适用") -> 0.10479574 | F22: =IF('资本'!G19>0,'资本'!H19/'资本'!G19-1,"不适用") -> 0.12475152 | G22: ='资本'!H19-'资本'!G19 -> 57941.377 | H22: ='资本'!H19/'资本'!F19-1 -> 0.047256409 | I22: —
A23: 每股账面价值B | B23: =IF('资本'!B20>0,'资本'!C20/'资本'!B20-1,"不适用") -> -0.044669535 | C23: =IF('资本'!C20>0,'资本'!D20/'资本'!C20-1,"不适用") -> 0.2005714 | D23: =IF('资本'!D20>0,'资本'!E20/'资本'!D20-1,"不适用") -> 0.15957755 | E23: =IF('资本'!E20>0,'资本'!F20/'资本'!E20-1,"不适用") -> 0.10479574 | F23: =IF('资本'!G20>0,'资本'!H20/'资本'!G20-1,"不适用") -> 0.12475152 | G23: ='资本'!H20-'资本'!G20 -> 38.627585 | H23: ='资本'!H20/'资本'!F20-1 -> 0.047256409 | I23: —
A24: 回购入账额 | B24: =IF('资本'!B23>0,'资本'!C23/'资本'!B23-1,"不适用") -> -0.70191523 | C24: =IF('资本'!C23>0,'资本'!D23/'资本'!C23-1,"不适用") -> 0.11766903 | D24: =IF('资本'!D23>0,'资本'!E23/'资本'!D23-1,"不适用") -> -0.67491087 | E24: =IF('资本'!E23>0,'资本'!F23/'资本'!E23-1,"不适用") -> -1 | F24: =IF('资本'!G23>0,'资本'!H23/'资本'!G23-1,"不适用") -> 不适用 | G24: ='资本'!H23-'资本'!G23 -> 4762 | H24: 期间数不比较 | I24: —
A25: 回购现金支付 | B25: =IF('资本'!B24>0,'资本'!C24/'资本'!B24-1,"不适用") -> -0.70976682 | C25: =IF('资本'!C24>0,'资本'!D24/'资本'!C24-1,"不适用") -> 0.16768526 | D25: =IF('资本'!D24>0,'资本'!E24/'资本'!D24-1,"不适用") -> -0.68182314 | E25: =IF('资本'!E24>0,'资本'!F24/'资本'!E24-1,"不适用") -> -1 | F25: =IF('资本'!G24>0,'资本'!H24/'资本'!G24-1,"不适用") -> 不适用 | G25: ='资本'!H24-'资本'!G24 -> 4444 | H25: 期间数不比较 | I25: —
A26: 银行保险金融 | B26: =IF('股票组合'!B6>0,'股票组合'!C6/'股票组合'!B6-1,"不适用") -> -0.21898089 | C26: =IF('股票组合'!C6>0,'股票组合'!D6/'股票组合'!C6-1,"不适用") -> 0.12588418 | D26: =IF('股票组合'!D6>0,'股票组合'!E6/'股票组合'!D6-1,"不适用") -> 0.17022934 | E26: =IF('股票组合'!E6>0,'股票组合'!F6/'股票组合'!E6-1,"不适用") -> 0.13624609 | F26: =IF('股票组合'!G6>0,'股票组合'!H6/'股票组合'!G6-1,"不适用") -> 0.011271194 | G26: ='股票组合'!H6-'股票组合'!G6 -> 1053 | H26: ='股票组合'!H6/'股票组合'!F6-1 -> -0.092692718 | I26: ='股票组合'!H6/'股票组合'!H9 -> 0.29179471 | J26: 权益证券组合
A27: 消费品 | B27: =IF('股票组合'!B7>0,'股票组合'!C7/'股票组合'!B7-1,"不适用") -> -0.19960633 | C27: =IF('股票组合'!C7>0,'股票组合'!D7/'股票组合'!C7-1,"不适用") -> 0.31558878 | D27: =IF('股票组合'!D7>0,'股票组合'!E7/'股票组合'!D7-1,"不适用") -> -0.47923119 | E27: =IF('股票组合'!E7>0,'股票组合'!F7/'股票组合'!E7-1,"不适用") -> -0.093509246 | F27: =IF('股票组合'!G7>0,'股票组合'!H7/'股票组合'!G7-1,"不适用") -> 0.098507789 | G27: ='股票组合'!H7-'股票组合'!G7 -> 9011 | H27: ='股票组合'!H7/'股票组合'!F7-1 -> 0.058259789 | I27: ='股票组合'!H7/'股票组合'!H9 -> 0.31035367 | J27: 权益证券组合
A28: 商业工业及其他 | B28: =IF('股票组合'!B8>0,'股票组合'!C8/'股票组合'!B8-1,"不适用") -> 0.22232446 | C28: =IF('股票组合'!C8>0,'股票组合'!D8/'股票组合'!C8-1,"不适用") -> -0.13849094 | D28: =IF('股票组合'!D8>0,'股票组合'!E8/'股票组合'!D8-1,"不适用") -> 0.010875556 | E28: =IF('股票组合'!E8>0,'股票组合'!F8/'股票组合'!E8-1,"不适用") -> 0.31250332 | F28: =IF('股票组合'!G8>0,'股票组合'!H8/'股票组合'!G8-1,"不适用") -> 0.55155136 | G28: ='股票组合'!H8-'股票组合'!G8 -> 45792 | H28: ='股票组合'!H8/'股票组合'!F8-1 -> 0.30519277 | I28: ='股票组合'!H8/'股票组合'!H9 -> 0.39785162 | J28: 权益证券组合
A29: 权益证券总额 | B29: =IF('股票组合'!B9>0,'股票组合'!C9/'股票组合'!B9-1,"不适用") -> -0.119543 | C29: =IF('股票组合'!C9>0,'股票组合'!D9/'股票组合'!C9-1,"不适用") -> 0.14588737 | D29: =IF('股票组合'!D9>0,'股票组合'!E9/'股票组合'!D9-1,"不适用") -> -0.23245969 | E29: =IF('股票组合'!E9>0,'股票组合'!F9/'股票组合'!E9-1,"不适用") -> 0.096432832 | F29: =IF('股票组合'!G9>0,'股票组合'!H9/'股票组合'!G9-1,"不适用") -> 0.20847781 | G29: ='股票组合'!H9-'股票组合'!G9 -> 55856 | H29: ='股票组合'!H9/'股票组合'!F9-1 -> 0.087316726 | I29: —
A30: 经营现金流 | B30: =IF('现金流'!B6>0,'现金流'!C6/'现金流'!B6-1,"不适用") -> -0.052679636 | C30: =IF('现金流'!C6>0,'现金流'!D6/'现金流'!C6-1,"不适用") -> 0.31716198 | D30: =IF('现金流'!D6>0,'现金流'!E6/'现金流'!D6-1,"不适用") -> -0.37816083 | E30: =IF('现金流'!E6>0,'现金流'!F6/'现金流'!E6-1,"不适用") -> 0.50264775 | F30: =IF('现金流'!G6>0,'现金流'!H6/'现金流'!G6-1,"不适用") -> 0.031684772 | G30: ='现金流'!H6-'现金流'!G6 -> 665 | H30: 期间数不比较 | I30: —
A31: 资本支出 | B31: =IF('现金流'!B7>0,'现金流'!C7/'现金流'!B7-1,"不适用") -> 0.16480868 | C31: =IF('现金流'!C7>0,'现金流'!D7/'现金流'!C7-1,"不适用") -> 0.25510864 | D31: =IF('现金流'!D7>0,'现金流'!E7/'现金流'!D7-1,"不适用") -> -0.022309238 | E31: =IF('现金流'!E7>0,'现金流'!F7/'现金流'!E7-1,"不适用") -> 0.10281408 | F31: =IF('现金流'!G7>0,'现金流'!H7/'现金流'!G7-1,"不适用") -> 0.16325637 | G31: ='现金流'!H7-'现金流'!G7 -> 1492 | H31: 期间数不比较 | I31: —
A32: 经营现金流减资本支出 | B32: =IF('现金流'!B8>0,'现金流'!C8/'现金流'!B8-1,"不适用") -> -0.16309128 | C32: =IF('现金流'!C8>0,'现金流'!D8/'现金流'!C8-1,"不适用") -> 0.36100704 | D32: =IF('现金流'!D8>0,'现金流'!E8/'现金流'!D8-1,"不适用") -> -0.61003122 | E32: =IF('现金流'!E8>0,'现金流'!F8/'现金流'!E8-1,"不适用") -> 1.1558196 | F32: =IF('现金流'!G8>0,'现金流'!H8/'现金流'!G8-1,"不适用") -> -0.069794919 | G32: ='现金流'!H8-'现金流'!G8 -> -827 | H32: 期间数不比较 | I32: —
A33: 买入权益证券 | B33: =IF('现金流'!B9>0,'现金流'!C9/'现金流'!B9-1,"不适用") -> 7.0409564 | C33: =IF('现金流'!C9>0,'现金流'!D9/'现金流'!C9-1,"不适用") -> -0.7576623 | D33: =IF('现金流'!D9>0,'现金流'!E9/'现金流'!D9-1,"不适用") -> -0.43888956 | E33: =IF('现金流'!E9>0,'现金流'!F9/'现金流'!E9-1,"不适用") -> 0.83208834 | F33: =IF('现金流'!G9>0,'现金流'!H9/'现金流'!G9-1,"不适用") -> 4.5562606 | G33: ='现金流'!H9-'现金流'!G9 -> 32313 | H33: 期间数不比较 | I33: —
A34: 出售权益证券 | B34: =IF('现金流'!B10>0,'现金流'!C10/'现金流'!B10-1,"不适用") -> 1.1240457 | C34: =IF('现金流'!C10>0,'现金流'!D10/'现金流'!C10-1,"不适用") -> 0.20695699 | D34: =IF('现金流'!D10>0,'现金流'!E10/'现金流'!D10-1,"不适用") -> 2.5283158 | E34: =IF('现金流'!E10>0,'现金流'!F10/'现金流'!E10-1,"不适用") -> -0.78594996 | F34: =IF('现金流'!G10>0,'现金流'!H10/'现金流'!G10-1,"不适用") -> 1.3964803 | G34: ='现金流'!H10-'现金流'!G10 -> 16188 | H34: 期间数不比较 | I34: —
A35: 净买入权益证券 | B35: =IF('现金流'!B11>0,'现金流'!C11/'现金流'!B11-1,"不适用") -> 不适用 | C35: =IF('现金流'!C11>0,'现金流'!D11/'现金流'!C11-1,"不适用") -> -1.7053347 | D35: =IF('现金流'!D11>0,'现金流'!E11/'现金流'!D11-1,"不适用") -> 不适用 | E35: =IF('现金流'!E11>0,'现金流'!F11/'现金流'!E11-1,"不适用") -> 不适用 | F35: =IF('现金流'!G11>0,'现金流'!H11/'现金流'!G11-1,"不适用") -> 不适用 | G35: ='现金流'!H11-'现金流'!G11 -> 16125 | H35: 期间数不比较 | I35: —
A36: 企业收购净支付 | B36: =IF('现金流'!B12>0,'现金流'!C12/'现金流'!B12-1,"不适用") -> 22.232456 | C36: =IF('现金流'!C12>0,'现金流'!D12/'现金流'!C12-1,"不适用") -> -0.18784217 | D36: =IF('现金流'!D12>0,'现金流'!E12/'现金流'!D12-1,"不适用") -> -0.9539749 | E36: =IF('现金流'!E12>0,'现金流'!F12/'现金流'!E12-1,"不适用") -> 1.7121212 | F36: =IF('现金流'!G12>0,'现金流'!H12/'现金流'!G12-1,"不适用") -> 95.079208 | G36: ='现金流'!H12-'现金流'!G12 -> 9603 | H36: 期间数不比较 | I36: —

Sheet 来源
A1: 资料谱系与可比性
A3: 本地材料优先；补充网页的访问日期均为2026-10-22。URL是纯文本来源，不产生外部数据连接。
A6: L1 | B6: 材料/Berkshire_2025年报__brka-20251231.htm | F6: 2023–2025税后/税前利润、2024–2025期末余额、2023–2025现金流；以文件披露为准。
A7: L2 | B7: 材料/Berkshire_2026Q2季报__brka-20260630.htm | F7: 2026H1及2025H1损益/现金流；2026期末余额、企业收购及期后事项。
A8: L3 | B8: 材料/Berkshire_2026Q2业绩公告__d159922dex991.htm | F8: 交叉核对经营利润24,329、回购约4,800、浮存金177,500及等值A股数。
A9: E1 | B9: https://www.berkshirehathaway.com/2022ar/2022ar.pdf | F9: 2021年末权益证券行业公允价值。访问日2026-10-22；其他历史数字优先采用后续重述。
A10: E2 | B10: https://www.berkshirehathaway.com/2023ar/2023ar.pdf | F10: 2021–2022重述后利润/权益、2021–2023股数及现金流、2022–2023组合。访问日2026-10-22。
A11: E3 | B11: https://www.berkshirehathaway.com/qtrly/2ndqtr25.pdf | F11: 2025H1期末现金、短期国债、权益证券行业、浮存金、股数。访问日2026-10-22。
A12: L4 | B12: 材料/股东信/2022ltr.pdf | F12: 2021/2022浮存金约147/164十亿美元。
A13: L5 | B13: 材料/股东信/2025ltr.pdf | F13: 交接语境；署名Gregory E. Abel。未用于巴菲特游戏引文。
A15: 未独立审计或验证所给2025/2026材料的真实性，研究按材料内部披露构建。未把网页更新后的数字覆盖用户材料。原始材料存在部分早年HTML不可读的情况，游戏仅采用已能逐字核验的文件。

Sheet 历史决策
A1: 十次决定｜游戏与账本共用档案
A3: 年份为决定发生年，股东信年份可能是事后回顾；匹配度每题10分，只表示与实际选择一致，不表示优劣。
A5: 决定年份 | B5: 题目 | C5: 实际决定 | D5: 原文（每处不超过两句） | E5: 来源
A6: 1967 | B6: 纺织厂的现金，下一站在哪里？ | C6: 收购 National Indemnity，进入保险业。 | D6: In early 1967 cash generated by the textile operation was used to fund our entry into insurance via the purchase of National Indemnity Company. | E6: 材料/股东信/1985ltr.html · Shutdown of Textile Business
A7: 1972 | B7: 一盒巧克力，值什么？ | C7: 通过当时控制的 Blue Chip Stamps 收购 See’s。 | D7: We bought See’s for $25 million when its sales were $30 million and pre-tax earnings were less than $5 million. | E7: 材料/股东信/2007ltr.pdf · Businesses – The Great, the Good and the Gruesome，印刷页7
A8: 1983 | B8: 一家家具店，怎样成为合伙人？ | C8: 买下 90% 股权，家族保留一部分权益并继续经营。 | D8: We purchased 90% of the business - leaving 10% with members of the family who are involved in management - and have optioned 10% to certain key young family managers. | E8: 材料/股东信/1983ltr.html · Nebraska Furniture Mart
A9: 1985 | B9: 起家的纺织业务，还要继续吗？ | C9: 在当年 7 月决定关闭纺织业务。 | D9: In July we decided to close our textile operation, and by yearend this unpleasant job was largely completed. | E9: 材料/股东信/1985ltr.html · Shutdown of Textile Business
A10: 1994 | B10: 一笔消费品投资的下一步 | C10: 在 1994 年完成持续七年的买入，长期保有这份企业权益。 | D10: In August 1994 – yes, 1994 – Berkshire completed its seven-year purchase of the 400 million shares of Coca-Cola we now own. The total cost was $1.3 billion – then a very meaningful sum at Berkshire. | E10: 材料/股东信/2022ltr.pdf · The Secret Sauce，印刷页4
A11: 1995 | B11: 熟悉的保险公司，又一个选择 | C11: 1995 年谈妥交易，1996 年初完成全资收购。 | D11: Right after yearend, we completed the purchase of 100% of GEICO, the seventh largest auto insurer in the United States, with about 3.7 million cars insured. | E11: 材料/股东信/1995ltr.html · GEICO Corporation
A12: 1998 | B12: 再保险，值得做一笔大交易吗？ | C12: 收购 General Re，并保留专业团队的经营自主权。 | D12: On December 21, we completed our $22 billion acquisition of General Re Corp. | E12: 材料/股东信/1998ltr.pdf · General Re，印刷页9
A13: 2008 | B13: 能源繁荣时，怎样面对价格？ | C13: 在油气价格接近高峰时大量买入。 | D13: Without urging from Charlie or anyone else, I bought a large amount of ConocoPhillips stock when oil and gas prices were near their peak. | E13: 材料/股东信/2008ltr.pdf · Investments，印刷页16
A14: 2009 | B14: 在衰退里，如何看待铁路？ | C14: 提出收购方案并明确最高愿付价格，2009 年达成协议。 | D14: On the following day, I again got together with Matt and suggested that Berkshire would offer the railroad a better long-term home than it could expect as a public company. I also told him the maximum price that Berkshire would pay. | E14: 材料/股东信/2021ltr.pdf · BNSF 收购回顾，印刷页11
A15: 2011 | B15: 公司有了钱，回购怎么做？ | C15: 宣布以不超过账面价值 110% 的价格回购，超过上限后停止。 | D15: Last September, we announced that Berkshire would repurchase its shares at a price of up to 110% of book value. We were in the market for only a few days – buying $67 million of stock – before the price advanced beyond our limit. | E15: 材料/股东信/2011ltr.pdf · Share Repurchases，印刷页6
A18: 历史数值 | B18: 指标 | C18: 数值 | D18: 单位 / 注意
A19: 1972 | B19: See’s收购价 | C19: 25 | D19: 百万美元 | E19: 材料/股东信/2007ltr.pdf · Businesses – The Great, the Good and the Gruesome，印刷页7
A20: 1972 | B20: See’s当时销售额 | C20: 30 | D20: 百万美元 | E20: 材料/股东信/2007ltr.pdf · Businesses – The Great, the Good and the Gruesome，印刷页7
A21: 1972 | B21: See’s当时税前利润上限 | C21: 5 | D21: 百万美元；原文为小于，不是等于 | E21: 材料/股东信/2007ltr.pdf · Businesses – The Great, the Good and the Gruesome，印刷页7
A22: 1983 | B22: 收购NFM比例 | C22: 0.9 | D22: 比例 | E22: 材料/股东信/1983ltr.html · Nebraska Furniture Mart
A23: 1983 | B23: 家族保留比例 | C23: 0.1 | D23: 比例；另有10%期权安排 | E23: 材料/股东信/1983ltr.html · Nebraska Furniture Mart
A24: 1994 | B24: Coca-Cola累计成本 | C24: 1300 | D24: 百万美元 | E24: 材料/股东信/2022ltr.pdf · The Secret Sauce，印刷页4
A25: 1994 | B25: Coca-Cola股数（2022回顾口径） | C25: 400000000 | D25: 股；不可当作1994年未复权实际股数 | E25: 材料/股东信/2022ltr.pdf · The Secret Sauce，印刷页4
A26: 1995 | B26: GEICO最终持有比例 | C26: 1 | D26: 比例；1996年初完成 | E26: 材料/股东信/1995ltr.html · GEICO Corporation
A27: 1995 | B27: GEICO承保车辆约数 | C27: 3700000 | D27: 辆 | E27: 材料/股东信/1995ltr.html · GEICO Corporation
A28: 1998 | B28: General Re交易额 | C28: 22000 | D28: 百万美元 | E28: 材料/股东信/1998ltr.pdf · General Re，印刷页9
A29: 2011 | B29: 回购账面价值上限 | C29: 1.1 | D29: 倍；仅为当年历史规则 | E29: 材料/股东信/2011ltr.pdf · Share Repurchases，印刷页6
A30: 2011 | B30: 实际回购金额 | C30: 67 | D30: 百万美元 | E30: 材料/股东信/2011ltr.pdf · Share Repurchases，印刷页6

Sheet 取数索引
A1: 工作表单元格 | B1: 披露值 / 假设值 | C1: 文件名 + 章节 / 补充来源ID | D1: 口径说明
A2: 利润!B6 | B2: 870 | C2: 补充来源 E2：2023ar.pdf｜Item 7 Results of Operations，K-35（ASU 2018-12重述后）
A3: 利润!C6 | B3: -30 | C3: 补充来源 E2：2023ar.pdf｜Item 7 Results of Operations，K-35（ASU 2018-12重述后）
A4: 利润!D6 | B4: 5428 | C4: 材料/Berkshire_2025年报__brka-20251231.htm｜Item 7 Results of Operations，K-34
A5: 利润!E6 | B5: 9020 | C5: 材料/Berkshire_2025年报__brka-20251231.htm｜Item 7 Results of Operations，K-34
A6: 利润!F6 | B6: 7258 | C6: 材料/Berkshire_2025年报__brka-20251231.htm｜Item 7 Results of Operations，K-34
A7: 利润!G6 | B7: 3328 | C7: 材料/Berkshire_2026Q2季报__brka-20260630.htm｜Item 2 Results of Operations，p33
A8: 利润!H6 | B8: 3448 | C8: 材料/Berkshire_2026Q2季报__brka-20260630.htm｜Item 2 Results of Operations，p33
A9: 利润!B7 | B9: 4807 | C9: 补充来源 E2：2023ar.pdf｜Item 7 Results of Operations，K-35（ASU 2018-12重述后）
A10: 利润!C7 | B10: 6484 | C10: 补充来源 E2：2023ar.pdf｜Item 7 Results of Operations，K-35（ASU 2018-12重述后）
A11: 利润!D7 | B11: 9567 | C11: 材料/Berkshire_2025年报__brka-20251231.htm｜Item 7 Results of Operations，K-34
A12: 利润!E7 | B12: 13670 | C12: 材料/Berkshire_2025年报__brka-20251231.htm｜Item 7 Results of Operations，K-34
A13: 利润!F7 | B13: 12513 | C13: 材料/Berkshire_2025年报__brka-20251231.htm｜Item 7 Results of Operations，K-34
... A48: 利润!H14 | B48: 11444 | C48: 材料/Berkshire_2026Q2季报__brka-20260630.htm｜Item 2 Results of Operations，p33
A49: 利润!B15 | B49: 0 | C49: 补充来源 E2：2023ar.pdf｜Item 7 Results of Operations，K-35（ASU 2018-12重述后） | D49: 0表示该独立调整行在当期无披露金额，并非所有资产均无减值。
A50: 利润!C15 | B50: 0 | C50: 补充来源 E2：2023ar.pdf｜Item 7 Results of Operations，K-35（ASU 2018-12重述后） | D50: 0表示该独立调整行在当期无披露金额，并非所有资产均无减值。
A51: 利润!D15 | B51: 0 | C51: 材料/Berkshire_2025年报__brka-20251231.htm｜Item 7 Results of Operations，K-34 | D51: 0表示该独立调整行在当期无披露金额，并非所有资产均无减值。
A52: 利润!E15 | B52: 0 | C52: 材料/Berkshire_2025年报__brka-20251231.htm｜Item 7 Results of Operations，K-34 | D52: 0表示该独立调整行在当期无披露金额，并非所有资产均无减值。
A53: 利润!F15 | B53: -8255 | C53: 材料/Berkshire_2025年报__brka-20251231.htm｜Item 7 Results of Operations，K-34 | D53: 0表示该独立调整行在当期无披露金额，并非所有资产均无减值。
A54: 利润!G15 | B54: -3760 | C54: 材料/Berkshire_2026Q2季报__brka-20260630.htm｜Item 2 Results of Operations，p33 | D54: 0表示该独立调整行在当期无披露金额，并非所有资产均无减值。
A55: 利润!H15 | B55: 0 | C55: 材料/Berkshire_2026Q2季报__brka-20260630.htm｜Item 2 Results of Operations，p33 | D55: 0表示该独立调整行在当期无披露金额，并非所有资产均无减值。
A56: 利润!B17 | B56: 89937 | C56: 补充来源 E2：2023ar.pdf｜Item 7 Results of Operations，K-35（ASU 2018-12重述后）
A57: 利润!C17 | B57: -22759 | C57: 补充来源 E2：2023ar.pdf｜Item 7 Results of Operations，K-35（ASU 2018-12重述后）
A58: 利润!D17 | B58: 96223 | C58: 材料/Berkshire_2025年报__brka-20251231.htm｜Item 7 Results of Operations，K-34
A59: 利润!E17 | B59: 88995 | C59: 材料/Berkshire_2025年报__brka-20251231.htm｜Item 7 Results of Operations，K-34
A60: 利润!F17 | B60: 66968 | C60: 材料/Berkshire_2025年报__brka-20251231.htm｜Item 7 Results of Operations，K-34
A61: 利润!G17 | B61: 16973 | C61: 材料/Berkshire_2026Q2季报__brka-20260630.htm｜Item 2 Results of Operations，p33
A62: 利润!H17 | B62: 35773 | C62: 材料/Berkshire_2026Q2季报__brka-20260630.htm｜Item 2 Results of Operations，p33
A63: 资本!B6 | B63: 147000 | C63: 材料/股东信/2022ltr.pdf｜The Past Year in Brief，印刷页6（2021为147、2022为164十亿美元，约数） | D63: 浮存金为约数，年末176,000采用年报；2026季报称增加约1,100，不能与粗粒度年末数精确相减。
A64: 资本!C6 | B64: 164000 | C64: 材料/股东信/2022ltr.pdf｜The Past Year in Brief，印刷页6（2021为147、2022为164十亿美元，约数） | D64: 浮存金为约数，年末176,000采用年报；2026季报称增加约1,100，不能与粗粒度年末数精确相减。
A65: 资本!D6 | B65: 169000 | C65: 材料/Berkshire_2025年报__brka-20251231.htm｜Item 7 Insurance—Investment Income，K-41 | D65: 浮存金为约数，年末176,000采用年报；2026季报称增加约1,100，不能与粗粒度年末数精确相减。
A66: 资本!E6 | B66: 171000 | C66: 材料/Berkshire_2025年报__brka-20251231.htm｜Item 7 Insurance—Investment Income，K-41 | D66: 浮存金为约数，年末176,000采用年报；2026季报称增加约1,100，不能与粗粒度年末数精确相减。
A67: 资本!F6 | B67: 176000 | C67: 材料/Berkshire_2025年报__brka-20251231.htm｜Item 7 Insurance—Investment Income，K-41 | D67: 浮存金为约数，年末176,000采用年报；2026季报称增加约1,100，不能与粗粒度年末数精确相减。
A68: 资本!G6 | B68: 174000 | C68: 补充来源 E3：2025二季报 2ndqtr25.pdf｜Item 2 Insurance—Investment Income，p35 | D68: 浮存金为约数，年末176,000采用年报；2026季报称增加约1,100，不能与粗粒度年末数精确相减。
A69: 资本!H6 | B69: 177500 | C69: 材料/Berkshire_2026Q2季报__brka-20260630.htm｜Item 2 Insurance—Investment Income，p38 | D69: 浮存金为约数，年末176,000采用年报；2026季报称增加约1,100，不能与粗粒度年末数精确相减。
A70: 资本!B8 | B70: 85319 | C70: 补充来源 E2：2023ar.pdf｜Consolidated Statements of Changes in Shareholders’ Equity，K-73；现金见Cash Flows K-74
A71: 资本!C8 | B71: 32260 | C71: 补充来源 E2：2023ar.pdf｜Consolidated Statements of Changes in Shareholders’ Equity，K-73；现金见Cash Flows K-74
A72: 资本!D8 | B72: 33672 | C72: 补充来源 E2：2023ar.pdf｜Consolidated Balance Sheets，K-70–71
A73: 资本!E8 | B73: 44333 | C73: 材料/Berkshire_2025年报__brka-20251231.htm｜Consolidated Balance Sheets / Statements of Changes in Shareholders’ Equity
A74: 资本!F8 | B74: 47719 | C74: 材料/Berkshire_2025年报__brka-20251231.htm｜Consolidated Balance Sheets / Statements of Changes in Shareholders’ Equity
...
