Workbook

Sheet 说明
B2: AI 的电从哪来 · 数据表
B3: 编制日期：2026-10-22；网页来源访问日期：2026-10-22。研究与展示用途，不构成投资建议。
B5: 用途 | C5: 汇集研究报告与 3D 网页用到的全部数据：每行注明来源名称、发布日期、口径说明与出处定位；汇总与图表全部用公式从明细计算。
B6: 颜色约定
C7: 蓝底：输入——披露数据（原始材料或网页来源），可追溯到“来源清单”。
C8: 橙底：输入——假设（见“假设”页），修改后汇总、图表、网页数据自动重算。
C9: 绿底：公式——本表计算，请勿手工覆盖。
B10: 工作表
C11: 汇总：七个部分的关键结论数字 + 7 张图表（图表数据块也是公式）。
C12: 网页数据：网页第一、二部分出现的所有数字（键值对，公式），据此导出 web/data/web-data.json。
C13: 假设：2030 年情景、2030 年“其他”电源占比、美国 2024 年天然气占比、指引取值位置、每 GW 投资、负荷率、核电容量系数。
C14: D1 数据中心用电｜D2 电源结构（含美国电网）｜D3 科技公司资本开支与电力｜D4 Meta 三季报（原始材料）｜D5 Constellation（原始材料）
C15: D6 购电协议（逐笔）｜D7 聚变｜D8 成本与瓶颈｜D9 托卡马克部件参数与网页卡片文字｜来源清单
B16: 性质分类 | C16: 披露事实 / 官方估计（如 IEA 模型估计的历史数）/ 官方预测 / 公司指引 / 公司目标 / 第三方估计 / 本表计算 / 假设。
B17: 口径提醒 | C17: ① IEA 数据中心“用电量”为设施总用电；“为数据中心供电的发电量”为发电侧口径（含输配损耗），两者不同。
C18: ② 各公司资本开支口径不同：微软含融资租赁（电话会口径），Meta 含融资租赁本金，Alphabet 与亚马逊为购置物业与设备（亚马逊为总额）。
C19: ③ 购电协议容量为合同/公告容量，不等于实际发电量；均未披露电价。先进堆合同多为意向或选择权。
C20: ④ 2030 年电源结构中，可再生、气、核为 IEA 给出的数值，煤电与“其他”依赖“其他占比”假设推算。
B21: 财务数字 | C21: Meta 与 Constellation 的财务数字以 材料/ 目录中的原始 10-Q、10-K 为准（D4、D5）；其他公司来自其官方披露。

Sheet 汇总
A1: 汇总：关键结论数字（全部为公式，从明细页与假设页计算）
A2: 绿底单元格均为公式；修改“假设”页橙色单元格（如 2030 年情景、指引取值位置、每 GW 投资）后自动重算。右侧为图表及其数据块（同样为公式）。
A4: 编号 | B4: 指标 | C4: 数值 | D4: 单位 | E4: 说明 | Q4: 图表数据 1：全球数据中心用电（TWh）
A5: 一、全球数据中心用电（IEA） | Q5: 类别 | R5: 美国 | S5: 中国 | T5: 欧洲 | U5: 其他地区
A6: S-A01 | B6: 2024 年全球数据中心用电量 | C6: ='D1_数据中心用电'!$E$5 -> 415 | D6: TWh | E6: IEA 2025 年版 | Q6: 2024 | R6: ='D1_数据中心用电'!$E$27 -> 183 | S6: ='D1_数据中心用电'!$E$30 -> 102 | T6: ='D1_数据中心用电'!$E$33 -> 68 | U6: ='D1_数据中心用电'!$E$5-'D1_数据中心用电'!$E$27-'D1_数据中心用电'!$E$30-'D1_数据中心用电'!$E$33 -> 62
A7: S-A02 | B7: 2025 年全球数据中心用电量 | C7: ='D1_数据中心用电'!$E$6 -> 485 | D7: TWh | E7: IEA 2026 年更新版 | Q7: 2025 | R7: ='D1_数据中心用电'!$E$28 -> 224 | S7: ='D1_数据中心用电'!$E$31 -> 117 | T7: ='D1_数据中心用电'!$E$34 -> 72 | U7: ='D1_数据中心用电'!$E$6-'D1_数据中心用电'!$E$28-'D1_数据中心用电'!$E$31-'D1_数据中心用电'!$E$34 -> 72
A8: S-A03 | B8: 2030 年全球数据中心用电量（所选情景） | C8: =IF('假设'!$C$5="起飞",'D1_数据中心用电'!$E$9,IF('假设'!$C$5="高效",'D1_数据中心用电'!$E$10,IF('假设'!$C$5="逆风",'D1_数据中心用电'!$E$11,'D1_数据中心用电'!$E$7))) -> 945 | D8: TWh | E8: 情景在“假设”页选择 | Q8: 2030（所选情景） | R8: ='D1_数据中心用电'!$E$29 -> 426 | S8: ='D1_数据中心用电'!$E$32 -> 277 | T8: ='D1_数据中心用电'!$E$35 -> 114 | U8: =$C$8-'D1_数据中心用电'!$E$29-'D1_数据中心用电'!$E$32-'D1_数据中心用电'!$E$35 -> 128
A9: S-A04 | B9: 2030 年全球数据中心用电量（基准情景） | C9: ='D1_数据中心用电'!$E$7 -> 945 | D9: TWh | Q9: 注：2030 年美、中、欧取基准情景，“其他地区”= 所选情景总量 − 三者。
A10: S-A05 | B10: 2035 年全球数据中心用电量（基准情景） | C10: ='D1_数据中心用电'!$E$8 -> 1193 | D10: TWh | E10: 探索性情景
A11: S-A06 | B11: 2025→2030 年均增速（所选情景） | C11: =($C$8/$C$7)^(1/5)-1 -> 0.14271523 | D11: % | E11: 复合年增长率
A12: S-A07 | B12: 2030 年用电量相当于 2024 年的倍数（所选情景） | C12: =$C$8/$C$6 -> 2.2771084 | D12: 倍
A13: S-A08 | B13: 2024 年数据中心占全球电力需求比例 | C13: ='D1_数据中心用电'!$E$5/'D1_数据中心用电'!$E$40 -> 0.015150962 | D13: % | E13: IEA 正文“约 1.5%”
A14: S-A09 | B14: 2025 年数据中心占全球电力需求比例 | C14: ='D1_数据中心用电'!$E$6/'D1_数据中心用电'!$E$41 -> 0.017199191 | D14: % | E14: IEA 正文“略高于 1.5%”（分母口径可能不同）
A15: S-A10 | B15: 2030 年数据中心占全球电力需求比例（所选情景） | C15: =$C$8/'D1_数据中心用电'!$E$42 -> 0.028130023 | D15: % | E15: IEA 正文“约 3%”
A16: S-A11 | B16: 2025–2030 年数据中心占全球新增电力需求比例（所选情景） | C16: =($C$8-'D1_数据中心用电'!$E$6)/('D1_数据中心用电'!$E$42-'D1_数据中心用电'!$E$41) -> 0.085264133 | D16: % | E16: IEA 正文“略低于 10%”
A17: S-A12 | B17: 美国数据中心用电量 2025 | C17: ='D1_数据中心用电'!$E$28 -> 224 | D17: TWh
A18: S-A13 | B18: 美国数据中心用电量 2030（基准） | C18: ='D1_数据中心用电'!$E$29 -> 426 | D18: TWh
A19: S-A14 | B19: 中国数据中心用电量 2025 | C19: ='D1_数据中心用电'!$E$31 -> 117 | D19: TWh
A20: S-A15 | B20: 中国数据中心用电量 2030（基准） | C20: ='D1_数据中心用电'!$E$32 -> 277 | D20: TWh
A21: S-A16 | B21: 欧洲数据中心用电量 2025 | C21: ='D1_数据中心用电'!$E$34 -> 72 | D21: TWh
A22: S-A17 | B22: 欧洲数据中心用电量 2030（基准） | C22: ='D1_数据中心用电'!$E$35 -> 114 | D22: TWh | Q22: 图表数据 2：为数据中心供电的发电量（TWh）
A23: S-A18 | B23: 美国占全球数据中心用电比例 2025 | C23: ='D1_数据中心用电'!$E$28/'D1_数据中心用电'!$E$6 -> 0.46185567 | D23: % | Q23: 类别 | R23: 煤电 | S23: 天然气 | T23: 可再生能源 | U23: 核电 | V23: 其他
A24: S-A19 | B24: 美中两国占 2025–2030 全球增量比例（基准） | C24: =(('D1_数据中心用电'!$E$29-'D1_数据中心用电'!$E$28)+('D1_数据中心用电'!$E$32-'D1_数据中心用电'!$E$31))/('D1_数据中心用电'!$E$7-'D1_数据中心用电'!$E$6) -> 0.78695652 | D24: % | E24: IEA 称“接近 80%” | Q24: 2024 | R24: ='D2_电源结构'!$E$11 -> 138 | S24: ='D2_电源结构'!$E$13 -> 119.6 | T24: ='D2_电源结构'!$E$12 -> 124.2 | U24: ='D2_电源结构'!$E$14 -> 69 | V24: ='D2_电源结构'!$E$15 -> 9.2
A25: S-A20 | B25: 美国数据中心占美国电力需求比例 2025 | C25: ='D1_数据中心用电'!$E$28/'D1_数据中心用电'!$E$44 -> 0.052942567 | D25: % | Q25: 2030（基准，推算） | R25: ='D2_电源结构'!$E$22 -> 210.25641 | S25: ='D2_电源结构'!$E$18 -> 340 | T25: ='D2_电源结构'!$E$17 -> 360 | U25: ='D2_电源结构'!$E$19 -> 120 | V25: ='D2_电源结构'!$E$23 -> 21.025641
A26: S-A21 | B26: 美国数据中心占美国电力需求比例 2030（基准） | C26: ='D1_数据中心用电'!$E$29/'D1_数据中心用电'!$E$45 -> 0.091475199 | D26: %
A27: S-A22 | B27: AI 专用数据中心用电 2025 | C27: ='D1_数据中心用电'!$E$20 -> 155 | D27: TWh | E27: 第三方读取 IEA 数据
A28: S-A23 | B28: AI 专用数据中心用电 2030（基准） | C28: ='D1_数据中心用电'!$E$21 -> 465 | D28: TWh
A29: S-A24 | B29: AI 专用占数据中心用电比例 2030（基准） | C29: ='D1_数据中心用电'!$E$21/'D1_数据中心用电'!$E$7 -> 0.49206349 | D29: %
A30: S-A25 | B30: 2030 年用电量隐含的设施装机（所选情景，按 IEA 2025 年利用率） | C30: =$C$8*1000/('假设'!$C$12*'D1_数据中心用电'!$E$24) -> 224.74315 | D30: GW | E30: IEA 基准情景装机为 226 GW，可对照
A31: S-A26 | B31: AI 专用数据中心用电 2025→2030 增量（基准） | C31: ='D1_数据中心用电'!$E$21-'D1_数据中心用电'!$E$20 -> 310 | D31: TWh
A32: 二、数据中心电源结构（桑基图数据，发电侧口径）
A33: S-B01 | B33: 2024 煤电 | C33: ='D2_电源结构'!$E$11 -> 138 | D33: TWh | E33: 占比 30%
A34: S-B02 | B34: 2024 天然气 | C34: ='D2_电源结构'!$E$13 -> 119.6 | D34: TWh | E34: 占比 26%
A35: S-B03 | B35: 2024 可再生能源 | C35: ='D2_电源结构'!$E$12 -> 124.2 | D35: TWh | E35: 占比 27%
A36: S-B04 | B36: 2024 核电 | C36: ='D2_电源结构'!$E$14 -> 69 | D36: TWh | E36: 占比 15%
A37: S-B05 | B37: 2024 其他 | C37: ='D2_电源结构'!$E$15 -> 9.2 | D37: TWh | E37: 残差
A38: S-B06 | B38: 2024 为数据中心供电的总发电量 | C38: ='D2_电源结构'!$E$5 -> 460 | D38: TWh
A39: S-B07 | B39: 2024 输配损耗等（发电量 − 用电量） | C39: ='D2_电源结构'!$E$16 -> 45 | D39: TWh
A40: S-B11 | B40: 2030 煤电（推算） | C40: ='D2_电源结构'!$E$22 -> 210.25641 | D40: TWh | E40: IEA：约 20% | Q40: 图表数据 3：四大科技公司资本开支（十亿美元）
A41: S-B12 | B41: 2030 天然气 | C41: ='D2_电源结构'!$E$18 -> 340 | D41: TWh | E41: IEA：约 340 | Q41: 类别 | R41: 微软 | S41: Alphabet | T41: 亚马逊 | U41: Meta
...

Sheet 网页数据
A1: 网页数据（网页 3D 场景使用的全部数字，均为公式，引用汇总与明细）
A2: 交付/web/data/web-data.json 由本页导出（脚本读取重算后的数值）；网页上出现的数字都能在这里按“键”找到。
A4: 键 | B4: 数值 | C4: 单位 | D4: 说明
A5: hero.dc2025 | B5: ='D1_数据中心用电'!$E$6 -> 485 | C5: TWh | D5: 2025 年全球数据中心用电
A6: hero.dc2030 | B6: ='D1_数据中心用电'!$E$7 -> 945 | C6: TWh | D6: 2030 年全球数据中心用电（基准情景）
A7: hero.capex2026 | B7: ='汇总'!$C$79 -> 735 | C7: 十亿美元 | D7: 四大科技公司 2026E 资本开支
A8: hero.nucfirm | B8: ='汇总'!$C$117 -> 9976 | C8: MW | D8: 科技公司核电确定购电协议
A9: flow.y2024.src.coal | B9: ='D2_电源结构'!$E$11 -> 138 | C9: TWh
A10: flow.y2024.src.gas | B10: ='D2_电源结构'!$E$13 -> 119.6 | C10: TWh
A11: flow.y2024.src.renew | B11: ='D2_电源结构'!$E$12 -> 124.2 | C11: TWh
A12: flow.y2024.src.nuclear | B12: ='D2_电源结构'!$E$14 -> 69 | C12: TWh
A13: flow.y2024.src.other | B13: ='D2_电源结构'!$E$15 -> 9.2 | C13: TWh
A14: flow.y2024.sink.us | B14: ='D1_数据中心用电'!$E$27 -> 183 | C14: TWh
A15: flow.y2024.sink.cn | B15: ='D1_数据中心用电'!$E$30 -> 102 | C15: TWh
A16: flow.y2024.sink.eu | B16: ='D1_数据中心用电'!$E$33 -> 68 | C16: TWh
A17: flow.y2024.sink.row | B17: ='D1_数据中心用电'!$E$5-'D1_数据中心用电'!$E$27-'D1_数据中心用电'!$E$30-'D1_数据中心用电'!$E$33 -> 62 | C17: TWh
A18: flow.y2024.sink.loss | B18: ='D2_电源结构'!$E$16 -> 45 | C18: TWh
A19: flow.y2024.gen | B19: ='D2_电源结构'!$E$5 -> 460 | C19: TWh
A20: flow.y2024.use | B20: ='D1_数据中心用电'!$E$5 -> 415 | C20: TWh
A21: flow.y2024.share | B21: ='汇总'!$C$13 -> 0.015150962 | C21: %
A22: flow.y2030.src.coal | B22: ='D2_电源结构'!$E$22 -> 210.25641 | C22: TWh
A23: flow.y2030.src.gas | B23: ='D2_电源结构'!$E$18 -> 340 | C23: TWh
A24: flow.y2030.src.renew | B24: ='D2_电源结构'!$E$17 -> 360 | C24: TWh
A25: flow.y2030.src.nuclear | B25: ='D2_电源结构'!$E$19 -> 120 | C25: TWh
A26: flow.y2030.src.other | B26: ='D2_电源结构'!$E$23 -> 21.025641 | C26: TWh
A27: flow.y2030.sink.us | B27: ='D1_数据中心用电'!$E$29 -> 426 | C27: TWh
A28: flow.y2030.sink.cn | B28: ='D1_数据中心用电'!$E$32 -> 277 | C28: TWh
A29: flow.y2030.sink.eu | B29: ='D1_数据中心用电'!$E$35 -> 114 | C29: TWh
A30: flow.y2030.sink.row | B30: ='D1_数据中心用电'!$E$7-'D1_数据中心用电'!$E$29-'D1_数据中心用电'!$E$32-'D1_数据中心用电'!$E$35 -> 128 | C30: TWh
A31: flow.y2030.sink.loss | B31: ='D2_电源结构'!$E$24 -> 106.28205 | C31: TWh
A32: flow.y2030.gen | B32: ='D2_电源结构'!$E$21 -> 1051.2821 | C32: TWh
A33: flow.y2030.use | B33: ='D1_数据中心用电'!$E$7 -> 945 | C33: TWh
A34: flow.y2030.share | B34: ='D1_数据中心用电'!$E$7/'D1_数据中心用电'!$E$42 -> 0.028130023 | C34: %
A35: flow.y2030.renewIncShare | B35: ='汇总'!$C$49 -> 0.39879445 | C35: %
A36: flow.y2030.gasIncShare | B36: ='汇总'!$C$50 -> 0.37274935 | C36: %
A37: flow.y2030.fossilShare | B37: ='汇总'!$C$47 -> 0.52341463 | C37: %
A38: flow.us2024.src.gas | B38: ='汇总'!$C$54 -> 83.165783 | C38: TWh
A39: flow.us2024.src.renew | B39: ='汇总'!$C$55 -> 48.68241 | C39: TWh
A40: flow.us2024.src.coal | B40: ='汇总'!$C$56 -> 40.568675 | C40: TWh
A41: flow.us2024.src.nuclear | B41: ='汇总'!$C$57 -> 30.426506 | C41: TWh
...

Sheet 假设
A1: 假设（橙色单元格可修改，相关结果自动联动）
A2: 这里的数值不是披露事实，而是本研究为计算设定的假设或常数；修改后，汇总、图表与“网页数据”页会自动重算。网页使用的 JSON 由“网页数据”页导出，改动后需重新导出网页数据才会同步到网页。
A4: 键 | B4: 假设项 | C4: 取值 | D4: 单位 | E4: 依据 | F4: 影响的结果
A5: scenario_2030 | B5: 2030 年全球数据中心用电情景（下拉选择） | C5: 基准 | D5: 情景 | E5: IEA 2026 年更新版四种情景：基准 945、起飞 1008、高效 868、逆风 833 TWh（D1 表 DC-03、DC-05～DC-07） | F5: 汇总 A 节 2030 年用电、增速、占比；图表 1
A6: other_share_2030 | B6: 2030 年数据中心供电中“其他”来源占比 | C6: 0.02 | D6: % | E6: IEA 未给出 2030 年“其他”占比；取 2024 年残差约 2%（D2 表 MIX-06） | F6: D2 表 2030 年总发电量、煤电与其他发电量；网页桑基图 2030 年
A7: us_gas_share_2024 | B7: 2024 年美国数据中心供电中天然气占比 | C7: 0.41 | D7: % | E7: IEA 原文“超过 40%”；取 41% 使四类合计约 100% | F7: 美国 2024 年电源结构（网页“美国 2024”视图）
A8: guidance_pos | B8: 资本开支指引在区间内的取值位置（0=下限，0.5=中值，1=上限） | C8: 0.5 | D8: 比例 | E8: 公司只给区间；默认取中值 | F8: Alphabet、Meta 2026 年资本开支；Meta 四季度隐含值
A9: capex_per_gw | B9: 每 GW AI 数据中心的全口径投资（含芯片与设施） | C9: 45 | D9: 十亿美元/GW | E9: 介于 Epoch AI 估计（约 300–380 亿美元/GW，D3 表 PW-13）与星际之门隐含值（约 570 亿美元/GW，PW-14）之间 | F9: 资本开支可支撑的 GW 推算（示意上限）
A10: ai_load_factor | B10: AI 数据中心年平均负荷率 | C10: 0.7 | D10: % | E10: Epoch AI：平均功率通常为装机的 60–80%（第三方估计） | F10: GW → 年用电量 TWh 的换算
A11: nuclear_cf | B11: 核电购电协议的年容量系数 | C11: 0.91 | D11: % | E11: 取 EIA 2025 年美国核电平均容量系数 91%（D2 表 GRID-11） | F11: 购电协议 MW → 年发电量 TWh
A12: hours | B12: 一年小时数 | C12: 8760 | D12: 小时 | E12: 常数 | F12: 所有 MW/GW 与 TWh 的换算

Sheet D1_数据中心用电
A1: D1 数据中心用电：全球、地区、情景与分母（IEA、LBNL、EIA）
A2: 蓝底=输入（披露数据）；橙底=输入（假设）；绿底=公式（本表计算）。“出处定位”给出原始材料的文件与章节，或网页链接；“访问日期”为网页查阅日期。
A4: 编号 | B4: 类别 | C4: 指标 | D4: 主体/地区 | E4: 数值 | F4: 单位 | G4: 期间 | H4: 性质 | I4: 口径说明 | J4: 来源名称 | K4: 发布日期 | L4: 出处定位（文件章节/表名或网页链接） | M4: 访问日期 | N4: 来源编号
A5: DC-01 | B5: 全球用电 | C5: 全球数据中心用电量 | D5: 全球 | E5: 415 | F5: TWh | G5: 2024 | H5: 官方估计 | I5: 含超大规模、托管、企业数据中心；设施总用电（IT×PUE）。IEA 附表 A.1 为 416 | J5: IEA《能源与人工智能》Energy and AI（世界能源展望特别报告） | K5: 2025-04（PDF 元数据 2025-04-11） | L5: https://iea.blob.core.windows.net/assets/b3a8b37f-32d1-4873-9eca-31cec5895264/EnergyandAI.pdf｜PDF 第 14 页执行摘要；附表 A.1 | M5: 2026-10-22 | N5: IEA25
A6: DC-02 | B6: 全球用电 | C6: 全球数据中心用电量 | D6: 全球 | E6: 485 | F6: TWh | G6: 2025 | H6: 官方估计 | I6: 同上口径；2026 年更新版首次给出 2025 年数 | J6: IEA《能源与人工智能关键问题》Key Questions on Energy and AI（2026 年更新版） | K6: 2026-04-16 | L6: https://iea.blob.core.windows.net/assets/3179f7f8-01f6-4dd6-bffa-c9f7b73f1dc9/KeyQuestionsonEnergyandAI.pdf｜PDF 第 10 页执行摘要；PDF 第 108 页表 A.1 | M6: 2026-10-22 | N6: IEA26
A7: DC-03 | B7: 全球用电 | C7: 全球数据中心用电量（基准情景） | D7: 全球 | E7: 945 | F7: TWh | G7: 2030 | H7: 官方预测 | I7: 基准情景；正文写“约 950 TWh”，附表 A.1 为 945 | J7: IEA《能源与人工智能关键问题》Key Questions on Energy and AI（2026 年更新版） | K7: 2026-04-16 | L7: https://iea.blob.core.windows.net/assets/3179f7f8-01f6-4dd6-bffa-c9f7b73f1dc9/KeyQuestionsonEnergyandAI.pdf｜PDF 第 108 页表 A.1（2025 年版附表为 946） | M7: 2026-10-22 | N7: IEA26
A8: DC-04 | B8: 全球用电 | C8: 全球数据中心用电量（基准情景） | D8: 全球 | E8: 1193 | F8: TWh | G8: 2035 | H8: 官方预测 | I8: 2035 年为探索性情景 | J8: IEA《能源与人工智能关键问题》Key Questions on Energy and AI（2026 年更新版） | K8: 2026-04-16 | L8: https://iea.blob.core.windows.net/assets/3179f7f8-01f6-4dd6-bffa-c9f7b73f1dc9/KeyQuestionsonEnergyandAI.pdf｜PDF 第 108 页表 A.1 | M8: 2026-10-22 | N8: IEA26
A9: DC-05 | B9: 全球用电 | C9: 全球数据中心用电量（起飞情景 Lift-Off） | D9: 全球 | E9: 1008 | F9: TWh | G9: 2030 | H9: 官方预测 | I9: AI 需求更快、供应链与电网瓶颈缓解 | J9: IEA《能源与人工智能关键问题》Key Questions on Energy and AI（2026 年更新版） | K9: 2026-04-16 | L9: https://iea.blob.core.windows.net/assets/3179f7f8-01f6-4dd6-bffa-c9f7b73f1dc9/KeyQuestionsonEnergyandAI.pdf｜PDF 第 108 页表 A.1 | M9: 2026-10-22 | N9: IEA26
A10: DC-06 | B10: 全球用电 | C10: 全球数据中心用电量（高效情景 High Efficiency） | D10: 全球 | E10: 868 | F10: TWh | G10: 2030 | H10: 官方预测 | I10: 能效提升更快 | J10: IEA《能源与人工智能关键问题》Key Questions on Energy and AI（2026 年更新版） | K10: 2026-04-16 | L10: https://iea.blob.core.windows.net/assets/3179f7f8-01f6-4dd6-bffa-c9f7b73f1dc9/KeyQuestionsonEnergyandAI.pdf｜PDF 第 108 页表 A.1 | M10: 2026-10-22 | N10: IEA26
A11: DC-07 | B11: 全球用电 | C11: 全球数据中心用电量（逆风情景 Headwinds） | D11: 全球 | E11: 833 | F11: TWh | G11: 2030 | H11: 官方预测 | I11: AI 应用放缓、瓶颈更严重 | J11: IEA《能源与人工智能关键问题》Key Questions on Energy and AI（2026 年更新版） | K11: 2026-04-16 | L11: https://iea.blob.core.windows.net/assets/3179f7f8-01f6-4dd6-bffa-c9f7b73f1dc9/KeyQuestionsonEnergyandAI.pdf｜PDF 第 108 页表 A.1 | M11: 2026-10-22 | N11: IEA26
A12: DC-08 | B12: 全球用电 | C12: 全球数据中心用电量（起飞情景） | D12: 全球 | E12: 1637 | F12: TWh | G12: 2035 | H12: 官方预测 | I12: 探索性情景 | J12: IEA《能源与人工智能关键问题》Key Questions on Energy and AI（2026 年更新版） | K12: 2026-04-16 | L12: https://iea.blob.core.windows.net/assets/3179f7f8-01f6-4dd6-bffa-c9f7b73f1dc9/KeyQuestionsonEnergyandAI.pdf｜PDF 第 108 页表 A.1 | M12: 2026-10-22 | N12: IEA26
A13: DC-09 | B13: 全球用电 | C13: 全球数据中心用电量（高效情景） | D13: 全球 | E13: 1013 | F13: TWh | G13: 2035 | H13: 官方预测 | I13: 探索性情景 | J13: IEA《能源与人工智能关键问题》Key Questions on Energy and AI（2026 年更新版） | K13: 2026-04-16 | L13: https://iea.blob.core.windows.net/assets/3179f7f8-01f6-4dd6-bffa-c9f7b73f1dc9/KeyQuestionsonEnergyandAI.pdf｜PDF 第 108 页表 A.1 | M13: 2026-10-22 | N13: IEA26
A14: DC-10 | B14: 全球用电 | C14: 全球数据中心用电量（逆风情景） | D14: 全球 | E14: 942 | F14: TWh | G14: 2035 | H14: 官方预测 | I14: 探索性情景 | J14: IEA《能源与人工智能关键问题》Key Questions on Energy and AI（2026 年更新版） | K14: 2026-04-16 | L14: https://iea.blob.core.windows.net/assets/3179f7f8-01f6-4dd6-bffa-c9f7b73f1dc9/KeyQuestionsonEnergyandAI.pdf｜PDF 第 108 页表 A.1 | M14: 2026-10-22 | N14: IEA26
A15: DC-11 | B15: 全球用电 | C15: 2025 年版报告给出的 2030 年区间下限（逆风） | D15: 全球 | E15: 669 | F15: TWh | G15: 2030 | H15: 官方预测 | I15: 2025 年版四情景区间 669–1264；2026 年版收窄为 833–1008 | J15: IEA《能源与人工智能》Energy and AI（世界能源展望特别报告） | K15: 2025-04（PDF 元数据 2025-04-11） | L15: https://iea.blob.core.windows.net/assets/b3a8b37f-32d1-4873-9eca-31cec5895264/EnergyandAI.pdf｜附件 A 表 A.1 | M15: 2026-10-22 | N15: IEA25
A16: DC-12 | B16: 全球用电 | C16: 2025 年版报告给出的 2030 年区间上限（起飞） | D16: 全球 | E16: 1264 | F16: TWh | G16: 2030 | H16: 官方预测 | I16: 同上 | J16: IEA《能源与人工智能》Energy and AI（世界能源展望特别报告） | K16: 2025-04（PDF 元数据 2025-04-11） | L16: https://iea.blob.core.windows.net/assets/b3a8b37f-32d1-4873-9eca-31cec5895264/EnergyandAI.pdf｜附件 A 表 A.1 | M16: 2026-10-22 | N16: IEA25
A17: DC-13 | B17: 全球用电 | C17: 全球数据中心用电量 | D17: 全球 | E17: 360 | F17: TWh | G17: 2023 | H17: 官方估计 | I17: 2026 年版附表（2025 年版为 361） | J17: IEA《能源与人工智能关键问题》Key Questions on Energy and AI（2026 年更新版） | K17: 2026-04-16 | L17: https://iea.blob.core.windows.net/assets/3179f7f8-01f6-4dd6-bffa-c9f7b73f1dc9/KeyQuestionsonEnergyandAI.pdf｜PDF 第 108 页表 A.1 | M17: 2026-10-22 | N17: IEA26
A18: DC-14 | B18: 全球用电 | C18: 数据中心用电同比增速 | D18: 全球 | E18: 0.17 | F18: % | G18: 2025 | H18: 官方估计 | J18: IEA《能源与人工智能关键问题》Key Questions on Energy and AI（2026 年更新版） | K18: 2026-04-16 | L18: https://iea.blob.core.windows.net/assets/3179f7f8-01f6-4dd6-bffa-c9f7b73f1dc9/KeyQuestionsonEnergyandAI.pdf｜PDF 第 9 页执行摘要 | M18: 2026-10-22 | N18: IEA26
A19: DC-15 | B19: 全球用电 | C19: AI 专用数据中心用电同比增速 | D19: 全球 | E19: 0.5 | F19: % | G19: 2025 | H19: 官方估计 | I19: AI 专用 = 大量配备专用加速器服务器的数据中心 | J19: IEA《能源与人工智能关键问题》Key Questions on Energy and AI（2026 年更新版） | K19: 2026-04-16 | L19: https://iea.blob.core.windows.net/assets/3179f7f8-01f6-4dd6-bffa-c9f7b73f1dc9/KeyQuestionsonEnergyandAI.pdf｜PDF 第 9–10 页执行摘要 | M19: 2026-10-22 | N19: IEA26
A20: DC-16 | B20: 全球用电 | C20: AI 专用数据中心用电量 | D20: 全球 | E20: 155 | F20: TWh | G20: 2025 | H20: 第三方估计 | I20: OWID 读取 IEA 2026 图表数据所得；约占当年总量三分之一 | J20: Our World in Data：数据中心和人工智能用多少电（图表数据来源 IEA 2026） | K20: 2026-07-20 | L20: https://ourworldindata.org/how-much-energy-do-data-centers-and-artificial-intelligence-use｜图表“数据中心用电：AI 专用 vs 其他” | M20: 2026-10-22 | N20: OWID26
A21: DC-17 | B21: 全球用电 | C21: AI 专用数据中心用电量（基准情景） | D21: 全球 | E21: 465 | F21: TWh | G21: 2030 | H21: 官方预测 | I21: 约为 2030 年数据中心总用电的一半 | J21: IEA《能源与人工智能关键问题》Key Questions on Energy and AI（2026 年更新版） | K21: 2026-04-16 | L21: https://iea.blob.core.windows.net/assets/3179f7f8-01f6-4dd6-bffa-c9f7b73f1dc9/KeyQuestionsonEnergyandAI.pdf｜PDF 第 26 页 | M21: 2026-10-22 | N21: IEA26
A22: DC-18 | B22: 全球用电 | C22: 数据中心装机容量（设施） | D22: 全球 | E22: 114 | F22: GW | G22: 2025 | H22: 官方估计 | I22: 设施总容量 | J22: IEA《能源与人工智能关键问题》Key Questions on Energy and AI（2026 年更新版） | K22: 2026-04-16 | L22: https://iea.blob.core.windows.net/assets/3179f7f8-01f6-4dd6-bffa-c9f7b73f1dc9/KeyQuestionsonEnergyandAI.pdf｜PDF 第 108 页表 A.1 | M22: 2026-10-22 | N22: IEA26
A23: DC-19 | B23: 全球用电 | C23: 数据中心装机容量（设施，基准情景） | D23: 全球 | E23: 226 | F23: GW | G23: 2030 | H23: 官方预测 | J23: IEA《能源与人工智能关键问题》Key Questions on Energy and AI（2026 年更新版） | K23: 2026-04-16 | L23: https://iea.blob.core.windows.net/assets/3179f7f8-01f6-4dd6-bffa-c9f7b73f1dc9/KeyQuestionsonEnergyandAI.pdf｜PDF 第 108 页表 A.1 | M23: 2026-10-22 | N23: IEA26
A24: DC-20 | B24: 全球用电 | C24: 数据中心平均利用率（容量系数） | D24: 全球 | E24: 0.48 | F24: % | G24: 2025 | H24: 官方估计 | I24: 用电量 ÷（装机 × 8760 小时） | J24: IEA《能源与人工智能关键问题》Key Questions on Energy and AI（2026 年更新版） | K24: 2026-04-16 | L24: https://iea.blob.core.windows.net/assets/3179f7f8-01f6-4dd6-bffa-c9f7b73f1dc9/KeyQuestionsonEnergyandAI.pdf｜PDF 第 108 页表 A.1 | M24: 2026-10-22 | N24: IEA26
A25: DC-21 | B25: 全球用电 | C25: 数据中心平均 PUE | D25: 全球 | E25: 1.38 | F25: 倍 | G25: 2025 | H25: 官方估计 | I25: 设施总用电 ÷ IT 用电；2024 年 1.41 | J25: IEA《能源与人工智能关键问题》Key Questions on Energy and AI（2026 年更新版） | K25: 2026-04-16 | L25: https://iea.blob.core.windows.net/assets/3179f7f8-01f6-4dd6-bffa-c9f7b73f1dc9/KeyQuestionsonEnergyandAI.pdf｜PDF 第 108 页表 A.1 | M25: 2026-10-22 | N25: IEA26
A26: DC-22 | B26: 全球用电 | C26: 数据中心平均 PUE（基准情景） | D26: 全球 | E26: 1.29 | F26: 倍 | G26: 2030 | H26: 官方预测 | J26: IEA《能源与人工智能关键问题》Key Questions on Energy and AI（2026 年更新版） | K26: 2026-04-16 | L26: https://iea.blob.core.windows.net/assets/3179f7f8-01f6-4dd6-bffa-c9f7b73f1dc9/KeyQuestionsonEnergyandAI.pdf｜PDF 第 108 页表 A.1 | M26: 2026-10-22 | N26: IEA26
A27: DC-30 | B27: 地区 | C27: 美国数据中心用电量 | D27: 美国 | E27: 183 | F27: TWh | G27: 2024 | H27: 官方估计 | I27: IEA 模型口径（与 LBNL 口径不同） | J27: IEA《能源与人工智能关键问题》Key Questions on Energy and AI（2026 年更新版） | K27: 2026-04-16 | L27: https://iea.blob.core.windows.net/assets/3179f7f8-01f6-4dd6-bffa-c9f7b73f1dc9/KeyQuestionsonEnergyandAI.pdf｜PDF 第 110 页表 A.4 | M27: 2026-10-22 | N27: IEA26
A28: DC-31 | B28: 地区 | C28: 美国数据中心用电量 | D28: 美国 | E28: 224 | F28: TWh | G28: 2025 | H28: 官方估计 | I28: 同上 | J28: IEA《能源与人工智能关键问题》Key Questions on Energy and AI（2026 年更新版） | K28: 2026-04-16 | L28: https://iea.blob.core.windows.net/assets/3179f7f8-01f6-4dd6-bffa-c9f7b73f1dc9/KeyQuestionsonEnergyandAI.pdf｜PDF 第 110 页表 A.4 | M28: 2026-10-22 | N28: IEA26
A29: DC-32 | B29: 地区 | C29: 美国数据中心用电量（基准情景） | D29: 美国 | E29: 426 | F29: TWh | G29: 2030 | H29: 官方预测 | I29: 同上 | J29: IEA《能源与人工智能关键问题》Key Questions on Energy and AI（2026 年更新版） | K29: 2026-04-16 | L29: https://iea.blob.core.windows.net/assets/3179f7f8-01f6-4dd6-bffa-c9f7b73f1dc9/KeyQuestionsonEnergyandAI.pdf｜PDF 第 110 页表 A.4 | M29: 2026-10-22 | N29: IEA26
A30: DC-33 | B30: 地区 | C30: 中国数据中心用电量 | D30: 中国 | E30: 102 | F30: TWh | G30: 2024 | H30: 官方估计 | I30: IEA 模型口径 | J30: IEA《能源与人工智能关键问题》Key Questions on Energy and AI（2026 年更新版） | K30: 2026-04-16 | L30: https://iea.blob.core.windows.net/assets/3179f7f8-01f6-4dd6-bffa-c9f7b73f1dc9/KeyQuestionsonEnergyandAI.pdf｜PDF 第 110 页表 A.4 | M30: 2026-10-22 | N30: IEA26
A31: DC-34 | B31: 地区 | C31: 中国数据中心用电量 | D31: 中国 | E31: 117 | F31: TWh | G31: 2025 | H31: 官方估计 | I31: 同上 | J31: IEA《能源与人工智能关键问题》Key Questions on Energy and AI（2026 年更新版） | K31: 2026-04-16 | L31: https://iea.blob.core.windows.net/assets/3179f7f8-01f6-4dd6-bffa-c9f7b73f1dc9/KeyQuestionsonEnergyandAI.pdf｜PDF 第 110 页表 A.4 | M31: 2026-10-22 | N31: IEA26
A32: DC-35 | B32: 地区 | C32: 中国数据中心用电量（基准情景） | D32: 中国 | E32: 277 | F32: TWh | G32: 2030 | H32: 官方预测 | I32: 同上 | J32: IEA《能源与人工智能关键问题》Key Questions on Energy and AI（2026 年更新版） | K32: 2026-04-16 | L32: https://iea.blob.core.windows.net/assets/3179f7f8-01f6-4dd6-bffa-c9f7b73f1dc9/KeyQuestionsonEnergyandAI.pdf｜PDF 第 110 页表 A.4 | M32: 2026-10-22 | N32: IEA26
A33: DC-36 | B33: 地区 | C33: 欧洲数据中心用电量 | D33: 欧洲 | E33: 68 | F33: TWh | G33: 2024 | H33: 官方估计 | I33: IEA 模型口径 | J33: IEA《能源与人工智能关键问题》Key Questions on Energy and AI（2026 年更新版） | K33: 2026-04-16 | L33: https://iea.blob.core.windows.net/assets/3179f7f8-01f6-4dd6-bffa-c9f7b73f1dc9/KeyQuestionsonEnergyandAI.pdf｜PDF 第 110 页表 A.4 | M33: 2026-10-22 | N33: IEA26
A34: DC-37 | B34: 地区 | C34: 欧洲数据中心用电量 | D34: 欧洲 | E34: 72 | F34: TWh | G34: 2025 | H34: 官方估计 | I34: 同上 | J34: IEA《能源与人工智能关键问题》Key Questions on Energy and AI（2026 年更新版） | K34: 2026-04-16 | L34: https://iea.blob.core.windows.net/assets/3179f7f8-01f6-4dd6-bffa-c9f7b73f1dc9/KeyQuestionsonEnergyandAI.pdf｜PDF 第 110 页表 A.4 | M34: 2026-10-22 | N34: IEA26
A35: DC-38 | B35: 地区 | C35: 欧洲数据中心用电量（基准情景） | D35: 欧洲 | E35: 114 | F35: TWh | G35: 2030 | H35: 官方预测 | I35: 同上（2025 年版为 113） | J35: IEA《能源与人工智能关键问题》Key Questions on Energy and AI（2026 年更新版） | K35: 2026-04-16 | L35: https://iea.blob.core.windows.net/assets/3179f7f8-01f6-4dd6-bffa-c9f7b73f1dc9/KeyQuestionsonEnergyandAI.pdf｜PDF 第 110 页表 A.4 | M35: 2026-10-22 | N35: IEA26
A36: DC-46 | B36: 地区 | C36: 美国数据中心用电量 | D36: 美国 | E36: 154 | F36: TWh | G36: 2023 | H36: 官方估计 | I36: IEA 模型口径（LBNL 同年估计为 176） | J36: IEA《能源与人工智能关键问题》Key Questions on Energy and AI（2026 年更新版） | K36: 2026-04-16 | L36: https://iea.blob.core.windows.net/assets/3179f7f8-01f6-4dd6-bffa-c9f7b73f1dc9/KeyQuestionsonEnergyandAI.pdf｜PDF 第 110 页表 A.4 | M36: 2026-10-22 | N36: IEA26
A37: DC-47 | B37: 地区 | C37: 中国数据中心用电量 | D37: 中国 | E37: 84 | F37: TWh | G37: 2023 | H37: 官方估计 | I37: IEA 模型口径 | J37: IEA《能源与人工智能关键问题》Key Questions on Energy and AI（2026 年更新版） | K37: 2026-04-16 | L37: https://iea.blob.core.windows.net/assets/3179f7f8-01f6-4dd6-bffa-c9f7b73f1dc9/KeyQuestionsonEnergyandAI.pdf｜PDF 第 110 页表 A.4 | M37: 2026-10-22 | N37: IEA26
A38: DC-48 | B38: 地区 | C38: 欧洲数据中心用电量 | D38: 欧洲 | E38: 66 | F38: TWh | G38: 2023 | H38: 官方估计 | I38: IEA 模型口径 | J38: IEA《能源与人工智能关键问题》Key Questions on Energy and AI（2026 年更新版） | K38: 2026-04-16 | L38: https://iea.blob.core.windows.net/assets/3179f7f8-01f6-4dd6-bffa-c9f7b73f1dc9/KeyQuestionsonEnergyandAI.pdf｜PDF 第 110 页表 A.4 | M38: 2026-10-22 | N38: IEA26
... A52: DC-61 | B52: 科技公司 | C52: 大型科技公司资本开支 | D52: 五家公司 | E52: 400 | F52: 十亿美元 | G52: 2025 | H52: 官方估计 | I52: IEA 原文“超过 4000 亿美元” | J52: IEA《能源与人工智能关键问题》Key Questions on Energy and AI（2026 年更新版） | K52: 2026-04-16 | L52: https://iea.blob.core.windows.net/assets/3179f7f8-01f6-4dd6-bffa-c9f7b73f1dc9/KeyQuestionsonEnergyandAI.pdf｜PDF 第 9 页执行摘要 | M52: 2026-10-22 | N52: IEA26
A53: DC-62 | B53: 科技公司 | C53: 大型科技公司资本开支 2026 年预期增幅 | D53: 五家公司 | E53: 0.75 | F53: % | G53: 2026 | H53: 官方预测 | J53: IEA《能源与人工智能关键问题》Key Questions on Energy and AI（2026 年更新版） | K53: 2026-04-16 | L53: https://iea.blob.core.windows.net/assets/3179f7f8-01f6-4dd6-bffa-c9f7b73f1dc9/KeyQuestionsonEnergyandAI.pdf｜PDF 第 9 页执行摘要 | M53: 2026-10-22 | N53: IEA26
A54: DC-63 | B54: 供给 | C54: 计划作为数据中心专用电源的新增燃气装机 | D54: 全球（主要在美国） | E54: 100 | F54: GW | G54: 2026 | H54: 官方估计 | I54: 原文“超过 100 GW”，以现场发电为主 | J54: IEA《能源与人工智能关键问题》Key Questions on Energy and AI（2026 年更新版） | K54: 2026-04-16 | L54: https://iea.blob.core.windows.net/assets/3179f7f8-01f6-4dd6-bffa-c9f7b73f1dc9/KeyQuestionsonEnergyandAI.pdf｜PDF 第 49 页 §5.2 | M54: 2026-10-22 | N54: IEA26
...

Sheet D2_电源结构
A1: D2 数据中心电源结构与美国电网结构（IEA、EIA；含本表计算的桑基图数值）
A2: 蓝底=输入（披露数据）；橙底=输入（假设）；绿底=公式（本表计算）。“出处定位”给出原始材料的文件与章节，或网页链接；“访问日期”为网页查阅日期。
A4: 编号 | B4: 类别 | C4: 指标 | D4: 主体/地区 | E4: 数值 | F4: 单位 | G4: 期间 | H4: 性质 | I4: 口径说明 | J4: 来源名称 | K4: 发布日期 | L4: 出处定位（文件章节/表名或网页链接） | M4: 访问日期 | N4: 来源编号
A5: MIX-01 | B5: 全球 2024 | C5: 为数据中心供电的发电量 | D5: 全球 | E5: 460 | F5: TWh | G5: 2024 | H5: 官方估计 | I5: 发电侧口径，含输配损耗，大于用电量 415 | J5: IEA《能源与人工智能》Energy and AI（世界能源展望特别报告） | K5: 2025-04（PDF 元数据 2025-04-11） | L5: https://iea.blob.core.windows.net/assets/b3a8b37f-32d1-4873-9eca-31cec5895264/EnergyandAI.pdf｜PDF 第 86 页 §2.5.3 | M5: 2026-10-22 | N5: IEA25
A6: MIX-02 | B6: 全球 2024 | C6: 煤电占比 | D6: 全球 | E6: 0.3 | F6: % | G6: 2024 | H6: 官方估计 | I6: 原文“约 30%”，中国占比最高 | J6: IEA《能源与人工智能》Energy and AI（世界能源展望特别报告） | K6: 2025-04（PDF 元数据 2025-04-11） | L6: https://iea.blob.core.windows.net/assets/b3a8b37f-32d1-4873-9eca-31cec5895264/EnergyandAI.pdf｜PDF 第 86 页 | M6: 2026-10-22 | N6: IEA25
A7: MIX-03 | B7: 全球 2024 | C7: 可再生能源占比 | D7: 全球 | E7: 0.27 | F7: % | G7: 2024 | H7: 官方估计 | I7: 风电、光伏、水电为主 | J7: IEA《能源与人工智能》Energy and AI（世界能源展望特别报告） | K7: 2025-04（PDF 元数据 2025-04-11） | L7: https://iea.blob.core.windows.net/assets/b3a8b37f-32d1-4873-9eca-31cec5895264/EnergyandAI.pdf｜PDF 第 86 页 | M7: 2026-10-22 | N7: IEA25
A8: MIX-04 | B8: 全球 2024 | C8: 天然气发电占比 | D8: 全球 | E8: 0.26 | F8: % | G8: 2024 | H8: 官方估计 | J8: IEA《能源与人工智能》Energy and AI（世界能源展望特别报告） | K8: 2025-04（PDF 元数据 2025-04-11） | L8: https://iea.blob.core.windows.net/assets/b3a8b37f-32d1-4873-9eca-31cec5895264/EnergyandAI.pdf｜PDF 第 86 页 | M8: 2026-10-22 | N8: IEA25
A9: MIX-05 | B9: 全球 2024 | C9: 核电占比 | D9: 全球 | E9: 0.15 | F9: % | G9: 2024 | H9: 官方估计 | J9: IEA《能源与人工智能》Energy and AI（世界能源展望特别报告） | K9: 2025-04（PDF 元数据 2025-04-11） | L9: https://iea.blob.core.windows.net/assets/b3a8b37f-32d1-4873-9eca-31cec5895264/EnergyandAI.pdf｜PDF 第 86 页 | M9: 2026-10-22 | N9: IEA25
A10: MIX-06 | B10: 全球 2024 | C10: 其他（残差）占比 | D10: 全球 | E10: =1-$E$6-$E$7-$E$8-$E$9 -> 0.02 | F10: % | G10: 2024 | H10: 本表计算 | I10: 100% 减去上述四项 | J10: 本表计算（公式见单元格） | K10: 2026-10-22 | M10: — | N10: CALC
A11: MIX-07 | B11: 全球 2024 | C11: 煤电供数据中心发电量 | D11: 全球 | E11: =$E$5*$E$6 -> 138 | F11: TWh | G11: 2024 | H11: 本表计算 | I11: 占比 × 460 | J11: 本表计算（公式见单元格） | K11: 2026-10-22 | M11: — | N11: CALC
A12: MIX-08 | B12: 全球 2024 | C12: 可再生能源供数据中心发电量 | D12: 全球 | E12: =$E$5*$E$7 -> 124.2 | F12: TWh | G12: 2024 | H12: 本表计算 | I12: 占比 × 460 | J12: 本表计算（公式见单元格） | K12: 2026-10-22 | M12: — | N12: CALC
A13: MIX-09 | B13: 全球 2024 | C13: 天然气供数据中心发电量 | D13: 全球 | E13: =$E$5*$E$8 -> 119.6 | F13: TWh | G13: 2024 | H13: 本表计算 | I13: 占比 × 460 | J13: 本表计算（公式见单元格） | K13: 2026-10-22 | M13: — | N13: CALC
A14: MIX-10 | B14: 全球 2024 | C14: 核电供数据中心发电量 | D14: 全球 | E14: =$E$5*$E$9 -> 69 | F14: TWh | G14: 2024 | H14: 本表计算 | I14: 占比 × 460 | J14: 本表计算（公式见单元格） | K14: 2026-10-22 | M14: — | N14: CALC
A15: MIX-11 | B15: 全球 2024 | C15: 其他供数据中心发电量 | D15: 全球 | E15: =$E$5*$E$10 -> 9.2 | F15: TWh | G15: 2024 | H15: 本表计算 | I15: 占比 × 460 | J15: 本表计算（公式见单元格） | K15: 2026-10-22 | M15: — | N15: CALC
A16: MIX-12 | B16: 全球 2024 | C16: 输配损耗等（发电量 − 用电量） | D16: 全球 | E16: =$E$5-'D1_数据中心用电'!$E$5 -> 45 | F16: TWh | G16: 2024 | H16: 本表计算 | I16: 460 − 415 | J16: 本表计算（公式见单元格） | K16: 2026-10-22 | M16: — | N16: CALC
A17: MIX-20 | B17: 全球 2030 | C17: 可再生能源供数据中心发电量（基准情景） | D17: 全球 | E17: 360 | F17: TWh | G17: 2030 | H17: 官方预测 | I17: 原文：较当前增加 200 TWh 以上，2030 年达 360 TWh，超过总发电量三分之一 | J17: IEA《能源与人工智能关键问题》Key Questions on Energy and AI（2026 年更新版） | K17: 2026-04-16 | L17: https://iea.blob.core.windows.net/assets/3179f7f8-01f6-4dd6-bffa-c9f7b73f1dc9/KeyQuestionsonEnergyandAI.pdf｜PDF 第 49 页 §5.3 | M17: 2026-10-22 | N17: IEA26
A18: MIX-21 | B18: 全球 2030 | C18: 天然气供数据中心发电量（基准情景） | D18: 全球 | E18: 340 | F18: TWh | G18: 2030 | H18: 官方预测 | I18: 原文“约 340 TWh”，占比约 30% | J18: IEA《能源与人工智能关键问题》Key Questions on Energy and AI（2026 年更新版） | K18: 2026-04-16 | L18: https://iea.blob.core.windows.net/assets/3179f7f8-01f6-4dd6-bffa-c9f7b73f1dc9/KeyQuestionsonEnergyandAI.pdf｜PDF 第 50 页 §5.3 | M18: 2026-10-22 | N18: IEA26
A19: MIX-22 | B19: 全球 2030 | C19: 核电供数据中心发电量（基准情景） | D19: 全球 | E19: 120 | F19: TWh | G19: 2030 | H19: 官方预测 | I19: 原文“接近 120 TWh”，2025 年约 75 TWh | J19: IEA《能源与人工智能关键问题》Key Questions on Energy and AI（2026 年更新版） | K19: 2026-04-16 | L19: https://iea.blob.core.windows.net/assets/3179f7f8-01f6-4dd6-bffa-c9f7b73f1dc9/KeyQuestionsonEnergyandAI.pdf｜PDF 第 50 页 §5.3 | M19: 2026-10-22 | N19: IEA26
A20: MIX-23 | B20: 全球 2030 | C20: 煤电占数据中心供电比例（基准情景） | D20: 全球 | E20: 0.2 | F20: % | G20: 2030 | H20: 官方预测 | I20: 原文“约 20%”，主要在中国 | J20: IEA《能源与人工智能关键问题》Key Questions on Energy and AI（2026 年更新版） | K20: 2026-04-16 | L20: https://iea.blob.core.windows.net/assets/3179f7f8-01f6-4dd6-bffa-c9f7b73f1dc9/KeyQuestionsonEnergyandAI.pdf｜PDF 第 50 页 §5.3 | M20: 2026-10-22 | N20: IEA26
A21: MIX-24 | B21: 全球 2030 | C21: 为数据中心供电的总发电量（推算） | D21: 全球 | E21: =($E$17+$E$18+$E$19)/(1-$E$20-'假设'!$C$6) -> 1051.2821 | F21: TWh | G21: 2030 | H21: 本表计算 | I21: IEA 只说“超过 1000 TWh”；用 (可再生+气+核)÷(1−煤占比−其他占比) 推算，其他占比为假设 | J21: 本表计算（公式见单元格） | K21: 2026-10-22 | M21: — | N21: CALC
A22: MIX-25 | B22: 全球 2030 | C22: 煤电供数据中心发电量（推算） | D22: 全球 | E22: =$E$21*$E$20 -> 210.25641 | F22: TWh | G22: 2030 | H22: 本表计算 | I22: 总发电量 × 20% | J22: 本表计算（公式见单元格） | K22: 2026-10-22 | M22: — | N22: CALC
A23: MIX-26 | B23: 全球 2030 | C23: 其他供数据中心发电量（推算） | D23: 全球 | E23: =$E$21*'假设'!$C$6 -> 21.025641 | F23: TWh | G23: 2030 | H23: 本表计算 | I23: 总发电量 × 假设占比 | J23: 本表计算（公式见单元格） | K23: 2026-10-22 | M23: — | N23: CALC
A24: MIX-27 | B24: 全球 2030 | C24: 输配损耗等（发电量 − 用电量） | D24: 全球 | E24: =$E$21-'D1_数据中心用电'!$E$7 -> 106.28205 | F24: TWh | G24: 2030 | H24: 本表计算 | I24: 推算发电量 − 945 | J24: 本表计算（公式见单元格） | K24: 2026-10-22 | M24: — | N24: CALC
A25: MIX-28 | B25: 全球 2025 | C25: 核电供数据中心发电量 | D25: 全球 | E25: 75 | F25: TWh | G25: 2025 | H25: 官方估计 | I25: 原文“约 75 TWh” | J25: IEA《能源与人工智能关键问题》Key Questions on Energy and AI（2026 年更新版） | K25: 2026-04-16 | L25: https://iea.blob.core.windows.net/assets/3179f7f8-01f6-4dd6-bffa-c9f7b73f1dc9/KeyQuestionsonEnergyandAI.pdf｜PDF 第 50 页 §5.3 | M25: 2026-10-22 | N25: IEA26
A26: MIX-30 | B26: 美国 2024 | C26: 天然气占美国数据中心供电比例 | D26: 美国 | E26: ='假设'!$C$7 -> 0.41 | F26: % | G26: 2024 | H26: 假设 | I26: IEA 原文“超过 40%”，取假设值使四项合计约 100% | J26: 本研究假设（见“假设”工作表） | K26: 2026-10-22 | L26: “假设”页 | M26: — | N26: ASSUME
A27: MIX-31 | B27: 美国 2024 | C27: 可再生能源占比 | D27: 美国 | E27: 0.24 | F27: % | G27: 2024 | H27: 官方估计 | I27: 主要为光伏和风电 | J27: IEA《能源与人工智能》Energy and AI（世界能源展望特别报告） | K27: 2025-04（PDF 元数据 2025-04-11） | L27: https://iea.blob.core.windows.net/assets/b3a8b37f-32d1-4873-9eca-31cec5895264/EnergyandAI.pdf｜PDF 第 87 页 | M27: 2026-10-22 | N27: IEA25
A28: MIX-32 | B28: 美国 2024 | C28: 煤电占比 | D28: 美国 | E28: 0.2 | F28: % | G28: 2024 | H28: 官方估计 | I28: 原文“约 20%” | J28: IEA《能源与人工智能》Energy and AI（世界能源展望特别报告） | K28: 2025-04（PDF 元数据 2025-04-11） | L28: https://iea.blob.core.windows.net/assets/b3a8b37f-32d1-4873-9eca-31cec5895264/EnergyandAI.pdf｜PDF 第 87 页 | M28: 2026-10-22 | N28: IEA25
A29: MIX-33 | B29: 美国 2024 | C29: 核电占比 | D29: 美国 | E29: 0.15 | F29: % | G29: 2024 | H29: 官方估计 | I29: 原文“接近 15%” | J29: IEA《能源与人工智能》Energy and AI（世界能源展望特别报告） | K29: 2025-04（PDF 元数据 2025-04-11） | L29: https://iea.blob.core.windows.net/assets/b3a8b37f-32d1-4873-9eca-31cec5895264/EnergyandAI.pdf｜PDF 第 87 页 | M29: 2026-10-22 | N29: IEA25
A30: MIX-34 | B30: 美国 2024 | C30: 发电量/用电量系数（借用全球 2024） | D30: 美国 | E30: =$E$5/'D1_数据中心用电'!$E$5 -> 1.1084337 | F30: 倍 | G30: 2024 | H30: 本表计算 | I30: 美国未单独披露，借用全球 460÷415 | J30: 本表计算（公式见单元格） | K30: 2026-10-22 | M30: — | N30: CALC
A31: MIX-35 | B31: 美国 2024 | C31: 为美国数据中心供电的发电量（推算） | D31: 美国 | E31: ='D1_数据中心用电'!$E$27*$E$30 -> 202.84337 | F31: TWh | G31: 2024 | H31: 本表计算 | I31: 183 × 系数 | J31: 本表计算（公式见单元格） | K31: 2026-10-22 | M31: — | N31: CALC
A32: MIX-40 | B32: 中国 2024 | C32: 煤电占中国数据中心供电比例 | D32: 中国 | E32: 0.7 | F32: % | G32: 2024 | H32: 官方估计 | I32: 原文“约 70%”，数据中心多在东部 | J32: IEA《能源与人工智能》Energy and AI（世界能源展望特别报告） | K32: 2025-04（PDF 元数据 2025-04-11） | L32: https://iea.blob.core.windows.net/assets/b3a8b37f-32d1-4873-9eca-31cec5895264/EnergyandAI.pdf｜PDF 第 88 页 | M32: 2026-10-22 | N32: IEA25
A33: MIX-41 | B33: 中国 2024 | C33: 可再生能源占比 | D33: 中国 | E33: 0.2 | F33: % | G33: 2024 | H33: 官方估计 | I33: 原文“接近 20%” | J33: IEA《能源与人工智能》Energy and AI（世界能源展望特别报告） | K33: 2025-04（PDF 元数据 2025-04-11） | L33: https://iea.blob.core.windows.net/assets/b3a8b37f-32d1-4873-9eca-31cec5895264/EnergyandAI.pdf｜PDF 第 88 页 | M33: 2026-10-22 | N33: IEA25
A34: MIX-42 | B34: 中国 2024 | C34: 核电占比 | D34: 中国 | E34: 0.1 | F34: % | G34: 2024 | H34: 官方估计 | I34: 原文“接近 10%”，其余为天然气 | J34: IEA《能源与人工智能》Energy and AI（世界能源展望特别报告） | K34: 2025-04（PDF 元数据 2025-04-11） | L34: https://iea.blob.core.windows.net/assets/b3a8b37f-32d1-4873-9eca-31cec5895264/EnergyandAI.pdf｜PDF 第 88 页 | M34: 2026-10-22 | N34: IEA25
A35: MIX-50 | B35: 结论 | C35: 2024–2030 年可再生能源满足的数据中心新增需求比例 | D35: 全球 | E35: 0.5 | F35: % | G35: 2024–2030 | H35: 官方预测 | I35: 原文“接近一半” | J35: IEA《能源与人工智能》Energy and AI（世界能源展望特别报告） | K35: 2025-04（PDF 元数据 2025-04-11） | L35: https://iea.blob.core.windows.net/assets/b3a8b37f-32d1-4873-9eca-31cec5895264/EnergyandAI.pdf｜PDF 第 86 页图 2.20 说明 | M35: 2026-10-22 | N35: IEA25
A36: MIX-51 | B36: 结论 | C36: 2024–2030 年天然气与煤电合计满足的新增需求比例 | D36: 全球 | E36: 0.4 | F36: % | G36: 2024–2030 | H36: 官方预测 | I36: 原文“超过 40%” | J36: IEA《能源与人工智能》Energy and AI（世界能源展望特别报告） | K36: 2025-04（PDF 元数据 2025-04-11） | L36: https://iea.blob.core.windows.net/assets/b3a8b37f-32d1-4873-9eca-31cec5895264/EnergyandAI.pdf｜PDF 第 86 页 | M36: 2026-10-22 | N36: IEA25
A37: MIX-52 | B37: 结论 | C37: 2024–2035 年为数据中心新增的天然气发电量 | D37: 全球（主要在美国） | E37: 175 | F37: TWh | G37: 2024–2035 | H37: 官方预测 | I37: 起飞情景 +290 TWh | J37: IEA《能源与人工智能》Energy and AI（世界能源展望特别报告） | K37: 2025-04（PDF 元数据 2025-04-11） | L37: https://iea.blob.core.windows.net/assets/b3a8b37f-32d1-4873-9eca-31cec5895264/EnergyandAI.pdf｜PDF 第 49 页（执行摘要） | M37: 2026-10-22 | N37: IEA25
A38: MIX-53 | B38: 结论 | C38: 2024–2030 年美国为数据中心新增的天然气发电量 | D38: 美国 | E38: 130 | F38: TWh | G38: 2024–2030 | H38: 官方预测 | I38: 原文“超过 130 TWh”；可再生能源 +110 TWh | J38: IEA《能源与人工智能》Energy and AI（世界能源展望特别报告） | K38: 2025-04（PDF 元数据 2025-04-11） | L38: https://iea.blob.core.windows.net/assets/b3a8b37f-32d1-4873-9eca-31cec5895264/EnergyandAI.pdf｜PDF 第 87 页 | M38: 2026-10-22 | N38: IEA25
A39: GRID-01 | B39: 美国电网 2025 | C39: 美国公用事业级总发电量 | D39: 美国 | E39: 4429.5 | F39: TWh | G39: 2025 | H39: 披露事实 | I39: 公用事业级，不含小型分布式光伏 | J39: EIA《电力月报》表 1.1 分能源净发电量 | K39: 2026-09-24 | L39: https://www.eia.gov/electricity/monthly/epm_table_grapher.php?t=epmt_1_01｜表 1.1 | M39: 2026-10-22 | N39: EIA_EPM11
A40: GRID-02 | B40: 美国电网 2025 | C40: 天然气发电量 | D40: 美国 | E40: 1807.3 | F40: TWh | G40: 2025 | H40: 披露事实 | J40: EIA《电力月报》表 1.1 分能源净发电量 | K40: 2026-09-24 | L40: https://www.eia.gov/electricity/monthly/epm_table_grapher.php?t=epmt_1_01｜表 1.1 | M40: 2026-10-22 | N40: EIA_EPM11
A41: GRID-03 | B41: 美国电网 2025 | C41: 核电发电量 | D41: 美国 | E41: 784.8 | F41: TWh | G41: 2025 | H41: 披露事实 | J41: EIA《电力月报》表 1.1 分能源净发电量 | K41: 2026-09-24 | L41: https://www.eia.gov/electricity/monthly/epm_table_grapher.php?t=epmt_1_01｜表 1.1 | M41: 2026-10-22 | N41: EIA_EPM11
...

Sheet D3_科技公司资本开支
A1: D3 美国科技巨头资本开支、指引与电力相关披露（各公司财报、电话会及官网）
A2: 蓝底=输入（披露数据）；橙底=输入（假设）；绿底=公式（本表计算）。“出处定位”给出原始材料的文件与章节，或网页链接；“访问日期”为网页查阅日期。
A4: 编号 | B4: 类别 | C4: 指标 | D4: 主体/地区 | E4: 数值 | F4: 单位 | G4: 期间 | H4: 性质 | I4: 口径说明 | J4: 来源名称 | K4: 发布日期 | L4: 出处定位（文件章节/表名或网页链接） | M4: 访问日期 | N4: 来源编号
A5: CQ-MS-24Q1 | B5: 季度资本开支 | C5: 微软资本开支 | D5: 微软 | E5: 14 | F5: 十亿美元 | G5: 2024Q1（FY24 Q3） | H5: 披露事实 | I5: 微软口径：含融资租赁的资本开支（电话会口径） | J5: 微软 FY24 Q3 业绩电话会（投资者关系页） | K5: 2024-04-25 | L5: https://www.microsoft.com/en-us/investor/events/fy-2024/earnings-fy-2024-q3｜CFO 发言 | M5: 2026-10-22 | N5: MSFT24Q3
A6: CQ-MS-24Q2 | B6: 季度资本开支 | C6: 微软资本开支 | D6: 微软 | E6: 19 | F6: 十亿美元 | G6: 2024Q2（FY24 Q4） | H6: 披露事实 | I6: 微软口径：含融资租赁的资本开支（电话会口径） | J6: 微软 FY24 Q4 业绩电话会 | K6: 2024-07-30 | L6: https://www.microsoft.com/en-us/investor/events/fy-2024/earnings-fy-2024-q4｜CFO 发言 | M6: 2026-10-22 | N6: MSFT24Q4
A7: CQ-MS-24Q3 | B7: 季度资本开支 | C7: 微软资本开支 | D7: 微软 | E7: 20 | F7: 十亿美元 | G7: 2024Q3（FY25 Q1） | H7: 披露事实 | I7: 微软口径：含融资租赁的资本开支（电话会口径） | J7: 微软 FY25 Q1 业绩电话会 | K7: 2024-10-30 | L7: https://www.microsoft.com/en-us/investor/events/fy-2025/earnings-fy-2025-q1｜CFO 发言 | M7: 2026-10-22 | N7: MSFT25Q1
A8: CQ-MS-24Q4 | B8: 季度资本开支 | C8: 微软资本开支 | D8: 微软 | E8: 22.6 | F8: 十亿美元 | G8: 2024Q4（FY25 Q2） | H8: 披露事实 | I8: 微软口径：含融资租赁的资本开支（电话会口径） | J8: 微软 FY25 Q2 业绩电话会 | K8: 2025-01-29 | L8: https://www.microsoft.com/en-us/investor/events/fy-2025/earnings-fy-2025-q2｜CFO 发言 | M8: 2026-10-22 | N8: MSFT25Q2
A9: CQ-MS-25Q1 | B9: 季度资本开支 | C9: 微软资本开支 | D9: 微软 | E9: 21.4 | F9: 十亿美元 | G9: 2025Q1（FY25 Q3） | H9: 披露事实 | I9: 微软口径：含融资租赁的资本开支（电话会口径） | J9: 微软 FY25 Q3 业绩电话会 | K9: 2025-04-30 | L9: https://www.microsoft.com/en-us/investor/events/fy-2025/earnings-fy-2025-q3｜CFO 发言 | M9: 2026-10-22 | N9: MSFT25Q3
A10: CQ-MS-25Q2 | B10: 季度资本开支 | C10: 微软资本开支 | D10: 微软 | E10: 24.2 | F10: 十亿美元 | G10: 2025Q2（FY25 Q4） | H10: 披露事实 | I10: 微软口径：含融资租赁的资本开支（电话会口径）；含融资租赁 65 亿 | J10: 微软 FY25 Q4 业绩电话会 | K10: 2025-07-30 | L10: https://www.microsoft.com/en-us/investor/events/fy-2025/earnings-fy-2025-q4｜CFO 发言 | M10: 2026-10-22 | N10: MSFT25Q4
A11: CQ-MS-25Q3 | B11: 季度资本开支 | C11: 微软资本开支 | D11: 微软 | E11: 34.9 | F11: 十亿美元 | G11: 2025Q3（FY26 Q1） | H11: 披露事实 | I11: 微软口径：含融资租赁的资本开支（电话会口径）；含融资租赁 111 亿 | J11: 微软 FY26 Q1 业绩电话会 | K11: 2025-10-29 | L11: https://www.microsoft.com/en-us/investor/events/fy-2026/earnings-fy-2026-q1｜CFO 发言 | M11: 2026-10-22 | N11: MSFT26Q1
A12: CQ-MS-25Q4 | B12: 季度资本开支 | C12: 微软资本开支 | D12: 微软 | E12: 37.5 | F12: 十亿美元 | G12: 2025Q4（FY26 Q2） | H12: 披露事实 | I12: 微软口径：含融资租赁的资本开支（电话会口径）；含融资租赁 67 亿 | J12: 微软 FY26 Q2 业绩电话会 | K12: 2026-01-28 | L12: https://www.microsoft.com/en-us/investor/events/fy-2026/earnings-fy-2026-q2｜CFO 发言 | M12: 2026-10-22 | N12: MSFT26Q2
A13: CQ-MS-26Q1 | B13: 季度资本开支 | C13: 微软资本开支 | D13: 微软 | E13: 31.9 | F13: 十亿美元 | G13: 2026Q1（FY26 Q3） | H13: 披露事实 | I13: 微软口径：含融资租赁的资本开支（电话会口径）；含融资租赁 47 亿 | J13: 微软 FY26 Q3 业绩电话会 | K13: 2026-04-29 | L13: https://www.microsoft.com/en-us/investor/events/fy-2026/earnings-fy-2026-q3｜CFO 发言 | M13: 2026-10-22 | N13: MSFT26Q3
A14: CQ-MS-26Q2 | B14: 季度资本开支 | C14: 微软资本开支 | D14: 微软 | E14: 41 | F14: 十亿美元 | G14: 2026Q2（FY26 Q4） | H14: 披露事实 | I14: 微软口径：含融资租赁的资本开支（电话会口径）；含融资租赁 56 亿；含元器件涨价影响 | J14: 微软 FY26 Q4 业绩电话会 | K14: 2026-07-29 | L14: https://www.microsoft.com/en-us/investor/events/fy-2026/earnings-fy-2026-q4｜CFO 发言 | M14: 2026-10-22 | N14: MSFT26Q4
A15: CY-GO-2024 | B15: 年度资本开支 | C15: Alphabet 资本开支 | D15: Alphabet | E15: 52.535 | F15: 十亿美元 | G15: 2024 | H15: 披露事实 | I15: Alphabet 口径：购置物业与设备（现金流量表） | J15: Alphabet 2025 年四季度及全年业绩（8-K 附件 99.1） | K15: 2026-02-04 | L15: https://www.sec.gov/Archives/edgar/data/1652044/000165204426000012/googexhibit991q42025.htm｜现金流量表 2024 列 | M15: 2026-10-22 | N15: GOOG25Q4
A16: CY-GO-2025 | B16: 年度资本开支 | C16: Alphabet 资本开支 | D16: Alphabet | E16: 91.447 | F16: 十亿美元 | G16: 2025 | H16: 披露事实 | I16: Alphabet 口径：购置物业与设备（现金流量表） | J16: Alphabet 2025 年四季度及全年业绩（8-K 附件 99.1） | K16: 2026-02-04 | L16: https://www.sec.gov/Archives/edgar/data/1652044/000165204426000012/googexhibit991q42025.htm｜现金流量表 2025 列 | M16: 2026-10-22 | N16: GOOG25Q4
... A19: CQ-GO-25Q4 | B19: 季度资本开支 | C19: Alphabet 资本开支 | D19: Alphabet | E19: 27.851 | F19: 十亿美元 | G19: 2025Q4 | H19: 披露事实 | I19: Alphabet 口径：购置物业与设备（现金流量表） | J19: Alphabet 2025 年四季度及全年业绩（8-K 附件 99.1） | K19: 2026-02-04 | L19: https://www.sec.gov/Archives/edgar/data/1652044/000165204426000012/googexhibit991q42025.htm｜现金流量表 | M19: 2026-10-22 | N19: GOOG25Q4
A20: CQ-GO-25Q3 | B20: 季度资本开支 | C20: Alphabet 资本开支（推算） | D20: Alphabet | E20: =$E$16-$E$17-$E$18-$E$19 -> 23.953 | F20: 十亿美元 | G20: 2025Q3 | H20: 本表计算 | I20: 全年 − 其余三个季度 | J20: 本表计算（公式见单元格） | K20: 2026-10-22 | M20: — | N20: CALC
A21: CQ-GO-26Q1 | B21: 季度资本开支 | C21: Alphabet 资本开支 | D21: Alphabet | E21: 35.674 | F21: 十亿美元 | G21: 2026Q1 | H21: 披露事实 | I21: Alphabet 口径：购置物业与设备（现金流量表） | J21: Alphabet 2026 年一季度业绩（8-K 附件 99.1） | K21: 2026-04-29 | L21: https://www.sec.gov/Archives/edgar/data/0001652044/000165204426000043/googexhibit991q12026.htm｜现金流量表 | M21: 2026-10-22 | N21: GOOG26Q1
A22: CQ-GO-26Q2 | B22: 季度资本开支 | C22: Alphabet 资本开支 | D22: Alphabet | E22: 44.924 | F22: 十亿美元 | G22: 2026Q2 | H22: 披露事实 | I22: Alphabet 口径：购置物业与设备（现金流量表） | J22: Alphabet 2026 年二季度业绩（8-K 附件 99.1）及业绩电话会 | K22: 2026-07-22 | L22: https://www.sec.gov/Archives/edgar/data/0001652044/000165204426000066/googexhibit991q22026.htm｜现金流量表 | M22: 2026-10-22 | N22: GOOG26Q2
A23: CY-AM-2024 | B23: 年度资本开支 | C23: 亚马逊资本开支 | D23: 亚马逊 | E23: 82.999 | F23: 十亿美元 | G23: 2024 | H23: 披露事实 | I23: 亚马逊口径：购置物业与设备总额（未扣除处置收入与激励） | J23: 亚马逊 2025 年四季度业绩（8-K 附件 99.1） | K23: 2026-02-05 | L23: https://www.sec.gov/Archives/edgar/data/1018724/000101872426000002/amzn-20251231xex991.htm｜十二个月现金流 2024 列 | M23: 2026-10-22 | N23: AMZN25Q4
A24: CY-AM-2025 | B24: 年度资本开支 | C24: 亚马逊资本开支 | D24: 亚马逊 | E24: 131.819 | F24: 十亿美元 | G24: 2025 | H24: 披露事实 | I24: 亚马逊口径：购置物业与设备总额（未扣除处置收入与激励） | J24: 亚马逊 2025 年四季度业绩（8-K 附件 99.1） | K24: 2026-02-05 | L24: https://www.sec.gov/Archives/edgar/data/1018724/000101872426000002/amzn-20251231xex991.htm｜十二个月现金流 2025 列 | M24: 2026-10-22 | N24: AMZN25Q4
A25: CQ-AM-25Q1 | B25: 季度资本开支 | C25: 亚马逊资本开支 | D25: 亚马逊 | E25: 25.019 | F25: 十亿美元 | G25: 2025Q1 | H25: 披露事实 | I25: 亚马逊口径：购置物业与设备总额（未扣除处置收入与激励） | J25: 亚马逊 2026 年一季度业绩（8-K 附件 99.1） | K25: 2026-04-29 | L25: https://www.sec.gov/Archives/edgar/data/0001018724/000101872426000012/amzn-20260331xex991.htm｜上年同期列 | M25: 2026-10-22 | N25: AMZN26Q1
A26: CQ-AM-25Q2 | B26: 季度资本开支 | C26: 亚马逊资本开支 | D26: 亚马逊 | E26: 32.183 | F26: 十亿美元 | G26: 2025Q2 | H26: 披露事实 | I26: 亚马逊口径：购置物业与设备总额（未扣除处置收入与激励） | J26: 亚马逊 2026 年二季度业绩（8-K 附件 99.1） | K26: 2026-07-30 | L26: https://www.sec.gov/Archives/edgar/data/0001018724/000101872426000024/amzn-20260630xex991.htm｜上年同期列 | M26: 2026-10-22 | N26: AMZN26Q2
A27: CQ-AM-25Q4 | B27: 季度资本开支 | C27: 亚马逊资本开支 | D27: 亚马逊 | E27: 39.522 | F27: 十亿美元 | G27: 2025Q4 | H27: 披露事实 | I27: 亚马逊口径：购置物业与设备总额（未扣除处置收入与激励） | J27: 亚马逊 2025 年四季度业绩（8-K 附件 99.1） | K27: 2026-02-05 | L27: https://www.sec.gov/Archives/edgar/data/1018724/000101872426000002/amzn-20251231xex991.htm｜现金流量表 | M27: 2026-10-22 | N27: AMZN25Q4
A28: CQ-AM-25Q3 | B28: 季度资本开支 | C28: 亚马逊资本开支（推算） | D28: 亚马逊 | E28: =$E$24-$E$25-$E$26-$E$27 -> 35.095 | F28: 十亿美元 | G28: 2025Q3 | H28: 本表计算 | I28: 全年 − 其余三个季度 | J28: 本表计算（公式见单元格） | K28: 2026-10-22 | M28: — | N28: CALC
A29: CQ-AM-26Q1 | B29: 季度资本开支 | C29: 亚马逊资本开支 | D29: 亚马逊 | E29: 44.203 | F29: 十亿美元 | G29: 2026Q1 | H29: 披露事实 | I29: 亚马逊口径：购置物业与设备总额（未扣除处置收入与激励） | J29: 亚马逊 2026 年一季度业绩（8-K 附件 99.1） | K29: 2026-04-29 | L29: https://www.sec.gov/Archives/edgar/data/0001018724/000101872426000012/amzn-20260331xex991.htm｜现金流量表 | M29: 2026-10-22 | N29: AMZN26Q1
A30: CQ-AM-26Q2 | B30: 季度资本开支 | C30: 亚马逊资本开支 | D30: 亚马逊 | E30: 54.208 | F30: 十亿美元 | G30: 2026Q2 | H30: 披露事实 | I30: 亚马逊口径：购置物业与设备总额（未扣除处置收入与激励） | J30: 亚马逊 2026 年二季度业绩（8-K 附件 99.1） | K30: 2026-07-30 | L30: https://www.sec.gov/Archives/edgar/data/0001018724/000101872426000024/amzn-20260630xex991.htm｜现金流量表 | M30: 2026-10-22 | N30: AMZN26Q2
A31: CY-ME-2024 | B31: 年度资本开支 | C31: Meta 资本开支 | D31: Meta | E31: 39.225 | F31: 十亿美元 | G31: 2024 | H31: 披露事实 | I31: Meta 口径：购置物业与设备 + 融资租赁本金（372.56 + 19.69） | J31: Meta 2025 年四季度及全年业绩新闻稿 | K31: 2026-01-28 | L31: https://investor.atmeta.com/investor-news/press-release-details/2026/Meta-Reports-Fourth-Quarter-and-Full-Year-2025-Results/default.aspx｜现金流量表 | M31: 2026-10-22 | N31: META25Q4
A32: CY-ME-2025 | B32: 年度资本开支 | C32: Meta 资本开支 | D32: Meta | E32: 72.215 | F32: 十亿美元 | G32: 2025 | H32: 披露事实 | I32: Meta 口径：购置物业与设备 + 融资租赁本金（696.91 + 25.24） | J32: Meta 2025 年四季度及全年业绩新闻稿 | K32: 2026-01-28 | L32: https://investor.atmeta.com/investor-news/press-release-details/2026/Meta-Reports-Fourth-Quarter-and-Full-Year-2025-Results/default.aspx｜新闻稿“722.2 亿美元” | M32: 2026-10-22 | N32: META25Q4
A33: CQ-ME-25Q1 | B33: 季度资本开支 | C33: Meta 资本开支 | D33: Meta | E33: 13.692 | F33: 十亿美元 | G33: 2025Q1 | H33: 披露事实 | I33: Meta 口径：购置物业与设备 + 融资租赁本金；两项取自季度报表同期列后相加 | J33: Meta 2026 年一季度业绩新闻稿 | K33: 2026-04-29 | L33: https://investor.atmeta.com/investor-news/press-release-details/2026/Meta-Reports-First-Quarter-2026-Results/default.aspx｜上年同期列 | M33: 2026-10-22 | N33: META26Q1
A34: CQ-ME-25Q2 | B34: 季度资本开支 | C34: Meta 资本开支 | D34: Meta | E34: 17.012 | F34: 十亿美元 | G34: 2025Q2 | H34: 披露事实 | I34: Meta 口径：购置物业与设备 + 融资租赁本金；同上 | J34: Meta 2026 年二季度业绩新闻稿 | K34: 2026-07-29 | L34: https://investor.atmeta.com/investor-news/press-release-details/2026/Meta-Reports-Second-Quarter-2026-Results/default.aspx｜上年同期列 | M34: 2026-10-22 | N34: META26Q2
A35: CQ-ME-25Q3 | B35: 季度资本开支 | C35: Meta 资本开支 | D35: Meta | E35: 19.374 | F35: 十亿美元 | G35: 2025Q3 | H35: 披露事实 | I35: Meta 口径：购置物业与设备 + 融资租赁本金；同上 | J35: Meta 2026 年三季度业绩新闻稿 | K35: 2026-10-21 | L35: https://investor.atmeta.com/investor-news/press-release-details/2026/Meta-Reports-Third-Quarter-2026-Results/default.aspx｜上年同期列 | M35: 2026-10-22 | N35: META26Q3
A36: CQ-ME-25Q4 | B36: 季度资本开支 | C36: Meta 资本开支 | D36: Meta | E36: 22.137 | F36: 十亿美元 | G36: 2025Q4 | H36: 披露事实 | I36: Meta 口径：购置物业与设备 + 融资租赁本金 | J36: Meta 2025 年四季度及全年业绩新闻稿 | K36: 2026-01-28 | L36: https://investor.atmeta.com/investor-news/press-release-details/2026/Meta-Reports-Fourth-Quarter-and-Full-Year-2025-Results/default.aspx｜新闻稿“221.4 亿美元” | M36: 2026-10-22 | N36: META25Q4
A37: CQ-ME-26Q1 | B37: 季度资本开支 | C37: Meta 资本开支 | D37: Meta | E37: 19.84 | F37: 十亿美元 | G37: 2026Q1 | H37: 披露事实 | I37: Meta 口径：购置物业与设备 + 融资租赁本金 | J37: Meta 2026 年一季度业绩新闻稿 | K37: 2026-04-29 | L37: https://investor.atmeta.com/investor-news/press-release-details/2026/Meta-Reports-First-Quarter-2026-Results/default.aspx｜新闻稿“198.4 亿美元” | M37: 2026-10-22 | N37: META26Q1
A38: CQ-ME-26Q2 | B38: 季度资本开支 | C38: Meta 资本开支 | D38: Meta | E38: 31.08 | F38: 十亿美元 | G38: 2026Q2 | H38: 披露事实 | I38: Meta 口径：购置物业与设备 + 融资租赁本金 | J38: Meta 2026 年二季度业绩新闻稿 | K38: 2026-07-29 | L38: https://investor.atmeta.com/investor-news/press-release-details/2026/Meta-Reports-Second-Quarter-2026-Results/default.aspx｜新闻稿“310.8 亿美元” | M38: 2026-10-22 | N38: META26Q2
A39: CQ-ME-26Q3 | B39: 季度资本开支 | C39: Meta 资本开支 | D39: Meta | E39: ='D4_Meta三季报'!$E$5 -> 34.91 | F39: 十亿美元 | G39: 2026Q3 | H39: 披露事实 | I39: Meta 口径：购置物业与设备 + 融资租赁本金；引用 D4 原始材料 10-Q | J39: Meta Platforms, Inc. 10-Q 季报（截至 2026-09-30 的季度） | K39: 2026-10-21（签署日） | L39: 材料/Meta_2026Q3季报__meta-20260930.htm｜见 D4 META-01 | M39: 原始材料 | N39: M1
A40: CQ-ME-CHK | B40: 季度资本开支 | C40: 核对：Meta 2026 年前三季度（季度相加 − 10-Q 累计） | D40: Meta | E40: =$E$37+$E$38+$E$39-'D4_Meta三季报'!$E$6 -> 0.01 | F40: 十亿美元 | G40: 2026 年前三季度 | H40: 本表计算 | I40: 差值应接近 0（四舍五入误差） | J40: 本表计算（公式见单元格） | K40: 2026-10-22 | M40: — | N40: CALC
A41: G-MS-2026 | B41: 指引 | C41: 微软 2026 自然年资本开支预期（租赁重分类后） | D41: 微软 | E41: 175 | F41: 十亿美元 | G41: 2026E | H41: 公司指引 | I41: 2026-07-29 称“约 1750 亿美元”；4 月给出的约 1900 亿口径因部分融资租赁改为经营租赁而下调，公司称投资计划未变 | J41: 微软 FY26 Q4 业绩电话会 | K41: 2026-07-29 | L41: https://www.microsoft.com/en-us/investor/events/fy-2026/earnings-fy-2026-q4｜CFO 发言 | M41: 2026-10-22 | N41: MSFT26Q4
A42: G-MS-2026B | B42: 指引 | C42: 微软 2026 自然年资本开支预期（重分类前口径） | D42: 微软 | E42: 190 | F42: 十亿美元 | G42: 2026E | H42: 公司指引 | I42: 含约 250 亿美元元器件涨价影响 | J42: 微软 FY26 Q3 业绩电话会 | K42: 2026-04-29 | L42: https://www.microsoft.com/en-us/investor/events/fy-2026/earnings-fy-2026-q3｜CFO 发言 | M42: 2026-10-22 | N42: MSFT26Q3
A43: G-GO-2026L | B43: 指引 | C43: Alphabet 2026 年资本开支指引下限 | D43: Alphabet | E43: 195 | F43: 十亿美元 | G43: 2026E | H43: 公司指引 | I43: 2 月 175–185 → 4 月 180–190 → 7 月 195–205 | J43: Alphabet 2026 年二季度业绩（8-K 附件 99.1）及业绩电话会 | K43: 2026-07-22 | L43: https://www.sec.gov/Archives/edgar/data/0001652044/000165204426000066/googexhibit991q22026.htm｜业绩电话会 | M43: 2026-10-22 | N43: GOOG26Q2
...

Sheet D4_Meta三季报
A1: D4 Meta 2026 年三季报（10-Q）关键数据——原始材料，财务数字以此为准
A2: 蓝底=输入（披露数据）；橙底=输入（假设）；绿底=公式（本表计算）。“出处定位”给出原始材料的文件与章节，或网页链接；“访问日期”为网页查阅日期。
A4: 编号 | B4: 类别 | C4: 指标 | D4: 主体/地区 | E4: 数值 | F4: 单位 | G4: 期间 | H4: 性质 | I4: 口径说明 | J4: 来源名称 | K4: 发布日期 | L4: 出处定位（文件章节/表名或网页链接） | M4: 访问日期 | N4: 来源编号
A5: META-01 | B5: 资本开支 | C5: 资本开支（含融资租赁本金支付） | D5: Meta | E5: 34.91 | F5: 十亿美元 | G5: 2026Q3 | H5: 披露事实 | I5: 购置物业与设备 + 融资租赁本金支付 | J5: Meta Platforms, Inc. 10-Q 季报（截至 2026-09-30 的季度） | K5: 2026-10-21（签署日） | L5: 材料/Meta_2026Q3季报__meta-20260930.htm｜第 2 项 MD&A“第三季度业绩概览” | M5: 原始材料 | N5: M1
A6: META-02 | B6: 资本开支 | C6: 资本开支（含融资租赁本金支付） | D6: Meta | E6: 85.82 | F6: 十亿美元 | G6: 2026 年前三季度 | H6: 披露事实 | I6: 同上 | J6: Meta Platforms, Inc. 10-Q 季报（截至 2026-09-30 的季度） | K6: 2026-10-21（签署日） | L6: 材料/Meta_2026Q3季报__meta-20260930.htm｜MD&A“流动性与资本资源” | M6: 原始材料 | N6: M1
A7: META-03 | B7: 资本开支 | C7: 购置物业与设备 | D7: Meta | E7: 83.055 | F7: 十亿美元 | G7: 2026 年前三季度 | H7: 披露事实 | I7: 现金流量表 | J7: Meta Platforms, Inc. 10-Q 季报（截至 2026-09-30 的季度） | K7: 2026-10-21（签署日） | L7: 材料/Meta_2026Q3季报__meta-20260930.htm｜简明合并现金流量表 | M7: 原始材料 | N7: M1
A8: META-04 | B8: 资本开支 | C8: 融资租赁本金支付 | D8: Meta | E8: 2.769 | F8: 十亿美元 | G8: 2026 年前三季度 | H8: 披露事实 | I8: 现金流量表 | J8: Meta Platforms, Inc. 10-Q 季报（截至 2026-09-30 的季度） | K8: 2026-10-21（签署日） | L8: 材料/Meta_2026Q3季报__meta-20260930.htm｜简明合并现金流量表 | M8: 原始材料 | N8: M1
A9: META-05 | B9: 资本开支 | C9: 购置物业与设备 | D9: Meta | E9: 48.308 | F9: 十亿美元 | G9: 2025 年前三季度 | H9: 披露事实 | I9: 现金流量表（上年同期） | J9: Meta Platforms, Inc. 10-Q 季报（截至 2026-09-30 的季度） | K9: 2026-10-21（签署日） | L9: 材料/Meta_2026Q3季报__meta-20260930.htm｜简明合并现金流量表 | M9: 原始材料 | N9: M1
A10: META-06 | B10: 资本开支 | C10: 融资租赁本金支付 | D10: Meta | E10: 1.77 | F10: 十亿美元 | G10: 2025 年前三季度 | H10: 披露事实 | I10: 现金流量表（上年同期） | J10: Meta Platforms, Inc. 10-Q 季报（截至 2026-09-30 的季度） | K10: 2026-10-21（签署日） | L10: 材料/Meta_2026Q3季报__meta-20260930.htm｜简明合并现金流量表 | M10: 原始材料 | N10: M1
A11: META-07 | B11: 资本开支 | C11: 2025 年前三季度资本开支（含融资租赁本金） | D11: Meta | E11: =$E$9+$E$10 -> 50.078 | F11: 十亿美元 | G11: 2025 年前三季度 | H11: 本表计算 | I11: 与 2026 年同口径 | J11: 本表计算（公式见单元格） | K11: 2026-10-22 | M11: — | N11: CALC
A12: META-08 | B12: 资本开支 | C12: 2026 年前三季度资本开支同比增速 | D12: Meta | E12: =$E$6/$E$11-1 -> 0.71372659 | F12: % | G12: 2026 年前三季度 | H12: 本表计算 | J12: 本表计算（公式见单元格） | K12: 2026-10-22 | M12: — | N12: CALC
A13: META-09 | B13: 资本开支 | C13: 2026 年资本开支指引下限 | D13: Meta | E13: 135 | F13: 十亿美元 | G13: 2026 | H13: 公司指引 | I13: “约 1350 亿至 1450 亿美元”，用于 AI 与核心业务 | J13: Meta Platforms, Inc. 10-Q 季报（截至 2026-09-30 的季度） | K13: 2026-10-21（签署日） | L13: 材料/Meta_2026Q3季报__meta-20260930.htm｜MD&A“投资活动现金流” | M13: 原始材料 | N13: M1
A14: META-10 | B14: 资本开支 | C14: 2026 年资本开支指引上限 | D14: Meta | E14: 145 | F14: 十亿美元 | G14: 2026 | H14: 公司指引 | I14: 同上 | J14: Meta Platforms, Inc. 10-Q 季报（截至 2026-09-30 的季度） | K14: 2026-10-21（签署日） | L14: 材料/Meta_2026Q3季报__meta-20260930.htm｜MD&A“投资活动现金流” | M14: 原始材料 | N14: M1
A15: META-11 | B15: 资本开支 | C15: 2026 年四季度隐含资本开支（按指引中值） | D15: Meta | E15: =($E$13+$E$14)/2-$E$6 -> 54.18 | F15: 十亿美元 | G15: 2026Q4E | H15: 本表计算 | I15: 指引中值 − 前三季度实际；取中值为假设 | J15: 本表计算（公式见单元格） | K15: 2026-10-22 | M15: — | N15: CALC
A16: META-38 | B16: 经营 | C16: 营业收入 | D16: Meta | E16: 181.712 | F16: 十亿美元 | G16: 2026 年前三季度 | H16: 披露事实 | J16: Meta Platforms, Inc. 10-Q 季报（截至 2026-09-30 的季度） | K16: 2026-10-21（签署日） | L16: 材料/Meta_2026Q3季报__meta-20260930.htm｜简明合并利润表 | M16: 原始材料 | N16: M1
A17: META-39 | B17: 经营 | C17: 物业与设备折旧 | D17: Meta | E17: 6.81 | F17: 十亿美元 | G17: 2026Q3 | H17: 披露事实 | I17: 其中服务器与网络资产折旧 53.4 亿 | J17: Meta Platforms, Inc. 10-Q 季报（截至 2026-09-30 的季度） | K17: 2026-10-21（签署日） | L17: 材料/Meta_2026Q3季报__meta-20260930.htm｜附注 6 | M17: 原始材料 | N17: M1
A18: META-40 | B18: 经营 | C18: 物业与设备折旧 | D18: Meta | E18: 4.76 | F18: 十亿美元 | G18: 2025Q3 | H18: 披露事实 | J18: Meta Platforms, Inc. 10-Q 季报（截至 2026-09-30 的季度） | K18: 2026-10-21（签署日） | L18: 材料/Meta_2026Q3季报__meta-20260930.htm｜附注 6 | M18: 原始材料 | N18: M1
A19: META-12 | B19: 经营 | C19: 营业收入 | D19: Meta | E19: 64.601 | F19: 十亿美元 | G19: 2026Q3 | H19: 披露事实 | J19: Meta Platforms, Inc. 10-Q 季报（截至 2026-09-30 的季度） | K19: 2026-10-21（签署日） | L19: 材料/Meta_2026Q3季报__meta-20260930.htm｜简明合并利润表 | M19: 原始材料 | N19: M1
A20: META-13 | B20: 经营 | C20: 营业收入 | D20: Meta | E20: 51.242 | F20: 十亿美元 | G20: 2025Q3 | H20: 披露事实 | J20: Meta Platforms, Inc. 10-Q 季报（截至 2026-09-30 的季度） | K20: 2026-10-21（签署日） | L20: 材料/Meta_2026Q3季报__meta-20260930.htm｜简明合并利润表 | M20: 原始材料 | N20: M1
A21: META-14 | B21: 经营 | C21: 营业利润 | D21: Meta | E21: 12.988 | F21: 十亿美元 | G21: 2026Q3 | H21: 披露事实 | I21: 含 98.9 亿美元多州总检察长和解费用 | J21: Meta Platforms, Inc. 10-Q 季报（截至 2026-09-30 的季度） | K21: 2026-10-21（签署日） | L21: 材料/Meta_2026Q3季报__meta-20260930.htm｜简明合并利润表 | M21: 原始材料 | N21: M1
A22: META-15 | B22: 经营 | C22: 营业利润 | D22: Meta | E22: 20.535 | F22: 十亿美元 | G22: 2025Q3 | H22: 披露事实 | J22: Meta Platforms, Inc. 10-Q 季报（截至 2026-09-30 的季度） | K22: 2026-10-21（签署日） | L22: 材料/Meta_2026Q3季报__meta-20260930.htm｜简明合并利润表 | M22: 原始材料 | N22: M1
A23: META-16 | B23: 经营 | C23: 经营活动现金流 | D23: Meta | E23: 96.873 | F23: 十亿美元 | G23: 2026 年前三季度 | H23: 披露事实 | J23: Meta Platforms, Inc. 10-Q 季报（截至 2026-09-30 的季度） | K23: 2026-10-21（签署日） | L23: 材料/Meta_2026Q3季报__meta-20260930.htm｜简明合并现金流量表 | M23: 原始材料 | N23: M1
A24: META-17 | B24: 经营 | C24: 折旧与摊销 | D24: Meta | E24: 19.509 | F24: 十亿美元 | G24: 2026 年前三季度 | H24: 披露事实 | I24: 上年同期 13.205 | J24: Meta Platforms, Inc. 10-Q 季报（截至 2026-09-30 的季度） | K24: 2026-10-21（签署日） | L24: 材料/Meta_2026Q3季报__meta-20260930.htm｜简明合并现金流量表 | M24: 原始材料 | N24: M1
A25: META-18 | B25: 经营 | C25: 折旧与摊销 | D25: Meta | E25: 13.205 | F25: 十亿美元 | G25: 2025 年前三季度 | H25: 披露事实 | J25: Meta Platforms, Inc. 10-Q 季报（截至 2026-09-30 的季度） | K25: 2026-10-21（签署日） | L25: 材料/Meta_2026Q3季报__meta-20260930.htm｜简明合并现金流量表 | M25: 原始材料 | N25: M1
A26: META-19 | B26: 资产 | C26: 服务器与网络资产（原值） | D26: Meta | E26: 133.626 | F26: 十亿美元 | G26: 2026-09-30 | H26: 披露事实 | I26: 2025 年末 98.040 | J26: Meta Platforms, Inc. 10-Q 季报（截至 2026-09-30 的季度） | K26: 2026-10-21（签署日） | L26: 材料/Meta_2026Q3季报__meta-20260930.htm｜附注 6 物业与设备 | M26: 原始材料 | N26: M1
A27: META-20 | B27: 资产 | C27: 服务器与网络资产（原值） | D27: Meta | E27: 98.04 | F27: 十亿美元 | G27: 2025-12-31 | H27: 披露事实 | J27: Meta Platforms, Inc. 10-Q 季报（截至 2026-09-30 的季度） | K27: 2026-10-21（签署日） | L27: 材料/Meta_2026Q3季报__meta-20260930.htm｜附注 6 | M27: 原始材料 | N27: M1
A28: META-21 | B28: 资产 | C28: 在建工程（主要为数据中心、服务器与网络） | D28: Meta | E28: 89.499 | F28: 十亿美元 | G28: 2026-09-30 | H28: 披露事实 | I28: 2025 年末 50.521 | J28: Meta Platforms, Inc. 10-Q 季报（截至 2026-09-30 的季度） | K28: 2026-10-21（签署日） | L28: 材料/Meta_2026Q3季报__meta-20260930.htm｜附注 6 | M28: 原始材料 | N28: M1
A29: META-22 | B29: 资产 | C29: 在建工程 | D29: Meta | E29: 50.521 | F29: 十亿美元 | G29: 2025-12-31 | H29: 披露事实 | J29: Meta Platforms, Inc. 10-Q 季报（截至 2026-09-30 的季度） | K29: 2026-10-21（签署日） | L29: 材料/Meta_2026Q3季报__meta-20260930.htm｜附注 6 | M29: 原始材料 | N29: M1
A30: META-23 | B30: 资产 | C30: 物业与设备净值 | D30: Meta | E30: 253.222 | F30: 十亿美元 | G30: 2026-09-30 | H30: 披露事实 | I30: 2025 年末 176.400 | J30: Meta Platforms, Inc. 10-Q 季报（截至 2026-09-30 的季度） | K30: 2026-10-21（签署日） | L30: 材料/Meta_2026Q3季报__meta-20260930.htm｜附注 6 | M30: 原始材料 | N30: M1
A31: META-24 | B31: 资产 | C31: 物业与设备净值 | D31: Meta | E31: 176.4 | F31: 十亿美元 | G31: 2025-12-31 | H31: 披露事实 | J31: Meta Platforms, Inc. 10-Q 季报（截至 2026-09-30 的季度） | K31: 2026-10-21（签署日） | L31: 材料/Meta_2026Q3季报__meta-20260930.htm｜附注 6 | M31: 原始材料 | N31: M1
A32: META-25 | B32: 承诺 | C32: 尚未起租的经营与融资租赁 | D32: Meta | E32: 355.73 | F32: 十亿美元 | G32: 2026-09-30 | H32: 披露事实 | I32: 数据中心、能源相关基础设施、托管与网络；2026–2036 年起租，租期 1–30 年 | J32: Meta Platforms, Inc. 10-Q 季报（截至 2026-09-30 的季度） | K32: 2026-10-21（签署日） | L32: 材料/Meta_2026Q3季报__meta-20260930.htm｜附注 10 承诺与或有事项 | M32: 原始材料 | N32: M1
A33: META-26 | B33: 承诺 | C33: 不可撤销合同承诺 | D33: Meta | E33: 454.52 | F33: 十亿美元 | G33: 2026-09-30 | H33: 披露事实 | I33: 主要为第三方云容量、服务器与网络投资、数据中心能源服务协议、Reality Labs 硬件 | J33: Meta Platforms, Inc. 10-Q 季报（截至 2026-09-30 的季度） | K33: 2026-10-21（签署日） | L33: 材料/Meta_2026Q3季报__meta-20260930.htm｜附注 10 | M33: 原始材料 | N33: M1
A34: META-27 | B34: 承诺 | C34: 其中 2026 年剩余期间到期 | D34: Meta | E34: 45.85 | F34: 十亿美元 | G34: 2026Q4 | H34: 披露事实 | J34: Meta Platforms, Inc. 10-Q 季报（截至 2026-09-30 的季度） | K34: 2026-10-21（签署日） | L34: 材料/Meta_2026Q3季报__meta-20260930.htm｜附注 10 | M34: 原始材料 | N34: M1
A35: META-28 | B35: 承诺 | C35: 其中 2027 年到期 | D35: Meta | E35: 121.41 | F35: 十亿美元 | G35: 2027 | H35: 披露事实 | J35: Meta Platforms, Inc. 10-Q 季报（截至 2026-09-30 的季度） | K35: 2026-10-21（签署日） | L35: 材料/Meta_2026Q3季报__meta-20260930.htm｜附注 10 | M35: 原始材料 | N35: M1
A36: META-29 | B36: 承诺 | C36: 或有云容量采购义务（五年内，上限） | D36: Meta | E36: 14.72 | F36: 十亿美元 | G36: 2026-09-30 | H36: 披露事实 | I36: 若云服务商转售可减少 | J36: Meta Platforms, Inc. 10-Q 季报（截至 2026-09-30 的季度） | K36: 2026-10-21（签署日） | L36: 材料/Meta_2026Q3季报__meta-20260930.htm｜附注 10 | M36: 原始材料 | N36: M1
A37: META-30 | B37: 承诺 | C37: 为多年期基础设施采购协议托管的受限现金 | D37: Meta | E37: 10.8 | F37: 十亿美元 | G37: 2026-09-30 | H37: 披露事实 | I37: 预计 2028–2030 年释放 | J37: Meta Platforms, Inc. 10-Q 季报（截至 2026-09-30 的季度） | K37: 2026-10-21（签署日） | L37: 材料/Meta_2026Q3季报__meta-20260930.htm｜附注 4 金融工具 | M37: 原始材料 | N37: M1
A38: META-31 | B38: 数据中心合资 | C38: 路易斯安那数据中心合资项目总开发成本（估） | D38: Meta 与合作方 | E38: 27 | F38: 十亿美元 | G38: 2025-10 签署 | H38: 披露事实 | I38: Meta 持股 20%；租约 2029 年起租，初始 4 年、最长 20 年；提供残值担保 | J38: Meta Platforms, Inc. 10-Q 季报（截至 2026-09-30 的季度） | K38: 2026-10-21（签署日） | L38: 材料/Meta_2026Q3季报__meta-20260930.htm｜附注 5 非上市权益投资“数据中心合资” | M38: 原始材料 | N38: M1
A39: META-32 | B39: 数据中心合资 | C39: 得克萨斯数据中心合资项目总开发成本（估） | D39: Meta 与合作方 | E39: 14 | F39: 十亿美元 | G39: 2026-07 签署 | H39: 披露事实 | I39: Meta 持股 20%；租约 2028 年起租 | J39: Meta Platforms, Inc. 10-Q 季报（截至 2026-09-30 的季度） | K39: 2026-10-21（签署日） | L39: 材料/Meta_2026Q3季报__meta-20260930.htm｜附注 5 | M39: 原始材料 | N39: M1
A40: META-33 | B40: 数据中心合资 | C40: 对两家数据中心合资企业的最大损失敞口 | D40: Meta | E40: 68.404 | F40: 十亿美元 | G40: 2026-09-30 | H40: 披露事实 | I40: 含最大残值担保 41.493、租赁承诺 18.476 | J40: Meta Platforms, Inc. 10-Q 季报（截至 2026-09-30 的季度） | K40: 2026-10-21（签署日） | L40: 材料/Meta_2026Q3季报__meta-20260930.htm｜附注 5 | M40: 原始材料 | N40: M1
A41: META-34 | B41: 融资 | C41: 长期债券本金余额 | D41: Meta | E41: 84 | F41: 十亿美元 | G41: 2026-09-30 | H41: 披露事实 | I41: 2026 年 5 月新发 250 亿美元 | J41: Meta Platforms, Inc. 10-Q 季报（截至 2026-09-30 的季度） | K41: 2026-10-21（签署日） | L41: 材料/Meta_2026Q3季报__meta-20260930.htm｜附注 9 长期债务 | M41: 原始材料 | N41: M1
...

Sheet D5_Constellation
A1: D5 Constellation 2025 年报（10-K）与 2026 年二季报（10-Q）关键数据——原始材料
A2: 蓝底=输入（披露数据）；橙底=输入（假设）；绿底=公式（本表计算）。“出处定位”给出原始材料的文件与章节，或网页链接；“访问日期”为网页查阅日期。
A4: 编号 | B4: 类别 | C4: 指标 | D4: 主体/地区 | E4: 数值 | F4: 单位 | G4: 期间 | H4: 性质 | I4: 口径说明 | J4: 来源名称 | K4: 发布日期 | L4: 出处定位（文件章节/表名或网页链接） | M4: 访问日期 | N4: 来源编号
A5: CEG-01 | B5: 规模 | C5: 收购 Calpine 后总装机 | D5: Constellation | E5: 55 | F5: GW | G5: 2026-01 | H5: 披露事实 | I5: 核电、燃气、地热、水电、风电、光伏 | J5: Constellation Energy Corp. 10-K 年报（2025 财年） | K5: 2026-02-24（签署日） | L5: 材料/Constellation_2025年报__ceg-20251231.htm｜第 1 项“业务” | M5: 原始材料 | N5: M2
A6: CEG-02 | B6: 规模 | C6: 自有发电装机（未含 Calpine） | D6: Constellation | E6: 31676 | F6: MW | G6: 2025-12-31 | H6: 披露事实 | I6: 按权益比例；另有合同电源 4798 MW | J6: Constellation Energy Corp. 10-K 年报（2025 财年） | K6: 2026-02-24（签署日） | L6: 材料/Constellation_2025年报__ceg-20251231.htm｜“我们的运营” | M6: 原始材料 | N6: M2
A7: CEG-03 | B7: 规模 | C7: 核电装机 | D7: Constellation | E7: 22 | F7: GW | G7: 2025 | H7: 披露事实 | I7: 14 座电站、25 台机组 | J7: Constellation Energy Corp. 10-K 年报（2025 财年） | K7: 2026-02-24（签署日） | L7: 材料/Constellation_2025年报__ceg-20251231.htm｜“核电设施” | M7: 原始材料 | N7: M2
A8: CEG-04 | B8: 规模 | C8: 核电发电量 | D8: Constellation | E8: 182690 | F8: GWh | G8: 2025 | H8: 披露事实 | I8: 按权益比例；2024 年 181711 | J8: Constellation Energy Corp. 10-K 年报（2025 财年） | K8: 2026-02-24（签署日） | L8: 材料/Constellation_2025年报__ceg-20251231.htm｜MD&A 售电与供电量表 | M8: 原始材料 | N8: M2
A9: CEG-05 | B9: 规模 | C9: 核电机组容量系数 | D9: Constellation | E9: 0.947 | F9: % | G9: 2025 | H9: 披露事实 | I9: 不含 Salem、STP；2024 年 94.6% | J9: Constellation Energy Corp. 10-K 年报（2025 财年） | K9: 2026-02-24（签署日） | L9: 材料/Constellation_2025年报__ceg-20251231.htm｜MD&A“核电机组容量系数” | M9: 原始材料 | N9: M2
