Workbook

Sheet 封面
B2: MemoryFab
B3: 内存芯片公司 · 16 个季度经营模拟
B4: 逐季利润表 · 资产负债表 · 现金流量表 · 经营分析
B7: 期末股东权益 | D7: 累计净利润 | F7: 权益倍数 | H7: 累计营业收入
B8: =资产负债表!Q16 | D8: =利润表!R20 | F8: =资产负债表!Q16/34.96 | H8: =利润表!R6
B9: 十亿美元 | D9: 十亿美元 | F9: 倍 | H9: 十亿美元
B12: 颜色约定：输入格 / 公式格 / 假设格
D13: 引擎原始数据（输入格）
D14: 公式计算（自动联动）
D15: 假设与参数（可修改）
B18: 数据来源
B19: 本工作簿的全部财务数字来自本机经营模拟引擎（game id: memfab-deepseek）的逐季返回与最终导出，原始文件为 工作/export.json（history[1..16]）与 工作/state_q0.json（第 0 季末状态）。“原始数据”页逐项列示引擎字段；“数据源”页给出每个科目的字段路径。基准价、可变成本、固定费用、折旧年限、利率等为从报表行为反推的模型参数，均以“假设”标注，不是引擎披露的事实。
B24: 说明：这是研究与展示用的经营模拟复盘，不构成投资建议；不评价任何证券的价格，不给出买入、卖出或持有建议。所有金额单位为十亿美元，数量为千片（kwafers），单价为百万美元/千片，另有注明的除外。修改“假设与参数”页的黄色格，三张表、比率与敏感性会自动重算。

Sheet 原始数据
A1: 原始数据：引擎逐季返回
A2: 蓝色底纹为引擎导出的原始输入；本页不做任何加工。字段路径见“数据源”页。
A3: 单位：金额十亿美元；数量千片；单价百万美元/千片。数据源：工作/export.json → history[q].decision / market / operations / income_statement / cash_flow / balance_sheet。
A4: 决策与市场 | L4: 经营 | R4: 利润表 | AE4: 现金流量表 | AH4: 资产负债表与补充
A5: 季度 | B5: 价格指数 | C5: HBM价格指数 | D5: 普通需求 | E5: HBM需求 | F5: 开工率 | G5: 可售比例 | H5: 资本开支 | I5: HBM研发 | J5: HBM份额 | K5: 净借款 | L5: 产量 | M5: HBM产量 | N5: 普通销量 | O5: HBM销量 | P5: 单位成本 | Q5: 产能 | R5: 营业收入 | S5: 普通收入 | T5: HBM收入 | U5: 营业成本 | V5: 存货跌价 | W5: 毛利 | X5: 毛利率 | Y5: 研发费用 | Z5: 销售管理费用 | AA5: 营业利润 | AB5: 净利息 | AC5: 所得税 | AD5: 净利润 | AE5: 经营现金流 | AF5: 投资现金流 | AG5: 筹资现金流 | AH5: 折旧 | AI5: 期末现金 | AJ5: 期末存货 | AK5: 净固定资产 | AL5: 总资产 | AM5: 借款 | AN5: 紧急授信 | AO5: 股东权益 | AP5: 期末存货量 | AQ5: 期末产能
A6: 季 | B6: 倍 | C6: 倍 | D6: 千片 | E6: 千片 | F6: % | G6: % | H6: 十亿美元 | I6: 十亿美元 | J6: % | K6: 十亿美元 | L6: 千片 | M6: 千片 | N6: 千片 | O6: 千片 | P6: 百万美元/千片 | Q6: 千片/季 | R6: 十亿美元 | S6: 十亿美元 | T6: 十亿美元 | U6: 十亿美元 | V6: 十亿美元 | W6: 十亿美元 | X6: % | Y6: 十亿美元 | Z6: 十亿美元 | AA6: 十亿美元 | AB6: 十亿美元 | AC6: 十亿美元 | AD6: 十亿美元 | AE6: 十亿美元 | AF6: 十亿美元 | AG6: 十亿美元 | AH6: 十亿美元 | AI6: 十亿美元 | AJ6: 十亿美元 | AK6: 十亿美元 | AL6: 十亿美元 | AM6: 十亿美元 | AN6: 十亿美元 | AO6: 十亿美元 | AP6: 千片 | AQ6: 千片/季
A7: 1 | B7: 0.8 | C7: 1.6 | D7: 240 | E7: 5 | F7: 0.8 | G7: 1 | H7: 1.5 | I7: 3 | J7: 0 | K7: 2 | L7: 240 | M7: 0 | N7: 240 | O7: 0 | P7: 17.5 | Q7: 300 | R7: 4.608 | S7: 4.608 | T7: 0 | U7: 4.128 | V7: 0 | W7: 0.48 | X7: 0.1042 | Y7: 3.8 | Z7: 0.25 | AA7: -3.57 | AB7: 0.01 | AC7: 0 | AD7: -3.58 | AE7: -1.652 | AF7: -1.5 | AG7: 2 | AH7: 2 | AI7: 8.848 | AJ7: 1.032 | AK7: 29.5 | AL7: 39.38 | AM7: 8 | AN7: 0 | AO7: 31.38 | AP7: 60 | AQ7: 300
A8: 2 | B8: 0.56 | C8: 1.4 | D8: 210 | E8: 5 | F8: 1 | G8: 1 | H8: 2.5 | I8: 0 | J8: 0 | K8: 4 | L8: 300 | M8: 0 | N8: 210 | O8: 0 | P8: 15 | Q8: 300 | R8: 2.8224 | S8: 2.8224 | T8: 0 | U8: 3.6168 | V8: 0.3898 | W8: -0.7944 | X8: -0.2815 | Y8: 0.8 | Z8: 0.25 | AA8: -1.8444 | AB8: 0.0492 | AC8: 0 | AD8: -1.8936 | AE8: -0.7768 | AF8: -2.5 | AG8: 4 | AH8: 2 | AI8: 9.5712 | AJ8: 1.9152 | AK8: 30 | AL8: 41.4864 | AM8: 12 | AN8: 0 | AO8: 29.4864 | AP8: 150 | AQ8: 300
A9: 3 | B9: 0.5 | C9: 1.3 | D9: 205 | E9: 6 | F9: 1 | G9: 1 | H9: 3 | I9: 0 | J9: 0 | K9: 3 | L9: 300 | M9: 0 | N9: 205 | O9: 0 | P9: 15 | Q9: 300 | R9: 2.46 | S9: 2.46 | T9: 0 | U9: 3.6222 | V9: 0.6997 | W9: -1.1622 | X9: -0.4724 | Y9: 0.8 | Z9: 0.25 | AA9: -2.2122 | AB9: 0.1034 | AC9: 0 | AD9: -2.3156 | AE9: -1.1934 | AF9: -3 | AG9: 3 | AH9: 2 | AI9: 8.3778 | AJ9: 2.793 | AK9: 31 | AL9: 42.1708 | AM9: 15 | AN9: 0 | AO9: 27.1708 | AP9: 245 | AQ9: 300
A10: 4 | B10: 0.53 | C10: 1.4 | D10: 215 | E10: 8 | F10: 1 | G10: 1 | H10: 1.5 | I10: 0 | J10: 0.02 | K10: 1 | L10: 300 | M10: 6 | N10: 215 | O10: 6 | P10: 15 | Q10: 300 | R10: 2.9364 | S10: 2.7348 | T10: 0.2016 | U10: 3.3778 | V10: 0.4146 | W10: -0.4414 | X10: -0.1503 | Y10: 0.8 | Z10: 0.25 | AA10: -1.4914 | AB10: 0.158 | AC10: 0 | AD10: -1.6494 | AE10: -0.7716 | AF10: -1.5 | AG10: 1 | AH10: 2 | AI10: 7.1062 | AJ10: 3.9152 | AK10: 30.5 | AL10: 41.5214 | AM10: 16 | AN10: 0 | AO10: 25.5214 | AP10: 324 | AQ10: 300
A11: 5 | B11: 0.6 | C11: 1.6 | D11: 235 | E11: 12 | F11: 1 | G11: 1 | H11: 3.5 | I11: 0 | J11: 0.0333 | K11: 0 | L11: 300 | M11: 9.99 | N11: 235 | O11: 9.99 | P11: 15.25 | Q11: 300 | R11: 3.7676 | S11: 3.384 | T11: 0.3836 | U11: 3.3435 | V11: 0 | W11: 0.4241 | X11: 0.1126 | Y11: 0.8 | Z11: 0.25 | AA11: -0.6259 | AB11: 0.1832 | AC11: 0 | AD11: -0.809 | AE11: 0.0345 | AF11: -3.5 | AG11: 0 | AH11: 2.075 | AI11: 3.6406 | AJ11: 5.1467 | AK11: 31.925 | AL11: 40.7124 | AM11: 16 | AN11: 0 | AO11: 24.7124 | AP11: 379.01 | AQ11: 300
A12: 6 | B12: 0.72 | C12: 1.9 | D12: 260 | E12: 18 | F12: 1 | G12: 1 | H12: 3 | I12: 0 | J12: 0.058 | K12: 0 | L12: 308.33 | M12: 17.88 | N12: 260 | O12: 17.88 | P12: 15.378 | Q12: 308.33 | R12: 5.3083 | S12: 4.4928 | T12: 0.8155 | U12: 4.0086 | V12: 0 | W12: 1.2997 | X12: 0.2448 | Y12: 0.8 | Z12: 0.25 | AA12: 0.2497 | AB12: 0.2109 | AC12: 0.0058 | AD12: 0.033 | AE12: 1.4999 | AF12: -3 | AG12: 0 | AH12: 2.2 | AI12: 2.1406 | AJ12: 5.8798 | AK12: 32.725 | AL12: 40.7454 | AM12: 16 | AN12: 0 | AO12: 24.7454 | AP12: 409.46 | AQ12: 308.33
A13: 7 | B13: 0.83 | C13: 2.3 | D13: 285 | E13: 26 | F13: 1 | G13: 1 | H13: 3 | I13: 0 | J13: 0.085 | K13: 0 | L13: 320.83 | M13: 27.27 | N13: 285 | O13: 26 | P13: 15.442 | Q13: 320.83 | R13: 7.1124 | S13: 5.6772 | T13: 1.4352 | U13: 4.6424 | V13: 0 | W13: 2.47 | X13: 0.3473 | Y13: 0.8 | Z13: 0.25 | AA13: 1.42 | AB13: 0.2229 | AC13: 0.1796 | AD13: 1.0176 | AE13: 3.0558 | AF13: -3 | AG13: 0 | AH13: 2.35 | AI13: 2.1963 | AJ13: 6.1916 | AK13: 33.375 | AL13: 41.7629 | AM13: 16 | AN13: 0 | AO13: 25.7629 | AP13: 418.02 | AQ13: 320.83
A14: 8 | B14: 0.92 | C14: 2.8 | D14: 305 | E14: 36 | F14: 1 | G14: 1 | H14: 5 | I14: 0 | J14: 0.11 | K14: 0 | L14: 320.83 | M14: 35.29 | N14: 305 | O14: 35.29 | P14: 15.675 | Q14: 320.83 | R14: 9.106 | S14: 6.7344 | T14: 2.3716 | U14: 5.1777 | V14: 0 | W14: 3.9283 | X14: 0.4314 | Y14: 0.8 | Z14: 0.25 | AA14: 2.8783 | AB14: 0.2224 | AC14: 0.3984 | AD14: 2.2575 | AE14: 4.831 | AF14: -5 | AG14: 0 | AH14: 2.425 | AI14: 2.0274 | AJ14: 6.0431 | AK14: 35.95 | AL14: 44.0204 | AM14: 16 | AN14: 0 | AO14: 28.0204 | AP14: 398.56 | AQ14: 320.83
A15: 9 | B15: 1 | C15: 3.4 | D15: 320 | E15: 48 | F15: 1 | G15: 1 | H15: 4.5 | I15: 0 | J15: 0.142 | K15: 0 | L15: 337.5 | M15: 47.92 | N15: 320 | O15: 47.92 | P15: 15.667 | Q15: 337.5 | R15: 11.5907 | S15: 7.68 | T15: 3.9107 | U15: 5.6706 | V15: 0 | W15: 5.92 | X15: 0.5108 | Y15: 0.8 | Z15: 0.25 | AA15: 4.87 | AB15: 0.2238 | AC15: 0.6969 | AD15: 3.9493 | AE15: 6.9325 | AF15: -4.5 | AG15: 0 | AH15: 2.6 | AI15: 4.4598 | AJ15: 5.6599 | AK15: 37.85 | AL15: 47.9698 | AM15: 16 | AN15: 0 | AO15: 31.9698 | AP15: 368.14 | AQ15: 337.5
A16: 10 | B16: 0.97 | C16: 4 | D16: 320 | E16: 60 | F16: 1 | G16: 1 | H16: 1.5 | I16: 0 | J16: 0.172 | K16: -2 | L16: 350 | M16: 60.2 | N16: 320 | O16: 60 | P16: 15.714 | Q16: 350 | R16: 13.2096 | S16: 7.4496 | T16: 5.76 | U16: 5.9137 | V16: 0 | W16: 7.2959 | X16: 0.5523 | Y16: 0.8 | Z16: 0.25 | AA16: 6.2459 | AB16: 0.2043 | AC16: 0.9062 | AD16: 5.1353 | AE16: 8.299 | AF16: -1.5 | AG16: -2 | AH16: 2.75 | AI16: 9.2589 | AJ16: 5.2462 | AK16: 36.6 | AL16: 51.1051 | AM16: 14 | AN16: 0 | AO16: 37.1051 | AP16: 337.94 | AQ16: 350
A17: 11 | B17: 1.06 | C17: 4.6 | D17: 340 | E17: 74 | F17: 1 | G17: 1 | H17: 4 | I17: 0 | J17: 0.221 | K17: 0 | L17: 362.5 | M17: 80.11 | N17: 340 | O17: 74 | P17: 15.759 | Q17: 362.5 | R17: 16.8192 | S17: 8.6496 | T17: 8.1696 | U17: 6.577 | V17: 0 | W17: 10.2422 | X17: 0.609 | Y17: 0.8 | Z17: 0.25 | AA17: 9.1922 | AB17: 0.1359 | AC17: 1.3584 | AD17: 7.6979 | AE17: 11.4623 | AF17: -4 | AG17: 0 | AH17: 2.9 | AI17: 16.7212 | AJ17: 4.3818 | AK17: 37.7 | AL17: 58.8029 | AM17: 14 | AN17: 0 | AO17: 44.8029 | AP17: 280.33 | AQ17: 362.5
A18: 12 | B18: 1.28 | C18: 5.4 | D18: 365 | E18: 90 | F18: 1 | G18: 1 | H18: 1.5 | I18: 0 | J18: 0.245 | K18: -5 | L18: 391.67 | M18: 95.96 | N18: 365 | O18: 90 | P18: 15.596 | Q18: 391.67 | R18: 22.8768 | S18: 11.2128 | T18: 11.664 | U18: 7.1952 | V18: 0 | W18: 15.6816 | X18: 0.6855 | Y18: 0.8 | Z18: 0.25 | AA18: 14.6316 | AB18: 0.0762 | AC18: 2.1833 | AD18: 12.372 | AE18: 16.6089 | AF18: -1.5 | AG18: -5 | AH18: 3.15 | AI18: 26.8301 | AJ18: 3.2949 | AK18: 36.05 | AL18: 66.175 | AM18: 9 | AN18: 0 | AO18: 57.175 | AP18: 211.03 | AQ18: 391.67
... A22: 16 | B22: 4.55 | C22: 9.6 | D22: 510 | E22: 185 | F22: 1 | G22: 1 | H22: 1.5 | I22: 0 | J22: 0.44 | K22: 0 | L22: 437.5 | M22: 192.5 | N22: 245 | O22: 185 | P22: 15.8 | Q22: 437.5 | R22: 69.378 | S22: 26.754 | T22: 42.624 | U22: 6.9125 | V22: 0 | W22: 62.4655 | X22: 0.9004 | Y22: 0.8 | Z22: 0.25 | AA22: 61.4155 | AB22: -1.0051 | AC22: 9.3631 | AD22: 53.0575 | AE22: 56.7825 | AF22: -1.5 | AG22: 0 | AH22: 3.725 | AI22: 180.9249 | AJ22: 0 | AK22: 27.85 | AL22: 208.7749 | AM22: 0 | AN22: 0 | AO22: 208.7749 | AP22: 0 | AQ22: 437.5
A24: 合计 | H24: =SUM(H7:H22) | I24: =SUM(I7:I22) | K24: =SUM(K7:K22) | L24: =SUM(L7:L22) | M24: =SUM(M7:M22) | N24: =SUM(N7:N22) | O24: =SUM(O7:O22) | R24: =SUM(R7:R22) | S24: =SUM(S7:S22) | T24: =SUM(T7:T22) | U24: =SUM(U7:U22) | V24: =SUM(V7:V22) | W24: =SUM(W7:W22) | Y24: =SUM(Y7:Y22) | Z24: =SUM(Z7:Z22) | AA24: =SUM(AA7:AA22) | AB24: =SUM(AB7:AB22) | AC24: =SUM(AC7:AC22) | AD24: =SUM(AD7:AD22) | AE24: =SUM(AE7:AE22) | AF24: =SUM(AF7:AF22) | ... AH24: =SUM(AH7:AH22) | AI24: =AI22 | AJ24: =AJ22 | AK24: =AK22 | AL24: =AL22 | AM24: =AM22 | AN24: =AN22 | AO24: =AO22 | AP24: =AP22 | AQ24: =AQ22
A26: 注：季度行 7–22 对应 Q1–Q16；“合计/期末”行对流量项目求和、对存量项目取 Q16 期末值。所有蓝色格可直接修改以做情景测试，但会与引擎原始值不一致，仅供分析。

Sheet 利润表
A1: 利润表（逐季）
A2: 单位：十亿美元；比率除外。绿色为公式格，自动引用“原始数据”。
A5: 项目 | B5: Q1 | C5: Q2 | D5: Q3 | E5: Q4 | F5: Q5 | G5: Q6 | H5: Q7 | I5: Q8 | J5: Q9 | K5: Q10 | L5: Q11 | M5: Q12 | N5: Q13 | O5: Q14 | P5: Q15 | Q5: Q16 | R5: 合计 | S5: 说明 / 公式
A6: 营业收入 | B6: =B7+B8 | C6: =C7+C8 | D6: =D7+D8 | E6: =E7+E8 | F6: =F7+F8 | G6: =G7+G8 | H6: =H7+H8 | I6: =I7+I8 | ... Q6: =Q7+Q8 | R6: =SUM(B6:Q6) | S6: 普通内存收入 + HBM 收入
A7: 其中：普通内存 | B7: ='原始数据'!S7 | C7: ='原始数据'!S8 | D7: ='原始数据'!S9 | E7: ='原始数据'!S10 | F7: ='原始数据'!S11 | G7: ='原始数据'!S12 | H7: ='原始数据'!S13 | I7: ='原始数据'!S14 | J7: ='原始数据'!S15 | K7: ='原始数据'!S16 | L7: ='原始数据'!S17 | M7: ='原始数据'!S18 | N7: ='原始数据'!S19 | O7: ='原始数据'!S20 | P7: ='原始数据'!S21 | Q7: ='原始数据'!S22 | R7: =SUM(B7:Q7) | S7: 原始数据 S 列
A8: 其中：HBM | B8: ='原始数据'!T7 | C8: ='原始数据'!T8 | D8: ='原始数据'!T9 | E8: ='原始数据'!T10 | F8: ='原始数据'!T11 | G8: ='原始数据'!T12 | H8: ='原始数据'!T13 | I8: ='原始数据'!T14 | J8: ='原始数据'!T15 | K8: ='原始数据'!T16 | L8: ='原始数据'!T17 | M8: ='原始数据'!T18 | N8: ='原始数据'!T19 | O8: ='原始数据'!T20 | P8: ='原始数据'!T21 | Q8: ='原始数据'!T22 | R8: =SUM(B8:Q8) | S8: 原始数据 T 列
A9: 营业成本（含存货跌价） | B9: ='原始数据'!U7 | C9: ='原始数据'!U8 | D9: ='原始数据'!U9 | E9: ='原始数据'!U10 | F9: ='原始数据'!U11 | G9: ='原始数据'!U12 | H9: ='原始数据'!U13 | I9: ='原始数据'!U14 | J9: ='原始数据'!U15 | K9: ='原始数据'!U16 | L9: ='原始数据'!U17 | M9: ='原始数据'!U18 | N9: ='原始数据'!U19 | O9: ='原始数据'!U20 | P9: ='原始数据'!U21 | Q9: ='原始数据'!U22 | R9: =SUM(B9:Q9) | S9: 原始数据 U 列
A10: 其中：存货跌价 | B10: ='原始数据'!V7 | C10: ='原始数据'!V8 | D10: ='原始数据'!V9 | E10: ='原始数据'!V10 | F10: ='原始数据'!V11 | G10: ='原始数据'!V12 | H10: ='原始数据'!V13 | I10: ='原始数据'!V14 | J10: ='原始数据'!V15 | K10: ='原始数据'!V16 | L10: ='原始数据'!V17 | M10: ='原始数据'!V18 | N10: ='原始数据'!V19 | O10: ='原始数据'!V20 | P10: ='原始数据'!V21 | Q10: ='原始数据'!V22 | R10: =SUM(B10:Q10) | S10: 原始数据 V 列
A11: 毛利 | B11: =B6-B9 | C11: =C6-C9 | D11: =D6-D9 | E11: =E6-E9 | F11: =F6-F9 | G11: =G6-G9 | H11: =H6-H9 | I11: =I6-I9 | ... Q11: =Q6-Q9 | R11: =SUM(B11:Q11) | S11: 营业收入 − 营业成本
A12: 毛利率 | B12: =IFERROR(B11/B6,0) | C12: =IFERROR(C11/C6,0) | D12: =IFERROR(D11/D6,0) | E12: =IFERROR(E11/E6,0) | F12: =IFERROR(F11/F6,0) | G12: =IFERROR(G11/G6,0) | H12: =IFERROR(H11/H6,0) | I12: =IFERROR(I11/I6,0) | ... R12: =IFERROR(R11/R6,0) | S12: 毛利 ÷ 营业收入
A13: 研发费用 | B13: ='原始数据'!Y7 | C13: ='原始数据'!Y8 | D13: ='原始数据'!Y9 | E13: ='原始数据'!Y10 | F13: ='原始数据'!Y11 | G13: ='原始数据'!Y12 | H13: ='原始数据'!Y13 | I13: ='原始数据'!Y14 | J13: ='原始数据'!Y15 | K13: ='原始数据'!Y16 | L13: ='原始数据'!Y17 | M13: ='原始数据'!Y18 | N13: ='原始数据'!Y19 | O13: ='原始数据'!Y20 | P13: ='原始数据'!Y21 | Q13: ='原始数据'!Y22 | R13: =SUM(B13:Q13) | S13: 原始数据 Y 列（含基础 0.8 + HBM 额外研发）
A14: 销售及管理费用 | B14: ='原始数据'!Z7 | C14: ='原始数据'!Z8 | D14: ='原始数据'!Z9 | E14: ='原始数据'!Z10 | F14: ='原始数据'!Z11 | G14: ='原始数据'!Z12 | H14: ='原始数据'!Z13 | I14: ='原始数据'!Z14 | J14: ='原始数据'!Z15 | K14: ='原始数据'!Z16 | L14: ='原始数据'!Z17 | M14: ='原始数据'!Z18 | N14: ='原始数据'!Z19 | O14: ='原始数据'!Z20 | P14: ='原始数据'!Z21 | Q14: ='原始数据'!Z22 | R14: =SUM(B14:Q14) | S14: 原始数据 Z 列
A15: 营业利润 | B15: =B11-B13-B14 | C15: =C11-C13-C14 | D15: =D11-D13-D14 | E15: =E11-E13-E14 | F15: =F11-F13-F14 | G15: =G11-G13-G14 | H15: =H11-H13-H14 | I15: =I11-I13-I14 | ... Q15: =Q11-Q13-Q14 | R15: =SUM(B15:Q15) | S15: 毛利 − 研发 − 销售管理费用
A16: 营业利润率 | B16: =IFERROR(B15/B6,0) | C16: =IFERROR(C15/C6,0) | D16: =IFERROR(D15/D6,0) | E16: =IFERROR(E15/E6,0) | F16: =IFERROR(F15/F6,0) | G16: =IFERROR(G15/G6,0) | H16: =IFERROR(H15/H6,0) | I16: =IFERROR(I15/I6,0) | ... R16: =IFERROR(R15/R6,0) | S16: 营业利润 ÷ 营业收入
A17: 净利息费用（收益为负） | B17: ='原始数据'!AB7 | C17: ='原始数据'!AB8 | D17: ='原始数据'!AB9 | E17: ='原始数据'!AB10 | F17: ='原始数据'!AB11 | G17: ='原始数据'!AB12 | H17: ='原始数据'!AB13 | I17: ='原始数据'!AB14 | J17: ='原始数据'!AB15 | K17: ='原始数据'!AB16 | L17: ='原始数据'!AB17 | M17: ='原始数据'!AB18 | N17: ='原始数据'!AB19 | O17: ='原始数据'!AB20 | P17: ='原始数据'!AB21 | Q17: ='原始数据'!AB22 | R17: =SUM(B17:Q17) | S17: 原始数据 AB 列
A18: 税前利润 | B18: =B15-B17 | C18: =C15-C17 | D18: =D15-D17 | E18: =E15-E17 | F18: =F15-F17 | G18: =G15-G17 | H18: =H15-H17 | I18: =I15-I17 | ... Q18: =Q15-Q17 | R18: =SUM(B18:Q18) | S18: 营业利润 − 净利息费用
A19: 所得税 | B19: ='原始数据'!AC7 | C19: ='原始数据'!AC8 | D19: ='原始数据'!AC9 | E19: ='原始数据'!AC10 | F19: ='原始数据'!AC11 | G19: ='原始数据'!AC12 | H19: ='原始数据'!AC13 | I19: ='原始数据'!AC14 | J19: ='原始数据'!AC15 | K19: ='原始数据'!AC16 | L19: ='原始数据'!AC17 | M19: ='原始数据'!AC18 | N19: ='原始数据'!AC19 | O19: ='原始数据'!AC20 | P19: ='原始数据'!AC21 | Q19: ='原始数据'!AC22 | R19: =SUM(B19:Q19) | S19: 原始数据 AC 列（15%，亏损不征）
A20: 净利润 | B20: =B18-B19 | C20: =C18-C19 | D20: =D18-D19 | E20: =E18-E19 | F20: =F18-F19 | G20: =G18-G19 | H20: =H18-H19 | I20: =I18-I19 | ... Q20: =Q18-Q19 | R20: =SUM(B20:Q20) | S20: 税前利润 − 所得税
A21: 净利率 | B21: =IFERROR(B20/B6,0) | C21: =IFERROR(C20/C6,0) | D21: =IFERROR(D20/D6,0) | E21: =IFERROR(E20/E6,0) | F21: =IFERROR(F20/F6,0) | G21: =IFERROR(G20/G6,0) | H21: =IFERROR(H20/H6,0) | I21: =IFERROR(I20/I6,0) | ... R21: =IFERROR(R20/R6,0) | S21: 净利润 ÷ 营业收入
A22: 校验：净利润 − 引擎值 | B22: =B20-'原始数据'!AD7 | C22: =C20-'原始数据'!AD8 | D22: =D20-'原始数据'!AD9 | E22: =E20-'原始数据'!AD10 | F22: =F20-'原始数据'!AD11 | G22: =G20-'原始数据'!AD12 | H22: =H20-'原始数据'!AD13 | I22: =I20-'原始数据'!AD14 | J22: =J20-'原始数据'!AD15 | K22: =K20-'原始数据'!AD16 | L22: =L20-'原始数据'!AD17 | M22: =M20-'原始数据'!AD18 | N22: =N20-'原始数据'!AD19 | O22: =O20-'原始数据'!AD20 | P22: =P20-'原始数据'!AD21 | Q22: =Q20-'原始数据'!AD22 | R22: =SUM(B22:Q22) | S22: 应为 0；用于验证公式
A24: 读表提示
A25: • 毛利率在 Q2–Q4 为负，是价格跌破完全成本、且存货按市价 95% 计提跌价的结果；跌价不转回，会在复苏期转化为更高毛利。
A26: • 研发费用 Q1 为 3.80（基础 0.8 + HBM 3.0），Q2 起回到 0.80；这是 Q1 账面亏损的主因，不是经营恶化。
A27: • 营业利润、税前利润、净利润均为公式；修改“原始数据”任一输入，三行自动重算。

Sheet 资产负债表
A1: 资产负债表（逐季末）
A2: 单位：十亿美元；比率除外。绿色为公式格，自动引用“原始数据”。
A5: 项目 | B5: Q1 | C5: Q2 | D5: Q3 | E5: Q4 | F5: Q5 | G5: Q6 | H5: Q7 | I5: Q8 | J5: Q9 | K5: Q10 | L5: Q11 | M5: Q12 | N5: Q13 | O5: Q14 | P5: Q15 | Q5: Q16 | R5: Q16 / 期末 | S5: 说明 / 公式
A6: 货币资金 | B6: ='原始数据'!AI7 | C6: ='原始数据'!AI8 | D6: ='原始数据'!AI9 | E6: ='原始数据'!AI10 | F6: ='原始数据'!AI11 | G6: ='原始数据'!AI12 | H6: ='原始数据'!AI13 | I6: ='原始数据'!AI14 | J6: ='原始数据'!AI15 | K6: ='原始数据'!AI16 | L6: ='原始数据'!AI17 | M6: ='原始数据'!AI18 | N6: ='原始数据'!AI19 | O6: ='原始数据'!AI20 | P6: ='原始数据'!AI21 | Q6: ='原始数据'!AI22 | R6: =Q6 | S6: 原始数据 AI 列
A7: 存货 | B7: ='原始数据'!AJ7 | C7: ='原始数据'!AJ8 | D7: ='原始数据'!AJ9 | E7: ='原始数据'!AJ10 | F7: ='原始数据'!AJ11 | G7: ='原始数据'!AJ12 | H7: ='原始数据'!AJ13 | I7: ='原始数据'!AJ14 | J7: ='原始数据'!AJ15 | K7: ='原始数据'!AJ16 | L7: ='原始数据'!AJ17 | M7: ='原始数据'!AJ18 | N7: ='原始数据'!AJ19 | O7: ='原始数据'!AJ20 | P7: ='原始数据'!AJ21 | Q7: ='原始数据'!AJ22 | R7: =Q7 | S7: 原始数据 AJ 列（已计提跌价后的净额）
A8: 流动资产合计 | B8: =B6+B7 | C8: =C6+C7 | D8: =D6+D7 | E8: =E6+E7 | F8: =F6+F7 | G8: =G6+G7 | H8: =H6+H7 | I8: =I6+I7 | ... Q8: =Q6+Q7 | R8: =Q8 | S8: 货币资金 + 存货
A9: 净固定资产 | B9: ='原始数据'!AK7 | C9: ='原始数据'!AK8 | D9: ='原始数据'!AK9 | E9: ='原始数据'!AK10 | F9: ='原始数据'!AK11 | G9: ='原始数据'!AK12 | H9: ='原始数据'!AK13 | I9: ='原始数据'!AK14 | J9: ='原始数据'!AK15 | K9: ='原始数据'!AK16 | L9: ='原始数据'!AK17 | M9: ='原始数据'!AK18 | N9: ='原始数据'!AK19 | O9: ='原始数据'!AK20 | P9: ='原始数据'!AK21 | Q9: ='原始数据'!AK22 | R9: =Q9 | S9: 原始数据 AK 列（原值 − 累计折旧）
A10: 总资产 | B10: =B8+B9 | C10: =C8+C9 | D10: =D8+D9 | E10: =E8+E9 | F10: =F8+F9 | G10: =G8+G9 | H10: =H8+H9 | I10: =I8+I9 | ... Q10: =Q8+Q9 | R10: =Q10 | S10: 流动资产合计 + 净固定资产
A12: 银行借款 | B12: ='原始数据'!AM7 | C12: ='原始数据'!AM8 | D12: ='原始数据'!AM9 | E12: ='原始数据'!AM10 | F12: ='原始数据'!AM11 | G12: ='原始数据'!AM12 | H12: ='原始数据'!AM13 | I12: ='原始数据'!AM14 | J12: ='原始数据'!AM15 | K12: ='原始数据'!AM16 | L12: ='原始数据'!AM17 | M12: ='原始数据'!AM18 | N12: ='原始数据'!AM19 | O12: ='原始数据'!AM20 | P12: ='原始数据'!AM21 | Q12: ='原始数据'!AM22 | R12: =Q12 | S12: 原始数据 AM 列
A13: 紧急授信 | B13: ='原始数据'!AN7 | C13: ='原始数据'!AN8 | D13: ='原始数据'!AN9 | E13: ='原始数据'!AN10 | F13: ='原始数据'!AN11 | G13: ='原始数据'!AN12 | H13: ='原始数据'!AN13 | I13: ='原始数据'!AN14 | J13: ='原始数据'!AN15 | K13: ='原始数据'!AN16 | L13: ='原始数据'!AN17 | M13: ='原始数据'!AN18 | N13: ='原始数据'!AN19 | O13: ='原始数据'!AN20 | P13: ='原始数据'!AN21 | Q13: ='原始数据'!AN22 | R13: =Q13 | S13: 原始数据 AN 列（本局全程为 0）
A14: 负债合计 | B14: =B12+B13 | C14: =C12+C13 | D14: =D12+D13 | E14: =E12+E13 | F14: =F12+F13 | G14: =G12+G13 | H14: =H12+H13 | I14: =I12+I13 | ... Q14: =Q12+Q13 | R14: =Q14 | S14: 银行借款 + 紧急授信
A16: 股东权益 | B16: ='原始数据'!AO7 | C16: ='原始数据'!AO8 | D16: ='原始数据'!AO9 | E16: ='原始数据'!AO10 | F16: ='原始数据'!AO11 | G16: ='原始数据'!AO12 | H16: ='原始数据'!AO13 | I16: ='原始数据'!AO14 | J16: ='原始数据'!AO15 | K16: ='原始数据'!AO16 | L16: ='原始数据'!AO17 | M16: ='原始数据'!AO18 | N16: ='原始数据'!AO19 | O16: ='原始数据'!AO20 | P16: ='原始数据'!AO21 | Q16: ='原始数据'!AO22 | R16: =Q16 | S16: 原始数据 AO 列（总资产 − 负债）
A17: 负债和股东权益合计 | B17: =B14+B16 | C17: =C14+C16 | D17: =D14+D16 | E17: =E14+E16 | F17: =F14+F16 | G17: =G14+G16 | H17: =H14+H16 | I17: =I14+I16 | ... Q17: =Q14+Q16 | R17: =Q17 | S17: 负债合计 + 股东权益
A19: 资产平衡检查 | B19: =B10-B17 | C19: =C10-C17 | D19: =D10-D17 | E19: =E10-E17 | F19: =F10-F17 | G19: =G10-G17 | H19: =H10-H17 | I19: =I10-I17 | ... Q19: =Q10-Q17 | R19: =MAX(MAX(B19:Q19),-MIN(B19:Q19)) | S19: 总资产 − 负债和股东权益；应为 0
A20: 与引擎总资产差异 | B20: =B10-'原始数据'!AL7 | C20: =C10-'原始数据'!AL8 | D20: =D10-'原始数据'!AL9 | E20: =E10-'原始数据'!AL10 | F20: =F10-'原始数据'!AL11 | G20: =G10-'原始数据'!AL12 | H20: =H10-'原始数据'!AL13 | I20: =I10-'原始数据'!AL14 | J20: =J10-'原始数据'!AL15 | K20: =K10-'原始数据'!AL16 | L20: =L10-'原始数据'!AL17 | M20: =M10-'原始数据'!AL18 | N20: =N10-'原始数据'!AL19 | O20: =O10-'原始数据'!AL20 | P20: =P10-'原始数据'!AL21 | Q20: =Q10-'原始数据'!AL22 | R20: =MAX(MAX(B20:Q20),-MIN(B20:Q20)) | S20: 总资产 − 原始数据 AL；应为 0
A22: 资产负债率 | B22: =IFERROR(B14/B10,0) | C22: =IFERROR(C14/C10,0) | D22: =IFERROR(D14/D10,0) | E22: =IFERROR(E14/E10,0) | F22: =IFERROR(F14/F10,0) | G22: =IFERROR(G14/G10,0) | H22: =IFERROR(H14/H10,0) | I22: =IFERROR(I14/I10,0) | ... Q22: =IFERROR(Q14/Q10,0) | R22: =Q22 | S22: 负债合计 ÷ 总资产
A23: 净负债 | B23: =B14-B6 | C23: =C14-C6 | D23: =D14-D6 | E23: =E14-E6 | F23: =F14-F6 | G23: =G14-G6 | H23: =H14-H6 | I23: =I14-I6 | ... Q23: =Q14-Q6 | R23: =Q23 | S23: 负债合计 − 货币资金；负数为净现金
A24: 净负债 / 股东权益 | B24: =IFERROR(B23/B16,0) | C24: =IFERROR(C23/C16,0) | D24: =IFERROR(D23/D16,0) | E24: =IFERROR(E23/E16,0) | F24: =IFERROR(F23/F16,0) | G24: =IFERROR(G23/G16,0) | H24: =IFERROR(H23/H16,0) | I24: =IFERROR(I23/I16,0) | ... Q24: =IFERROR(Q23/Q16,0) | R24: =Q24 | S24: 净负债 ÷ 股东权益
A25: 流动比率 | B25: =IF(B14=0,"—",B8/B14) | C25: =IF(C14=0,"—",C8/C14) | D25: =IF(D14=0,"—",D8/D14) | E25: =IF(E14=0,"—",E8/E14) | F25: =IF(F14=0,"—",F8/F14) | G25: =IF(G14=0,"—",G8/G14) | H25: =IF(H14=0,"—",H8/H14) | I25: =IF(I14=0,"—",I8/I14) | ... Q25: =IF(Q14=0,"—",Q8/Q14) | R25: =IF(Q14=0,"—",Q8/Q14) | S25: 流动资产合计 ÷ 负债合计
A27: 期末存货（千片） | B27: ='原始数据'!AP7 | C27: ='原始数据'!AP8 | D27: ='原始数据'!AP9 | E27: ='原始数据'!AP10 | F27: ='原始数据'!AP11 | G27: ='原始数据'!AP12 | H27: ='原始数据'!AP13 | I27: ='原始数据'!AP14 | J27: ='原始数据'!AP15 | K27: ='原始数据'!AP16 | L27: ='原始数据'!AP17 | M27: ='原始数据'!AP18 | N27: ='原始数据'!AP19 | O27: ='原始数据'!AP20 | P27: ='原始数据'!AP21 | Q27: ='原始数据'!AP22 | R27: =Q27 | S27: 原始数据 AP 列
A28: 期末产能（千片/季） | B28: ='原始数据'!AQ7 | C28: ='原始数据'!AQ8 | D28: ='原始数据'!AQ9 | E28: ='原始数据'!AQ10 | F28: ='原始数据'!AQ11 | G28: ='原始数据'!AQ12 | H28: ='原始数据'!AQ13 | I28: ='原始数据'!AQ14 | J28: ='原始数据'!AQ15 | K28: ='原始数据'!AQ16 | L28: ='原始数据'!AQ17 | M28: ='原始数据'!AQ18 | N28: ='原始数据'!AQ19 | O28: ='原始数据'!AQ20 | P28: ='原始数据'!AQ21 | Q28: ='原始数据'!AQ22 | R28: =Q28 | S28: 原始数据 AQ 列
A30: 读表提示
A31: • 存货在 Q7 达到峰值 6.19（418 千片），随后在 Q8–Q14 的去库存中转化为利润；Q14 起清零。
A32: • 负债从 Q1 的 8.0 升到 Q4–Q9 的 16.0，Q13 还清；期末为净现金 180.92，零负债。
A33: • “资产平衡检查”“与引擎总资产差异”两行应恒为 0；若不为 0，说明公式或输入被改动。

Sheet 现金流量表
A1: 现金流量表（逐季）
A2: 单位：十亿美元。经营现金流按“净利润 + 折旧 − 存货变动”重算，并与引擎值逐季核对。
A5: 项目 | B5: Q1 | C5: Q2 | D5: Q3 | E5: Q4 | F5: Q5 | G5: Q6 | H5: Q7 | I5: Q8 | J5: Q9 | K5: Q10 | L5: Q11 | M5: Q12 | N5: Q13 | O5: Q14 | P5: Q15 | Q5: Q16 | R5: 合计 | S5: 说明 / 公式
A6: 净利润 | B6: =利润表!B20 | C6: =利润表!C20 | D6: =利润表!D20 | E6: =利润表!E20 | F6: =利润表!F20 | G6: =利润表!G20 | H6: =利润表!H20 | I6: =利润表!I20 | ... Q6: =利润表!Q20 | R6: =SUM(B6:Q6) | S6: 利润表第 20 行
A7: 加：折旧 | B7: ='原始数据'!AH7 | C7: ='原始数据'!AH8 | D7: ='原始数据'!AH9 | E7: ='原始数据'!AH10 | F7: ='原始数据'!AH11 | G7: ='原始数据'!AH12 | H7: ='原始数据'!AH13 | I7: ='原始数据'!AH14 | J7: ='原始数据'!AH15 | K7: ='原始数据'!AH16 | L7: ='原始数据'!AH17 | M7: ='原始数据'!AH18 | N7: ='原始数据'!AH19 | O7: ='原始数据'!AH20 | P7: ='原始数据'!AH21 | Q7: ='原始数据'!AH22 | R7: =SUM(B7:Q7) | S7: 原始数据 AH 列（非现金费用）
A8: 存货变动（期末 − 期初） | B8: =-('原始数据'!AJ7-假设与参数!$B$6) | C8: =-('原始数据'!AJ8-'原始数据'!AJ7) | D8: =-('原始数据'!AJ9-'原始数据'!AJ8) | E8: =-('原始数据'!AJ10-'原始数据'!AJ9) | F8: =-('原始数据'!AJ11-'原始数据'!AJ10) | G8: =-('原始数据'!AJ12-'原始数据'!AJ11) | H8: =-('原始数据'!AJ13-'原始数据'!AJ12) | I8: =-('原始数据'!AJ14-'原始数据'!AJ13) | J8: =-('原始数据'!AJ15-'原始数据'!AJ14) | K8: =-('原始数据'!AJ16-'原始数据'!AJ15) | L8: =-('原始数据'!AJ17-'原始数据'!AJ16) | M8: =-('原始数据'!AJ18-'原始数据'!AJ17) | N8: =-('原始数据'!AJ19-'原始数据'!AJ18) | O8: =-('原始数据'!AJ20-'原始数据'!AJ19) | P8: =-('原始数据'!AJ21-'原始数据'!AJ20) | Q8: =-('原始数据'!AJ22-'原始数据'!AJ21) | R8: =SUM(B8:Q8) | S8: 负数为存货增加、占用现金
A9: 经营现金流（计算） | B9: =B6+B7+B8 | C9: =C6+C7+C8 | D9: =D6+D7+D8 | E9: =E6+E7+E8 | F9: =F6+F7+F8 | G9: =G6+G7+G8 | H9: =H6+H7+H8 | I9: =I6+I7+I8 | ... Q9: =Q6+Q7+Q8 | R9: =SUM(B9:Q9) | S9: 净利润 + 折旧 − 存货增加
A10: 经营现金流（引擎） | B10: ='原始数据'!AE7 | C10: ='原始数据'!AE8 | D10: ='原始数据'!AE9 | E10: ='原始数据'!AE10 | F10: ='原始数据'!AE11 | G10: ='原始数据'!AE12 | H10: ='原始数据'!AE13 | I10: ='原始数据'!AE14 | J10: ='原始数据'!AE15 | K10: ='原始数据'!AE16 | L10: ='原始数据'!AE17 | M10: ='原始数据'!AE18 | N10: ='原始数据'!AE19 | O10: ='原始数据'!AE20 | P10: ='原始数据'!AE21 | Q10: ='原始数据'!AE22 | R10: =SUM(B10:Q10) | S10: 原始数据 AE 列
A11: 差异 | B11: =B9-B10 | C11: =C9-C10 | D11: =D9-D10 | E11: =E9-E10 | F11: =F9-F10 | G11: =G9-G10 | H11: =H9-H10 | I11: =I9-I10 | ... Q11: =Q9-Q10 | R11: =MAX(MAX(B11:Q11),-MIN(B11:Q11)) | S11: 计算值 − 引擎值；应为 0
A12: 投资现金流（−资本开支） | B12: ='原始数据'!AF7 | C12: ='原始数据'!AF8 | D12: ='原始数据'!AF9 | E12: ='原始数据'!AF10 | F12: ='原始数据'!AF11 | G12: ='原始数据'!AF12 | H12: ='原始数据'!AF13 | I12: ='原始数据'!AF14 | J12: ='原始数据'!AF15 | K12: ='原始数据'!AF16 | L12: ='原始数据'!AF17 | M12: ='原始数据'!AF18 | N12: ='原始数据'!AF19 | O12: ='原始数据'!AF20 | P12: ='原始数据'!AF21 | Q12: ='原始数据'!AF22 | R12: =SUM(B12:Q12) | S12: 原始数据 AF 列
A13: 筹资现金流（净借款） | B13: ='原始数据'!AG7 | C13: ='原始数据'!AG8 | D13: ='原始数据'!AG9 | E13: ='原始数据'!AG10 | F13: ='原始数据'!AG11 | G13: ='原始数据'!AG12 | H13: ='原始数据'!AG13 | I13: ='原始数据'!AG14 | J13: ='原始数据'!AG15 | K13: ='原始数据'!AG16 | L13: ='原始数据'!AG17 | M13: ='原始数据'!AG18 | N13: ='原始数据'!AG19 | O13: ='原始数据'!AG20 | P13: ='原始数据'!AG21 | Q13: ='原始数据'!AG22 | R13: =SUM(B13:Q13) | S13: 原始数据 AG 列
A14: 现金净变动 | B14: =B10+B12+B13 | C14: =C10+C12+C13 | D14: =D10+D12+D13 | E14: =E10+E12+E13 | F14: =F10+F12+F13 | G14: =G10+G12+G13 | H14: =H10+H12+H13 | I14: =I10+I12+I13 | ... Q14: =Q10+Q12+Q13 | R14: =SUM(B14:Q14) | S14: 经营 + 投资 + 筹资
A15: 期初现金 | B15: =假设与参数!$B$5 | C15: =B16 | D15: =C16 | E15: =D16 | F15: =E16 | G15: =F16 | H15: =G16 | I15: =H16 | J15: =I16 | ... Q15: =P16 | R15: =B15 | S15: Q1 取假设页期初值；其后取上季期末
A16: 期末现金（计算） | B16: =B15+B14 | C16: =C15+C14 | D16: =D15+D14 | E16: =E15+E14 | F16: =F15+F14 | G16: =G15+G14 | H16: =H15+H14 | I16: =I15+I14 | ... Q16: =Q15+Q14 | R16: =Q16 | S16: 期初现金 + 现金净变动
A17: 期末现金（引擎） | B17: ='原始数据'!AI7 | C17: ='原始数据'!AI8 | D17: ='原始数据'!AI9 | E17: ='原始数据'!AI10 | F17: ='原始数据'!AI11 | G17: ='原始数据'!AI12 | H17: ='原始数据'!AI13 | I17: ='原始数据'!AI14 | J17: ='原始数据'!AI15 | K17: ='原始数据'!AI16 | L17: ='原始数据'!AI17 | M17: ='原始数据'!AI18 | N17: ='原始数据'!AI19 | O17: ='原始数据'!AI20 | P17: ='原始数据'!AI21 | Q17: ='原始数据'!AI22 | R17: =Q17 | S17: 原始数据 AI 列
A18: 差异 | B18: =B16-B17 | C18: =C16-C17 | D18: =D16-D17 | E18: =E16-E17 | F18: =F16-F17 | G18: =G16-G17 | H18: =H16-H17 | I18: =I16-I17 | ... Q18: =Q16-Q17 | R18: =MAX(MAX(B18:Q18),-MIN(B18:Q18)) | S18: 计算值 − 引擎值；应为 0
A19: 自由现金流 | B19: =B10-'原始数据'!H7 | C19: =C10-'原始数据'!H8 | D19: =D10-'原始数据'!H9 | E19: =E10-'原始数据'!H10 | F19: =F10-'原始数据'!H11 | G19: =G10-'原始数据'!H12 | H19: =H10-'原始数据'!H13 | I19: =I10-'原始数据'!H14 | J19: =J10-'原始数据'!H15 | K19: =K10-'原始数据'!H16 | L19: =L10-'原始数据'!H17 | M19: =M10-'原始数据'!H18 | N19: =N10-'原始数据'!H19 | O19: =O10-'原始数据'!H20 | P19: =P10-'原始数据'!H21 | Q19: =Q10-'原始数据'!H22 | R19: =SUM(B19:Q19) | S19: 经营现金流 − 资本开支
A20: 累计自由现金流 | B20: =B19 | C20: =B20+C19 | D20: =C20+D19 | E20: =D20+E19 | F20: =E20+F19 | G20: =F20+G19 | H20: =G20+H19 | I20: =H20+I19 | J20: =I20+J19 | ... Q20: =P20+Q19 | R20: =Q20 | S20: 逐季累加
A22: 读表提示
A23: • 本局经营现金流 16 季累计 217.42，资本开支累计 40.50，自由现金流累计 176.92。
A24: • 存货变动是经营现金流与净利润差异的主因：Q2–Q7 累库（现金流出），Q8–Q14 去库（现金流入）。
A25: • 期末现金由“期初 + 经营 + 投资 + 筹资”独立重算，与引擎值逐季核对，差异应为 0。

Sheet 假设与参数
A1: 假设与参数
A2: 黄色格为可修改的假设输入；蓝色格为引擎披露的期初状态；绿色格为公式。修改后所有报表、比率与敏感性自动联动。
A4: 参数 | B4: 数值 | C4: 单位 | D4: 类型 | E4: 依据 / 说明
A5: 期初现金 | B5: 10 | C5: 十亿美元 | D5: 披露 | E5: 第 0 季末 state：cash
A6: 期初存货 | B6: 0.96 | C6: 十亿美元 | D6: 披露 | E6: 第 0 季末 state：inventory（60 千片）
A7: 期初净固定资产 | B7: 30 | C7: 十亿美元 | D7: 披露 | E7: 第 0 季末 state：ppe_net
A8: 期初借款 | B8: 6 | C8: 十亿美元 | D8: 披露 | E8: 第 0 季末 state：debt
A9: 期初股东权益 | B9: 34.96 | C9: 十亿美元 | D9: 披露 | E9: 第 0 季末 state：equity
A10: 期初总资产 | B10: 40.96 | C10: 十亿美元 | D10: 披露 | E10: 第 0 季末 state：total_assets
A11: 期初产能 | B11: 300 | C11: 千片/季 | D11: 披露 | E11: 第 0 季末 state：capacity_kwafers
A12: 普通内存基准价 | B12: 24 | C12: 百万美元/千片 | D12: 假设 | E12: 反推：Q1 收入 4.608 ÷ 240 千片 ÷ 0.80 = 24.0
A13: 可变成本 | B13: 5 | C13: 百万美元/千片 | D13: 假设 | E13: 反推：单位成本 = 5 + (折旧+1.0)×1000÷产量
A14: 季度固定制造费用 | B14: 1 | C14: 十亿美元 | D14: 假设 | E14: 反推：与折旧一起构成固定成本；不随产量变化
A15: 折旧年限 | B15: 20 | C15: 季度 | D15: 假设 | E15: 规则：资本开支按 20 个季度直线折旧
A16: 维持性资本开支 | B16: 1.5 | C16: 十亿美元/季 | D16: 假设 | E16: 规则：每季先要 15 亿美元维持现有产能
... A31: 紧急授信季利率 | B31: 0.03 | C31: % | D31: 披露 | E31: 规则：季利率 3%
A34: 这些参数是怎么来的
A35: • “披露”来自游戏规则 /rules 与初始 state；“假设”是从 16 季三张表反推出来的模型参数，不是引擎披露的事实。
A36: • 反推校验：用上述参数重算的收入、单位成本、利息、所得税、资产负债表和现金流量表，与引擎值的最大误差均在 0.0005 以内。
A37: • 颜色：黄色 = 假设输入；蓝色 = 引擎披露的期初数据；绿色 = 公式。改黄色格，分析页的敏感性与报表会自动重算。
A38: • 免责：本工作簿是经营模拟复盘，不构成投资建议。

Sheet 分析
A1: 经营分析：16 季比率、现金流与敏感性
A2: 所有数值均为公式，引用三张表与“假设与参数”。单位：十亿美元；比率为百分比。
A3: 累计营业收入 | C3: 累计净利润 | E3: 期末股东权益 | G3: 权益倍数 | I3: 累计经营现金流 | K3: 累计资本开支
A4: =利润表!R6 | C4: =利润表!R20 | E4: =资产负债表!Q16 | G4: =E4/假设与参数!B9 | I4: =现金流量表!R10 | K4: =SUM(原始数据!H7:H22)
A5: 十亿美元 | C5: 十亿美元 | E5: 十亿美元 | G5: 倍 | I5: 十亿美元 | K5: 十亿美元
A7: 累计自由现金流 | C7: HBM 收入占比 | E7: 峰值存货 | G7: 峰值有息负债 | I7: 最低现金 | K7: 期末净负债
A8: =现金流量表!R20 | C8: =利润表!R8/利润表!R6 | E8: =MAX(资产负债表!B7:Q7) | G8: =MAX(资产负债表!B14:Q14) | I8: =MIN(资产负债表!B6:Q6) | K8: =资产负债表!Q23
A9: 十亿美元 | C9: % | E9: 十亿美元 | G9: 十亿美元 | I9: 十亿美元 | K9: 十亿美元（负=净现金）
A12: 指标 | B12: Q1 | C12: Q2 | D12: Q3 | E12: Q4 | F12: Q5 | G12: Q6 | H12: Q7 | I12: Q8 | J12: Q9 | K12: Q10 | L12: Q11 | M12: Q12 | N12: Q13 | O12: Q14 | P12: Q15 | Q12: Q16 | R12: 合计/平均 | S12: 口径
A13: 营业收入 | B13: =利润表!B6 | C13: =利润表!C6 | D13: =利润表!D6 | E13: =利润表!E6 | F13: =利润表!F6 | G13: =利润表!G6 | H13: =利润表!H6 | I13: =利润表!I6 | ... Q13: =利润表!Q6 | R13: =SUM(B13:Q13) | S13: 利润表
A14: 毛利 | B14: =利润表!B11 | C14: =利润表!C11 | D14: =利润表!D11 | E14: =利润表!E11 | F14: =利润表!F11 | G14: =利润表!G11 | H14: =利润表!H11 | I14: =利润表!I11 | ... Q14: =利润表!Q11 | R14: =SUM(B14:Q14) | S14: 利润表
A15: 毛利率 | B15: =IFERROR(B14/B13,0) | C15: =IFERROR(C14/C13,0) | D15: =IFERROR(D14/D13,0) | E15: =IFERROR(E14/E13,0) | F15: =IFERROR(F14/F13,0) | G15: =IFERROR(G14/G13,0) | H15: =IFERROR(H14/H13,0) | I15: =IFERROR(I14/I13,0) | ... R15: =IFERROR(R14/R13,0) | S15: 毛利 ÷ 营业收入
A16: 净利润 | B16: =利润表!B20 | C16: =利润表!C20 | D16: =利润表!D20 | E16: =利润表!E20 | F16: =利润表!F20 | G16: =利润表!G20 | H16: =利润表!H20 | I16: =利润表!I20 | ... Q16: =利润表!Q20 | R16: =SUM(B16:Q16) | S16: 利润表
A17: 净利率 | B17: =IFERROR(B16/B13,0) | C17: =IFERROR(C16/C13,0) | D17: =IFERROR(D16/D13,0) | E17: =IFERROR(E16/E13,0) | F17: =IFERROR(F16/F13,0) | G17: =IFERROR(G16/G13,0) | H17: =IFERROR(H16/H13,0) | I17: =IFERROR(I16/I13,0) | ... R17: =IFERROR(R16/R13,0) | S17: 净利润 ÷ 营业收入
A18: 经营现金流 | B18: =现金流量表!B10 | C18: =现金流量表!C10 | D18: =现金流量表!D10 | E18: =现金流量表!E10 | F18: =现金流量表!F10 | G18: =现金流量表!G10 | H18: =现金流量表!H10 | I18: =现金流量表!I10 | ... Q18: =现金流量表!Q10 | R18: =SUM(B18:Q18) | S18: 现金流量表（引擎值）
A19: 资本开支 | B19: ='原始数据'!H7 | C19: ='原始数据'!H8 | D19: ='原始数据'!H9 | E19: ='原始数据'!H10 | F19: ='原始数据'!H11 | G19: ='原始数据'!H12 | H19: ='原始数据'!H13 | I19: ='原始数据'!H14 | J19: ='原始数据'!H15 | K19: ='原始数据'!H16 | L19: ='原始数据'!H17 | M19: ='原始数据'!H18 | N19: ='原始数据'!H19 | O19: ='原始数据'!H20 | P19: ='原始数据'!H21 | Q19: ='原始数据'!H22 | R19: =SUM(B19:Q19) | S19: 原始数据 H 列
A20: 自由现金流 | B20: =B18-B19 | C20: =C18-C19 | D20: =D18-D19 | E20: =E18-E19 | F20: =F18-F19 | G20: =G18-G19 | H20: =H18-H19 | I20: =I18-I19 | ... Q20: =Q18-Q19 | R20: =SUM(B20:Q20) | S20: 经营现金流 − 资本开支
A21: 期末现金 | B21: =资产负债表!B6 | C21: =资产负债表!C6 | D21: =资产负债表!D6 | E21: =资产负债表!E6 | F21: =资产负债表!F6 | G21: =资产负债表!G6 | H21: =资产负债表!H6 | I21: =资产负债表!I6 | ... Q21: =资产负债表!Q6 | R21: =Q21 | S21: 资产负债表
A22: 有息负债 | B22: =资产负债表!B14 | C22: =资产负债表!C14 | D22: =资产负债表!D14 | E22: =资产负债表!E14 | F22: =资产负债表!F14 | G22: =资产负债表!G14 | H22: =资产负债表!H14 | I22: =资产负债表!I14 | ... Q22: =资产负债表!Q14 | R22: =Q22 | S22: 资产负债表（借款 + 紧急授信）
A23: 净负债 | B23: =B22-B21 | C23: =C22-C21 | D23: =D22-D21 | E23: =E22-E21 | F23: =F22-F21 | G23: =G22-G21 | H23: =H22-H21 | I23: =I22-I21 | ... Q23: =Q22-Q21 | R23: =Q23 | S23: 有息负债 − 现金
A24: 股东权益 | B24: =资产负债表!B16 | C24: =资产负债表!C16 | D24: =资产负债表!D16 | E24: =资产负债表!E16 | F24: =资产负债表!F16 | G24: =资产负债表!G16 | H24: =资产负债表!H16 | I24: =资产负债表!I16 | ... Q24: =资产负债表!Q16 | R24: =Q24 | S24: 资产负债表
A25: 平均股东权益 | B25: =(假设与参数!$B$9+B24)/2 | C25: =(B24+C24)/2 | D25: =(C24+D24)/2 | E25: =(D24+E24)/2 | F25: =(E24+F24)/2 | G25: =(F24+G24)/2 | H25: =(G24+H24)/2 | I25: =(H24+I24)/2 | J25: =(I24+J24)/2 | ... Q25: =(P24+Q24)/2 | R25: =AVERAGE(B25:Q25) | S25: 期初、期末平均
A26: 单季 ROE | B26: =IFERROR(B16/B25,0) | C26: =IFERROR(C16/C25,0) | D26: =IFERROR(D16/D25,0) | E26: =IFERROR(E16/E25,0) | F26: =IFERROR(F16/F25,0) | G26: =IFERROR(G16/G25,0) | H26: =IFERROR(H16/H25,0) | I26: =IFERROR(I16/I25,0) | ... Q26: =IFERROR(Q16/Q25,0) | R26: =AVERAGE(B26:Q26) | S26: 净利润 ÷ 平均股东权益
A27: 年化 ROE | B27: =B26*假设与参数!$B$21 | C27: =C26*假设与参数!$B$21 | D27: =D26*假设与参数!$B$21 | E27: =E26*假设与参数!$B$21 | F27: =F26*假设与参数!$B$21 | G27: =G26*假设与参数!$B$21 | H27: =H26*假设与参数!$B$21 | I27: =I26*假设与参数!$B$21 | ... Q27: =Q26*假设与参数!$B$21 | R27: =R26*假设与参数!B21 | S27: 单季 ROE × 4
A28: 平均总资产 | B28: =(假设与参数!$B$10+资产负债表!B10)/2 | C28: =(资产负债表!B10+资产负债表!C10)/2 | D28: =(资产负债表!C10+资产负债表!D10)/2 | E28: =(资产负债表!D10+资产负债表!E10)/2 | F28: =(资产负债表!E10+资产负债表!F10)/2 | G28: =(资产负债表!F10+资产负债表!G10)/2 | H28: =(资产负债表!G10+资产负债表!H10)/2 | I28: =(资产负债表!H10+资产负债表!I10)/2 | J28: =(资产负债表!I10+资产负债表!J10)/2 | ... Q28: =(资产负债表!P10+资产负债表!Q10)/2 | R28: =AVERAGE(B28:Q28) | S28: 期初、期末平均
A29: 年化 ROA | B29: =IFERROR(B16/B28*假设与参数!$B$21,0) | C29: =IFERROR(C16/C28*假设与参数!$B$21,0) | D29: =IFERROR(D16/D28*假设与参数!$B$21,0) | E29: =IFERROR(E16/E28*假设与参数!$B$21,0) | F29: =IFERROR(F16/F28*假设与参数!$B$21,0) | G29: =IFERROR(G16/G28*假设与参数!$B$21,0) | H29: =IFERROR(H16/H28*假设与参数!$B$21,0) | I29: =IFERROR(I16/I28*假设与参数!$B$21,0) | ... Q29: =IFERROR(Q16/Q28*假设与参数!$B$21,0) | R29: =AVERAGE(B29:Q29) | S29: 净利润 ÷ 平均总资产 × 4
A30: 存货（期末） | B30: =资产负债表!B7 | C30: =资产负债表!C7 | D30: =资产负债表!D7 | E30: =资产负债表!E7 | F30: =资产负债表!F7 | G30: =资产负债表!G7 | H30: =资产负债表!H7 | I30: =资产负债表!I7 | ... Q30: =资产负债表!Q7 | R30: =Q30 | S30: 资产负债表
A31: 平均存货 | B31: =(假设与参数!$B$6+B30)/2 | C31: =(B30+C30)/2 | D31: =(C30+D30)/2 | E31: =(D30+E30)/2 | F31: =(E30+F30)/2 | G31: =(F30+G30)/2 | H31: =(G30+H30)/2 | I31: =(H30+I30)/2 | J31: =(I30+J30)/2 | ... Q31: =(P30+Q30)/2 | R31: =AVERAGE(B31:Q31) | S31: 期初、期末平均
A32: 营业成本 | B32: =利润表!B9 | C32: =利润表!C9 | D32: =利润表!D9 | E32: =利润表!E9 | F32: =利润表!F9 | G32: =利润表!G9 | H32: =利润表!H9 | I32: =利润表!I9 | ... Q32: =利润表!Q9 | R32: =SUM(B32:Q32) | S32: 利润表
A33: 存货周转天数 | B33: =IFERROR(B31/B32*假设与参数!$B$22,0) | C33: =IFERROR(C31/C32*假设与参数!$B$22,0) | D33: =IFERROR(D31/D32*假设与参数!$B$22,0) | E33: =IFERROR(E31/E32*假设与参数!$B$22,0) | F33: =IFERROR(F31/F32*假设与参数!$B$22,0) | G33: =IFERROR(G31/G32*假设与参数!$B$22,0) | H33: =IFERROR(H31/H32*假设与参数!$B$22,0) | I33: =IFERROR(I31/I32*假设与参数!$B$22,0) | ... Q33: =IFERROR(Q31/Q32*假设与参数!$B$22,0) | R33: =AVERAGEIF(B33:Q33,">0") | S33: 平均存货 ÷ 营业成本 × 90
A34: 存货周转率 | B34: =IFERROR(B32/B31,0) | C34: =IFERROR(C32/C31,0) | D34: =IFERROR(D32/D31,0) | E34: =IFERROR(E32/E31,0) | F34: =IFERROR(F32/F31,0) | G34: =IFERROR(G32/G31,0) | H34: =IFERROR(H32/H31,0) | I34: =IFERROR(I32/I31,0) | ... Q34: =IFERROR(Q32/Q31,0) | R34: =AVERAGEIF(B34:Q34,">0") | S34: 营业成本 ÷ 平均存货
A35: 资产负债率 | B35: =IFERROR(B22/资产负债表!B10,0) | C35: =IFERROR(C22/资产负债表!C10,0) | D35: =IFERROR(D22/资产负债表!D10,0) | E35: =IFERROR(E22/资产负债表!E10,0) | F35: =IFERROR(F22/资产负债表!F10,0) | G35: =IFERROR(G22/资产负债表!G10,0) | H35: =IFERROR(H22/资产负债表!H10,0) | I35: =IFERROR(I22/资产负债表!I10,0) | ... Q35: =IFERROR(Q22/资产负债表!Q10,0) | R35: =IFERROR(AVERAGE(B22:Q22)/AVERAGE(资产负债表!B10:Q10),0) | S35: 有息负债 ÷ 总资产
A36: 净负债 / 股东权益 | B36: =IFERROR(B23/B24,0) | C36: =IFERROR(C23/C24,0) | D36: =IFERROR(D23/D24,0) | E36: =IFERROR(E23/E24,0) | F36: =IFERROR(F23/F24,0) | G36: =IFERROR(G23/G24,0) | H36: =IFERROR(H23/H24,0) | I36: =IFERROR(I23/I24,0) | ... Q36: =IFERROR(Q23/Q24,0) | R36: =IFERROR(Q23/Q24,0) | S36: 净负债 ÷ 股东权益
A37: 产能利用率 | B37: =IFERROR('原始数据'!L7/'原始数据'!Q7,0) | C37: =IFERROR('原始数据'!L8/'原始数据'!Q8,0) | D37: =IFERROR('原始数据'!L9/'原始数据'!Q9,0) | E37: =IFERROR('原始数据'!L10/'原始数据'!Q10,0) | F37: =IFERROR('原始数据'!L11/'原始数据'!Q11,0) | G37: =IFERROR('原始数据'!L12/'原始数据'!Q12,0) | H37: =IFERROR('原始数据'!L13/'原始数据'!Q13,0) | I37: =IFERROR('原始数据'!L14/'原始数据'!Q14,0) | J37: =IFERROR('原始数据'!L15/'原始数据'!Q15,0) | K37: =IFERROR('原始数据'!L16/'原始数据'!Q16,0) | L37: =IFERROR('原始数据'!L17/'原始数据'!Q17,0) | M37: =IFERROR('原始数据'!L18/'原始数据'!Q18,0) | N37: =IFERROR('原始数据'!L19/'原始数据'!Q19,0) | O37: =IFERROR('原始数据'!L20/'原始数据'!Q20,0) | P37: =IFERROR('原始数据'!L21/'原始数据'!Q21,0) | Q37: =IFERROR('原始数据'!L22/'原始数据'!Q22,0) | R37: =AVERAGE(B37:Q37) | S37: 产量 ÷ 产能
A38: HBM 产量占比 | B38: =IFERROR('原始数据'!M7/'原始数据'!L7,0) | C38: =IFERROR('原始数据'!M8/'原始数据'!L8,0) | D38: =IFERROR('原始数据'!M9/'原始数据'!L9,0) | E38: =IFERROR('原始数据'!M10/'原始数据'!L10,0) | F38: =IFERROR('原始数据'!M11/'原始数据'!L11,0) | G38: =IFERROR('原始数据'!M12/'原始数据'!L12,0) | H38: =IFERROR('原始数据'!M13/'原始数据'!L13,0) | I38: =IFERROR('原始数据'!M14/'原始数据'!L14,0) | J38: =IFERROR('原始数据'!M15/'原始数据'!L15,0) | K38: =IFERROR('原始数据'!M16/'原始数据'!L16,0) | L38: =IFERROR('原始数据'!M17/'原始数据'!L17,0) | M38: =IFERROR('原始数据'!M18/'原始数据'!L18,0) | N38: =IFERROR('原始数据'!M19/'原始数据'!L19,0) | O38: =IFERROR('原始数据'!M20/'原始数据'!L20,0) | P38: =IFERROR('原始数据'!M21/'原始数据'!L21,0) | Q38: =IFERROR('原始数据'!M22/'原始数据'!L22,0) | R38: =AVERAGE(B38:Q38) | S38: HBM 产量 ÷ 总产量
A39: HBM 收入占比 | B39: =IFERROR(利润表!B8/利润表!B6,0) | C39: =IFERROR(利润表!C8/利润表!C6,0) | D39: =IFERROR(利润表!D8/利润表!D6,0) | E39: =IFERROR(利润表!E8/利润表!E6,0) | F39: =IFERROR(利润表!F8/利润表!F6,0) | G39: =IFERROR(利润表!G8/利润表!G6,0) | H39: =IFERROR(利润表!H8/利润表!H6,0) | I39: =IFERROR(利润表!I8/利润表!I6,0) | ... Q39: =IFERROR(利润表!Q8/利润表!Q6,0) | R39: =AVERAGE(B39:Q39) | S39: HBM 收入 ÷ 营业收入
A40: 收入环比增速 | C40: =IFERROR(C13/B13-1,0) | D40: =IFERROR(D13/C13-1,0) | E40: =IFERROR(E13/D13-1,0) | F40: =IFERROR(F13/E13-1,0) | G40: =IFERROR(G13/F13-1,0) | H40: =IFERROR(H13/G13-1,0) | I40: =IFERROR(I13/H13-1,0) | J40: =IFERROR(J13/I13-1,0) | ... Q40: =IFERROR(Q13/P13-1,0) | R40: =AVERAGE(B40:Q40) | S40: 本季 ÷ 上季 − 1
A41: EBITDA | B41: =利润表!B15+现金流量表!B7 | C41: =利润表!C15+现金流量表!C7 | D41: =利润表!D15+现金流量表!D7 | E41: =利润表!E15+现金流量表!E7 | F41: =利润表!F15+现金流量表!F7 | G41: =利润表!G15+现金流量表!G7 | H41: =利润表!H15+现金流量表!H7 | I41: =利润表!I15+现金流量表!I7 | ... Q41: =利润表!Q15+现金流量表!Q7 | R41: =SUM(B41:Q41) | S41: 营业利润 + 折旧
A42: EBITDA 利润率 | B42: =IFERROR(B41/B13,0) | C42: =IFERROR(C41/C13,0) | D42: =IFERROR(D41/D13,0) | E42: =IFERROR(E41/E13,0) | F42: =IFERROR(F41/F13,0) | G42: =IFERROR(G41/G13,0) | H42: =IFERROR(H41/H13,0) | I42: =IFERROR(I41/I13,0) | ... R42: =IFERROR(R41/R13,0) | S42: EBITDA ÷ 营业收入
A43: 累计净利润 | B43: =B16 | C43: =B43+C16 | D43: =C43+D16 | E43: =D43+E16 | F43: =E43+F16 | G43: =F43+G16 | H43: =G43+H16 | I43: =H43+I16 | J43: =I43+J16 | ... Q43: =P43+Q16 | R43: =Q43 | S43: 逐季累加
...

Sheet 图表
A1: 图表：16 季关键曲线
A2: 数据源：利润表、资产负债表、现金流量表与“分析”页；单位为十亿美元或百分比。

Sheet 数据源
A1: 数据源与追溯
A2: 每个财务科目对应的引擎字段；所有原始值归档在 工作/export.json。
A4: 科目 | B4: 引擎字段路径 | C4: 说明
A5: 营业收入 | B5: history[q].income_statement.revenue | C5: 普通内存 + HBM 收入合计
A6: 普通内存收入 | B6: history[q].income_statement.revenue_std | C6: ＝ 销量 × 24.0 × 价格指数
A7: HBM 收入 | B7: history[q].income_statement.revenue_hbm | C7: ＝ HBM 销量 × 24.0 × HBM 价格指数
A8: 营业成本 | B8: history[q].income_statement.cogs | C8: 含存货跌价；加权平均成本
A9: 存货跌价 | B9: history[q].income_statement.inventory_writedown | C9: 市价 × 95% 低于账面成本时计提
A10: 研发费用 | B10: history[q].income_statement.rnd | C10: 基础 0.8 + 当季 HBM 额外研发
A11: 销售管理费用 | B11: history[q].income_statement.sga | C11: 固定 0.25/季
A12: 净利息 | B12: history[q].income_statement.net_interest | C12: 期初借款 × 1.5% − 期初现金 × 0.8%
A13: 所得税 | B13: history[q].income_statement.tax | C13: 税前利润 × 15%，亏损不征
A14: 净利润 | B14: history[q].income_statement.net_income | C14: 税前利润 − 所得税
A15: 经营现金流 | B15: history[q].cash_flow.operating | C15: 净利润 + 折旧 − 存货增加
... A33: 最终结果 | B33: 工作/export.json → final / cumulative_net_income | C33: 期末权益 208.7749；累计净利 173.8149
A36: 校验结果（16 季最大绝对误差）
A37: 校验项 | B37: 最大误差 | C37: 结论
A38: 营业收入 = 销量 × 24 × 价格指数 | B38: 0.0004 十亿美元 | C38: 四舍五入范围内一致
A39: 单位成本 = 5 + (折旧+1)×1000÷产量 | B39: 0.0005 百万美元/千片 | C39: 一致
A40: 净利息 = 期初借款×1.5% − 期初现金×0.8% | B40: 0.00005 十亿美元 | C40: 一致
A41: 所得税 = max(0,税前)×15% | B41: 0.00005 十亿美元 | C41: 一致
A42: 资产 = 负债 + 权益 | B42: 0.0001 十亿美元 | C42: 一致
A43: 期末现金 = 期初 + 经营 + 投资 + 筹资 | B43: 0.0001 十亿美元 | C43: 一致
A44: 存货跌价 = max(0, 成本 − 市价×95%) | B44: 逐季一致 | C44: 一致
