Workbook

Sheet 封面说明
A1: AI 的电从哪来 · 数据表
A2: Supporting data workbook for the industry research report | 2026-10-22 | v1.0
A4: 这份工作簿是什么
A5: 本工作簿是《AI 的电从哪来》研究报告的数据底稿，覆盖：全球与美国数据中心用电、科技巨头 2026 年资本开支、Meta 最新季报、核电长期购电协议、美国数据中心供电结构、LCOE、聚变公司融资与时间表、以及电网/设备/许可瓶颈。 所有明细行都标注了来源编号（S01–S34，见“来源清单”）、发布日期和口径说明。汇总页的每个数字都由公式从明细表计算，不是手工填入。改动“假设与情景”中的黄色输入格，汇总页、图表和网页数据底稿会同步变化。
A12: 工作表索引
A13: 工作表 | B13: 内容
A14: 汇总 | B14: 核心数字与 2 张图表（另见“图表”页）；全部为公式
A15: 假设与情景 | B15: 31 个参数：事实、假设、计算；黄色可改
A16: 需求_全球 | B16: 2024 / 2030 / 2035 全球数据中心用电
A17: 需求_区域 | B17: 美国、中国、欧洲、其他地区拆分
A18: 科技巨头_CapEx | B18: 五家公司 2026 年资本开支指引
A19: Meta_财务 | B19: 2026Q3 收入、资本开支、承诺、合资企业
A20: 核电_PPA | B20: 10 笔长期核电/聚变购电协议 + Meta 组合
A21: 供给结构 | B21: 美国数据中心 2024 vs 2030 电源结构
A22: 成本_LCOE | B22: Lazard 2026 LCOE 与核电 PPA 价格
A23: 聚变_公司 | B23: 8 家聚变公司融资、时间表、PPA
A24: 瓶颈指标 | B24: 互联队列、变压器、燃机、Vogtle 等
A25: 来源清单 | B25: 34 个来源的机构、日期、定位
A28: 阅读约定
A29: 黄色：输入格（披露事实或假设） | C29: 蓝色：公式格（自动计算） | E29: 绿色：关键结果格
A31: 重要说明
A32: 1. 本工作簿是研究与展示用的分析，不是投资建议；不提供买入、卖出、持有评级或目标价，也不评价股价。 2. 财务数字以任务提供的三份原始文件为准；网页来源标注了链接与访问日期。 3. 标注为“假设”的参数不是公司披露。关键假设：美国 2030 年占全球数据中心用电 47%、2030 年电源结构、Meta 2024–2026 年用电增速 30%、核电年利用小时 7,884。 4. 价格为分析师估算（Jefferies）或“未披露”，未用假设替代未披露价格。 5. 数据截至 2026-10-22；之后发生的事件未纳入。 6. 本工作簿不含网址二维码、微信号、手机号、邮箱、公司标志或国旗。

Sheet 汇总
A1: AI 的电从哪来：核心数字与图表
A2: 全部数值由明细表公式计算；改动“假设与情景”的黄色格，本页与图表自动更新。数据截至 2026-10-22。
A4: 一、需求：AI 用了多少电
A5: 指标 | B5: 数值 | C5: 单位 | D5: 口径 / 公式 | E5: 来源
A6: 全球数据中心用电（2024） | B6: =需求_全球!B5 -> 415 | C6: TWh | D6: IEA 基准口径 | E6: S04
A7: 全球数据中心用电（2030） | B7: =需求_全球!B6 -> 945 | C7: TWh | D7: IEA 基准情景 | E7: S04
A8: 全球数据中心用电（2035） | B8: =需求_全球!B7 -> 1200 | C8: TWh | D8: IEA 基准情景 | E8: S04
A9: 2024–2030 复合增速 | B9: =(需求_全球!B6/需求_全球!B5)^(1/6)-1 -> 0.14700141 | C9: % | D9: （2030/2024）^(1/6)-1 | E9: S04
A10: 美国数据中心用电（2024） | B10: =需求_区域!C5 -> 186.75 | C10: TWh | D10: 全球 415 × 45% | E10: S04
A11: 美国数据中心用电（2030） | B11: =需求_区域!E5 -> 444.15 | C11: TWh | D11: 全球 945 × 47%（假设 A07） | E11: S04
A12: 美国 2030 年数据中心用电 / 2025 年全国发电量 | B12: =B11/假设与情景!C14 -> 0.10025959 | C12: % | D12: 444 / 4,430 | E12: S17
A13: 美国 2030 年较 2024 年增量 | B13: =B11-B10 -> 257.4 | C13: TWh | D13: 约 257 TWh | E13: 计算
A14: Meta 数据中心用电（2024，披露） | B14: =假设与情景!C16 -> 18.061781 | C14: TWh | D14: 18,061,781 MWh | E14: S06
A15: Meta 数据中心用电（2026，估算） | B15: =假设与情景!C16*(1+假设与情景!C17)^2 -> 30.52441 | C15: TWh | D15: 2024 基数 ×（1+30%）²（假设 A13） | E15: S06
A16: Meta 2026 估算用电 / 美国 2030 需求 | B16: =B15/B11 -> 0.068725453 | C16: % | D16: 约 6.9% | E16: 计算
A18: 二、供给：电从哪里来（美国数据中心，2030）
A19: 电源 | B19: 2030 TWh | C19: 2030 占比 | D19: 2024 TWh | E19: 2024→2030 增量（TWh） | F19: 来源
A20: 天然气 | B20: =供给结构!E5 -> 204.309 | C20: =供给结构!D5 -> 0.46 | D20: =供给结构!C5 -> 74.7 | E20: =供给结构!F5 -> 129.609 | F20: S05
A21: 可再生能源 | B21: =供给结构!E6 -> 146.5695 | C21: =供给结构!D6 -> 0.33 | D21: =供给结构!C6 -> 44.82 | E21: =供给结构!F6 -> 101.7495 | F21: S05
A22: 核电 | B22: =供给结构!E7 -> 88.83 | C22: =供给结构!D7 -> 0.2 | D22: =供给结构!C7 -> 37.35 | E22: =供给结构!F7 -> 51.48 | F22: S05
A23: 煤电 | B23: =供给结构!E8 -> 4.4415 | C23: =供给结构!D8 -> 0.01 | D23: =供给结构!C8 -> 28.0125 | E23: =供给结构!F8 -> -23.571 | F23: S05
A24: 其他 | B24: =供给结构!E9 -> 0 | C24: =供给结构!D9 -> 0 | D24: =供给结构!C9 -> 1.8675 | E24: =供给结构!F9 -> -1.8675 | F24: S05
A25: 合计 | B25: =SUM(B20:B24) -> 444.15 | C25: =SUM(C20:C24) -> 1 | D25: =SUM(D20:D24) -> 186.75 | E25: =SUM(E20:E24) -> 257.4
A26: 2030 年非化石电源占比 | B26: =(B21+B22+B24)/B25 -> 0.53
A28: 三、资本开支与 Meta 案例
A29: 指标 | B29: 数值 | C29: 单位 | D29: 口径 / 公式 | E29: 来源
A30: 五家科技巨头 2026 年资本开支合计 | B30: =科技巨头_CapEx!D10/100 -> 8000 | C30: 亿美元 | D30: Amazon + Microsoft + Alphabet + Meta + Oracle 中值 | E30: S27,S28,S29,S01
A31: Meta 2026 年资本开支下限 | B31: =Meta_财务!B21/100 -> 1350 | C31: 亿美元 | D31: 公司指引 | E31: S01
A32: Meta 2026 年资本开支上限 | B32: =Meta_财务!B22/100 -> 1450 | C32: 亿美元 | D32: 公司指引 | E32: S01
A33: Meta Q3 2026 单季资本开支 | B33: =Meta_财务!B10/100 -> 349.1 | C33: 亿美元 | D33: 含融资租赁本金 | E33: S01
A34: Meta 9M 2026 资本开支 | B34: =Meta_财务!D10/100 -> 858.2 | C34: 亿美元 | D34: 含融资租赁本金 | E34: S01
A35: Meta Q4 隐含资本开支（下限） | B35: =Meta_财务!B24/100 -> 491.8 | C35: 亿美元 | D35: 全年下限 - 9M | E35: S01
A36: Meta Q4 隐含资本开支（上限） | B36: =Meta_财务!B25/100 -> 591.8 | C36: 亿美元 | D36: 全年上限 - 9M | E36: S01
A37: Meta Q3 资本开支 / 营业收入 | B37: =Meta_财务!B19 -> 0.54039411 | C37: % | D37: 349.1 / 646.0 | E37: S01
A38: Meta 9M 资本开支 / 营业收入 | B38: =Meta_财务!B20 -> 0.47228581 | C38: % | D38: 858.2 / 1,817.1 | E38: S01
A39: Meta 非取消合同承诺 | B39: =Meta_财务!B37/100 -> 4545.2 | C39: 亿美元 | D39: 2026-09-30 | E39: S01
A40: Meta 尚未开始的租赁义务 | B40: =Meta_财务!B38/100 -> 3557.3 | C40: 亿美元 | D40: 数据中心、能源基础设施等 | E40: S01
A42: 四、核电、聚变与成本
A43: 指标 | B43: 数值 | C43: 单位 | D43: 口径 / 公式 | E43: 来源
A44: 公开披露长期核电协议合计 | B44: =核电_PPA!E15 -> 9507 | C44: MW | D44: 10 笔交易 | E44: S02,S03,S07,S08,S09,S10,S11,S13,S14,S15
...

Sheet 图表
A1: 图表集：需求、供给、资本开支、核电、聚变与成本
A2: 所有图表均引用明细表或汇总页的公式单元格；修改“假设与情景”的黄色输入格后自动更新。

Sheet 假设与情景
A1: 假设与情景：所有可调参数集中在这里
A2: 黄色=输入格（披露事实或假设），蓝色=公式格，绿色=结果格。修改黄色格，汇总、图表和网页数据底稿的公式会联动。
A4: 编号 | B4: 参数 | C4: 取值 | D4: 单位 | E4: 类型 | F4: 来源 | G4: 说明 / 依据
A5: A01 | B5: 全球数据中心用电量（2024） | C5: 415 | D5: TWh | E5: 事实 | F5: S04｜IEA｜2025-04 | G5: IEA：占全球用电约 1.5%，相当于英国全年用电量
A6: A02 | B6: 全球数据中心用电量（2030，基准情景） | C6: 945 | D6: TWh | E6: 事实 | F6: S04｜IEA｜2025-04 | G6: IEA 基准情景，接近日本全国用电量
A7: A03 | B7: 全球数据中心用电量（2035，基准情景） | C7: 1200 | D7: TWh | E7: 事实 | F7: S04｜IEA｜2025-04 | G7: IEA 基准情景
A8: A04 | B8: 全球数据中心用电量（2035，低情景） | C8: 700 | D8: TWh | E8: 事实 | F8: S04｜IEA｜2025-04 | G8: IEA 各情景区间下沿（高效情景等）
A9: A05 | B9: 全球数据中心用电量（2035，高情景） | C9: 1700 | D9: TWh | E9: 事实 | F9: S04｜IEA｜2025-04 | G9: IEA 各情景区间上沿（Lift-Off 等）
A10: A06 | B10: 美国占全球数据中心用电比重（2024） | C10: 0.45 | D10: % | E10: 事实 | F10: S04｜IEA｜2025-04 | G10: IEA：美国 45%、中国 25%、欧洲 15%
A11: A07 | B11: 美国占全球数据中心用电比重（2030） | C11: 0.47 | D11: % | E11: 假设 | F11: S04｜IEA｜2025-04 | G11: 假设：美国 AI 资本开支集中，份额较 2024 年略升；IEA 称美国占增量最大份额。用于将全球 945 TWh 拆分为美国 444 TWh
A12: A08 | B12: 全球用电量（2024） | C12: 27000 | D12: TWh | E12: 假设 | F12: S04｜IEA｜2025-04 | G12: 用于计算占比；IEA 口径全球用电约 27,000 TWh，415/27,000≈1.5%
A13: A09 | B13: 全球用电量（2030） | C13: 33000 | D13: TWh | E13: 假设 | F13: S04｜IEA｜2025-04 | G13: 用于计算占比；假设 2024–2030 年全球用电年均增长约 3.4%
A14: A10 | B14: 美国 2025 年净发电量 | C14: 4430 | D14: TWh | E14: 事实 | F14: S17｜EIA｜2026-03-05 | G14: EIA：2025 年美国净发电量 4,430 TWh，同比 +2.8%
A15: A11 | B15: 美国 2030 年净发电量 | C15: 4650 | D15: TWh | E15: 假设 | F15: S17｜EIA｜2026-03-05 | G15: 假设 2025–2030 年年均增长约 1.0%，用于计算数据中心占全国发电量比重
A16: A12 | B16: Meta 数据中心用电量（2024） | C16: 18.061781 | D16: TWh | E16: 事实 | F16: S06｜Meta｜2025-12-31 | G16: Meta 2025 环境数据索引：2024 年数据中心用电 18,061,781 MWh；总用电 18,423,634 MWh；PUE 1.08
... A18: A14 | B18: 核电年利用小时数 | C18: 7884 | D18: 小时 | E18: 假设 | F18: S02｜Constellation｜2026-02-24 | G18: 按 90% 容量因子折算（Constellation 2025 年核电机组容量因子 94.7%）
A19: A15 | B19: Meta 已签约核电容量（首批） | C19: =1.092+2.1+1.2+0.69 -> 5.082 | D19: GW | E19: 计算 | F19: S07｜Meta｜2026-01-09；S08｜Utility Dive｜2026-01-09；S09｜Constellation｜2026-10-22 | G19: Clinton 1.092 + Vistra 2.10 + Oklo 1.20 + TerraPower 0.69 = 5.082 GW；不含选择权与后续扩建
A20: A16 | B20: Meta 核电选择权/扩建容量 | C20: =2.1+0.518 -> 2.618 | D20: GW | E20: 计算 | F20: S07｜Meta｜2026-01-09；S08｜Utility Dive｜2026-01-09 | G20: TerraPower 最多再 6 台 Natrium（2.1 GW）+ 其他扩建/升级 0.518 GW；合计使总规模达到 Meta 披露的“最高 7.7 GW”
A21: A17 | B21: 美国数据中心供电结构（2024，天然气） | C21: 0.4 | D21: % | E21: 事实 | F21: S05｜IEA｜2025-04 | G21: IEA：美国数据中心用电中天然气 >40%、可再生 24%、核 20%、煤 15%
A22: A18 | B22: 美国数据中心供电结构（2024，可再生） | C22: 0.24 | D22: % | E22: 事实 | F22: S05｜IEA｜2025-04 | G22: 同上
A23: A19 | B23: 美国数据中心供电结构（2024，核） | C23: 0.2 | D23: % | E23: 事实 | F23: S05｜IEA｜2025-04 | G23: 同上
A24: A20 | B24: 美国数据中心供电结构（2024，煤） | C24: 0.15 | D24: % | E24: 事实 | F24: S05｜IEA｜2025-04 | G24: 同上
A25: A21 | B25: 美国数据中心供电结构（2024，其他） | C25: 0.01 | D25: % | E25: 假设 | F25: S05｜IEA｜2025-04 | G25: 残差项，含油、地热等
A26: A22 | B26: 美国数据中心供电结构（2030，天然气） | C26: 0.46 | D26: % | E26: 假设 | F26: S05｜IEA｜2025-04 | G26: 假设：气电仍是最大增量来源；按 2030 年美国 444 TWh、气电 204 TWh 计，较 2024 年 +130 TWh，与 IEA “+130 TWh”一致
A27: A23 | B27: 美国数据中心供电结构（2030，可再生） | C27: 0.33 | D27: % | E27: 假设 | F27: S05｜IEA｜2025-04 | G27: 假设：可再生占比由 24% 升至 33%，增量约 +102 TWh，接近 IEA “+110 TWh”
A28: A24 | B28: 美国数据中心供电结构（2030，核） | C28: 0.2 | D28: % | E28: 假设 | F28: S05｜IEA｜2025-04 | G28: 假设：现有核电保持 20%，SMR 2030 年前贡献有限；2035 年低排放电源占比超过 50%
A29: A25 | B29: 美国数据中心供电结构（2030，煤） | C29: 0.01 | D29: % | E29: 假设 | F29: S05｜IEA｜2025-04 | G29: 假设：煤电占比由 15% 降至 1%，主要被气电与可再生替代
A30: A26 | B30: 美国数据中心供电结构（2030，其他） | C30: 0 | D30: % | E30: 假设 | F30: S05｜IEA｜2025-04 | G30: 残差项
A31: A27 | B31: Meta 2026 年资本开支（指引下限） | C31: 135000 | D31: 百万美元 | E31: 事实 | F31: S01｜Meta｜2026-10-21 | G31: Meta 2026 年第三季度 10-Q：预计 2026 年资本开支 1,350–1,450 亿美元
A32: A28 | B32: Meta 2026 年资本开支（指引上限） | C32: 145000 | D32: 百万美元 | E32: 事实 | F32: S01｜Meta｜2026-10-21 | G32: 同上
... A35: A31 | B35: 欧元兑美元汇率 | C35: 1.08 | D35: USD/EUR | E35: 假设 | F35: S12｜ESG Today｜2026-07-31 | G35: 用于将 Proxima Fusion 的欧元融资折算为美元
A37: 说明：A07（美国 2030 年份额）和 A22–A26（2030 年供电结构）是本报告的核心情景假设；改变它们会同步改变汇总页、供给结构页与网页。A13（Meta 用电增速）仅用于把 2024 年披露用电外推到 2026 年，不是公司指引。

Sheet 需求_全球
A1: 全球数据中心用电：现状与 2030 / 2035 预测
A2: 口径：数据中心自身用电（含自建与租赁、含 IT 与制冷等基础设施），不含加密货币挖矿等非 AI 负载的单独拆分。
A4: 年份 | B4: 全球数据中心用电量（TWh） | C4: 低情景（TWh） | D4: 高情景（TWh） | E4: 全球用电量（TWh） | F4: 占全球用电比重 | G4: 年均增速 | H4: 来源 | I4: 口径说明
A5: 2024 | B5: 415 | C5: — | D5: — | E5: 27000 | F5: =B5/E5 -> 0.01537037 | G5: — | H5: S04｜IEA｜2025-04 | I5: 占全球用电约 1.5%；美国 45%、中国 25%、欧洲 15%
A6: 2030 | B6: 945 | C6: — | D6: — | E6: 33000 | F6: =B6/E6 -> 0.028636364 | G6: =(B6/B5)^(1/6)-1 -> 0.14700141 | H6: S04｜IEA｜2025-04 | I6: IEA 基准情景；较 2024 年翻倍以上，接近日本全国用电量
A7: 2035 | B7: 1200 | C7: 700 | D7: 1700 | E7: 33500 | F7: =B7/E7 -> 0.035820896 | G7: =(B7/B6)^(1/5)-1 -> 0.048938166 | H7: S04｜IEA｜2025-04 | I7: IEA 基准情景 1,200 TWh；各情景区间 700–1,700 TWh
A9: 来源：IEA《Energy and AI》（2025-04）执行摘要与能源供给章节。IEA 原文：2024 年 415 TWh（约全球 1.5%）、2030 年约 945 TWh、2035 年约 1,200 TWh；各情景区间 700–1,700 TWh。全球用电量为本报告为计算占比而设的假设（A08、A09）。

Sheet 需求_区域
A1: 区域拆分：美国、中国、欧洲与其他地区
A2: 2024 年份额来自 IEA；2030 年美国份额为假设（A07），欧洲 2030 年 150 TWh 来自 IEA（经人民日报海外版引述）。
A4: 地区 | B4: 2024 份额 | C4: 2024 TWh | D4: 2030 份额 | E4: 2030 TWh | F4: 2024→2030 增量（TWh） | G4: 来源 | H4: 说明
A5: 美国 | B5: 0.45 | C5: =需求_全球!B5*B5 -> 186.75 | D5: 0.47 | E5: =需求_全球!B6*D5 -> 444.15 | F5: =E5-C5 -> 257.4 | G5: S04｜IEA｜2025-04 | H5: 2024 年份额为 IEA 披露；2030 年份额为本报告假设（A07）
A6: 中国 | B6: 0.25 | C6: =需求_全球!B5*B6 -> 103.75 | D6: 0.25 | E6: =需求_全球!B6*D6 -> 236.25 | F6: =E6-C6 -> 132.5 | G6: S04｜IEA｜2025-04 | H6: IEA：中国 2024 年占 25%；2030 年份额假设维持 25%
A7: 欧洲 | B7: 0.15 | C7: =需求_全球!B5*B7 -> 62.25 | D7: =E7/需求_全球!B6 -> 0.15873016 | E7: 150 | F7: =E7-C7 -> 87.75 | G7: S04｜IEA｜2025-04；S31｜人民日报｜2026-02-26 | H7: 2024 年 15%；2030 年 150 TWh 来自 IEA（经人民日报海外版引述），约当前 3 倍
A8: 其他地区 | B8: 0.15 | C8: =需求_全球!B5*B8 -> 62.25 | D8: =1-SUM(D5:D7) -> 0.12126984 | E8: =需求_全球!B6-SUM(E5:E7) -> 114.6 | F8: =E8-C8 -> 52.35 | G8: S04｜IEA｜2025-04 | H8: 残差项
A9: 合计 | B9: =SUM(B5:B8) -> 1 | C9: =SUM(C5:C8) -> 415 | D9: =SUM(D5:D8) -> 1 | E9: =SUM(E5:E8) -> 945 | F9: =SUM(F5:F8) -> 530

Sheet 科技巨头_CapEx
A1: 美国科技巨头 2026 年资本开支指引
A2: 单位：百万美元。Microsoft、Oracle 的财年与自然年不完全一致，已在口径说明中标注。
A4: 公司 | B4: 2026 下限（百万美元） | C4: 2026 上限（百万美元） | D4: 中值（百万美元） | E4: 中值（亿美元） | F4: 来源 | G4: 发布日期 | H4: 口径说明
A5: Amazon | B5: 220000 | C5: 220000 | D5: =AVERAGE(B5:C5) -> 220000 | E5: =D5/100 -> 2200 | F5: S28｜BusinessDay｜2026-10-20 | G5: 2026-10-20 | H5: 2026 年资本开支约 2,200 亿美元，7 月由约 2,000 亿美元上调；含非 AI 基础设施
A6: Microsoft | B6: 190000 | C6: 190000 | D6: =AVERAGE(B6:C6) -> 190000 | E6: =D6/100 -> 1900 | F6: S27｜C114｜2026-05-07 | G6: 2026-05-07 | H6: 2026 自然年约 1,900 亿美元，其中约 250 亿美元来自零部件涨价
A7: Alphabet | B7: 195000 | C7: 205000 | D7: =AVERAGE(B7:C7) -> 200000 | E7: =D7/100 -> 2000 | F7: S29｜ET Datacenters｜2026-07-24 | G7: 2026-07-24 | H7: 2026 年指引 1,950–2,050 亿美元，较此前 1,800–1,900 亿上调；Q2 资本开支 449 亿美元
A8: Meta | B8: 135000 | C8: 145000 | D8: =AVERAGE(B8:C8) -> 140000 | E8: =D8/100 -> 1400 | F8: S01｜Meta｜2026-10-21 | G8: 2026-10-21 | H8: 2026 年指引 1,350–1,450 亿美元；Q3 单季 349.1 亿美元
A9: Oracle | B9: 50000 | C9: 50000 | D9: =AVERAGE(B9:C9) -> 50000 | E9: =D9/100 -> 500 | F9: S27｜C114｜2026-05-07 | G9: 2026-05-07 | H9: FY2026（非自然年）资本开支约 500 亿美元
A10: 五家合计 | B10: =SUM(B5:B9) -> 790000 | C10: =SUM(C5:C9) -> 810000 | D10: =SUM(D5:D9) -> 800000 | E10: =D10/100 -> 8000 | H10: 合计约 8,000 亿美元，与 Morgan Stanley 对 2026 年的预测一致
A12: 第三方对行业总量的预测
A13: 机构 | B13: 指标 | C13: 数值（十亿美元） | D13: 说明 | H13: 来源
A14: Morgan Stanley | B14: 2026 年五大科技巨头资本开支 | C14: 800 | D14: 约为 2025 年的 2 倍、2024 年的 3 倍 | H14: S27
A15: Morgan Stanley | B15: 2027 年五大科技巨头资本开支 | C15: 1100 | D15: 预计超过 1.1 万亿美元 | H15: S27
A16: S&P Global Ratings | B16: 2025–2030 年六家科技公司 AI 相关资本开支 | C16: 7000 | D16: 合计可能超过 7 万亿美元，含表外安排 | H16: S28

Sheet Meta_财务
A1: Meta 2026 年第三季度：收入、资本开支与表内外承诺
A2: 单位：百万美元。Q3 = 2026 年 7–9 月；9M = 2026 年 1–9 月。数据取自 Meta Form 10-Q（2026-10-21）。
A4: 一、损益与资本开支
A5: 指标 | B5: Q3 2026 | C5: Q3 2025 | D5: 9M 2026 | E5: 9M 2025 | F5: 来源 | G5: 说明
A6: 营业收入 | B6: 64601 | C6: 51242 | D6: 181712 | E6: 141073 | F6: S01｜Meta｜2026-10-21 | G6: Q3 同比 +26%；9M 同比 +29%
A7: 总成本与费用 | B7: 51613 | C7: 30707 | D7: 127077 | E7: 82542 | F7: S01｜Meta｜2026-10-21 | G7: Q3 含 98.9 亿美元多州总检察长和解相关费用
A8: 经营利润 | B8: 12988 | C8: 20535 | D8: 54635 | E8: 58531 | F8: S01｜Meta｜2026-10-21 | G8: Q3 经营利润率 20%，去年同期 40%
A9: 净利润 | B9: 9860 | C9: — | D9: 52480 | E9: — | F9: S01｜Meta｜2026-10-21 | G9: Q3 稀释 EPS 3.83 美元；9M 净利润取自现金流量表
A10: 资本开支（含融资租赁本金） | B10: 34910 | C10: — | D10: 85820 | E10: — | F10: S01｜Meta｜2026-10-21 | G10: Q3 349.1 亿美元；9M 858.2 亿美元
A11: 购置物业与设备（现金流口径） | B11: — | C11: — | D11: 83055 | E11: 48308 | F11: S01｜Meta｜2026-10-21 | G11: 9M 2026 同比 +72%
A13: 二、派生指标（全部为公式）
A14: 指标 | B14: 数值 | C14: 单位 | D14: 计算口径
A15: Q3 营业收入同比 | B15: =B6/C6-1 -> 0.26070411 | C15: % | D15: Q3 2026 / Q3 2025 - 1
A16: 9M 营业收入同比 | B16: =D6/E6-1 -> 0.28807072 | C16: % | D16: 9M 2026 / 9M 2025 - 1
A17: Q3 经营利润率 | B17: =B8/B6 -> 0.20104952 | C17: % | D17: 经营利润 / 营业收入
A18: 9M 经营利润率 | B18: =D8/D6 -> 0.30066809 | C18: % | D18: 经营利润 / 营业收入
A19: Q3 资本开支 / 营业收入 | B19: =B10/B6 -> 0.54039411 | C19: % | D19: 资本开支（含融资租赁本金）/ 营业收入
A20: 9M 资本开支 / 营业收入 | B20: =D10/D6 -> 0.47228581 | C20: % | D20: 资本开支（含融资租赁本金）/ 营业收入
A21: 2026 资本开支指引下限 | B21: =假设与情景!C31 -> 135000 | C21: 百万美元 | D21: 公司指引（A27）
A22: 2026 资本开支指引上限 | B22: =假设与情景!C32 -> 145000 | C22: 百万美元 | D22: 公司指引（A28）
A23: 2026 资本开支指引中值 | B23: =AVERAGE(B21:B22) -> 140000 | C23: 百万美元 | D23: 下限与上限平均
A24: Q4 隐含资本开支（下限） | B24: =B21-D10 -> 49180 | C24: 百万美元 | D24: 全年下限 - 9M 实际
A25: Q4 隐含资本开支（上限） | B25: =B22-D10 -> 59180 | C25: 百万美元 | D25: 全年上限 - 9M 实际
A26: Q4 隐含环比（下限） | B26: =B24/B10-1 -> 0.4087654 | C26: % | D26: Q4 隐含下限 / Q3 实际 - 1
A27: Q4 隐含环比（上限） | B27: =B25/B10-1 -> 0.69521627 | C27: % | D27: Q4 隐含上限 / Q3 实际 - 1
A28: 9M 收入年化 | B28: =D6*4/3 -> 242282.67 | C28: 百万美元 | D28: 9M 收入 × 4/3
A29: 资本开支 / 年化收入（下限） | B29: =B21/B28 -> 0.55720041 | C29: % | D29: 指引下限 / 年化收入
A30: 资本开支 / 年化收入（上限） | B30: =B22/B28 -> 0.59847451 | C30: % | D30: 指引上限 / 年化收入
A31: 非取消合同承诺 / 年化收入 | B31: =B37/B28 -> 1.8759906 | C31: 倍 | D31: 合同承诺 / 年化收入
A32: 未开始租赁 / 年化收入 | B32: =B38/B28 -> 1.4682437 | C32: 倍 | D32: 未开始租赁 / 年化收入
A33: 三、资产负债表与承诺
A34: 项目 | B34: 金额（百万美元） | C34: 来源 | D34: 说明
A35: 现金、现金等价物与有价证券 | B35: 82450 | C35: S01 | D35: 2026-09-30
A36: 长期债务本金 | B36: 84000 | C36: S01 | D36: 固定利率高级无抵押票据；2027 年到期 27.5 亿美元
A37: 非取消合同承诺 | B37: 454520 | C37: S01 | D37: 主要为第三方云容量、服务器与网络、数据中心能源服务协议
A38: 尚未开始的租赁义务 | B38: 355730 | C38: S01 | D38: 数据中心、能源相关基础设施、托管与网络；2026–2036 年陆续开始
A39: 其中：2026 年内到期 | B39: 45850 | C39: S01 | D39: 合同承诺到期额
A40: 其中：2027 年内到期 | B40: 121410 | C40: S01 | D40: 合同承诺到期额
A41: 数据中心合资企业最大剩余价值担保 | B41: 41493 | C41: S34 | D41: Louisiana + Texas 两个 VIE；Meta 持 20%

Sheet 核电_PPA
A1: 核电与科技公司的长期购电协议 / 长期合同
A2: 价格为分析师估算或未披露；未披露的项目在价格列留空，不以假设代替。期限按公开披露，部分交易只披露“长期”。
A4: 编号 | B4: 科技公司 | C4: 电力/核电公司 | D4: 电站 | E4: 规模（MW） | F4: 期限（年） | G4: 起始 | H4: 状态 | I4: 价格（美元/MWh） | J4: 价格说明 | K4: 来源 | L4: 备注
A5: N01 | B5: Microsoft | C5: Constellation | D5: Crane（原 Three Mile Island 1 号） | E5: 835 | F5: 20 | G5: 2027–2028（待重启） | H5: 已签，重启中 | I5: — | J5: Jefferies 估算 ≥110 美元/MWh | K5: S02｜Constellation｜2026-02-24；S23｜Bloomberg｜2025-06-03 | L5: 重启支持；DOE 提供最高 10 亿美元贷款担保；835 MW 零排放容量
A6: N02 | B6: Meta | C6: Constellation | D6: Clinton | E6: 1092 | F6: 20 | G6: 2027-06 | H6: 已签，运行中 | I6: 80 | J6: Jefferies 估算约 80 美元/MWh | K6: S02｜Constellation｜2026-02-24；S09｜Constellation｜2026-10-22；S23｜Bloomberg｜2025-06-03 | L6: 支持再许可与继续运行 20 年；+30 MW 升级至 2029 年完成；1,092 MW 为当前容量
A7: N03 | B7: Amazon | C7: Talen | D7: Susquehanna | E7: 1920 | F7: — | G7: 逐步爬坡，2032 年满功率；合同至 2042 | H7: 已签，front-of-meter 改造中 | I7: — | J7: 未披露 | K7: S10｜Talen｜2025-06-13 | L7: 长期 PPA，含延期权；Talen 作为零售电力供应商
A8: N04 | B8: Meta | C8: Vistra | D8: Beaver Valley / Perry / Davis-Besse | E8: 2100 | F8: 20 | G8: 未披露 | H8: 已签 | I8: — | J8: 未披露 | K8: S07｜Meta｜2026-01-09；S08｜Utility Dive｜2026-01-09 | L8: >2.1 GW；含 Ohio 两站升级；20 年协议
A9: N05 | B9: Meta | C9: Oklo | D9: Pike County, Ohio（SMR） | E9: 1200 | F9: — | G9: 2030 首期，2034 全容量 | H9: 已签，开发中 | I9: — | J9: 未披露 | K9: S07｜Meta｜2026-01-09；S08｜Utility Dive｜2026-01-09 | L9: 1.2 GW 电力园区；预建设 2026 年启动
A10: N06 | B10: Meta | C10: TerraPower | D10: Natrium（钠冷快堆） | E10: 690 | F10: — | G10: ≥2032 | H10: 已签，开发中 | I10: — | J10: 未披露 | K10: S07｜Meta｜2026-01-09；S08｜Utility Dive｜2026-01-09 | L10: 2×345 MW；另有 6 台、最多 2.1 GW 的购电权，目标 2035 年交付
A11: N07 | B11: Google | C11: Kairos Power | D11: Hermes / 后续电站（氟盐冷却） | E11: 500 | F11: — | G11: 2030 首堆，2035 全规模 | H11: 已签，开发中 | I11: — | J11: 未披露 | K11: S15｜Kairos｜2024-10-14 | L11: 500 MW 总承诺；首堆 35 MW 级
A12: N08 | B12: Google | C12: Commonwealth Fusion Systems | D12: ARC（聚变托卡马克） | E12: 200 | F12: — | G12: early 2030s | H12: 已签， contingent on SPARC Q>1 | I12: — | J12: 未披露 | K12: S11｜CFS｜2025-06-30 | L12: 全球首个聚变商业购电协议之一；ARC 净出力 400 MW
A13: N09 | B13: Microsoft | C13: Helion | D13: Orion（聚变 FRC） | E13: 50 | F13: — | G13: 2028（原 2029） | H13: 已签，建设中 | I13: — | J13: 未披露 | K13: S13｜Helion｜2026-06-04；S14｜Reuters｜2023-05-10 | L13: 首个聚变 PPA；Constellation 作为电力营销方
A14: N10 | B14: Meta | C14: Constellation | D14: 未披露（多个核电机组） | E14: 920 | F14: 18 | G14: 2029–2032 | H14: 已签 | I14: — | J14: 未披露 | K14: S03｜Constellation｜2026-08-06 | L14: 2026 年 Q2 新增 920 MW 长期 PPA（15–20 年）；其中 Walmart 176 MW 支持 Dresden +30 MW
A15: 合计 | E15: =SUM(E5:E14) -> 9507 | L15: 10 笔公开披露的长期合同；不代表行业全部交易
A17: 按科技公司汇总（MW）
A18: 科技公司 | B18: 合计 MW | C18: 其中已运行/在建 | D18: 说明 | E18: 来源
A19: Microsoft | B19: =SUMIF($B$5:$B$14,A19,$E$5:$E$14) -> 885 | C19: =SUMIF($B$5:$B$14,A19,$E$5:$E$14) -> 885 | D19: Crane 835 + Helion 50（聚变，2028） | E19: S02,S13
A20: Meta | B20: =SUMIF($B$5:$B$14,A20,$E$5:$E$14) -> 6002 | C20: =SUMIF($B$5:$B$14,A20,$E$5:$E$14) -> 6002 | D20: Clinton 1,092 + Vistra 2,100 + Oklo 1,200 + TerraPower 690 + 2026Q2 新增 920 | E20: S02,S03,S07,S08
A21: Amazon | B21: =SUMIF($B$5:$B$14,A21,$E$5:$E$14) -> 1920 | C21: =SUMIF($B$5:$B$14,A21,$E$5:$E$14) -> 1920 | D21: Susquehanna 1,920 | E21: S10
A22: Google | B22: =SUMIF($B$5:$B$14,A22,$E$5:$E$14) -> 700 | C22: =SUMIF($B$5:$B$14,A22,$E$5:$E$14) -> 700 | D22: Kairos 500 + CFS 200（聚变，early 2030s） | E22: S11,S15
A23: 合计 | B23: =SUM(B19:B22) -> 9507
A25: Meta 核电组合：按公司披露的“最高 7.7 GW”口径
A26: 项目 | B26: MW | C26: 状态 | D26: 起始 | E26: 来源
A27: Clinton（Constellation） | B27: 1092 | C27: 运行中，20 年 PPA | D27: 2027-06 | E27: S02,S09
A28: Vistra（Beaver Valley / Perry / Davis-Besse） | B28: 2100 | C28: 运行中 + 升级 | D28: 未披露 | E28: S07,S08
A29: Oklo（Pike County, OH） | B29: 1200 | C29: 开发中 | D29: 2030 首期 | E29: S07,S08
A30: TerraPower（2×345 MW Natrium） | B30: 690 | C30: 开发中 | D30: ≥2032 | E30: S07,S08
A31: TerraPower 选择权 + 其他扩建 | B31: 2618 | C31: 选择权/规划 | D31: 至 2035 | E31: S07,S08
A32: 合计（最高口径） | B32: =SUM(B27:B31) -> 7700
A33: 其中：首批已签约（不含选择权） | B33: =SUM(B27:B30) -> 5082
A34: 最高口径年发电量（TWh，按 7,884 小时） | B34: =B32*假设与情景!C18/1000000 -> 60.7068
A35: 首批年发电量（TWh） | B35: =B33*假设与情景!C18/1000000 -> 40.066488
A36: 首批年发电量 / Meta 2026 估算用电 | B36: =B35/(假设与情景!C16*(1+假设与情景!C17)^2) -> 1.3126048
A37: 最高口径年发电量 / Meta 2026 估算用电 | B37: =B34/(假设与情景!C16*(1+假设与情景!C17)^2) -> 1.9887952

Sheet 供给结构
A1: 美国数据中心用电的来源结构：2024 vs 2030
A2: 2024 年份额来自 IEA；2030 年份额为假设（A22–A26）。TWh 由美国数据中心总用电量乘以份额得到。
A3: 美国数据中心用电（TWh） | B3: 2024 | C3: =需求_区域!C5 -> 186.75 | D3: 2030 | E3: =需求_区域!E5 -> 444.15
A4: 电源 | B4: 2024 份额 | C4: 2024 TWh | D4: 2030 份额 | E4: 2030 TWh | F4: 2024→2030 增量（TWh） | G4: 来源 | H4: 说明
A5: 天然气 | B5: =假设与情景!C21 -> 0.4 | C5: =$C$3*B5 -> 74.7 | D5: =假设与情景!C26 -> 0.46 | E5: =$E$3*D5 -> 204.309 | F5: =E5-C5 -> 129.609 | G5: S05｜IEA｜2025-04 | H5: 2024 年 >40%；2030 年假设 46%
A6: 可再生能源 | B6: =假设与情景!C22 -> 0.24 | C6: =$C$3*B6 -> 44.82 | D6: =假设与情景!C27 -> 0.33 | E6: =$E$3*D6 -> 146.5695 | F6: =E6-C6 -> 101.7495 | G6: S05｜IEA｜2025-04 | H6: 2024 年 24%；2030 年假设 33%
A7: 核电 | B7: =假设与情景!C23 -> 0.2 | C7: =$C$3*B7 -> 37.35 | D7: =假设与情景!C28 -> 0.2 | E7: =$E$3*D7 -> 88.83 | F7: =E7-C7 -> 51.48 | G7: S05｜IEA｜2025-04 | H7: 2024 年约 20%；2030 年假设维持 20%
A8: 煤电 | B8: =假设与情景!C24 -> 0.15 | C8: =$C$3*B8 -> 28.0125 | D8: =假设与情景!C29 -> 0.01 | E8: =$E$3*D8 -> 4.4415 | F8: =E8-C8 -> -23.571 | G8: S05｜IEA｜2025-04 | H8: 2024 年约 15%；2030 年假设降至 1%
A9: 其他 | B9: =假设与情景!C25 -> 0.01 | C9: =$C$3*B9 -> 1.8675 | D9: =假设与情景!C30 -> 0 | E9: =$E$3*D9 -> 0 | F9: =E9-C9 -> -1.8675 | G9: S05｜IEA｜2025-04 | H9: 残差项
A10: 合计 | B10: =SUM(B5:B9) -> 1 | C10: =SUM(C5:C9) -> 186.75 | D10: =SUM(D5:D9) -> 1 | E10: =SUM(E5:E9) -> 444.15 | F10: =SUM(F5:F9) -> 257.4
A12: 校验：2024 份额合计 | B12: =B10 -> 1
A13: 校验：2030 份额合计 | B13: =D10 -> 1
A14: 2030 年非化石电源占比 | B14: =(E6+E7+E9)/E10 -> 0.53
A15: 气电增量（IEA 口径 +130 TWh） | B15: =F5 -> 129.609
A16: 可再生增量（IEA 口径 +110 TWh） | B16: =F6 -> 101.7495

Sheet 成本_LCOE
A1: 新建电源的平准化度电成本（LCOE）与核电 PPA 价格
A2: Lazard 2026 版 LCOE+（v19.0），未补贴、60% 债务/40% 权益、税后 IRR 7.7%。核电为 Vogtle 口径的新建成本。
A4: 技术 | B4: 低（美元/MWh） | C4: 高（美元/MWh） | D4: 中值 | E4: 来源 | F4: 说明
A5: 光伏（公用事业规模） | B5: 40 | C5: 98 | D5: =AVERAGE(B5:C5) -> 69 | E5: S16｜Lazard｜2026-06 | F5: Lazard 2026 v19.0，未补贴、60% 债务/40% 权益
A6: 陆上风电 | B6: 37 | C6: 99 | D6: =AVERAGE(B6:C6) -> 68 | E6: S16｜Lazard｜2026-06 | F6: 同上
A7: 燃气联合循环（CCGT） | B7: 51 | C7: 129 | D7: =AVERAGE(B7:C7) -> 90 | E7: S16｜Lazard｜2026-06 | F7: 同上；燃气价格 3.45 美元/MMBtu
A8: 核电（新建，Vogtle 口径） | B8: 175 | C8: 255 | D8: =AVERAGE(B8:C8) -> 215 | E8: S16｜Lazard｜2026-06 | F8: 同上；基于 Vogtle 3&4 公开成本
A9: 燃气调峰 | B9: 144 | C9: 276 | D9: =AVERAGE(B9:C9) -> 210 | E9: S16｜Lazard｜2026-06 | F9: 同上
A10: 煤电 | B10: 72 | C10: 177 | D10: =AVERAGE(B10:C10) -> 124.5 | E10: S16｜Lazard｜2026-06 | F10: 同上；不含运输与储存
A12: 核电 PPA 价格（分析师估算，非公司披露）
A13: 交易 | B13: 价格（美元/MWh） | C13: 类型 | D13: 来源 | E13: 说明
A14: Meta–Constellation Clinton | B14: 80 | C14: 分析师估算 | D14: S23 | E14: Jefferies：运营中的核电站，价格低于重启项目
A15: Microsoft–Constellation Crane | B15: 110 | C15: 分析师估算下限 | D15: S23 | E15: Jefferies：至少 110 美元/MWh；重启资本开支约 16 亿美元
A17: 新建核电 LCOE 中值 / Meta PPA 价格 | B17: =D8/B14 -> 2.6875
A18: 新建核电 LCOE 中值 - Meta PPA（美元/MWh） | B18: =D8-B14 -> 135
A19: 新建核电 LCOE 中值 - Microsoft PPA（美元/MWh） | B19: =D8-B15 -> 105
A20: 光伏 LCOE 中值 / 核电 LCOE 中值 | B20: =D5/D8 -> 0.32093023

Sheet 聚变_公司
A1: 主要聚变公司：融资、时间表与科技公司购电协议
A2: 融资单位：百万美元；Proxima 的欧元融资按 1.08 折算为美元（A31）。估值为最近一轮投后估值或并购对价，未披露留空。
A4: 公司 | B4: 国家 | C4: 技术路线 | D4: 累计融资（百万美元） | E4: 估值（百万美元） | F4: 目标装机（MW） | G4: 并网/供电时间 | H4: 已签 PPA（MW） | I4: 科技公司购电方 | J4: 来源 | K4: 说明
A5: Commonwealth Fusion Systems (CFS) | B5: 美国 | C5: 高温超导托卡马克 | D5: 4000 | E5: — | F5: 400 | G5: early 2030s | H5: 200 | I5: Google 200 MW；Eni >10 亿美元 | J5: S11｜CFS｜2025-06-30；S12｜ESG Today｜2026-07-31；S25｜NNN｜2026-10-22 | K5: SPARC 约 80% 完成，首次等离子体目标 2027；ARC 400 MW 落地弗吉尼亚 Chesterfield；2026-04 提交 PJM 并网申请
A6: Helion Energy | B6: 美国 | C6: 场反位形（FRC） | D6: 1500 | E6: 15500 | F6: 50 | G6: 2028 | H6: 50 | I6: Microsoft 50 MW | J6: S13｜Helion｜2026-06-04；S14｜Reuters｜2023-05-10；S25｜NNN｜2026-10-22 | K6: Polaris 实现 D-T 运行、等离子体 >1.5 亿°C；Orion 50 MW 建设中；G 轮 4.65 亿美元，后增至 5 亿美元
A7: TAE Technologies | B7: 美国 | C7: 场反位形（FRC） | D7: 1300 | E7: 6000 | F7: 50 | G7: 2030s | H7: 0 | I7: 无 | J7: S25｜NNN｜2026-10-22 | K7: Copernicus 建设中；首座 50 MW 级电站 Da Vinci 选址中；2025-12 与 Trump Media 合并，交易估值 >60 亿美元
A8: Type One Energy | B8: 美国 | C8: 仿星器 | D8: 400 | E8: — | F8: 400 | G8: mid-2030s | H8: 0 | I8: TVA（意向书） | J8: S26｜ENR｜2026-10-07 | K8: Infinity One 原型 2027 年开工；Infinity Two 400 MW，常规岛 2028、聚变岛 2030
A9: Pacific Fusion | B9: 美国 | C9: 脉冲惯性约束 | D9: 900 | E9: — | F9: — | G9: 2030（净增益） | H9: 0 | I9: 无 | J9: S25｜NNN｜2026-10-22 | K9: 2026-08 在阿尔伯克基动工建设示范系统；目标 2030 年实现设施净增益
A10: Tokamak Energy | B10: 英国 | C10: 球形托卡马克 | D10: 335 | E10: — | F10: — | G10: 2030s | H10: 0 | I10: 无 | J10: S25｜NNN｜2026-10-22 | K10: ST80-HTS 设计阶段；2026-08 表示不再自建示范电站，转向 HTS 磁体与 STEP 合作
A11: Proxima Fusion | B11: 德国 | C11: 准等角仿星器 | D11: 700 | E11: 2600 | F11: — | G11: early 2030s | H11: 0 | I11: RWE/巴伐利亚（MoU） | J11: S25｜NNN｜2026-10-22 | K11: 2026-07 融资 4.11 亿欧元，累计 >6.5 亿欧元；Alpha 示范装置选址 Garching
A12: Zap Energy | B12: 美国 | C12: Z 箍缩 | D12: 324 | E12: — | F12: 50 | G12: 2030s | H12: 0 | I12: 无 | J12: S25｜NNN｜2026-10-22 | K12: Century 平台运行；2026-05 DOE 批准约 50 MWe 模块预概念设计
A13: 8 家样本合计 | D13: =SUM(D5:D12) -> 9459 | H13: =SUM(H5:H12) -> 250 | K13: 样本合计不等于行业总额；仅用于展示头部公司量级
A15: 行业总量：FIA 2026 年报告
A16: 指标 | B16: 数值 | C16: 单位 | D16: 来源 | E16: 说明
A17: 累计私人融资（自 2021 年调查起） | B17: 14240 | C17: 百万美元 | D17: S24 | E17: 56 家公司；约 16,000 名员工
A18: 截至 2026 年 7 月的 12 个月融资 | B18: 4480 | C18: 百万美元 | D18: S24 | E18: 创纪录，较上年约 +69%
A19: 被调查公司数 | B19: 56 | C19: 家 | D19: S24
A20: 行业员工数 | B20: 16000 | C20: 人 | D20: S24
A22: CFS 累计融资 / 行业累计 | B22: =D5/B17 -> 0.28089888
A23: 8 家样本 / 行业累计 | B23: =D13/B17 -> 0.66425562
A24: 已签聚变 PPA 合计（MW） | B24: =H13 -> 250
A25: 其中：Google–CFS | B25: =H5 -> 200
A26: 其中：Microsoft–Helion | B26: =H6 -> 50

Sheet 瓶颈指标
A1: 成本与瓶颈：关键量化指标
A2: 部分指标为区间或文本（如交付周期），不能直接参与计算；已在单位列标注。
A4: 指标 | B4: 数值 | C4: 单位 | D4: 来源 | E4: 说明
A5: 美国输电互联队列活跃容量 | B5: 2061 | C5: GW | D5: S18｜LBNL｜2026-06 | E5: 发电与储能；不含负荷队列
A6: 2025 年投运项目从申请到商运的中位时间 | B6: 61 | C6: 个月 | D6: S18｜LBNL｜2026-06 | E6: 2015 年 36 个月、2008 年 22 个月
A7: 2000–2020 年请求项目中最终投运的比例 | B7: 0.19 | C7: % | D7: S18｜LBNL｜2026-06 | E7: 按项目数；按容量 13%
A8: 大型变压器交付周期 | B8: 24–48 | C8: 个月 | D8: S21｜DigitalToday｜2026-07-15 | E8: 2020 年前为 6–12 个月；100 MVA/230 kV 以上 >36 个月
A9: 变压器价格较 2020 年前涨幅 | B9: 50–80 | C9: % | D9: S21｜DigitalToday｜2026-07-15 | E9: 铜、取向电工钢、熟练工与试验能力共同约束
A10: GE Vernova 燃机设备在手订单 | B10: 116 | C10: GW | D10: S19｜GE Vernova｜2026-07-22 | E10: 2026 年 6 月底；公司预计 2026 年底至少 125 GW
A11: GE Vernova 燃机年产能（2026Q3） | B11: 20 | C11: GW/年 | D11: S19｜GE Vernova｜2026-07-22 | E11: 2028 年 24 GW/年、2030 年 30 GW/年
A12: IEA：因电网约束面临延期的数据中心项目比例 | B12: 0.2 | C12: % | D12: S04｜IEA｜2025-04 | E12: 全球计划项目
A13: IEA：新建输电线路典型工期 | B13: 4–8 | C13: 年 | D13: S04｜IEA｜2025-04 | E13: 发达经济体
A14: Vogtle 3&4 最终成本 | B14: 350 | C14: 亿美元 | D14: S22｜E&E News｜2024-04-30 | E14: 最初预算 140 亿美元；晚 7 年
A15: Vogtle 3&4 延期 | B15: 7 | C15: 年 | D15: S22｜E&E News｜2024-04-30 | E15: 两台机组 2024 年投运
A16: Meta Hyperion 单位投资 | B16: 100 | C16: 亿美元/GW | D16: S30｜Nasdaq｜2026-07-14 | E16: 5 GW、>500 亿美元
A17: 铀现货价（U3O8） | B17: 89.63 | C17: 美元/磅 | D17: S25｜NNN｜2026-10-22 | E17: 2026-10-22；长期合同价 96.50 美元/磅
A18: 全球数据中心投资（2024） | B18: 5000 | C18: 亿美元 | D18: S04｜IEA｜2025-04 | E18: 较 2022 年接近翻倍
A19: 标普：六家科技公司 2025–2030 AI 资本开支 | B19: 70000 | C19: 亿美元 | D19: S28｜BusinessDay｜2026-10-20 | E19: 合计可能超过 7 万亿美元；含表外安排
A22: 本报告对瓶颈的判断
A23: 电力系统的约束正在从“燃料够不够”转向“能不能按时拿到并网、变压器、燃机和施工队伍”。IEA 估计约 20% 的已规划数据中心项目可能因电网约束延期；美国活跃互联队列 2,061 GW，2025 年投运项目从申请到商运的中位时间为 61 个月。对科技公司而言，能否锁定长期、可调度、无碳的电力，比电价本身更关键。

Sheet 来源清单
A1: 来源清单：每个数字都能追到这里
A2: “材料”指任务提供的三份原始文件；网页来源均标注访问日期 2026-10-22。链接为文本，不是可点击超链接。
A4: 编号 | B4: 来源名称 | C4: 发布机构 | D4: 标题 | E4: 发布日期 | F4: 类型 | G4: 定位 / 链接 | H4: 访问日期
A5: S01 | B5: Meta Platforms 2026 年第三季度报告（Form 10-Q） | C5: Meta Platforms, Inc. | D5: Form 10-Q for the quarterly period ended September 30, 2026 | E5: 2026-10-21 | F5: 公司原始披露 | G5: 材料/Meta_2026Q3季报__meta-20260930.htm：MD&A、Note 5、Note 10、合并现金流量表 | H5: 2026-10-22
A6: S02 | B6: Constellation Energy 2025 年年报（Form 10-K） | C6: Constellation Energy Corporation | D6: 2025 Annual Report on Form 10-K | E6: 2026-02-24 | F6: 公司原始披露 | G6: 材料/Constellation_2025年报__ceg-20251231.htm：Item 1 Business、Item 7 MD&A、Note 16 | H6: 2026-10-22
A7: S03 | B7: Constellation Energy 2026 年第二季度报告（Form 10-Q） | C7: Constellation Energy Corporation | D7: Form 10-Q for the quarterly period ended June 30, 2026 | E7: 2026-08-06 | F7: 公司原始披露 | G7: 材料/Constellation_2026Q2季报__ceg-20260630.htm：MD&A、Note 2、Note 13 | H7: 2026-10-22
A8: S04 | B8: IEA《Energy and AI》执行摘要 | C8: International Energy Agency | D8: Energy and AI – Executive summary | E8: 2025-04 | F8: 国际组织研究 | G8: https://www.iea.org/reports/energy-and-ai（2026-10-22 经互联网档案馆访问） | H8: 2026-10-22
A9: S05 | B9: IEA《Energy and AI》能源供给章节 | C9: International Energy Agency | D9: Energy and AI – Energy supply for AI | E9: 2025-04 | F9: 国际组织研究 | G9: https://www.iea.org/reports/energy-and-ai/energy-supply-for-ai（2026-10-22 访问） | H9: 2026-10-22
A10: S06 | B10: Meta 2025 环境数据索引（2024 年数据） | C10: Meta Platforms, Inc. | D10: 2025 Environmental Data Index | E10: 2025-12-31 | F10: 公司可持续披露 | G10: Electricity 2.1、PUE 2.4；https://sustainability.atmeta.com/asset/2025-environmental-data-index/（2026-10-22 访问） | H10: 2026-10-22
A11: S07 | B11: Meta 核能项目公告 | C11: Meta Platforms, Inc. | D11: Meta announces nuclear energy projects to power American AI leadership | E11: 2026-01-09 | F11: 公司公告 | G11: https://about.fb.com/news/2026/01/meta-nuclear-energy-projects-power-american-ai-leadership/（2026-10-22 访问） | H11: 2026-10-22
A12: S08 | B12: Utility Dive：Meta 与 Oklo、Vistra、TerraPower 签约 | C12: Utility Dive | D12: Meta inks nuclear deals for up to 6.6 GW from Oklo, Vistra, TerraPower | E12: 2026-01-09 | F12: 行业媒体 | G12: https://www.utilitydive.com/news/meta-nuclear-deal-oklo-vistra-terrapower-ai-data-centers/809215/（2026-10-22 访问） | H12: 2026-10-22
A13: S09 | B13: Constellation：Clinton Clean Energy Center 设施页 | C13: Constellation Energy Corporation | D13: Clinton Clean Energy Center | E13: 2026-10-22 | F13: 公司网站 | G13: 装机 1,092 MW；20 年 Meta 协议庆祝活动；https://www.constellationenergy.com/about/locations/clinton-clean-energy-center.html（2026-10-22 访问） | H13: 2026-10-22
A14: S10 | B14: Talen Energy 与 Amazon 扩大核电合作（新闻稿转载） | C14: World-Energy / Talen Energy | D14: Talen and Amazon Sign 1.92 GW Nuclear Energy PPA | E14: 2025-06-13 | F14: 公司公告转载 | G14: https://www.world-energy.org/article/52524.html（2026-10-22 访问） | H14: 2026-10-22
A15: S11 | B15: Google 与 Commonwealth Fusion Systems 战略合作 | C15: Commonwealth Fusion Systems | D15: Google and Commonwealth Fusion Systems Sign Strategic Partnership | E15: 2025-06-30 | F15: 公司公告 | G15: 200 MW PPA；ARC 400 MW 净出力；early 2030s；https://cfs.energy/news-and-media/google-and-commonwealth-fusion-systems-sign-strategic-partnership/（2026-10-22 访问） | H15: 2026-10-22
... A38: S34 | B38: Meta 2026 年第三季度数据：数据中心合资企业 | C38: Meta Platforms, Inc. | D38: Form 10-Q Note 5 – Data Center Ventures | E38: 2026-10-21 | F38: 公司原始披露 | G38: Louisiana 合资企业总开发成本约 270 亿美元、Texas 约 140 亿美元，Meta 持 20%；租赁承诺 184.76 亿美元；最大剩余价值担保 414.93 亿美元 | H38: 2026-10-22
