Workbook

Sheet 汇总
A1: 汇总｜AI 的电从哪来
A2: 所有数值均由公式从“数据明细”或“假设与模型”取得。图表随输入更新；访问与版本日期：2026-10-22。
A3: 核心指标
A4: 指标 | B4: 公式结果 | C4: 单位 | D4: 口径 | E4: 来源 | F4: 发布日期
A5: 全球数据中心用电（2025） | B5: =INDEX(数据明细!$F$4:$F$243,MATCH("G003",数据明细!$A$4:$A$243,0)) -> 485 | C5: TWh | D5: IEA 2026更新估计 | E5: =INDEX(数据明细!$K$4:$K$243,MATCH("G003",数据明细!$A$4:$A$243,0)) -> IEA《Key Questions on Energy and AI》 | F5: =INDEX(数据明细!$L$4:$L$243,MATCH("G003",数据明细!$A$4:$A$243,0)) -> 2026-04-16
A6: 全球数据中心用电（2030中央预测） | B6: =INDEX(数据明细!$F$4:$F$243,MATCH("G006",数据明细!$A$4:$A$243,0)) -> 950 | C6: TWh | D6: IEA 2026中央预测 | E6: =INDEX(数据明细!$K$4:$K$243,MATCH("G006",数据明细!$A$4:$A$243,0)) -> IEA《Key Questions on Energy and AI》 | F6: =INDEX(数据明细!$L$4:$L$243,MATCH("G006",数据明细!$A$4:$A$243,0)) -> 2026-04-16
A7: 2025—2030用电增量 | B7: =B6-B5 -> 465 | C7: TWh | D7: 公式：2030减2025 | E7: =INDEX(数据明细!$K$4:$K$243,MATCH("G006",数据明细!$A$4:$A$243,0)) -> IEA《Key Questions on Energy and AI》 | F7: =INDEX(数据明细!$L$4:$L$243,MATCH("G006",数据明细!$A$4:$A$243,0)) -> 2026-04-16
A8: 2025—2030复合增速 | B8: =(B6/B5)^(1/5)-1 -> 0.1439219 | C8: 比例 | D8: 公式：5年复合增速 | E8: =INDEX(数据明细!$K$4:$K$243,MATCH("G006",数据明细!$A$4:$A$243,0)) -> IEA《Key Questions on Energy and AI》 | F8: =INDEX(数据明细!$L$4:$L$243,MATCH("G006",数据明细!$A$4:$A$243,0)) -> 2026-04-16
A9: Meta数据中心用电（2024） | B9: =INDEX(数据明细!$F$4:$F$243,MATCH("M019",数据明细!$A$4:$A$243,0))/1000000 -> 18.061781 | C9: TWh | D9: FY2024，不含办公室 | E9: =INDEX(数据明细!$K$4:$K$243,MATCH("M019",数据明细!$A$4:$A$243,0)) -> Meta 2025 Environmental Data Index | F9: =INDEX(数据明细!$L$4:$L$243,MATCH("M019",数据明细!$A$4:$A$243,0)) -> 2025-10-17
A10: Meta数据中心用电同比 | B10: =INDEX(数据明细!$F$4:$F$243,MATCH("M019",数据明细!$A$4:$A$243,0))/INDEX(数据明细!$F$4:$F$243,MATCH("M020",数据明细!$A$4:$A$243,0))-1 -> 0.20609391 | C10: 比例 | D10: 公式：2024相对2023 | E10: =INDEX(数据明细!$K$4:$K$243,MATCH("M019",数据明细!$A$4:$A$243,0)) -> Meta 2025 Environmental Data Index | F10: =INDEX(数据明细!$L$4:$L$243,MATCH("M019",数据明细!$A$4:$A$243,0)) -> 2025-10-17
A11: Meta资本开支（2026Q3） | B11: =INDEX(数据明细!$F$4:$F$243,MATCH("M001",数据明细!$A$4:$A$243,0)) -> 34.91 | C11: 十亿美元 | D11: 含融资租赁本金 | E11: =INDEX(数据明细!$K$4:$K$243,MATCH("M001",数据明细!$A$4:$A$243,0)) -> Meta 2026年三季度Form 10-Q | F11: =INDEX(数据明细!$L$4:$L$243,MATCH("M001",数据明细!$A$4:$A$243,0)) -> 2026-10-21
A12: Meta资本开支（2026年1—9月） | B12: =INDEX(数据明细!$F$4:$F$243,MATCH("M002",数据明细!$A$4:$A$243,0))+INDEX(数据明细!$F$4:$F$243,MATCH("M003",数据明细!$A$4:$A$243,0)) -> 85.824 | C12: 十亿美元 | D12: 公式：购置设备+融资租赁本金 | E12: =INDEX(数据明细!$K$4:$K$243,MATCH("M002",数据明细!$A$4:$A$243,0)) -> Meta 2026年三季度Form 10-Q | F12: =INDEX(数据明细!$L$4:$L$243,MATCH("M002",数据明细!$A$4:$A$243,0)) -> 2026-10-21
A13: 物理供电份额合计校验 | B13: =SUM(B17:B21) -> 1 | C13: 比例 | D13: 应等于100%；含剩余项公式 | E13: =INDEX(数据明细!$K$4:$K$243,MATCH("G041",数据明细!$A$4:$A$243,0)) -> IEA《Energy and AI》 | F13: =INDEX(数据明细!$L$4:$L$243,MATCH("G041",数据明细!$A$4:$A$243,0)) -> 2025-04-10
A15: 2024全球数据中心物理供电结构｜网页同源
A16: 能源 | B16: 份额 | C16: 按415 TWh折算 | D16: 性质 | E16: 来源 | F16: 发布日期
A17: 煤炭 | B17: =INDEX(数据明细!$F$4:$F$243,MATCH("G039",数据明细!$A$4:$A$243,0)) -> 0.3 | C17: =B17*INDEX(数据明细!$F$4:$F$243,MATCH("G001",数据明细!$A$4:$A$243,0)) -> 124.5 | D17: IEA约份额；折算为计算值 | E17: =INDEX(数据明细!$K$4:$K$243,MATCH("G039",数据明细!$A$4:$A$243,0)) -> IEA《Energy and AI》 | F17: =INDEX(数据明细!$L$4:$L$243,MATCH("G039",数据明细!$A$4:$A$243,0)) -> 2025-04-10
A18: 天然气 | B18: =INDEX(数据明细!$F$4:$F$243,MATCH("G038",数据明细!$A$4:$A$243,0)) -> 0.26 | C18: =B18*INDEX(数据明细!$F$4:$F$243,MATCH("G001",数据明细!$A$4:$A$243,0)) -> 107.9 | D18: IEA约份额；折算为计算值 | E18: =INDEX(数据明细!$K$4:$K$243,MATCH("G038",数据明细!$A$4:$A$243,0)) -> IEA《Energy and AI》 | F18: =INDEX(数据明细!$L$4:$L$243,MATCH("G038",数据明细!$A$4:$A$243,0)) -> 2025-04-10
A19: 可再生能源 | B19: =INDEX(数据明细!$F$4:$F$243,MATCH("G037",数据明细!$A$4:$A$243,0)) -> 0.27 | C19: =B19*INDEX(数据明细!$F$4:$F$243,MATCH("G001",数据明细!$A$4:$A$243,0)) -> 112.05 | D19: IEA约份额；折算为计算值 | E19: =INDEX(数据明细!$K$4:$K$243,MATCH("G037",数据明细!$A$4:$A$243,0)) -> IEA《Energy and AI》 | F19: =INDEX(数据明细!$L$4:$L$243,MATCH("G037",数据明细!$A$4:$A$243,0)) -> 2025-04-10
A20: 核电 | B20: =INDEX(数据明细!$F$4:$F$243,MATCH("G040",数据明细!$A$4:$A$243,0)) -> 0.15 | C20: =B20*INDEX(数据明细!$F$4:$F$243,MATCH("G001",数据明细!$A$4:$A$243,0)) -> 62.25 | D20: IEA约份额；折算为计算值 | E20: =INDEX(数据明细!$K$4:$K$243,MATCH("G040",数据明细!$A$4:$A$243,0)) -> IEA《Energy and AI》 | F20: =INDEX(数据明细!$L$4:$L$243,MATCH("G040",数据明细!$A$4:$A$243,0)) -> 2025-04-10
A21: 其他（剩余项） | B21: =INDEX(数据明细!$F$4:$F$243,MATCH("G041",数据明细!$A$4:$A$243,0)) -> 0.02 | C21: =B21*INDEX(数据明细!$F$4:$F$243,MATCH("G001",数据明细!$A$4:$A$243,0)) -> 8.3 | D21: IEA约份额；折算为计算值 | E21: =INDEX(数据明细!$K$4:$K$243,MATCH("G041",数据明细!$A$4:$A$243,0)) -> IEA《Energy and AI》 | F21: =INDEX(数据明细!$L$4:$L$243,MATCH("G041",数据明细!$A$4:$A$243,0)) -> 2025-04-10
A22: 聚变（展示假设，不计入IEA合计） | B22: — | C22: =假设与模型!C14 -> 0 | D22: 展示假设；IEA未单列商业聚变 | E22: 本研究假设 | F22: 2026-10-22
A23: 合计/校验 | B23: =SUM(B17:B21) -> 1 | C23: =SUM(C17:C21) -> 415 | D23: 应分别为100%与415 TWh
A25: 2026日历年上半年资本开支｜定义不同，不作简单排名
A26: 公司 | B26: 公式结果 | C26: 单位 | D26: 原始口径与计算 | E26: 来源 | F26: 发布日期
A27: Meta | B27: =INDEX(数据明细!$F$4:$F$243,MATCH("M002",数据明细!$A$4:$A$243,0))+INDEX(数据明细!$F$4:$F$243,MATCH("M003",数据明细!$A$4:$A$243,0))-INDEX(数据明细!$F$4:$F$243,MATCH("M001",数据明细!$A$4:$A$243,0)) -> 50.914 | C27: 十亿美元 | D27: 9M购置设备+租赁本金减Q3资本开支；约数 | E27: =INDEX(数据明细!$K$4:$K$243,MATCH("M001",数据明细!$A$4:$A$243,0)) -> Meta 2026年三季度Form 10-Q | F27: =INDEX(数据明细!$L$4:$L$243,MATCH("M001",数据明细!$A$4:$A$243,0)) -> 2026-10-21
A28: Alphabet | B28: =INDEX(数据明细!$F$4:$F$243,MATCH("T001",数据明细!$A$4:$A$243,0)) -> 80.598 | C28: 十亿美元 | D28: H1购置物业及设备现金支出 | E28: =INDEX(数据明细!$K$4:$K$243,MATCH("T001",数据明细!$A$4:$A$243,0)) -> SEC Companyfacts：Alphabet | F28: =INDEX(数据明细!$L$4:$L$243,MATCH("T001",数据明细!$A$4:$A$243,0)) -> 2026-07-23
A29: Microsoft | B29: =INDEX(数据明细!$F$4:$F$243,MATCH("T007",数据明细!$A$4:$A$243,0))+INDEX(数据明细!$F$4:$F$243,MATCH("T005",数据明细!$A$4:$A$243,0))-INDEX(数据明细!$F$4:$F$243,MATCH("T006",数据明细!$A$4:$A$243,0)) -> 66.678 | C29: 十亿美元 | D29: 日历年Q1+（FY全年-FY前9月） | E29: =INDEX(数据明细!$K$4:$K$243,MATCH("T005",数据明细!$A$4:$A$243,0)) -> SEC Companyfacts：Microsoft | F29: =INDEX(数据明细!$L$4:$L$243,MATCH("T005",数据明细!$A$4:$A$243,0)) -> 2026-07-29
A30: Amazon | B30: =INDEX(数据明细!$F$4:$F$243,MATCH("T003",数据明细!$A$4:$A$243,0)) -> 98.411 | C30: 十亿美元 | D30: H1生产性资产购置现金支出 | E30: =INDEX(数据明细!$K$4:$K$243,MATCH("T003",数据明细!$A$4:$A$243,0)) -> SEC Companyfacts：Amazon | F30: =INDEX(数据明细!$L$4:$L$243,MATCH("T003",数据明细!$A$4:$A$243,0)) -> 2026-07-31
A32: 全球用电图表数据
A33: 年份 | B33: 用电量 | C33: 单位 | D33: 性质 | E33: 来源 | F33: 发布日期
A34: 2024 | B34: =INDEX(数据明细!$F$4:$F$243,MATCH("G001",数据明细!$A$4:$A$243,0)) -> 415 | C34: TWh | D34: IEA 2025估计 | E34: =INDEX(数据明细!$K$4:$K$243,MATCH("G001",数据明细!$A$4:$A$243,0)) -> IEA《Energy and AI》 | F34: =INDEX(数据明细!$L$4:$L$243,MATCH("G001",数据明细!$A$4:$A$243,0)) -> 2025-04-10
A35: 2025 | B35: =INDEX(数据明细!$F$4:$F$243,MATCH("G003",数据明细!$A$4:$A$243,0)) -> 485 | C35: TWh | D35: IEA 2026估计 | E35: =INDEX(数据明细!$K$4:$K$243,MATCH("G003",数据明细!$A$4:$A$243,0)) -> IEA《Key Questions on Energy and AI》 | F35: =INDEX(数据明细!$L$4:$L$243,MATCH("G003",数据明细!$A$4:$A$243,0)) -> 2026-04-16
A36: 2030 | B36: =INDEX(数据明细!$F$4:$F$243,MATCH("G006",数据明细!$A$4:$A$243,0)) -> 950 | C36: TWh | D36: IEA 2026中央预测 | E36: =INDEX(数据明细!$K$4:$K$243,MATCH("G006",数据明细!$A$4:$A$243,0)) -> IEA《Key Questions on Energy and AI》 | F36: =INDEX(数据明细!$L$4:$L$243,MATCH("G006",数据明细!$A$4:$A$243,0)) -> 2026-04-16
A38: 2030敏感性｜本研究乘数，不是IEA情景
A39: 情景 | B39: 用电量 | C39: 单位 | D39: 公式 | E39: 来源 | F39: 发布日期
A40: 低情景（0.8×） | B40: =假设与模型!C25 -> 760 | C40: TWh | D40: IEA 950 TWh×假设乘数 | E40: IEA+本研究假设 | F40: 2026-10-22
A41: 中央预测 | B41: =假设与模型!C26 -> 950 | C41: TWh | D41: IEA 950 TWh×假设乘数 | E41: IEA+本研究假设 | F41: 2026-10-22
A42: 高情景（1.2×） | B42: =假设与模型!C27 -> 1140 | C42: TWh | D42: IEA 950 TWh×假设乘数 | E42: IEA+本研究假设 | F42: 2026-10-22
A44: 100 MW示例负载｜完整可调模型见“假设与模型”
A45: 输出 | B45: 公式结果 | C45: 单位 | D45: 说明 | E45: 来源 | F45: 发布日期
...

Sheet 数据明细
A1: 数据明细｜报告与网页同源
A2: 每行均含来源、发布日期与口径。黄色为披露值/输入，蓝色为公式。访问日期：2026-10-22。
A3: 数据ID | B3: 主题 | C3: 指标 | D3: 主体/地区 | E3: 期间 | F3: 数值 | G3: 单位 | H3: 数据性质 | I3: 口径说明 | J3: 来源ID | K3: 来源名称 | L3: 发布日期 | M3: 章节/表名/定位 | N3: 网页链接/原始文件 | O3: 访问日期 | P3: 值修饰 | Q3: 补充说明
A4: G001 | B4: 全球用电 | C4: 数据中心用电量 | D4: 全球 | E4: 2024 | F4: 415 | G4: TWh | H4: 机构估计 | I4: 终端电力消费，非发电侧；约数 | J4: S01 | K4: IEA《Energy and AI》 | L4: 2025-04-10 | M4: 执行摘要；第2章图2.11、2.20、表2.3；第5章5.4 | N4: https://www.iea.org/reports/energy-and-ai | O4: 2026-10-22 | P4: 约
A5: G002 | B5: 全球用电 | C5: 数据中心占全球用电比重 | D5: 全球 | E5: 2024 | F5: 0.015 | G5: 比例 | H5: 机构估计 | I5: 与415 TWh同口径 | J5: S01 | K5: IEA《Energy and AI》 | L5: 2025-04-10 | M5: 执行摘要；第2章图2.11、2.20、表2.3；第5章5.4 | N5: https://www.iea.org/reports/energy-and-ai | O5: 2026-10-22 | P5: 约
A6: G003 | B6: 全球用电 | C6: 数据中心用电量 | D6: 全球 | E6: 2025 | F6: 485 | G6: TWh | H6: 机构估计 | I6: IEA 2026更新估计 | J6: S02 | K6: IEA《Key Questions on Energy and AI》 | L6: 2026-04-16 | M6: 执行摘要；第1章图1.1及后续专题 | N6: https://www.iea.org/reports/key-questions-on-energy-and-ai | O6: 2026-10-22 | P6: 约
A7: G004 | B7: 全球用电 | C7: 数据中心用电同比增速 | D7: 全球 | E7: 2025 | F7: 0.17 | G7: 比例 | H7: 机构估计 | I7: 2025相对2024；IEA修订后序列 | J7: S02 | K7: IEA《Key Questions on Energy and AI》 | L7: 2026-04-16 | M7: 执行摘要；第1章图1.1及后续专题 | N7: https://www.iea.org/reports/key-questions-on-energy-and-ai | O7: 2026-10-22 | P7: =
A8: G049 | B8: 全球用电 | C8: 数据中心占全球用电比重 | D8: 全球 | E8: 2025 | F8: 0.015 | G8: 比例 | H8: 机构估计 | I8: IEA正文为略高于1.5%；取约数展示 | J8: S02 | K8: IEA《Key Questions on Energy and AI》 | L8: 2026-04-16 | M8: 执行摘要；第1章图1.1及后续专题 | N8: https://www.iea.org/reports/key-questions-on-energy-and-ai | O8: 2026-10-22 | P8: 略超过
A9: G005 | B9: 全球用电 | C9: AI专用数据中心用电同比增速 | D9: 全球 | E9: 2025 | F9: 0.5 | G9: 比例 | H9: 机构估计 | I9: AI-focused data centres | J9: S02 | K9: IEA《Key Questions on Energy and AI》 | L9: 2026-04-16 | M9: 执行摘要；第1章图1.1及后续专题 | N9: https://www.iea.org/reports/key-questions-on-energy-and-ai | O9: 2026-10-22 | P9: =
A10: G006 | B10: 全球用电 | C10: 数据中心用电量：中央预测 | D10: 全球 | E10: 2030 | F10: 950 | G10: TWh | H10: 机构预测 | I10: IEA 2026更新中央预测 | J10: S02 | K10: IEA《Key Questions on Energy and AI》 | L10: 2026-04-16 | M10: 执行摘要；第1章图1.1及后续专题 | N10: https://www.iea.org/reports/key-questions-on-energy-and-ai | O10: 2026-10-22 | P10: 约
A11: G007 | B11: 全球用电 | C11: 数据中心占全球用电比重：预测 | D11: 全球 | E11: 2030 | F11: 0.03 | G11: 比例 | H11: 机构预测 | I11: 与950 TWh同口径 | J11: S02 | K11: IEA《Key Questions on Energy and AI》 | L11: 2026-04-16 | M11: 执行摘要；第1章图1.1及后续专题 | N11: https://www.iea.org/reports/key-questions-on-energy-and-ai | O11: 2026-10-22 | P11: 约
A12: G008 | B12: 全球用电 | C12: AI专用数据中心用电2030/2025倍数 | D12: 全球 | E12: 2030 | F12: 3 | G12: 倍 | H12: 机构预测 | I12: tripling；不是占总用电比例 | J12: S02 | K12: IEA《Key Questions on Energy and AI》 | L12: 2026-04-16 | M12: 执行摘要；第1章图1.1及后续专题 | N12: https://www.iea.org/reports/key-questions-on-energy-and-ai | O12: 2026-10-22 | P12: 约
A13: G009 | B13: 全球用电 | C13: 数据中心用电量：前版基准预测 | D13: 全球 | E13: 2030 | F13: 945 | G13: TWh | H13: 机构预测 | I13: IEA 2025 Base Case，保留作版本对照 | J13: S01 | K13: IEA《Energy and AI》 | L13: 2025-04-10 | M13: 执行摘要；第2章图2.11、2.20、表2.3；第5章5.4 | N13: https://www.iea.org/reports/energy-and-ai | O13: 2026-10-22 | P13: 约
A14: G010 | B14: 全球用电 | C14: 全球数据中心用电区域份额 | D14: 美国 | E14: 2024 | F14: 0.45 | G14: 比例 | H14: 机构估计 | I14: 区域终端用电份额 | J14: S01 | K14: IEA《Energy and AI》 | L14: 2025-04-10 | M14: 执行摘要；第2章图2.11、2.20、表2.3；第5章5.4 | N14: https://www.iea.org/reports/energy-and-ai | O14: 2026-10-22 | P14: 约
A15: G011 | B15: 全球用电 | C15: 全球数据中心用电区域份额 | D15: 中国 | E15: 2024 | F15: 0.25 | G15: 比例 | H15: 机构估计 | I15: 区域终端用电份额 | J15: S01 | K15: IEA《Energy and AI》 | L15: 2025-04-10 | M15: 执行摘要；第2章图2.11、2.20、表2.3；第5章5.4 | N15: https://www.iea.org/reports/energy-and-ai | O15: 2026-10-22 | P15: 约
... A44: G040 | B44: 物理供电结构 | C44: 2024年数据中心物理供电份额 | D44: 核电 | E44: 2024 | F44: 0.15 | G44: 比例 | H44: 机构估计 | I44: 现场发电与电网输入的物理供给侧，不是企业合同采购组合；IEA约数 | J44: S01 | K44: IEA《Energy and AI》 | L44: 2025-04-10 | M44: 执行摘要；第2章图2.11、2.20、表2.3；第5章5.4 | N44: https://www.iea.org/reports/energy-and-ai | O44: 2026-10-22 | P44: 约
A45: G041 | B45: 物理供电结构 | C45: 2024年数据中心物理供电份额：剩余项 | D45: 其他 | E45: 2024 | F45: =1-SUM(F41,F42,F43,F44) -> 0.02 | G45: 比例 | H45: 计算值 | I45: 1减去可再生、天然气、煤炭、核电约份额；含未单列来源，受四舍五入影响 | J45: S01 | K45: IEA《Energy and AI》 | L45: 2025-04-10 | M45: 执行摘要；第2章图2.11、2.20、表2.3；第5章5.4 | N45: https://www.iea.org/reports/energy-and-ai | O45: 2026-10-22 | P45: 约 | Q45: Excel中以公式计算。
A46: G042 | B46: 物理供电结构 | C46: 可再生能源满足2024—2030新增需求份额 | D46: 全球 | E46: 2024—2030 | F46: 0.5 | G46: 比例 | H46: 机构预测 | I46: 接近50%；不是2030总供电占比 | J46: S01 | K46: IEA《Energy and AI》 | L46: 2025-04-10 | M46: 执行摘要；第2章图2.11、2.20、表2.3；第5章5.4 | N46: https://www.iea.org/reports/energy-and-ai | O46: 2026-10-22 | P46: 接近
A47: G043 | B47: 物理供电结构 | C47: 天然气和煤炭满足2024—2030新增需求份额 | D47: 全球 | E47: 2024—2030 | F47: 0.4 | G47: 比例 | H47: 机构预测 | I47: 合计超过40%；不是2030总供电占比 | J47: S01 | K47: IEA《Energy and AI》 | L47: 2025-04-10 | M47: 执行摘要；第2章图2.11、2.20、表2.3；第5章5.4 | N47: https://www.iea.org/reports/energy-and-ai | O47: 2026-10-22 | P47: 超过
A48: G044 | B48: 物理供电结构 | C48: 数据中心燃气发电增量 | D48: 美国 | E48: 2024—2030 | F48: 130 | G48: TWh | H48: 机构预测 | I48: IEA 2025基准情景，超过该值 | J48: S01 | K48: IEA《Energy and AI》 | L48: 2025-04-10 | M48: 执行摘要；第2章图2.11、2.20、表2.3；第5章5.4 | N48: https://www.iea.org/reports/energy-and-ai | O48: 2026-10-22 | P48: 超过
A49: G045 | B49: 物理供电结构 | C49: 数据中心可再生发电增量 | D49: 美国 | E49: 2024—2030 | F49: 110 | G49: TWh | H49: 机构预测 | I49: IEA 2025基准情景 | J49: S01 | K49: IEA《Energy and AI》 | L49: 2025-04-10 | M49: 执行摘要；第2章图2.11、2.20、表2.3；第5章5.4 | N49: https://www.iea.org/reports/energy-and-ai | O49: 2026-10-22 | P49: 约
A50: G046 | B50: 物理供电结构 | C50: 数据中心发电相关二氧化碳排放 | D50: 全球 | E50: 2030 | F50: 320 | G50: MtCO2 | H50: 机构预测 | I50: IEA 2025基准情景峰值附近 | J50: S01 | K50: IEA《Energy and AI》 | L50: 2025-04-10 | M50: 执行摘要；第2章图2.11、2.20、表2.3；第5章5.4 | N50: https://www.iea.org/reports/energy-and-ai | O50: 2026-10-22 | P50: 约
A51: C001L | B51: 成本与交付 | C51: 全球平均LCOE | D51: 太阳能光伏 | E51: IEA 2025表2.3 | F51: 60 | G51: USD/MWh | H51: 机构估计 | I51: 全球平均平准化度电成本；不含并网及其他间接成本，不是PPA价格 | J51: S01 | K51: IEA《Energy and AI》 | L51: 2025-04-10 | M51: 第2章表2.3 Sources of electricity to match the needs of data centres | N51: https://www.iea.org/reports/energy-and-ai | O51: 2026-10-22 | P51: 约
A52: C001A | B52: 成本与交付 | C52: 典型建设期下限 | D52: 太阳能光伏 | E52: IEA 2025表2.3 | F52: 1 | G52: 年 | H52: 机构估计 | I52: 典型项目，不含供应链设备延误 | J52: S01 | K52: IEA《Energy and AI》 | L52: 2025-04-10 | M52: 第2章表2.3 | N52: https://www.iea.org/reports/energy-and-ai | O52: 2026-10-22 | P52: 约
A53: C001B | B53: 成本与交付 | C53: 典型建设期上限 | D53: 太阳能光伏 | E53: IEA 2025表2.3 | F53: 4 | G53: 年 | H53: 机构估计 | I53: 典型项目，不含供应链设备延误 | J53: S01 | K53: IEA《Energy and AI》 | L53: 2025-04-10 | M53: 第2章表2.3 | N53: https://www.iea.org/reports/energy-and-ai | O53: 2026-10-22 | P53: 约
A54: C002L | B54: 成本与交付 | C54: 全球平均LCOE | D54: 陆上风电 | E54: IEA 2025表2.3 | F54: 50 | G54: USD/MWh | H54: 机构估计 | I54: 全球平均平准化度电成本；不含并网及其他间接成本，不是PPA价格 | J54: S01 | K54: IEA《Energy and AI》 | L54: 2025-04-10 | M54: 第2章表2.3 Sources of electricity to match the needs of data centres | N54: https://www.iea.org/reports/energy-and-ai | O54: 2026-10-22 | P54: 约
A55: C002A | B55: 成本与交付 | C55: 典型建设期下限 | D55: 陆上风电 | E55: IEA 2025表2.3 | F55: 2 | G55: 年 | H55: 机构估计 | I55: 典型项目，不含供应链设备延误 | J55: S01 | K55: IEA《Energy and AI》 | L55: 2025-04-10 | M55: 第2章表2.3 | N55: https://www.iea.org/reports/energy-and-ai | O55: 2026-10-22 | P55: 约
A56: C002B | B56: 成本与交付 | C56: 典型建设期上限 | D56: 陆上风电 | E56: IEA 2025表2.3 | F56: 5 | G56: 年 | H56: 机构估计 | I56: 典型项目，不含供应链设备延误 | J56: S01 | K56: IEA《Energy and AI》 | L56: 2025-04-10 | M56: 第2章表2.3 | N56: https://www.iea.org/reports/energy-and-ai | O56: 2026-10-22 | P56: 约
A57: C003L | B57: 成本与交付 | C57: 全球平均LCOE | D57: 海上风电 | E57: IEA 2025表2.3 | F57: 110 | G57: USD/MWh | H57: 机构估计 | I57: 全球平均平准化度电成本；不含并网及其他间接成本，不是PPA价格 | J57: S01 | K57: IEA《Energy and AI》 | L57: 2025-04-10 | M57: 第2章表2.3 Sources of electricity to match the needs of data centres | N57: https://www.iea.org/reports/energy-and-ai | O57: 2026-10-22 | P57: 约
... A243: T020 | B243: 科技用电 | C243: 可再生电力年度匹配比例 | D243: Amazon全球运营 | E243: 2025 | F243: 1 | G243: 比例 | H243: 披露事实 | I243: 全球运营边界，含零售和履约；不是AWS单独或24/7口径 | J243: S31 | K243: Amazon 2025 Sustainability Report | L243: 2026-10-16 | M243: Climate and Energy—Renewable energy matching | N243: https://sustainability.aboutamazon.com/2025-amazon-sustainability-report.pdf | O243: 2026-10-22 | P243: =

Sheet 假设与模型
A1: 假设与模型｜修改黄色格，蓝色格自动更新
A2: 示例仅用于理解功率、电量、电费与损失的关系；不代表Meta实际项目，不是电价预测或投资模型。
A3: 参数ID | B3: 参数/结果 | C3: 输入值或公式结果 | D3: 单位 | E3: 性质 | F3: 来源名称 | G3: 发布日期 | H3: 口径说明
A4: A001 | B4: 示例数据中心IT负载 | C4: 100 | D4: MW | E4: 假设 | F4: 本研究假设/计算参数 | G4: 2026-10-22 | H4: 纯示例，不代表Meta或任何具体公司的实际负载。
A5: A002 | B5: 示例年平均负载率 | C5: 0.9 | D5: 比例 | E5: 假设 | F5: 本研究假设/计算参数 | G5: 2026-10-22 | H5: 实际IT负载相对额定IT负载的年平均比例。
A6: A003 | B6: 示例PUE | C6: 1.3 | D6: 倍 | E6: 假设 | F6: 本研究假设/计算参数 | G6: 2026-10-22 | H6: 总设施功率/IT功率；接近IEA 2030平均预测但不是任何公司的实际值。
A7: A004 | B7: 示例综合电价 | C7: 80 | D7: USD/MWh | E7: 假设 | F7: 本研究假设/计算参数 | G7: 2026-10-22 | H7: 仅用于敏感性演算，不是PPA报价、电价预测或投资建议。
A8: A005 | B8: 示例输配电及厂用损失率 | C8: 0.06 | D8: 比例 | E8: 假设 | F8: 本研究假设/计算参数 | G8: 2026-10-22 | H8: 用于从数据中心表计电量折算发电侧需求。
A9: A006 | B9: 示例全年小时数 | C9: 8760 | D9: 小时 | E9: 计算参数 | F9: 本研究假设/计算参数 | G9: 2026-10-22 | H9: 非闰年示例；不用于Meta 2024闰年平均功率。
A10: A007 | B10: 2030需求低情景乘数 | C10: 0.8 | D10: 倍 | E10: 假设 | F10: 本研究假设/计算参数 | G10: 2026-10-22 | H10: 乘以IEA 950 TWh中央预测，属于本研究敏感性，不是IEA情景。
A11: A008 | B11: 2030需求高情景乘数 | C11: 1.2 | D11: 倍 | E11: 假设 | F11: 本研究假设/计算参数 | G11: 2026-10-22 | H11: 乘以IEA 950 TWh中央预测，属于本研究敏感性，不是IEA情景。
A12: A009 | B12: 2030聚变供电基准假设 | C12: 0 | D12: TWh | E12: 假设 | F12: 本研究假设/计算参数 | G12: 2026-10-22 | H12: 基准不预设商业聚变供电；未来PPA单独列示，非预测聚变必然为零。
A13: A010 | B13: Meta 2024全年小时数 | C13: 8784 | D13: 小时 | E13: 计算参数 | F13: 本研究假设/计算参数 | G13: 2026-10-22 | H13: 2024为闰年，用于年度电量折算平均功率。
A14: A011 | B14: 2024聚变供电展示值 | C14: 0 | D14: TWh | E14: 展示假设 | F14: 本研究假设/计算参数 | G14: 2026-10-22 | H14: IEA物理供电结构未单列商业聚变；网页以0作展示，不代表实验装置没有聚变能量。
A18: 公式结果｜100 MW示例负载与2030敏感性
A19: R001 | B19: 示例IT年用电量 | C19: =假设与模型!C4*假设与模型!C5*假设与模型!C9/1000000 -> 0.7884 | D19: TWh | E19: 计算值 | F19: 本研究公式；外部输入见对应参数/数据明细 | G19: 2026-10-22 | H19: IT负载×负载率×全年小时；不含制冷等 overhead。
A20: R002 | B20: 示例设施总功率 | C20: =假设与模型!C4*假设与模型!C6 -> 130 | D20: MW | E20: 计算值 | F20: 本研究公式；外部输入见对应参数/数据明细 | G20: 2026-10-22 | H20: IT负载×PUE。
A21: R003 | B21: 示例数据中心表计年用电量 | C21: =假设与模型!C4*假设与模型!C6*假设与模型!C5*假设与模型!C9/1000000 -> 1.02492 | D21: TWh | E21: 计算值 | F21: 本研究公式；外部输入见对应参数/数据明细 | G21: 2026-10-22 | H21: IT负载×PUE×负载率×小时。
A22: R004 | B22: 示例非IT overhead年用电量 | C22: =C21-C19 -> 0.23652 | D22: TWh | E22: 计算值 | F22: 本研究公式；外部输入见对应参数/数据明细 | G22: 2026-10-22 | H22: 表计总电量减IT电量。
A23: R005 | B23: 示例发电侧所需电量 | C23: =C21/(1-假设与模型!C8) -> 1.0903404 | D23: TWh | E23: 计算值 | F23: 本研究公式；外部输入见对应参数/数据明细 | G23: 2026-10-22 | H23: 表计电量÷(1-损失率)。
A24: R006 | B24: 示例年度电费 | C24: =C21*假设与模型!C7 -> 81.9936 | D24: 百万USD | E24: 计算值 | F24: 本研究公式；外部输入见对应参数/数据明细 | G24: 2026-10-22 | H24: TWh×USD/MWh，数值恰为百万美元；不含容量费、税费和并网固定费。
A25: R007 | B25: 2030低情景用电 | C25: =INDEX(数据明细!$F$4:$F$243,MATCH("G006",数据明细!$A$4:$A$243,0))*假设与模型!C10 -> 760 | D25: TWh | E25: 计算值 | F25: 本研究公式；外部输入见对应参数/数据明细 | G25: 2026-10-22 | H25: IEA中央预测×本研究低情景乘数。
A26: R008 | B26: 2030中央情景用电 | C26: =INDEX(数据明细!$F$4:$F$243,MATCH("G006",数据明细!$A$4:$A$243,0)) -> 950 | D26: TWh | E26: 计算值 | F26: 本研究公式；外部输入见对应参数/数据明细 | G26: 2026-10-22 | H26: IEA 2026中央预测。
A27: R009 | B27: 2030高情景用电 | C27: =INDEX(数据明细!$F$4:$F$243,MATCH("G006",数据明细!$A$4:$A$243,0))*假设与模型!C11 -> 1140 | D27: TWh | E27: 计算值 | F27: 本研究公式；外部输入见对应参数/数据明细 | G27: 2026-10-22 | H27: IEA中央预测×本研究高情景乘数。
A28: R010 | B28: 2030聚变供电基准假设 | C28: =假设与模型!C12 -> 0 | D28: TWh | E28: 计算值 | F28: 本研究公式；外部输入见对应参数/数据明细 | G28: 2026-10-22 | H28: 基准不预设商业聚变；不是断言聚变一定为零。

Sheet 来源索引
A1: 来源索引｜一条来源，多处引用
A2: 网络资料访问日期均为2026-10-22；网页成品中仅展示来源名称和日期，不放可点击外部链接。
A3: 来源ID | B3: 来源名称 | C3: 类型 | D3: 发布日期 | E3: 常用定位 | F3: 网址/原始文件 | G3: 访问日期 | H3: 版本与口径备注
A4: S01 | B4: IEA《Energy and AI》 | C4: 机构报告 | D4: 2025-04-10 | E4: 执行摘要；第2章图2.11、2.20、表2.3；第5章5.4 | F4: https://www.iea.org/reports/energy-and-ai | G4: 2026-10-22 | H4: 2025年基准情景；全球发电侧/用电侧口径按具体数据行区分。
A5: S02 | B5: IEA《Key Questions on Energy and AI》 | C5: 机构报告 | D5: 2026-04-16 | E5: 执行摘要；第1章图1.1及后续专题 | F5: https://www.iea.org/reports/key-questions-on-energy-and-ai | G5: 2026-10-22 | H5: 2026年更新；2030年950 TWh为最新中央预测。
A6: S03 | B6: Meta 2026年三季度Form 10-Q | C6: 原始财报 | D6: 2026-10-21 | E6: MD&A；合并现金流量表；Note 4、5、10 | F6: 材料/Meta_2026Q3季报__meta-20260930.htm | G6: 2026-10-22 | H6: 财务数字以本地原始文件为准。
A7: S04 | B7: Constellation Energy 2025年Form 10-K | C7: 原始财报 | D7: 2026-02-24 | E7: ITEM 1、2、7；Nuclear Facilities；Sales and Supply Sources | F7: 材料/Constellation_2025年报__ceg-20251231.htm | G7: 2026-10-22 | H7: 财务与运营数字以本地原始文件为准。
A8: S05 | B8: Constellation Energy 2026年二季度Form 10-Q | C8: 原始财报 | D8: 2026-08-06 | E8: Note 3、13；MD&A Long-term Nuclear PPAs；Sales and Supply Sources | F8: 材料/Constellation_2026Q2季报__ceg-20260630.htm | G8: 2026-10-22 | H8: Crane审批与贷款状态采用此较新披露。
A9: S06 | B9: Meta 2025 Environmental Data Index | C9: 公司可持续数据 | D9: 2025-10-17 | E9: F页2.1 Electricity；2.4 Data Center Operations；附录PUE/WUE方法 | F9: https://sustainability.atmeta.com/asset/2025-environmental-data-index/ | G9: 2026-10-22 | H9: 日期采用PDF修订日；覆盖2024财年，是用电数据的年份而非2026年。
A10: S07 | B10: Meta：Nuclear Energy Projects | C10: 公司公告 | D10: 2026-01-09 | E10: Vistra、TerraPower、Oklo及Supporting Our Energy Future段落 | F10: https://about.fb.com/news/2026/01/meta-nuclear-energy-projects-power-american-ai-leadership/ | G10: 2026-10-22 | H10: 项目容量包括现有、增容与目标容量，不能视为已投运。
A11: S08 | B11: Constellation与Meta Clinton 20年协议公告 | C11: 公司公告 | D11: 2025-06-03 | E11: 首段及协议说明 | F11: https://www.constellationenergy.com/news/2025/constellation-meta-sign-20-year-deal-for-clean-reliable-nuclear-energy-in-illinois.html | G11: 2026-10-22 | H11: 1121 MW为公告所述电站无排放核能规模，30 MW为增容，口径不同。
A12: S09 | B12: Constellation与Google核电增容协议公告 | C12: 公司公告 | D12: 2026-10-06 | E12: 首段、Accelerating Grid Capacity Through Nuclear Uprates | F12: https://www.constellationenergy.com/news/2026/10/google-and-constellation-announce-landmark-agreement-to-bring-890-mw-of-new-nuclear-capacity-to-pjm-grid.html | G12: 2026-10-22 | H12: 890 MW为11台机组增容目标，首个增容预计2028年交付。
A13: S10 | B13: Constellation与Amazon Calvert Cliffs协议公告 | C13: 公司公告 | D13: 2026-09-30 | E13: 首三段 | F13: https://www.constellationenergy.com/news/2026/09/constellation-and-amazon-announce-20-year-power-purchase-agreement-at-calvert-cliffs.html | G13: 2026-10-22 | H13: 690 MW合同含190 MW增容；电力继续流入PJM电网。
A14: S11 | B14: SEC Companyfacts：Alphabet | C14: 监管数据 | D14: 2026-07-23 | E14: PaymentsToAcquirePropertyPlantAndEquipment；accn 0001652044-26-000071 | F14: https://data.sec.gov/api/xbrl/companyfacts/CIK0001652044.json | G14: 2026-10-22 | H14: 2026H1购置物业及设备的现金支出，不含Meta式融资租赁本金加总。
... A34: S31 | B34: Amazon 2025 Sustainability Report | C34: 公司可持续报告 | D34: 2026-10-16 | E34: Climate and Energy；Data Tables and Assurance Statements | F34: https://sustainability.aboutamazon.com/2025-amazon-sustainability-report.pdf | G34: 2026-10-22 | H34: 采用截至2026-10-16修订版；原始PDF创建日2026-07-14。42 GW为项目预期容量而非年用电量。

Sheet 口径说明
A1: 口径说明｜先看定义，再看数字
A2: 本页说明阅读和使用方法；完整未核实事项与假设同时列于README。
A3: 主题 | B3: 说明
A4: 研究边界 | B4: 本工作为能源与科技行业研究，不提供买入、卖出、持有、目标价，也不评价股价。
A5: 事实与假设 | B5: “披露事实”来自原始文件或公司公告；“机构估计/预测”保留机构口径；“公司目标/协议约定”不代表已经投运；“假设/计算参数”均可修改。
A6: 资本开支 | B6: Meta口径含融资租赁本金；Alphabet、Amazon、Microsoft按各自SEC XBRL标签。横向图只用于数量级对照，不视为完全同口径排名。资本开支包含服务器等IT设备，不能直接换算电力容量。
A7: 电力与功率 | B7: TWh是电量，GW/MW是功率。平均功率=电量÷小时数。PPA的MW通常描述合同或电站容量，不等于每年恒定输出，也不等于科技公司物理专线。
A8: 415与460 TWh | B8: 415 TWh是2024年终端电力消费；460 TWh是相应发电侧供电量，含厂自用和输配损失。网页能量流以415 TWh乘IEA物理结构约份额，仅作结构演示。
A9: 物理与合同结构 | B9: IEA物理结构按数据中心所在地电网和现场发电估计。企业的100%年度清洁/可再生匹配是合同口径，不意味着每小时物理用电均来自同一电源。
A10: 美国区域模型 | B10: LBNL的2023年176 TWh与IEA的2024年约180 TWh在年份、模型和覆盖范围上不同，不做未经调整的同比拼接。
A11: 核电容量 | B11: 电站现有容量、PPA协议量、增容量和未来投运容量分开列示。Crane部分输电升级最晚2030年，不是重启目标年。
A12: 聚变里程碑 | B12: Q>1、net facility gain、first plasma、demonstrate fusion energy不等于净上网电力。融资额、承诺出资、公共补助、项目资本开支、可提取额度和合并估值分开。
A13: 模型公式 | B13: 示例年度电费（百万USD）=IT MW×PUE×负载率×小时÷1,000,000×USD/MWh。发电侧电量=表计电量÷(1-损失率)。
A14: 颜色与编辑 | B14: 黄色单元格为可修改输入；蓝色单元格为公式。修改假设后，Excel或LibreOffice会重算汇总、图表和模型；网页为交付时静态同源快照，不会读取Excel并实时更新。
A15: 未核实事项 | B15: 商业PPA价格、多数项目精确投运日、科技公司2025/2026逐家同口径实际用电、聚变最终交付与部分累计融资最新口径未完全披露，详见README。
