Workbook

Sheet 说明
A1: SpaceX + Tesla｜合并财务分析模型
A2: 投委会内部讨论底稿｜截至2026-10-22｜所有金额除特别注明均为US$ million；本模型为研究和展示用途，不构成投资建议。
A4: 先看结论（公式链接至合并备考）
A5: 指标 | B5: 数值 | C5: 指标 | D5: 数值 | E5: 说明
A6: LTM经营利润 | B6: =合并备考!D6 -> 135613 | D6: =合并备考!D8 -> 2798 | E6: 未抵销汇总；LTM为2025Q4–2026Q3
A7: 期末现金＋短期投资 | B7: =合并备考!D12 -> -35895 | D7: =合并备考!D18 -> 135302 | E7: 现金为期末余额，不与LTM流量混淆
A8: 期末净现金 | B8: =合并备考!D19 -> 48367 | D8: =合并备考!D20 -> 86935 | E8: 含融资租赁；不含夹层项目
A9: Musk合并后经济持股（静态） | B9: =换股比例!F28 -> 2.4258992 | D9: =换股比例!K28 -> 0.33518917 | E9: 每1股Tesla换取SpaceX股数；经济权益非投票权
A12: 口径与使用说明
A13: 1. 期间：两家最近四个季度为2025Q4、2026Q1、2026Q2、2026Q3；最近完整财年为FY2025；LTM为四季相加。资产负债表使用2025-12-31、2026-03-31、2026-06-30、2026-09-30期末。
A14: 2. 毛利=营收−营收成本；自由现金流=经营现金流−资本开支。Capex以现金流出正数列示；Tesla包含能源发电及储能系统购买，SpaceX不含资本化利息等非PP&E项目。
A15: 3. SpaceX Q4经营数据=FY2025−9M2025；2026Q2/Q3 CFO和Capex由YTD差分。Tesla Q4由Q3 Update直接披露，另与10-K/10-Q比较期勾稽。
A16: 4. Tesla汽车报告分部含Services and other，能源为另一报告分部；Tesla分部利润只有毛利。SpaceX分部经营利润是CODM口径，SI是原AI分部的新名称。
A17: 5. 合并备考Headline是未抵销汇总，不是正式会计合并报表。已知Q3内部销售另列示例；完整LTM抵销、交叉投资、购买法和协同尚未确定。
A18: 6. 换股结构仅为假设：SpaceX发行Class A给Tesla股东；溢价应用于Tesla对价。四种方法均为相对定价情景，不给目标价，不评价股价贵不贵。
A19: 7. 持股：SpaceX实际Class A+B不含350m期权；IPO经济比例与最新股数静态比例分列。Tesla Proxy的19.8%使用调整分母，模型另列全部已发行股数口径17.7%。投票权不由经济比例推导。
A22: 数据来源与取数日期
A23: 来源ID | B23: 文件 / 网页 | C23: 用途 | D23: 取数 / 访问日期 | E23: 关键章节 / 表名
A24: SX-IPO | B24: 材料/SpaceX_招股书__spaceexplorationtechnologi.htm | C24: FY2025、Q1、分部、债务、关联交易、Musk持股、IPO | D24: 2026-10-22 | E24: F-4/F-5/F-8/F-58/F-63/F-95；Note 18/19；Security Ownership；Transactions with Tesla
A25: SX-Q2 | B25: 材料/SpaceX_2026Q2季报__spcx-20260630.htm | C25: Q2、YTD、分部、债务、关联交易 | D25: 2026-10-22 | E25: p.4–5/p.9；Note 9/17/18；MD&A
A26: SX-Q3 | B26: 材料/SpaceX_2026Q3业绩公告__spaceexplorationtechnologi.htm | C26: Q3、9M、期末资产负债、分部、Cursor | D26: 2026-10-22 | E26: p.3–11；Consolidated Statements；Segment Operating and Financial Data
A27: T-10K | B27: 材料/Tesla_2025年报__tsla-20251231.htm | C27: FY2025、分部、债务、关联交易 | D27: 2026-10-22 | E27: Consolidated Statements；Note 8/15/16
A28: T-10Q | B28: 材料/Tesla_2026Q3季报__tsla-20260930.htm | C28: Q3、期末、SpaceX投资、内部交易、股数 | D28: 2026-10-22 | E28: Balance Sheets；Note 1/2/8/13/14；Part II Item 5；封面
A29: T-Q3 | B29: 材料/Tesla_2026Q3业绩公告__exhibit9914.htm | C29: 季度经营、现金流、非GAAP、FCF定义 | D29: 2026-10-22 | E29: slides 4/27–32
A30: T-Proxy | B30: 材料/Tesla_2026股东大会委托书__tm267596-1_def14a.htm | C30: Musk持股、投票安排、关联交易 | D30: 2026-10-22 | E30: Ownership of Securities；Related Person Transactions；Voting Agreement
A31: MKT | B31: Yahoo Finance Chart API（SPCX/TSLA） | C31: 收盘价、20日成交量、20日加权价格 | D31: 2026-10-22 | E31: 完整接口URL见市场数据页；定价日为2026-10-21
A34: 颜色、假设与未核实事项
A35: 黄底：披露原始输入；蓝底：公式；橙底：可编辑假设。修改“换股比例”B7:B10或“敏感性”溢价率，相关换股与持股结果会自动更新。
A36: 假设：SpaceX发行Class A；收入倍数6.0x/2.0x；共同EBITDA倍数20.0x；基准溢价0%；未扣交叉持股、协同、交易成本、税务和奖励股稀释。
A37: 未核实：正式合并协议与会计收购方；完整LTM内部交易及对应折旧；SpaceX Q3债务本金/租赁拆分；交割后Musk持股和投票权；实际公众流通股；购买价格分配。
A38: 关联交易提示：Valor为董事关联而非Musk旗下；Boring、Musk Industries、安保、航空等不会因本次合并自动成为集团内部主体。
A41: 模型勾稽检查（应为0或TRUE）
A42: SpaceX LTM营收−分部合计 | B42: =SpaceX!G5-SUM(合并备考!C29:C31) -> 0
A43: Tesla LTM营收−分部合计 | B43: =Tesla!G5-SUM(合并备考!C27:C28) -> 0
A44: 合并收入−两家合计 | B44: =合并备考!D6-合并备考!B6-合并备考!C6 -> 0
A45: 合并现金−两家合计 | B45: =合并备考!D18-合并备考!B18-合并备考!C18 -> 0

Sheet SpaceX
A1: SpaceX｜历史财务与分部
A2: 单位：US$ million；LTM=2025Q4–2026Q3。黄底=披露输入，蓝底=公式，橙底=假设。Q4经营数据=FY2025−9M2025；现金/债务/权益为期末余额。
A4: 指标 | B4: 2025Q4 | C4: 2026Q1 | D4: 2026Q2 | E4: 2026Q3 | F4: FY2025 | G4: LTM | H4: 9M2025 / 支持 | I4: 出处 | J4: 口径
A5: 营收 Revenue | B5: =F5-H5 -> 4960 | C5: 4694 | D5: 7814 | E5: 14575 | F5: 18674 | G5: =SUM(B5:E5) -> 32043 | H5: 13714 | I5: 招股书F-5；Q2季报p.5；Q3公告p.9 | J5: GAAP；Q4=FY−9M2025
A6: 营收成本 Cost of revenue | B6: =F6-H6 -> 2502 | C6: 2388 | D6: 3495 | E6: 5478 | F6: 9451 | G6: =SUM(B6:E6) -> 13863 | H6: 6949 | I6: 招股书F-5；Q2季报p.5；Q3公告p.9 | J6: GAAP；Q4=FY−9M2025
A7: 毛利 Gross profit | B7: =B5-B6 -> 2458 | C7: =C5-C6 -> 2306 | D7: =D5-D6 -> 4319 | E7: =E5-E6 -> 9097 | F7: =F5-F6 -> 9223 | G7: =SUM(B7:E7) -> 18180 | H7: =H5-H6 -> 6765 | I7: 计算：营收−营收成本；原始报表见上行 | J7: 分析计算，非SpaceX报表小计
A8: 经营利润/(亏损) | B8: =F8-H8 -> -1373 | C8: -1943 | D8: -143 | E8: 2791 | F8: -2589 | G8: =SUM(B8:E8) -> -668 | H8: -1216 | I8: 招股书F-5；Q2季报p.5；Q3公告p.9 | J8: GAAP；Q4=FY−9M2025
A9: 净利润/(亏损)（合并口径） | B9: =F9-H9 -> -2347 | C9: -4276 | D9: -541 | E9: 4404 | F9: -4937 | G9: =SUM(B9:E9) -> -2760 | H9: -2590 | I9: 招股书F-5/F-64；Q2季报p.5；Q3公告p.9 | J9: GAAP；不与普通股股东应占口径混用
A10: 普通股股东应占净利润/(亏损) | B10: =F10-H10 -> -2347 | C10: -4947 | D10: -541 | E10: 4404 | F10: -4937 | G10: =SUM(B10:E10) -> -3431 | H10: -2590 | I10: 招股书F-64/F-95；Q3公告p.9 | J10: Q1含671 deemed dividend；仅作补充
A11: 经营现金流 CFO | B11: =F11-H11 -> 2665 | C11: =B32 -> 1047 | D11: =C32-B32 -> 2419 | E11: =D32-C32 -> 9631 | F11: 6785 | G11: =SUM(B11:E11) -> 15762 | H11: 4120 | I11: 招股书F-8/F-67；Q2季报p.9；Q3公告p.11 | J11: 2026Q2/Q3=相应YTD差分；Q4=FY−9M2025
A12: 资本开支 Capex（正数） | B12: =F12-H12 -> 6891 | C12: =B33 -> 10107 | D12: =C33-B33 -> 18369 | E12: =D33-C33 -> 19593 | F12: 20737 | G12: =SUM(B12:E12) -> 54960 | H12: 13846 | I12: 招股书F-8/F-67及Note 19；Q2季报Note 18；Q3公告p.3/p.11 | J12: 购置PP&E；不含资本化利息、证券投资及收购付款
A13: 自由现金流 FCF | B13: =B11-B12 -> -4226 | C13: =C11-C12 -> -9060 | D13: =D11-D12 -> -15950 | E13: =E11-E12 -> -9962 | F13: =F11-F12 -> -13952 | G13: =SUM(B13:E13) -> -39198 | H13: =H11-H12 -> -9726 | I13: 计算：CFO−Capex；定义与Tesla Q3 Update slide 32一致 | J13: 分析计算；SpaceX未直接披露
A14: 调整后 EBITDA（非GAAP） | B14: =F14-H14 -> 1471 | C14: 1127 | D14: 3538 | E14: 8809 | F14: 6584 | G14: =SUM(B14:E14) -> 14945 | H14: 5113 | I14: 招股书MD&A reconciliation；Q2季报MD&A；Q3公告p.9 | J14: 非GAAP；Q4=FY−9M2025
A17: 期末资产负债表（账面净额；不含受限现金）
A18: 指标 | B18: 2025-12-31 | C18: 2026-03-31 | D18: 2026-06-30 | E18: 2026-09-30 | F18: 出处 | G18: 口径
A19: 现金及现金等价物 | B19: 24747 | C19: 15852 | D19: 93522 | E19: 51294 | F19: 招股书F-4/F-63；Q2季报p.4；Q3公告p.10 | G19: 资产负债表科目
A20: 流动短期投资 / Marketable securities | B20: 0 | C20: 7823 | D20: 6487 | E20: 38561 | F20: 招股书F-4/F-63；Q2季报p.4；Q3公告p.10 | G20: 不含受限现金
A21: 现金＋短期投资 | B21: =B19+B20 -> 24747 | C21: =C19+C20 -> 23675 | D21: =D19+D20 -> 100009 | E21: =E19+E20 -> 89855 | F21: 计算：现金及现金等价物＋流动短期投资 | G21: 分析计算
A22: 债务及融资租赁－流动 | B22: 928 | C22: 1538 | D22: 2525 | E22: 2698 | F22: 招股书F-4/F-63；Q2季报p.4；Q3公告p.10 | G22: 含租赁；账面净额
A23: 债务及融资租赁－非流动 | B23: 21968 | C23: 28727 | D23: 36839 | E23: 36146 | F23: 招股书F-4/F-63；Q2季报p.4；Q3公告p.10 | G23: 含租赁；账面净额
A24: 有息负债合计（含融资租赁） | B24: =B22+B23 -> 22896 | C24: =C22+C23 -> 30265 | D24: =D22+D23 -> 39364 | E24: =E22+E23 -> 38844 | F24: 计算：流动＋非流动；Q2 Note 9可核对本金与净额 | G24: 不含夹层优先股
A25: 股东权益 | B25: 2573 | C25: 34533 | D25: 127224 | E25: 176768 | F25: 招股书F-4/F-63；Q2季报p.4；Q3公告p.10 | G25: 不含夹层可赎回可转换优先股
A26: 夹层可赎回可转换优先股 | B26: 38752 | C26: 7049 | D26: 0 | E26: 0 | F26: 招股书F-4/F-63；Q2季报p.4；Q3公告p.10 | G26: 不计入股东权益或有息负债
A27: 其中：关联方债务 | B27: 4507 | C27: 9041 | D27: 13329 | E27: 12897 | F27: 招股书Note 9/18；Q2季报Note 9/17；Q3公告p.10 | G27: 不等于Tesla债务；含Valor等
A30: 2026年YTD现金流支持值（披露输入；用于差分单季）
A31: 项目 | B31: 2026Q1 | C31: 2026H1 | D31: 2026M9 | E31: 出处 | F31: 口径
A32: CFO YTD | B32: 1047 | C32: 3466 | D32: 13097 | E32: Q2季报p.9；Q3公告p.11 | F32: 现金流出按正数输入
A33: Capex YTD | B33: 10107 | C33: 28476 | D33: 48069 | E33: Q2季报p.9；Q3公告p.11 | F33: 现金流出按正数输入
A35: 报告分部：收入、成本、毛利（计算）、经营利润、调整后EBITDA与Capex
A36: 分部 / 指标 | B36: 2025Q4 | C36: 2026Q1 | D36: 2026Q2 | E36: 2026Q3 | F36: FY2025 | G36: LTM | H36: 9M2025 / 支持 | I36: 出处 | J36: 口径
A37: Space｜收入 | B37: =F37-H37 -> 809 | C37: 619 | D37: 962 | E37: 1767 | F37: 4086 | G37: =SUM(B37:E37) -> 4157 | H37: 3277 | I37: 招股书Note 19—Segments（FY2025/Q1）；Q2季报Note 18；Q3公告p.3–6 | J37: Q4=FY−9M2025；SI为原AI分部新名称
A38: Space｜营收成本 | B38: =F38-H38 -> 248 | C38: 281 | D38: 329 | E38: 435 | F38: 1352 | G38: =SUM(B38:E38) -> 1293 | H38: 1104 | I38: 招股书Note 19—Segments（FY2025/Q1）；Q2季报Note 18；Q3公告p.3–6 | J38: 按披露分部
A39: Space｜毛利（计算） | B39: =B37-B38 -> 561 | C39: =C37-C38 -> 338 | D39: =D37-D38 -> 633 | E39: =E37-E38 -> 1332 | F39: =F37-F38 -> 2734 | G39: =SUM(B39:E39) -> 2864 | H39: =H37-H38 -> 2173 | I39: 招股书Note 19—Segments（FY2025/Q1）；Q2季报Note 18；Q3公告p.3–6 | J39: 毛利=收入−成本；非SpaceX CODM主要利润指标
A40: Space｜经营利润/(亏损) | B40: =F40-H40 -> -476 | C40: -662 | D40: -542 | E40: -7 | F40: -657 | G40: =SUM(B40:E40) -> -1687 | H40: -181 | I40: 招股书Note 19—Segments（FY2025/Q1）；Q2季报Note 18；Q3公告p.3–6 | J40: 按披露分部
A41: Space｜Segment Adj. EBITDA | B41: =F41-H41 -> -150 | C41: -351 | D41: -205 | E41: 357 | F41: 653 | G41: =SUM(B41:E41) -> -349 | H41: 803 | I41: 招股书Note 19—Segments（FY2025/Q1）；Q2季报Note 18；Q3公告p.3–6 | J41: 非GAAP
A42: Space｜Capex | B42: =F42-H42 -> 1014 | C42: 1052 | D42: 1174 | E42: 1606 | F42: 3832 | G42: =SUM(B42:E42) -> 4846 | H42: 2818 | I42: 招股书Note 19—Segments（FY2025/Q1）；Q2季报Note 18；Q3公告p.3–6 | J42: 按披露分部
A43: Connectivity｜收入 | B43: =F43-H43 -> 3228 | C43: 3257 | D43: 4291 | E43: 5248 | F43: 11387 | G43: =SUM(B43:E43) -> 16024 | H43: 8159 | I43: 招股书Note 19—Segments（FY2025/Q1）；Q2季报Note 18；Q3公告p.3–6 | J43: Q4=FY−9M2025；SI为原AI分部新名称
A44: Connectivity｜营收成本 | B44: =F44-H44 -> 1650 | C44: 1651 | D44: 2060 | E44: 2368 | F44: 5921 | G44: =SUM(B44:E44) -> 7729 | H44: 4271 | I44: 招股书Note 19—Segments（FY2025/Q1）；Q2季报Note 18；Q3公告p.3–6 | J44: 按披露分部
A45: Connectivity｜毛利（计算） | B45: =B43-B44 -> 1578 | C45: =C43-C44 -> 1606 | D45: =D43-D44 -> 2231 | E45: =E43-E44 -> 2880 | F45: =F43-F44 -> 5466 | G45: =SUM(B45:E45) -> 8295 | H45: =H43-H44 -> 3888 | I45: 招股书Note 19—Segments（FY2025/Q1）；Q2季报Note 18；Q3公告p.3–6 | J45: 毛利=收入−成本；非SpaceX CODM主要利润指标
A46: Connectivity｜经营利润/(亏损) | B46: =F46-H46 -> 1276 | C46: 1188 | D46: 1656 | E46: 2367 | F46: 4423 | G46: =SUM(B46:E46) -> 6487 | H46: 3147 | I46: 招股书Note 19—Segments（FY2025/Q1）；Q2季报Note 18；Q3公告p.3–6 | J46: 按披露分部
...

Sheet Tesla
A1: Tesla｜历史财务与分部
A2: 单位：US$ million；LTM=2025Q4–2026Q3。季度经营数据主要来自Q3 Update；FY2025来自10-K。Tesla报告分部利润为毛利，不是经营利润。
A4: 指标 | B4: 2025Q4 | C4: 2026Q1 | D4: 2026Q2 | E4: 2026Q3 | F4: FY2025 | G4: LTM | H4: 出处 | I4: 口径
A5: 营收 Revenue | B5: 24901 | C5: 22387 | D5: 28236 | E5: 28046 | F5: 94827 | G5: =SUM(B5:E5) -> 103570 | H5: 10-K Consolidated Statements of Operations；Q3 Update slide 27 | I5: GAAP
A6: 营收成本 Cost of revenue | B6: 19892 | C6: 17667 | D6: 23485 | E6: 22552 | F6: 77733 | G6: =SUM(B6:E6) -> 83596 | H6: 10-K Consolidated Statements of Operations；Q3 Update slide 27 | I6: GAAP
A7: 毛利 Gross profit | B7: =B5-B6 -> 5009 | C7: =C5-C6 -> 4720 | D7: =D5-D6 -> 4751 | E7: =E5-E6 -> 5494 | F7: =F5-F6 -> 17094 | G7: =SUM(B7:E7) -> 19974 | H7: Q3 Update slide 27；本模型营收−成本复核 | I7: GAAP；公式计算
A8: 经营利润 | B8: 1409 | C8: 941 | D8: 398 | E8: 718 | F8: 4355 | G8: =SUM(B8:E8) -> 3466 | H8: 10-K Consolidated Statements of Operations；Q3 Update slide 27 | I8: GAAP
A9: 净利润（含少数股东） | B9: 856 | C9: 491 | D9: 1128 | E9: 804 | F9: 3855 | G9: =SUM(B9:E9) -> 3279 | H9: 10-K Consolidated Statements of Operations；Q3 Update slide 27 | I9: GAAP合并口径
A10: 归属普通股股东净利润 | B10: 840 | C10: 477 | D10: 1114 | E10: 787 | F10: 3794 | G10: =SUM(B10:E10) -> 3218 | H10: 10-K Note 3；Q3 Update slide 27 | I10: GAAP；用于EPS的口径可能另有调整
A11: 经营现金流 CFO | B11: 3813 | C11: 3937 | D11: 4697 | E11: 6263 | F11: 14747 | G11: =SUM(B11:E11) -> 18710 | H11: 10-K Consolidated Statements of Cash Flows；Q3 Update slide 29 | I11: GAAP
A12: 资本开支 Capex（正数） | B12: 2393 | C12: 2493 | D12: 5789 | E12: 4732 | F12: 8527 | G12: =SUM(B12:E12) -> 15407 | H12: 10-K Consolidated Statements of Cash Flows；Q3 Update slide 29/31 | I12: 含能源发电及储能系统购买；现金流出正数
A13: 自由现金流 FCF | B13: =B11-B12 -> 1420 | C13: =C11-C12 -> 1444 | D13: =D11-D12 -> -1092 | E13: =E11-E12 -> 1531 | F13: =F11-F12 -> 6220 | G13: =SUM(B13:E13) -> 3303 | H13: Q3 Update slide 29/31/32 | I13: CFO−Capex
A14: 调整后 EBITDA（非GAAP） | B14: 4154 | C14: 3668 | D14: 3273 | E14: 3900 | F14: 14596 | G14: =SUM(B14:E14) -> 14995 | H14: Q3 Update slide 30/31 | I14: 非GAAP；与SpaceX定义不完全可比
A17: 期末资产负债表（US$ million）
A18: 指标 | B18: 2025-12-31 | C18: 2026-03-31 | D18: 2026-06-30 | E18: 2026-09-30 | F18: 出处 | G18: 口径
A19: 现金、现金等价物及短期投资合计 | B19: 44059 | C19: 44743 | D19: 43524 | E19: 45447 | F19: Q3 Update slide 28；10-K Consolidated Balance Sheets | G19: 不含受限现金
A20: 其中：现金及现金等价物 | B20: 16513 | E20: 17853 | F20: 10-K Consolidated Balance Sheets；10-Q Balance Sheets | G20: Q1/Q2未在四份材料中拆分
A21: 其中：短期投资 | B21: 27546 | E21: 27594 | F21: 10-K Consolidated Balance Sheets；10-Q Balance Sheets | G21: Q1/Q2未在四份材料中拆分
A22: 债务及融资租赁－流动 | B22: 1640 | C22: 1447 | D22: 1418 | E22: 1387 | F22: Q3 Update slide 28；10-K/10-Q Balance Sheets | G22: 账面净额
A23: 债务及融资租赁－非流动 | B23: 6736 | C23: 7782 | D23: 7924 | E23: 8136 | F23: Q3 Update slide 28；10-K/10-Q Balance Sheets | G23: 账面净额
A24: 有息负债合计（含融资租赁） | B24: =B22+B23 -> 8376 | C24: =C22+C23 -> 9229 | D24: =D22+D23 -> 9342 | E24: =E22+E23 -> 9523 | F24: 计算：流动＋非流动；10-Q Note 8 | G24: 不含可赎回NCI
A25: Tesla股东权益（不含NCI） | B25: 82137 | C25: 84116 | D25: 86858 | E25: 89289 | F25: Q3 Update slide 28；10-K/10-Q Balance Sheets | G25: 母公司股东权益
A26: 非控股权益 NCI | B26: 670 | C26: 629 | D26: 607 | E26: 546 | F26: Q3 Update slide 28；10-K/10-Q Balance Sheets | G26: 计入含NCI总权益
A27: 含NCI总权益 | B27: =B25+B26 -> 82807 | C27: =C25+C26 -> 84745 | D27: =D25+D26 -> 87465 | E27: =E25+E26 -> 89835 | F27: 计算：Tesla股东权益＋NCI | G27: 不含夹层可赎回NCI
A28: 可赎回NCI（夹层） | B28: 58 | C28: 57 | D28: 54 | E28: 54 | F28: Q3 Update slide 28；10-K/10-Q Balance Sheets | G28: 不计入总权益
A31: 报告分部：收入、成本与毛利（Tesla CODM仅披露毛利口径）
A32: 分部 / 指标 | B32: 2025Q4 | C32: 2026Q1 | D32: 2026Q2 | E32: 2026Q3 | F32: FY2025 | G32: LTM | H32: 9M2025 / 支持 | I32: 出处 / 口径
A33: Automotive｜收入 | B33: =F33-H33 -> 21064 | C33: 19979 | D33: 25097 | E33: 25165 | F33: 82056 | G33: =SUM(B33:E33) -> 91305 | H33: 60992 | I33: 10-K Note 16；10-Q Note 14；Q3 Update slide 27；Q4=FY−9M2025；汽车报告分部含Services and other
A34: Automotive｜营收成本 | B34: =F34-H34 -> 17153 | C34: 16211 | D34: 20986 | E34: 20625 | F34: 68764 | G34: =SUM(B34:E34) -> 74975 | H34: 51611 | I34: 10-K Note 16；10-Q Note 14；Q3 Update slide 27；Q4=FY−9M2025；汽车报告分部含Services and other
A35: Automotive｜毛利 | B35: =B33-B34 -> 3911 | C35: =C33-C34 -> 3768 | D35: =D33-D34 -> 4111 | E35: =E33-E34 -> 4540 | F35: =F33-F34 -> 13292 | G35: =SUM(B35:E35) -> 16330 | H35: =H33-H34 -> 9381 | I35: 10-K Note 16；10-Q Note 14；Q3 Update slide 27；Q4=FY−9M2025；汽车报告分部含Services and other
A36: Energy｜收入 | B36: =F36-H36 -> 3837 | C36: 2408 | D36: 3139 | E36: 2881 | F36: 12771 | G36: =SUM(B36:E36) -> 12265 | H36: 8934 | I36: 10-K Note 16；10-Q Note 14；Q3 Update slide 27；Q4=FY−9M2025
A37: Energy｜营收成本 | B37: =F37-H37 -> 2739 | C37: 1456 | D37: 2499 | E37: 1927 | F37: 8969 | G37: =SUM(B37:E37) -> 8621 | H37: 6230 | I37: 10-K Note 16；10-Q Note 14；Q3 Update slide 27；Q4=FY−9M2025
A38: Energy｜毛利 | B38: =B36-B37 -> 1098 | C38: =C36-C37 -> 952 | D38: =D36-D37 -> 640 | E38: =E36-E37 -> 954 | F38: =F36-F37 -> 3802 | G38: =SUM(B38:E38) -> 3644 | H38: =H36-H37 -> 2704 | I38: 10-K Note 16；10-Q Note 14；Q3 Update slide 27；Q4=FY−9M2025
A40: 注：Tesla未披露分部经营利润、净利润、经营现金流或分部资产负债；不得将汽车收入类别直接当作汽车报告分部。

Sheet 合并备考
A1: 合并备考｜SpaceX + Tesla
A2: 单位：US$ million；LTM经营数据＋2026-09-30期末资产负债。Headline为未抵销汇总，不包含协同、购买法、融资、税务或交叉持股会计处理。
A4: LTM经营汇总（未抵销）
A5: 指标 | B5: SpaceX | C5: Tesla | D5: 合计 | E5: 合计利润率 / 占比 | F5: 出处 / 说明
A6: 营收 | B6: =SpaceX!G5 -> 32043 | C6: =Tesla!G5 -> 103570 | D6: =B6+C6 -> 135613 | F6: 两家各自财务页；合计为简单相加，未抵销内部交易
A7: 毛利 | B7: =SpaceX!G7 -> 18180 | C7: =Tesla!G7 -> 19974 | D7: =B7+C7 -> 38154 | E7: =D7/D6 -> 0.28134471 | F7: 两家各自财务页；合计为简单相加，未抵销内部交易
A8: 经营利润 | B8: =SpaceX!G8 -> -668 | C8: =Tesla!G8 -> 3466 | D8: =B8+C8 -> 2798 | E8: =D8/D6 -> 0.02063224 | F8: 两家各自财务页；合计为简单相加，未抵销内部交易
A9: 净利润（合并口径） | B9: =SpaceX!G9 -> -2760 | C9: =Tesla!G9 -> 3279 | D9: =B9+C9 -> 519 | E9: =D9/D6 -> 0.0038270667 | F9: 两家各自财务页；合计为简单相加，未抵销内部交易
A10: 经营现金流 | B10: =SpaceX!G11 -> 15762 | C10: =Tesla!G11 -> 18710 | D10: =B10+C10 -> 34472 | F10: 两家各自财务页；合计为简单相加，未抵销内部交易
A11: 资本开支 | B11: =SpaceX!G12 -> 54960 | C11: =Tesla!G12 -> 15407 | D11: =B11+C11 -> 70367 | F11: 两家各自财务页；合计为简单相加，未抵销内部交易
A12: 自由现金流 | B12: =SpaceX!G13 -> -39198 | C12: =Tesla!G13 -> 3303 | D12: =B12+C12 -> -35895 | E12: =D12/D6 -> -0.26468701 | F12: 两家各自财务页；合计为简单相加，未抵销内部交易
A13: 调整后EBITDA（非GAAP） | B13: =SpaceX!G14 -> 14945 | C13: =Tesla!G14 -> 14995 | D13: =B13+C13 -> 29940 | E13: =D13/D6 -> 0.22077529 | F13: 两家各自财务页；合计为简单相加，未抵销内部交易
A16: 2026-09-30期末资产负债汇总（未抵销）
A17: 指标 | B17: SpaceX | C17: Tesla | D17: 合计 | E17: 占合计/补充 | F17: 出处 / 说明
A18: 现金＋短期投资 | B18: =SpaceX!E21 -> 89855 | C18: =Tesla!E19 -> 45447 | D18: =B18+C18 -> 135302 | F18: 两家期末资产负债表；未抵销
A19: 有息负债（含融资租赁） | B19: =SpaceX!E24 -> 38844 | C19: =Tesla!E24 -> 9523 | D19: =B19+C19 -> 48367 | F19: 两家期末资产负债表；未抵销
A20: 净现金（现金−债务） | B20: =B18-B19 -> 51011 | C20: =C18-C19 -> 35924 | D20: =B20+C20 -> 86935 | F20: 分析计算；不含受限现金
A21: 含NCI股东权益 | B21: =SpaceX!E25 -> 176768 | C21: =Tesla!E27 -> 89835 | D21: =B21+C21 -> 266603 | F21: 两家期末资产负债表；未抵销
A22: Tesla持有SpaceX股权投资（不重复相加） | B22: 0 | C22: 2865 | D22: =C22 -> 2865 | F22: Tesla 10-Q Note 1/2；列入其他非流动资产，不在现金及短期投资中；合并层面需消除交叉投资
A25: LTM收入与毛利结构（五个披露报告分部；毛利为可比分析计算）
A26: 业务分部 | B26: 所属公司 | C26: LTM收入 | D26: 收入占比 | E26: LTM毛利 | F26: 毛利占比 | G26: SpaceX分部经营利润 | H26: 出处 / 说明
A27: Automotive | B27: Tesla | C27: =Tesla!G33 -> 91305 | D27: =C27/$C$32 -> 0.67327616 | E27: =Tesla!G35 -> 16330 | F27: =E27/$E$32 -> 0.42800231 | G27: 未披露 | H27: Tesla 10-K Note 16；10-Q Note 14；分部利润为毛利
A28: Energy | B28: Tesla | C28: =Tesla!G36 -> 12265 | D28: =C28/$C$32 -> 0.090441182 | E28: =Tesla!G38 -> 3644 | F28: =E28/$E$32 -> 0.095507679 | G28: 未披露 | H28: Tesla 10-K Note 16；10-Q Note 14；分部利润为毛利
A29: Connectivity | B29: SpaceX | C29: =SpaceX!G43 -> 16024 | D29: =C29/$C$32 -> 0.11815976 | E29: =SpaceX!G45 -> 8295 | F29: =E29/$E$32 -> 0.2174084 | G29: =SpaceX!G46 -> 6487 | H29: SpaceX招股书Note 19；Q2 Note 18；Q3公告p.3–6；毛利=收入−成本
A30: SI | B30: SpaceX | C30: =SpaceX!G49 -> 11862 | D30: =C30/$C$32 -> 0.08746949 | E30: =SpaceX!G51 -> 7021 | F30: =E30/$E$32 -> 0.1840174 | G30: =SpaceX!G52 -> -5468 | H30: SpaceX招股书Note 19；Q2 Note 18；Q3公告p.3–6；毛利=收入−成本
A31: Space | B31: SpaceX | C31: =SpaceX!G37 -> 4157 | D31: =C31/$C$32 -> 0.030653403 | E31: =SpaceX!G39 -> 2864 | F31: =E31/$E$32 -> 0.075064213 | G31: =SpaceX!G40 -> -1687 | H31: SpaceX招股书Note 19；Q2 Note 18；Q3公告p.3–6；毛利=收入−成本
A32: 合计 | C32: =SUM(C27:C31) -> 135613 | D32: =SUM(D27:D31) -> 1 | E32: =SUM(E27:E31) -> 38154 | F32: =SUM(F27:F31) -> 1 | G32: =SUM(G27:G31) -> -668 | H32: SpaceX经营利润合计可与合并经营利润勾稽；Tesla分部经营利润未披露，因此G列不是合并经营利润。
A35: 已知内部交易抵销示例：仅2026Q3，非完整会计分录（假设）
A36: 项目 | B36: 未抵销合计 | C36: 抵销调整 | D36: 示例后数值 | E36: 依据 / 限制
A37: 2026Q3营收 | B37: =SpaceX!E5+Tesla!E5 -> 42621 | C37: =关联交易!D7 -> 221 | D37: =B37-C37 -> 42400 | E37: Tesla 10-Q Note 13：SpaceX Megapack收入221；假设仅移除该内部销售，不调整其他交易。
A38: 2026Q3毛利 | B38: =SpaceX!E7+Tesla!E7 -> 14591 | C38: =关联交易!F9 -> 50 | D38: =B38-C38 -> 14541 | E38: Tesla披露成本171，示例毛利影响=50；未调整SpaceX PP&E未实现利润及后续折旧，不能当作正式合并毛利。
A39: 2026Q3经营利润 | B39: =SpaceX!E8+Tesla!E8 -> 3509 | C39: 未估算 | D39: 未估算 | E39: 内部资产销售、折旧和费用对应关系未披露，避免以毛利影响替代经营利润影响。
A41: 合并解读：收入/毛利结构可用于业务讨论；正式会计合并仍需确定会计收购方、交易结构、内部交易全量清单、交叉投资和购买价格分配。

Sheet 换股比例
A1: 换股比例｜四种相对定价情景
A2: 结构假设：SpaceX发行Class A给Tesla股东；每1股Tesla换取X股SpaceX。溢价应用于Tesla每股对价；结果为目标交换比例与静态经济权益，不是目标价或投资建议。
A4: 输入与参考数据
A5: SpaceX现有股数（百万股） | B5: =持股!B11 -> 13579 | D5: Q3公告p.10；四舍五入
A6: Tesla现有股数（百万股） | B6: =持股!B22 -> 3952.7579 | D6: 10-Q封面；2026-10-15
A7: 基准溢价率（假设） | B7: 0 | D7: 应用于Tesla对价；基准为0%
A8: SpaceX EV / LTM Revenue（假设） | B8: 6 | D8: 仅用于收入倍数情景
A9: Tesla EV / LTM Revenue（假设） | B9: 2 | D9: 仅用于收入倍数情景
A10: 共同EV / LTM Adj. EBITDA（假设） | B10: 20 | D10: 仅用于EBITDA情景；非GAAP可比性有限
A14: 参考指标 | B14: SpaceX | C14: Tesla | D14: 出处 / 说明
A15: LTM营收 | B15: =SpaceX!G5 -> 32043 | C15: =Tesla!G5 -> 103570 | D15: 来自各自财务页
A16: 现金＋短期投资（2026-09-30） | B16: =SpaceX!E21 -> 89855 | C16: =Tesla!E19 -> 45447 | D16: 期末余额
A17: 有息负债（含融资租赁） | B17: =SpaceX!E24 -> 38844 | C17: =Tesla!E24 -> 9523 | D17: 账面净额
A18: LTM调整后EBITDA | B18: =SpaceX!G14 -> 14945 | C18: =Tesla!G14 -> 14995 | D18: 非GAAP
A19: 2026-10-21收盘价 | B19: =市场数据!B30 -> 159.31 | C19: =市场数据!B31 -> 386.47 | D19: Yahoo Finance；2026-10-22访问
A20: 20日成交量加权收盘价* | B20: =市场数据!B34 -> 156.21811 | C20: =市场数据!B35 -> 369.38878 | D20: 分析计算，不是官方VWAP
A21: Musk实际/受益持股（百万股） | B21: =持股!B8 -> 6068.5475 | C21: =持股!B19 -> 699.58088 | D21: 招股书 / Proxy
A23: 方法结果（基准溢价率链接至B7；股权价值单位：US$ million）
A27: 定价方法 | B27: SpaceX股权价值 | C27: Tesla股权价值 | D27: SpaceX每股价值 | E27: Tesla每股价值 | F27: 换股比例X | G27: 新发行SpaceX股数(m) | H27: 合并后总股数(m) | I27: SpaceX原股东 | J27: Tesla原股东 | K27: Musk合并后经济持股 | L27: 说明
A28: 收盘市值法 | B28: =B19*$B$5 -> 2163270.5 | C28: =C19*$B$6 -> 1527622.4 | D28: =B19 -> 159.31 | E28: =C19 -> 386.47 | F28: =E28*(1+$B$7)/D28 -> 2.4258992 | G28: =$B$6*F28 -> 9588.9923 | H28: =$B$5+G28 -> 23167.992 | I28: =$B$5/H28 -> 0.58611035 | J28: =G28/H28 -> 0.41388965 | K28: =($B$21+$C$21*F28)/H28 -> 0.33518917 | L28: 2026-10-21已完成交易日收盘价；股数见持股页
A29: 20日成交量加权收盘价法 | B29: =B20*$B$5 -> 2121285.8 | C29: =C20*$B$6 -> 1460104.4 | D29: =B20 -> 156.21811 | E29: =C20 -> 369.38878 | F29: =E29*(1+$B$7)/D29 -> 2.3645707 | G29: =$B$6*F29 -> 9346.5758 | H29: =$B$5+G29 -> 22925.576 | I29: =$B$5/H29 -> 0.59230792 | J29: =G29/H29 -> 0.40769208 | K29: =($B$21+$C$21*F29)/H29 -> 0.33686203 | L29: 截至2026-10-21的20个交易日；收盘价×成交量/成交量，分析计算，非官方VWAP
A30: LTM收入倍数法（假设） | B30: =B15*$B$8+B16-B17 -> 243269 | C30: =C15*$B$9+C16-C17 -> 243064 | D30: =B30/$B$5 -> 17.915089 | E30: =C30/$B$6 -> 61.492255 | F30: =E30*(1+$B$7)/D30 -> 3.432428 | G30: =$B$6*F30 -> 13567.557 | H30: =$B$5+G30 -> 27146.557 | I30: =$B$5/H30 -> 0.50021076 | J30: =G30/H30 -> 0.49978924 | K30: =($B$21+$C$21*F30)/H30 -> 0.31200305 | L30: EV/LTM Revenue：SpaceX 6.0x、Tesla 2.0x；假设，非市场一致预期
A31: LTM调整后EBITDA倍数法（假设） | B31: =B18*$B$10+B16-B17 -> 349911 | C31: =C18*$B$10+C16-C17 -> 335824 | D31: =B31/$B$5 -> 25.76854 | E31: =C31/$B$6 -> 84.959414 | F31: =E31*(1+$B$7)/D31 -> 3.2970209 | G31: =$B$6*F31 -> 13032.326 | H31: =$B$5+G31 -> 26611.326 | I31: =$B$5/H31 -> 0.51027146 | J31: =G31/H31 -> 0.48972854 | K31: =($B$21+$C$21*F31)/H31 -> 0.31471864 | L31: 共同EV/LTM Adj. EBITDA 20.0x；假设；两家公司非GAAP定义不完全可比
A33: 股权价值桥：市场法=每股价格×已发行股数；倍数法=EV×假设倍数＋现金及短期投资−有息负债。未扣交叉持股、协同、交易成本、税务、购买价格分配或奖励股稀释；收入/EBITDA倍数为可编辑假设。

Sheet 敏感性
A1: 敏感性｜溢价率 × 定价方法
A2: 行=Tesla对价溢价率（假设）；列=定价方法。每格为每1股Tesla换取的SpaceX股数；下表进一步给出Tesla原股东和Musk静态经济持股。
A4: 换股比例（SpaceX股 / Tesla股）
A5: Tesla对价溢价率 | B5: 收盘市值 | C5: 20日VWAP* | D5: 收入倍数 | E5: EBITDA倍数
A6: -0.2 | B6: =换股比例!$E$28*(1+$A6)/换股比例!$D$28 -> 1.9407194 | C6: =换股比例!$E$29*(1+$A6)/换股比例!$D$29 -> 1.8916566 | D6: =换股比例!$E$30*(1+$A6)/换股比例!$D$30 -> 2.7459424 | E6: =换股比例!$E$31*(1+$A6)/换股比例!$D$31 -> 2.6376167
A7: -0.1 | B7: =换股比例!$E$28*(1+$A7)/换股比例!$D$28 -> 2.1833093 | C7: =换股比例!$E$29*(1+$A7)/换股比例!$D$29 -> 2.1281137 | D7: =换股比例!$E$30*(1+$A7)/换股比例!$D$30 -> 3.0891852 | E7: =换股比例!$E$31*(1+$A7)/换股比例!$D$31 -> 2.9673188
A8: 0 | B8: =换股比例!$E$28*(1+$A8)/换股比例!$D$28 -> 2.4258992 | C8: =换股比例!$E$29*(1+$A8)/换股比例!$D$29 -> 2.3645707 | D8: =换股比例!$E$30*(1+$A8)/换股比例!$D$30 -> 3.432428 | E8: =换股比例!$E$31*(1+$A8)/换股比例!$D$31 -> 3.2970209
A9: 0.1 | B9: =换股比例!$E$28*(1+$A9)/换股比例!$D$28 -> 2.6684891 | C9: =换股比例!$E$29*(1+$A9)/换股比例!$D$29 -> 2.6010278 | D9: =换股比例!$E$30*(1+$A9)/换股比例!$D$30 -> 3.7756708 | E9: =换股比例!$E$31*(1+$A9)/换股比例!$D$31 -> 3.626723
A10: 0.2 | B10: =换股比例!$E$28*(1+$A10)/换股比例!$D$28 -> 2.911079 | C10: =换股比例!$E$29*(1+$A10)/换股比例!$D$29 -> 2.8374849 | D10: =换股比例!$E$30*(1+$A10)/换股比例!$D$30 -> 4.1189136 | E10: =换股比例!$E$31*(1+$A10)/换股比例!$D$31 -> 3.9564251
A11: 0.3 | B11: =换股比例!$E$28*(1+$A11)/换股比例!$D$28 -> 3.1536689 | C11: =换股比例!$E$29*(1+$A11)/换股比例!$D$29 -> 3.073942 | D11: =换股比例!$E$30*(1+$A11)/换股比例!$D$30 -> 4.4621564 | E11: =换股比例!$E$31*(1+$A11)/换股比例!$D$31 -> 4.2861272
A14: Tesla原股东合并后经济持股
A15: Tesla对价溢价率 | B15: 收盘市值 | C15: 20日VWAP* | D15: 收入倍数 | E15: EBITDA倍数
A16: -0.2 | B16: =(换股比例!$B$6*B6)/(换股比例!$B$5+换股比例!$B$6*B6) -> 0.36099406 | C16: =(换股比例!$B$6*C6)/(换股比例!$B$5+换股比例!$B$6*C6) -> 0.35510867 | D16: =(换股比例!$B$6*D6)/(换股比例!$B$5+换股比例!$B$6*D6) -> 0.4442363 | E16: =(换股比例!$B$6*E6)/(换股比例!$B$5+换股比例!$B$6*E6) -> 0.43432289
A17: -0.1 | B17: =(换股比例!$B$6*B7)/(换股比例!$B$5+换股比例!$B$6*B7) -> 0.38858377 | C17: =(换股比例!$B$6*C7)/(换股比例!$B$5+换股比例!$B$6*C7) -> 0.38251782 | D17: =(换股比例!$B$6*D7)/(换股比例!$B$5+换股比例!$B$6*D7) -> 0.47347404 | E17: =(换股比例!$B$6*E7)/(换股比例!$B$5+换股比例!$B$6*E7) -> 0.46345227
A18: 0 | B18: =(换股比例!$B$6*B8)/(换股比例!$B$5+换股比例!$B$6*B8) -> 0.41388965 | C18: =(换股比例!$B$6*C8)/(换股比例!$B$5+换股比例!$B$6*C8) -> 0.40769208 | D18: =(换股比例!$B$6*D8)/(换股比例!$B$5+换股比例!$B$6*D8) -> 0.49978924 | E18: =(换股比例!$B$6*E8)/(换股比例!$B$5+换股比例!$B$6*E8) -> 0.48972854
A19: 0.1 | B19: =(换股比例!$B$6*B9)/(换股比例!$B$5+换股比例!$B$6*B9) -> 0.43718402 | C19: =(换股比例!$B$6*C9)/(换股比例!$B$5+换股比例!$B$6*C9) -> 0.43089408 | D19: =(换股比例!$B$6*D9)/(换股比例!$B$5+换股比例!$B$6*D9) -> 0.52359924 | E19: =(换股比例!$B$6*E9)/(换股比例!$B$5+换股比例!$B$6*E9) -> 0.51355132
A20: 0.2 | B20: =(换股比例!$B$6*B10)/(换股比例!$B$5+换股比例!$B$6*B10) -> 0.45869755 | C20: =(换股比例!$B$6*C10)/(换股比例!$B$5+换股比例!$B$6*C10) -> 0.45234685 | D20: =(换股比例!$B$6*D10)/(换股比例!$B$5+换股比例!$B$6*D10) -> 0.54524552 | E20: =(换股比例!$B$6*E10)/(换股比例!$B$5+换股比例!$B$6*E10) -> 0.53524891
A21: 0.3 | B21: =(换股比例!$B$6*B11)/(换股比例!$B$5+换股比例!$B$6*B11) -> 0.47862693 | C21: =(换股比例!$B$6*C11)/(换股比例!$B$5+换股比例!$B$6*C11) -> 0.47224103 | D21: =(换股比例!$B$6*D11)/(换股比例!$B$5+换股比例!$B$6*D11) -> 0.5650102 | E21: =(换股比例!$B$6*E11)/(换股比例!$B$5+换股比例!$B$6*E11) -> 0.55509355
A24: Musk合并后静态经济持股
A25: Tesla对价溢价率 | B25: 收盘市值 | C25: 20日VWAP* | D25: 收入倍数 | E25: EBITDA倍数
A26: -0.2 | B26: =(持股!$B$8+持股!$B$19*B6)/(换股比例!$B$5+换股比例!$B$6*B6) -> 0.34946682 | C26: =(持股!$B$8+持股!$B$19*C6)/(换股比例!$B$5+换股比例!$B$6*C6) -> 0.35105541 | D26: =(持股!$B$8+持股!$B$19*D6)/(换股比例!$B$5+换股比例!$B$6*D6) -> 0.32699797 | E26: =(持股!$B$8+持股!$B$19*E6)/(换股比例!$B$5+换股比例!$B$6*E6) -> 0.32967381
A27: -0.1 | B27: =(持股!$B$8+持股!$B$19*B7)/(换股比例!$B$5+换股比例!$B$6*B7) -> 0.34201977 | C27: =(持股!$B$8+持股!$B$19*C7)/(换股比例!$B$5+换股比例!$B$6*C7) -> 0.3436571 | D27: =(持股!$B$8+持股!$B$19*D7)/(换股比例!$B$5+换股比例!$B$6*D7) -> 0.31910608 | E27: =(持股!$B$8+持股!$B$19*E7)/(换股比例!$B$5+换股比例!$B$6*E7) -> 0.32181117
A28: 0 | B28: =(持股!$B$8+持股!$B$19*B8)/(换股比例!$B$5+换股比例!$B$6*B8) -> 0.33518917 | C28: =(持股!$B$8+持股!$B$19*C8)/(换股比例!$B$5+换股比例!$B$6*C8) -> 0.33686203 | D28: =(持股!$B$8+持股!$B$19*D8)/(换股比例!$B$5+换股比例!$B$6*D8) -> 0.31200305 | E28: =(持股!$B$8+持股!$B$19*E8)/(换股比例!$B$5+换股比例!$B$6*E8) -> 0.31471864
A29: 0.1 | B29: =(持股!$B$8+持股!$B$19*B9)/(换股比例!$B$5+换股比例!$B$6*B9) -> 0.32890153 | C29: =(持股!$B$8+持股!$B$19*C9)/(换股比例!$B$5+换股比例!$B$6*C9) -> 0.33059932 | D29: =(持股!$B$8+持股!$B$19*D9)/(换股比例!$B$5+换股比例!$B$6*D9) -> 0.30557622 | E29: =(持股!$B$8+持股!$B$19*E9)/(换股比例!$B$5+换股比例!$B$6*E9) -> 0.30828837
A30: 0.2 | B30: =(持股!$B$8+持股!$B$19*B10)/(换股比例!$B$5+换股比例!$B$6*B10) -> 0.32309457 | C30: =(持股!$B$8+持股!$B$19*C10)/(换股比例!$B$5+换股比例!$B$6*C10) -> 0.32480876 | D30: =(持股!$B$8+持股!$B$19*D10)/(换股比例!$B$5+换股比例!$B$6*D10) -> 0.29973343 | E30: =(持股!$B$8+持股!$B$19*E10)/(换股比例!$B$5+换股比例!$B$6*E10) -> 0.30243173
A31: 0.3 | B31: =(持股!$B$8+持股!$B$19*B11)/(换股比例!$B$5+换股比例!$B$6*B11) -> 0.3177152 | C31: =(持股!$B$8+持股!$B$19*C11)/(换股比例!$B$5+换股比例!$B$6*C11) -> 0.31943889 | D31: =(持股!$B$8+持股!$B$19*D11)/(换股比例!$B$5+换股比例!$B$6*D11) -> 0.29439852 | E31: =(持股!$B$8+持股!$B$19*E11)/(换股比例!$B$5+换股比例!$B$6*E11) -> 0.29707523
A33: 说明：溢价率只改变Tesla新发行对价，不改变两家经营数据；持股比例未处理交叉持股、投票权、奖励股和购买法。

Sheet 市场数据
A1: 市场数据｜SPCX 与 TSLA
A2: 来源：Yahoo Finance Chart API（公开行情接口），访问日期：2026-10-22；仅使用截至2026-10-21已完成交易日，排除10月22日盘中数据。价格为USD/股，成交量为股。
A4: SPCX接口：https://query1.finance.yahoo.com/v8/finance/chart/SPCX?period1=1789000000&period2=1792800000&interval=1d&events=div%2Csplits
A5: TSLA接口：https://query1.finance.yahoo.com/v8/finance/chart/TSLA?period1=1789000000&period2=1792800000&interval=1d&events=div%2Csplits
A6: 日期 | B6: SPCX收盘 | C6: SPCX成交量 | D6: TSLA收盘 | E6: TSLA成交量 | F6: 出处
A7: 2026-09-24 | B7: 148.03 | C7: 72721400 | D7: 377.94 | E7: 26165700 | F7: Yahoo Finance Chart API；2026-10-22访问
A8: 2026-09-25 | B8: 148.68 | C8: 54595200 | D8: 372.11 | E8: 45999500 | F8: Yahoo Finance Chart API；2026-10-22访问
A9: 2026-09-28 | B9: 145.47 | C9: 83516700 | D9: 357.45 | E9: 39452900 | F9: Yahoo Finance Chart API；2026-10-22访问
A10: 2026-09-29 | B10: 149.24 | C10: 80056700 | D10: 352.84 | E10: 32492400 | F10: Yahoo Finance Chart API；2026-10-22访问
A11: 2026-09-30 | B11: 150.86 | C11: 79614200 | D11: 354.81 | E11: 39235800 | F11: Yahoo Finance Chart API；2026-10-22访问
A12: 2026-10-01 | B12: 148.07 | C12: 69092500 | D12: 354.11 | E12: 31080800 | F12: Yahoo Finance Chart API；2026-10-22访问
A13: 2026-10-02 | B13: 158.96 | C13: 119859100 | D13: 370.59 | E13: 55330100 | F13: Yahoo Finance Chart API；2026-10-22访问
A14: 2026-10-05 | B14: 171.09 | C14: 135688900 | D14: 378.73 | E14: 42232700 | F14: Yahoo Finance Chart API；2026-10-22访问
A15: 2026-10-06 | B15: 171.92 | C15: 106952400 | D15: 380.68 | E15: 27735400 | F15: Yahoo Finance Chart API；2026-10-22访问
A16: 2026-10-07 | B16: 167.6 | C16: 77473000 | D16: 377.81 | E16: 25594600 | F16: Yahoo Finance Chart API；2026-10-22访问
A17: 2026-10-08 | B17: 160.57 | C17: 71897800 | D17: 375 | E17: 28394900 | F17: Yahoo Finance Chart API；2026-10-22访问
A18: 2026-10-09 | B18: 162.57 | C18: 93042600 | D18: 382.7 | E18: 38952400 | F18: Yahoo Finance Chart API；2026-10-22访问
... A26: 2026-10-21 | B26: 159.31 | C26: 220785200 | D26: 386.47 | E26: 48875800 | F26: Yahoo Finance Chart API；2026-10-22访问
A28: 定价参考（公式）
A29: 最近完成交易日 | B29: =A26 -> 2026-10-21 | C29: 收盘价为接口原始值；VWAP*为分析计算，不是交易所官方VWAP
A30: SPCX收盘价 | B30: =B26 -> 159.31 | C30: 收盘价为接口原始值；VWAP*为分析计算，不是交易所官方VWAP
A31: TSLA收盘价 | B31: =D26 -> 386.47 | C31: 收盘价为接口原始值；VWAP*为分析计算，不是交易所官方VWAP
A32: SPCX 20日算术平均收盘价 | B32: =AVERAGE(B7:B26) -> 155.2445 | C32: 收盘价为接口原始值；VWAP*为分析计算，不是交易所官方VWAP
A33: TSLA 20日算术平均收盘价 | B33: =AVERAGE(D7:D26) -> 370.0295 | C33: 收盘价为接口原始值；VWAP*为分析计算，不是交易所官方VWAP
A34: SPCX 20日成交量加权收盘价 | B34: =SUMPRODUCT(B7:B26,C7:C26)/SUM(C7:C26) -> 156.21811 | C34: 收盘价为接口原始值；VWAP*为分析计算，不是交易所官方VWAP
A35: TSLA 20日成交量加权收盘价 | B35: =SUMPRODUCT(D7:D26,E7:E26)/SUM(E7:E26) -> 369.38878 | C35: 收盘价为接口原始值；VWAP*为分析计算，不是交易所官方VWAP
A37: * 20日窗口：2026-09-24至2026-10-21，共20个交易日。行情仅用于相对换股，不评价股价贵不贵。

Sheet 关联交易
A1: 关联交易与合并抵销检查表
A2: 单位：US$ million，除非另有说明。法律交易对手、会计主体和期间可能不同；不得将不同披露视角简单相加。
A4: 类别 | B4: 交易对手 / 方向 | C4: 期间 | D4: 收入 / 交易额 | E4: 成本 / 费用 | F4: 期末余额 / 其他 | G4: 出处 | H4: 合并时处理与限制
A5: Megapack | B5: Tesla → SpaceX；SpaceX PP&E采购 | C5: FY2025 | F5: 506 | G5: SpaceX招股书Note 18；Tesla 10-K Note 15 | H5: SpaceX一侧计入PP&E的采购；与Tesla收入披露存在视角差异，不能相加。
A6: Megapack | B6: Tesla → SpaceX；SpaceX PP&E采购 | C6: 2026Q1 / Q2 | F6: 329 | G6: SpaceX招股书Q1 Note 17；Q2季报Note 17 | H6: Q1=34、Q2=295；Q3 Tesla专属采购未单独披露。
A7: Megapack | B7: Tesla确认对SpaceX销售 | C7: 2026Q3 | D7: 221 | E7: 171 | G7: Tesla 10-Q Note 13 | H7: 合并时应抵销内部收入与对应成本，并核对SpaceX资产/折旧；本模型仅做Q3示例。
A8: Megapack | B8: Tesla确认对SpaceX销售 | C8: 2026M9 | D8: 626 | E8: 478 | G8: Tesla 10-Q Note 13 | H8: H1=405/307为9M−Q3；Q1/Q2各自金额未披露，不能构造完整LTM抵销。
A9: 内部销售毛利 | B9: Tesla对SpaceX Megapack | C9: 2026Q3 | D9: =D7 -> 221 | E9: =E7 -> 171 | F9: =D7-E7 -> 50 | G9: 计算：221−171=50 | H9: 见合并备考Q3示例；不是完整购买法分录。
A10: 应收/递延 | B10: SpaceX相关应收与递延收入 | C10: 2026-09-30 | F10: 729 | G10: Tesla 10-Q Note 13 | H10: 应收729、递延收入648（流动516、长期132）；需与SpaceX对应科目核对后抵销。
A11: 商业/许可/支持 | B11: SpaceX ↔ Tesla | C11: FY2025 / 截至2026年2月 | D11: 143.3 | E11: 11.4 | G11: Tesla 2026 Proxy Related Person Transactions | H11: Tesla收入143.3、费用11.4；2026年2月分别0.1/1.5；合并后内部抵销。
A12: 飞机使用 | B12: SpaceX ↔ Tesla | C12: FY2025 / 截至2026年2月 | E12: 0.4 | G12: Tesla 2026 Proxy；SpaceX招股书Transactions with Tesla | H12: 2026年2月0.02；合并后内部费用/收入抵销。
A13: X广告 | B13: Tesla → X（现属SpaceX） | C13: FY2025 | E13: 3.3 | G13: Tesla 2026 Proxy Related Person Transactions | H13: X已纳入SpaceX历史报表；合并后属于内部广告，抵销收入与费用。
A14: xAI商业/咨询 | B14: Tesla ↔ xAI（2026-02-02后属SpaceX） | C14: FY2025 / 截至2026年2月 | D14: 430.1 | E14: 4 | F14: 285 | G14: Tesla 2026 Proxy；10-K Note 15 | H14: 2025收入成本对应毛利145；与SpaceX采购披露口径不同，不能与上行简单相加。
A15: 股权投资 | B15: Tesla持有SpaceX Class A | C15: 2026Q1 / 2026-09-30 | F15: 2865 | G15: Tesla 10-Q Note 1/2；Q3 Update slide 29 | H15: 成本2,002；9M公允价值净收益863；合并层面消除交叉投资，具体处理取决于收购方与购买法。
A16: Valor融资 | B16: Valor（董事关联，非Musk旗下） | C16: 2026Q2 / Q3 | E16: 513 | F16: 12897 | G16: SpaceX Q2季报Note 9/17；Q3公告p.10 | H16: failed sale-leaseback；Q2利息327、H1利息513；不会因本次合并自动抵销。
A17: 其他Musk实体 | B17: The Boring Company：X办公室租金 / SpaceX隧道 | C17: 2025 | E17: 1 | G17: SpaceX招股书pp.244–246；Tesla Proxy | H17: 2024租金0.1、2026年1–4月0.3；SpaceX 2025隧道费用1。除非该实体纳入合并集团，否则不自动抵销。
A18: 其他Musk实体 | B18: Musk Industries：xAI物业租赁 | C18: 2025 | E18: 2 | G18: SpaceX招股书pp.244–246 | H18: 2024为0.5、2026年1–4月为1；属于关联方租赁，不随Tesla合并自动抵销。
A19: 其他Musk实体 | B19: Musk所有安保公司：SpaceX安保 | C19: 2025 | E19: 4 | G19: SpaceX招股书pp.244–246；Tesla Proxy | H19: 2023/2024为2/3，2026年1–4月为2；Tesla 2025承担4.8、截至2026年2月1.3；仍属外部或关联方费用。
A20: 其他Musk实体 | B20: Craft Aviation：飞机维护 | C20: 2025 | E20: 3 | G20: SpaceX招股书pp.244–246 | H20: 2023/2024为1/1，2026年1–4月为3；不随本次合并自动抵销。
A21: 其他Musk实体 | B21: Musk私人飞机公务报销 | C21: 2025 | E21: 2 | G21: SpaceX招股书pp.244–246 | H21: 2023/2024为0.1/3，2026年1–4月为0.2；不随本次合并自动抵销。
A22: 其他Musk实体 | B22: Musk信托从员工购买SpaceX二级股份 | C22: 2025 | D22: 1421 | G22: SpaceX招股书pp.244–246 | H22: 股东间二级交易，不是SpaceX融资收入；合并估值不得把它当作经营现金流。
A23: 其他Musk实体 | B23: Neuralink | C23: 披露期 | G23: SpaceX招股书及Tesla Proxy Related Person Transactions | H23: 文件提及但未披露具体交易金额；不能据此断言不存在交易，也不作估算。
A24: 合作框架 | B24: Tesla ↔ SpaceX：Terafab / Macrohard | C24: 截至2026Q3 | G24: SpaceX招股书Business—Collaboration with Tesla | H24: 仅一般框架，时间表、里程碑和Capex未确定；不纳入承诺资本开支或协同收益。
A27: 重要：合并备考 headline 采用未抵销汇总；由于完整LTM内部交易、对应资产与折旧、交叉持股购买法均未明确，本页只提供可核对的抵销起点，不构造完整会计合并报表。

Sheet 持股
A1: 马斯克持股与换股后的静态经济权益
A2: 股数单位：百万股；比例均为经济持股，除非特别注明。SpaceX招股书持股截至2026-05-01/IPO口径，Tesla Proxy截至2026-09-30；并非同一日期的更新持股。
A4: SpaceX：招股书披露与模型静态口径
A5: 项目 | B5: 数值 | C5: 单位 | D5: 出处 / 说明
A6: Musk Class A实际持股 | B6: 849.49444 | C6: 百万股 | D6: SpaceX招股书Security Ownership / IPO后实际持股；不含期权
A7: Musk Class B实际持股（不含350m期权） | B7: 5219.0531 | C7: 百万股 | D7: SpaceX招股书封面/Prospectus Summary；含受限Class B
A8: Musk合计实际持股 | B8: =B6+B7 -> 6068.5475 | C8: 百万股 | D8: 计算：Class A＋Class B
A9: IPO后总股数（全额超额配售） | B9: 13159.199 | C9: 百万股 | D9: SpaceX招股书IPO后股数；用于复核IPO经济比例
A10: IPO后经济持股（不含期权） | B10: =B8/B9 -> 0.46116392 | C10: % | D10: 分析计算：合计实际持股/IPO后总股数；约46.1%
A11: 最新模型股数（2026-09-30） | B11: 13579 | C11: 百万股 | D11: SpaceX Q3公告p.10；按百万股四舍五入
A12: 按最新股数的静态经济持股 | B12: =B8/B11 -> 0.44690681 | C12: % | D12: 分析计算：合计实际持股/最新模型股数；与IPO口径不同
A13: IPO后综合投票权（不行使超额配售） | B13: 0.824 | C13: % | D13: SpaceX招股书Prospectus Summary；Class B每股10票
A14: IPO后综合投票权（全额超额配售） | B14: 0.823 | C14: % | D14: SpaceX招股书Prospectus Summary；不是经济持股比例
A17: Tesla：Proxy披露与模型静态口径
A18: 项目 | B18: 数值 | C18: 单位 | D18: 出处 / 说明
A19: Musk受益拥有股数 | B19: 699.58088 | C19: 百万股 | D19: Tesla 2026 Proxy Ownership of Securities；截至2026-09-30
A20: Proxy调整后分母 | B20: 3528.9047 | C20: 百万股 | D20: 实际已发行股数剔除2025 CEO Performance Award 423.743904m
A21: Proxy披露比例（公式复核） | B21: =B19/B20 -> 0.19824307 | C21: % | D21: 计算：受益拥有股数/调整后分母；约19.8%
A22: 最新模型股数（2026-10-15） | B22: 3952.7579 | C22: 百万股 | D22: Tesla 10-Q封面；用于换股桥
A23: 按全部已发行股数的简单经济持股 | B23: =B19/B22 -> 0.17698551 | C23: % | D23: 分析计算：受益拥有股数/全部已发行股数；约17.7%
A24: 其中已质押股数 | B24: 207.49872 | C24: 百万股 | D24: Tesla 2026 Proxy Ownership of Securities
A25: 2025 CEO Performance Award已发行未Earned股 | B25: 423.7439 | C25: 百万股 | D25: Tesla Proxy Voting Agreement；截至2026-10-19仍未Earned
A28: 收盘市值法、0%溢价下的静态换股桥（公式）
A29: 选定情景 | B29: 收盘市值法；Tesla股东获得SpaceX Class A | D29: 仅为结构假设，未披露正式合并协议
A30: 每1股Tesla换取SpaceX股数 | B30: =换股比例!F28 -> 2.4258992 | D30: 换股比例页；溢价应用于Tesla对价
A31: Musk合并后股数 | B31: =B8+B19*B30 -> 7765.6602 | D31: 实际SpaceX股数＋Tesla受益股数×换股比例
A32: 合并后总股数 | B32: =换股比例!H28 -> 23167.992 | D32: SpaceX现有股数＋新发行股数
A33: Musk合并后经济持股 | B33: =B31/B32 -> 0.33518917 | D33: 静态经济权益桥，不是交割后受益权或投票权
A34: 较SpaceX最新股数口径变化 | B34: =B33-B12 -> -0.11171763 | D34: 百分点变化；不同日期/分母仅供参考
A35: 较SpaceX IPO经济持股口径变化 | B35: =B33-B10 -> -0.12597474 | D35: 百分点变化；IPO口径不含350m期权
A37: 控制权提示：SpaceX Class B每股10票且Class B单独选举51%董事；Tesla 2025 CEO奖励股存在特殊投票代理。合并后投票权、稀释、奖励股归属和交叉持股须由法律文件确认，不能用上述经济比例替代。
