Workbook

Sheet 说明
A1: 内存芯片公司 16 季经营：三张表与分析
A2: 游戏编号 memfab-opus · 数据导出日期 2026-10-22 · 金额单位：十亿美元 · 片数单位：千片/季
A4: 这本工作簿里有什么
A5: 原始数据 | B5: 引擎导出的逐季数字，原样录入（输入格）。来源：交付/data/raw/export_final.json 的 history[i] 各字段；期初数来自 state_before_Q01.json。
A6: 假设 | B6: 规则给定的参数（如税率15%、借款季利率1.5%）和我从报表反推的参数（如每千片变动成本0.005），每项注明性质和出处。
A7: 利润表 / 资产负债表 / 现金流量表 | B7: 逐季三张表。小计、合计、期末余额全部用公式从原始数据算出，三张表相互勾稽；底部绿色核对行显示与引擎数字的差额（应为0）。
A8: 分析 | B8: 毛利率、存货周转天数、经营现金流、自由现金流、净负债、ROE等指标，全部是公式；下方配图表。改「假设」页的每季天数、年化倍数等，结果自动变。
A9: 模型复现与情景 | B9: 用「假设」页的参数和每季决策，从头重算产量、成本、存货、收入、利润、现金和权益。默认复现实际结果（核对行≈0）；在黄色情景格里改决策或价格系数，期末权益等结果自动重算。
A10: 决策备注 | B10: 每季提交给引擎的决策备注原文。
A12: 颜色约定
A13: 浅黄底、蓝字 | B13: 输入格：引擎导出的原始数字、规则参数、推断参数、情景输入。可以改。
A14: 白底、黑字 | B14: 公式格：由输入格计算而来，不要手改。
A15: 浅绿底、绿字 | B15: 核对格：公式结果与引擎数字的差额，正常应为0（四舍五入误差在±0.01以内）。
A16: 浅紫底 | B16: 关键结果（公式）。
A18: 口径说明
A19: 营业成本 | B19: 引擎的营业成本含存货跌价损失（期末按可变现净值=0.95×市价减记，不转回），表中单列「其中：存货跌价」。HBM 片按订单生产，多产作废，其成本计入当季营业成本。
A20: 存货周转天数 | B20: 公式：（期初存货+期末存货）/2 ÷ 当季营业成本 × 每季天数（默认91.25天，假设）。另给片数口径：期末库存千片 ÷ 当季普通内存销量 × 每季天数。
A21: 净负债 | B21: 公式：借款+紧急授信−现金；负数表示净现金。
A22: ROE | B22: 公式：季度ROE=净利润÷（期初权益+期末权益）/2；年化=季度×4（年化倍数是假设，可改）。
A23: 推断参数 | B23: 「假设」页里标为「推断」的数字不是规则原文，是我用前两季报表反推、再用16季数据逐季核对得到的（模型复现核对行≈0）。它们是假设，不是引擎公开的事实。
A24: 免责声明 | B24: 这是经营模拟的研究和展示材料，市场、公司和数字都是虚构的，不构成任何投资建议。

Sheet 假设
A1: 假设与参数
A2: 黄色为输入格。性质：规则=规则原文给定；推断=从报表反推并用16季数据核对；假设=分析口径。
A4: 参数 | B4: 数值 | C4: 单位 | D4: 性质 | E4: 出处/说明
A5: 价格指数1.00对应的普通内存售价 | B5: 0.024 | C5: 十亿美元/千片 | D5: 推断 | E5: Q1 收入4.608÷销量240÷指数0.80；16季逐季核对
A6: 每千片变动成本 | B6: 0.005 | C6: 十亿美元/千片 | D6: 推断 | E6: Q1（产255）与Q2（产300）单位成本对比反推
A7: 工厂固定费用（不含折旧） | B7: 1 | C7: 十亿美元/季 | D7: 推断 | E7: 同上；扩产后不变（Q9起验证）
A8: 期初固定资产每季折旧 | B8: 2 | C8: 十亿美元/季 | D8: 推断 | E8: Q1-Q4 折旧均为2.0
A9: 资本开支折旧期 | B9: 20 | C9: 季 | D9: 规则 | E9: 规则：资本开支按20个季度直线折旧
A10: 资本开支投产（并开始折旧）滞后 | B10: 4 | C10: 季 | D10: 规则/推断 | E10: 规则：超出维持部分4个季度后形成新产能；折旧也从投产季开始（推断）
A11: 每千片/季新增产能投资 | B11: 0.12 | C11: 十亿美元 | D11: 规则 | E11: 规则：每1.2亿美元增加1千片/季
A12: 每季维持性资本开支 | B12: 1.5 | C12: 十亿美元/季 | D12: 规则 | E12: 规则：每季先要15亿美元维持现有产能
A13: 每季固定研发费用 | B13: 0.8 | C13: 十亿美元/季 | D13: 推断 | E13: Q1 研发3.8=固定0.8+HBM研发3.0；其余各季0.8
A14: 每季销售及管理费用 | B14: 0.25 | C14: 十亿美元/季 | D14: 推断 | E14: 16季均为0.25
A15: 存货减记测试中的销售费用率 | B15: 0.05 | C15: 比例 | D15: 规则 | E15: 规则：市价扣5%销售费用后低于成本则减记
A16: 所得税率（只对盈利征） | B16: 0.15 | C16: 比例 | D16: 规则 | E16: 规则
... A27: 情景：HBM价格系数 | B27: 1 | C27: 倍 | D27: 情景输入 | E27: 只影响「模型复现与情景」页；1.0=实际价格

Sheet 原始数据
A1: 引擎导出数据（原样录入，输入格）
A2: 来源：交付/data/raw/export_final.json → history[第i季]；B列为字段路径。金额：十亿美元；片数：千片/季。
A4: 项目 | B4: 来源字段 | C4: Q1 | D4: Q2 | E4: Q3 | F4: Q4 | G4: Q5 | H4: Q6 | I4: Q7 | J4: Q8 | K4: Q9 | L4: Q10 | M4: Q11 | N4: Q12 | O4: Q13 | P4: Q14 | Q4: Q15 | R4: Q16
A5: 决策
A6: 开工率 | B6: decision.utilization | C6: 0.85 | D6: 1 | E6: 1 | F6: 1 | G6: 1 | H6: 1 | I6: 1 | J6: 1 | K6: 1 | L6: 1 | M6: 1 | N6: 1 | O6: 1 | P6: 1 | Q6: 1 | R6: 1
A7: 出货比例 | B7: decision.sell_fraction | C7: 1 | D7: 1 | E7: 1 | F7: 1 | G7: 1 | H7: 1 | I7: 1 | J7: 1 | K7: 1 | L7: 1 | M7: 1 | N7: 1 | O7: 1 | P7: 1 | Q7: 1 | R7: 1
A8: 资本开支 | B8: decision.capex | C8: 1.5 | D8: 1.5 | E8: 1.5 | F8: 1.5 | G8: 4.5 | H8: 3.9 | I8: 3.3 | J8: 5.7 | K8: 6.3 | L8: 5.1 | M8: 1.5 | N8: 1.5 | O8: 1.5 | P8: 1.5 | Q8: 1.5 | R8: 1.5
A9: HBM 研发投入 | B9: decision.hbm_rnd | C9: 3 | D9: 0 | E9: 0 | F9: 0 | G9: 0 | H9: 0 | I9: 0 | J9: 0 | K9: 0 | L9: 0 | M9: 0 | N9: 0 | O9: 0 | P9: 0 | Q9: 0 | R9: 0
A10: HBM 产能占比 | B10: decision.hbm_share | C10: 0 | D10: 0 | E10: 0 | F10: 0.04 | G10: 0.05 | H10: 0.07 | I10: 0.11 | J10: 0.14 | K10: 0.17 | L10: 0.2 | M10: 0.235 | N10: 0.245 | O10: 0.26 | P10: 0.295 | Q10: 0.36 | R10: 0.405
A11: 新增借款（还款为负） | B11: decision.borrow | C11: 0 | D11: 0 | E11: 2 | F11: 2 | G11: 3.5 | H11: 1.5 | I11: 0 | J11: 0.5 | K11: 1.3 | L11: -2 | M11: -10 | N11: -4.8 | O11: 0 | P11: 0 | Q11: 0 | R11: 0
A12: 市场
A13: 普通内存价格指数 | B13: market.price_index | C13: 0.8 | D13: 0.56 | E13: 0.5 | F13: 0.53 | G13: 0.6 | H13: 0.72 | I13: 0.83 | J13: 0.92 | K13: 1 | L13: 0.97 | M13: 1.06 | N13: 1.28 | O13: 1.7 | P13: 2.65 | Q13: 3.9 | R13: 4.55
A14: HBM 价格指数 | B14: market.hbm_price_index | C14: 1.6 | D14: 1.4 | E14: 1.3 | F14: 1.4 | G14: 1.6 | H14: 1.9 | I14: 2.3 | J14: 2.8 | K14: 3.4 | L14: 4 | M14: 4.6 | N14: 5.4 | O14: 6.4 | P14: 7.6 | Q14: 8.8 | R14: 9.6
A15: 普通内存需求（千片） | B15: market.demand_kwafers | C15: 240 | D15: 210 | E15: 205 | F15: 215 | G15: 235 | H15: 260 | I15: 285 | J15: 305 | K15: 320 | L15: 320 | M15: 340 | N15: 365 | O15: 400 | P15: 440 | Q15: 480 | R15: 510
A16: HBM 需求（千片） | B16: market.hbm_demand_kwafers | C16: 5 | D16: 5 | E16: 6 | F16: 8 | G16: 12 | H16: 18 | I16: 26 | J16: 36 | K16: 48 | L16: 60 | M16: 74 | N16: 90 | O16: 110 | P16: 135 | Q16: 160 | R16: 185
A17: 运营
A18: 产能（千片/季） | B18: operations.capacity_kwafers | C18: 300 | D18: 300 | E18: 300 | F18: 300 | G18: 300 | H18: 300 | I18: 300 | J18: 300 | K18: 325 | L18: 345 | M18: 360 | N18: 395 | O18: 435 | P18: 465 | Q18: 465 | R18: 465
A19: 产量（千片） | B19: operations.produced_kwafers | C19: 255 | D19: 300 | E19: 300 | F19: 300 | G19: 300 | H19: 300 | I19: 300 | J19: 300 | K19: 325 | L19: 345 | M19: 360 | N19: 395 | O19: 435 | P19: 465 | Q19: 465 | R19: 465
A20: 其中 HBM 产量（千片） | B20: operations.hbm_kwafers | C20: 0 | D20: 0 | E20: 0 | F20: 12 | G20: 15 | H20: 21 | I20: 33 | J20: 42 | K20: 55.25 | L20: 69 | M20: 84.6 | N20: 96.77 | O20: 113.1 | P20: 137.17 | Q20: 167.4 | R20: 188.33
A21: 普通内存销量（千片） | B21: operations.std_sold_kwafers | C21: 240 | D21: 210 | E21: 205 | F21: 215 | G21: 235 | H21: 260 | I21: 285 | J21: 305 | K21: 320 | L21: 320 | M21: 340 | N21: 365 | O21: 400 | P21: 361.1 | Q21: 297.6 | R21: 276.67
A22: HBM 销量（千片） | B22: operations.hbm_sold_kwafers | C22: 0 | D22: 0 | E22: 0 | F22: 8 | G22: 12 | H22: 18 | I22: 26 | J22: 36 | K22: 48 | L22: 60 | M22: 74 | N22: 90 | O22: 110 | P22: 135 | Q22: 160 | R22: 185
A23: 单位生产成本（百万美元/千片） | B23: operations.unit_cost_musd | C23: 16.765 | D23: 15 | E23: 15 | F23: 15 | G23: 15.25 | H23: 15.5 | I23: 15.75 | J23: 16 | K23: 15.846 | L23: 15.783 | M23: 15.792 | N23: 15.557 | O23: 15.31 | P23: 15.194 | Q23: 15.355 | R23: 15.516
A24: HBM 量产资格（1=有） | B24: operations.hbm_qualified | C24: 0 | D24: 0 | E24: 0 | F24: 1 | G24: 1 | H24: 1 | I24: 1 | J24: 1 | K24: 1 | L24: 1 | M24: 1 | N24: 1 | O24: 1 | P24: 1 | Q24: 1 | R24: 1
A25: 利润表（引擎）
A26: 营业收入 | B26: income_statement.revenue | C26: 4.608 | D26: 2.8224 | E26: 2.46 | F26: 3.0036 | G26: 3.8448 | H26: 5.3136 | I26: 7.1124 | J26: 9.1536 | K26: 11.5968 | L26: 13.2096 | M26: 16.8192 | N26: 22.8768 | O26: 33.216 | P26: 47.59 | Q26: 61.6474 | R26: 72.8369
A27: 普通内存收入 | B27: income_statement.revenue_std | C27: 4.608 | D27: 2.8224 | E27: 2.46 | F27: 2.7348 | G27: 3.384 | H27: 4.4928 | I27: 5.6772 | J27: 6.7344 | K27: 7.68 | L27: 7.4496 | M27: 8.6496 | N27: 11.2128 | O27: 16.32 | P27: 22.966 | Q27: 27.8554 | R27: 30.2129
A28: HBM 收入 | B28: income_statement.revenue_hbm | C28: 0 | D28: 0 | E28: 0 | F28: 0.2688 | G28: 0.4608 | H28: 0.8208 | I28: 1.4352 | J28: 2.4192 | K28: 3.9168 | L28: 5.76 | M28: 8.1696 | N28: 11.664 | O28: 16.896 | P28: 24.624 | Q28: 33.792 | R28: 42.624
A29: 营业成本（含存货跌价） | B29: income_statement.cogs | C29: 3.9886 | D29: 3.6397 | E29: 3.6427 | F29: 3.44 | G29: 3.4116 | H29: 4.0613 | I29: 4.7719 | J29: 5.3549 | K29: 5.8588 | L29: 6.1052 | M29: 6.6867 | N29: 7.2084 | O29: 7.888 | P29: 7.5771 | Q29: 7.14 | R29: 7.215
A30: 存货跌价损失 | B30: income_statement.inventory_writedown | C30: 0 | D30: 0.4217 | E30: 0.7301 | F30: 0.4023 | G30: 0 | H30: 0 | I30: 0 | J30: 0 | K30: 0 | L30: 0 | M30: 0 | N30: 0 | O30: 0 | P30: 0 | Q30: 0 | R30: 0
A31: 毛利 | B31: income_statement.gross_profit | C31: 0.6194 | D31: -0.8173 | E31: -1.1827 | F31: -0.4364 | G31: 0.4332 | H31: 1.2523 | I31: 2.3405 | J31: 3.7987 | K31: 5.738 | L31: 7.1044 | M31: 10.1325 | N31: 15.6684 | O31: 25.328 | P31: 40.0128 | Q31: 54.5074 | R31: 65.6219
A32: 研发费用 | B32: income_statement.rnd | C32: 3.8 | D32: 0.8 | E32: 0.8 | F32: 0.8 | G32: 0.8 | H32: 0.8 | I32: 0.8 | J32: 0.8 | K32: 0.8 | L32: 0.8 | M32: 0.8 | N32: 0.8 | O32: 0.8 | P32: 0.8 | Q32: 0.8 | R32: 0.8
A33: 销售及管理费用 | B33: income_statement.sga | C33: 0.25 | D33: 0.25 | E33: 0.25 | F33: 0.25 | G33: 0.25 | H33: 0.25 | I33: 0.25 | J33: 0.25 | K33: 0.25 | L33: 0.25 | M33: 0.25 | N33: 0.25 | O33: 0.25 | P33: 0.25 | Q33: 0.25 | R33: 0.25
A34: 营业利润 | B34: income_statement.operating_income | C34: -3.4306 | D34: -1.8673 | E34: -2.2327 | F34: -1.4864 | G34: -0.6168 | H34: 0.2023 | I34: 1.2905 | J34: 2.7487 | K34: 4.688 | L34: 6.0544 | M34: 9.0825 | N34: 14.6184 | O34: 24.278 | P34: 38.9628 | Q34: 53.4574 | R34: 64.5719
A35: 净利息支出 | B35: income_statement.net_interest | C35: 0.01 | D35: 0.0358 | E35: 0.0539 | F35: 0.0891 | G35: 0.1202 | H35: 0.1793 | I35: 0.2083 | J35: 0.2092 | K35: 0.2182 | L35: 0.2214 | M35: 0.1815 | N35: 0.0319 | O35: -0.1228 | P35: -0.3144 | Q35: -0.6035 | R35: -0.9896
A36: 所得税 | B36: income_statement.tax | C36: 0 | D36: 0 | E36: 0 | F36: 0 | G36: 0 | H36: 0.0035 | I36: 0.1623 | J36: 0.3809 | K36: 0.6705 | L36: 0.8749 | M36: 1.3352 | N36: 2.188 | O36: 3.6601 | P36: 5.8916 | Q36: 8.1091 | R36: 9.8342
A37: 净利润 | B37: income_statement.net_income | C37: -3.4406 | D37: -1.9031 | E37: -2.2866 | F37: -1.5755 | G37: -0.737 | H37: 0.0196 | I37: 0.9199 | J37: 2.1586 | K37: 3.7994 | L37: 4.958 | M37: 7.5659 | N37: 12.3985 | O37: 20.7406 | P37: 33.3856 | Q37: 45.9517 | R37: 55.7273
A38: 现金流量（引擎）
A39: 经营活动现金流 | B39: cash_flow.operating | C39: -1.727 | D39: -0.7634 | E39: -1.1439 | F39: -0.6355 | G39: 0.1746 | H39: 1.5809 | I39: 3.1918 | J39: 5.0135 | K39: 7.0332 | L39: 8.3382 | M39: 11.4525 | N39: 16.6319 | O39: 25.4537 | P39: 37.6378 | Q39: 49.7667 | R39: 59.6173
A40: 投资活动现金流 | B40: cash_flow.investing | C40: -1.5 | D40: -1.5 | E40: -1.5 | F40: -1.5 | G40: -4.5 | H40: -3.9 | I40: -3.3 | J40: -5.7 | K40: -6.3 | L40: -5.1 | M40: -1.5 | N40: -1.5 | O40: -1.5 | P40: -1.5 | Q40: -1.5 | R40: -1.5
A41: 筹资活动现金流（不含紧急授信） | B41: cash_flow.financing | C41: 0 | D41: 0 | E41: 2 | F41: 2 | G41: 3.5 | H41: 1.5 | I41: 0 | J41: 0.5 | K41: 1.3 | L41: -2 | M41: -10 | N41: -4.8 | O41: 0 | P41: 0 | Q41: 0 | R41: 0
...

Sheet 利润表
A1: 利润表（逐季）
A2: 单位：十亿美元。所有数字为公式：引用「原始数据」页，小计由公式计算；底部为与引擎数字的核对。
A4: 项目 | B4: 单位/口径 | C4: Q1 | D4: Q2 | E4: Q3 | F4: Q4 | G4: Q5 | H4: Q6 | I4: Q7 | J4: Q8 | K4: Q9 | L4: Q10 | M4: Q11 | N4: Q12 | O4: Q13 | P4: Q14 | Q4: Q15 | R4: Q16 | S4: 16季合计
A5: 普通内存收入 | C5: =原始数据!C27 -> 4.608 | D5: =原始数据!D27 -> 2.8224 | E5: =原始数据!E27 -> 2.46 | F5: =原始数据!F27 -> 2.7348 | G5: =原始数据!G27 -> 3.384 | H5: =原始数据!H27 -> 4.4928 | I5: =原始数据!I27 -> 5.6772 | J5: =原始数据!J27 -> 6.7344 | ... R5: =原始数据!R27 -> 30.2129 | S5: =SUM(C5:R5) -> 165.2599
A6: HBM 收入 | C6: =原始数据!C28 -> 0 | D6: =原始数据!D28 -> 0 | E6: =原始数据!E28 -> 0 | F6: =原始数据!F28 -> 0.2688 | G6: =原始数据!G28 -> 0.4608 | H6: =原始数据!H28 -> 0.8208 | I6: =原始数据!I28 -> 1.4352 | J6: =原始数据!J28 -> 2.4192 | ... R6: =原始数据!R28 -> 42.624 | S6: =SUM(C6:R6) -> 152.8512
A7: 营业收入 | C7: =C5+C6 -> 4.608 | D7: =D5+D6 -> 2.8224 | E7: =E5+E6 -> 2.46 | F7: =F5+F6 -> 3.0036 | G7: =G5+G6 -> 3.8448 | H7: =H5+H6 -> 5.3136 | I7: =I5+I6 -> 7.1124 | J7: =J5+J6 -> 9.1536 | ... R7: =R5+R6 -> 72.8369 | S7: =SUM(C7:R7) -> 318.1111
A8: 营业成本（含存货跌价） | C8: =原始数据!C29 -> 3.9886 | D8: =原始数据!D29 -> 3.6397 | E8: =原始数据!E29 -> 3.6427 | F8: =原始数据!F29 -> 3.44 | G8: =原始数据!G29 -> 3.4116 | H8: =原始数据!H29 -> 4.0613 | I8: =原始数据!I29 -> 4.7719 | J8: =原始数据!J29 -> 5.3549 | ... R8: =原始数据!R29 -> 7.215 | S8: =SUM(C8:R8) -> 87.9899
A9: 其中：存货跌价损失 | C9: =原始数据!C30 -> 0 | D9: =原始数据!D30 -> 0.4217 | E9: =原始数据!E30 -> 0.7301 | F9: =原始数据!F30 -> 0.4023 | G9: =原始数据!G30 -> 0 | H9: =原始数据!H30 -> 0 | I9: =原始数据!I30 -> 0 | J9: =原始数据!J30 -> 0 | ... R9: =原始数据!R30 -> 0 | S9: =SUM(C9:R9) -> 1.5541
A10: 毛利 | C10: =C7-C8 -> 0.6194 | D10: =D7-D8 -> -0.8173 | E10: =E7-E8 -> -1.1827 | F10: =F7-F8 -> -0.4364 | G10: =G7-G8 -> 0.4332 | H10: =H7-H8 -> 1.2523 | I10: =I7-I8 -> 2.3405 | J10: =J7-J8 -> 3.7987 | ... R10: =R7-R8 -> 65.6219 | S10: =SUM(C10:R10) -> 230.1212
A11: 毛利率 | B11: % | C11: =IF(C7=0,0,C10/C7) -> 0.1344184 | D11: =IF(D7=0,0,D10/D7) -> -0.28957625 | E11: =IF(E7=0,0,E10/E7) -> -0.48077236 | F11: =IF(F7=0,0,F10/F7) -> -0.14529232 | G11: =IF(G7=0,0,G10/G7) -> 0.11267166 | H11: =IF(H7=0,0,H10/H7) -> 0.23567826 | I11: =IF(I7=0,0,I10/I7) -> 0.32907317 | J11: =IF(J7=0,0,J10/J7) -> 0.41499519 | ... R11: =IF(R7=0,0,R10/R7) -> 0.90094307 | S11: =S10/S7 -> 0.72339884
A12: 研发费用 | C12: =原始数据!C32 -> 3.8 | D12: =原始数据!D32 -> 0.8 | E12: =原始数据!E32 -> 0.8 | F12: =原始数据!F32 -> 0.8 | G12: =原始数据!G32 -> 0.8 | H12: =原始数据!H32 -> 0.8 | I12: =原始数据!I32 -> 0.8 | J12: =原始数据!J32 -> 0.8 | ... R12: =原始数据!R32 -> 0.8 | S12: =SUM(C12:R12) -> 15.8
A13: 其中：HBM 专项研发 | C13: =原始数据!C9 -> 3 | D13: =原始数据!D9 -> 0 | E13: =原始数据!E9 -> 0 | F13: =原始数据!F9 -> 0 | G13: =原始数据!G9 -> 0 | H13: =原始数据!H9 -> 0 | I13: =原始数据!I9 -> 0 | J13: =原始数据!J9 -> 0 | ... R13: =原始数据!R9 -> 0 | S13: =SUM(C13:R13) -> 3
A14: 销售及管理费用 | C14: =原始数据!C33 -> 0.25 | D14: =原始数据!D33 -> 0.25 | E14: =原始数据!E33 -> 0.25 | F14: =原始数据!F33 -> 0.25 | G14: =原始数据!G33 -> 0.25 | H14: =原始数据!H33 -> 0.25 | I14: =原始数据!I33 -> 0.25 | J14: =原始数据!J33 -> 0.25 | ... R14: =原始数据!R33 -> 0.25 | S14: =SUM(C14:R14) -> 4
A15: 营业利润 | C15: =C10-C12-C14 -> -3.4306 | D15: =D10-D12-D14 -> -1.8673 | E15: =E10-E12-E14 -> -2.2327 | F15: =F10-F12-F14 -> -1.4864 | G15: =G10-G12-G14 -> -0.6168 | H15: =H10-H12-H14 -> 0.2023 | I15: =I10-I12-I14 -> 1.2905 | J15: =J10-J12-J14 -> 2.7487 | ... R15: =R10-R12-R14 -> 64.5719 | S15: =SUM(C15:R15) -> 210.3212
A16: 净利息支出（收入为负） | C16: =原始数据!C35 -> 0.01 | D16: =原始数据!D35 -> 0.0358 | E16: =原始数据!E35 -> 0.0539 | F16: =原始数据!F35 -> 0.0891 | G16: =原始数据!G35 -> 0.1202 | H16: =原始数据!H35 -> 0.1793 | I16: =原始数据!I35 -> 0.2083 | J16: =原始数据!J35 -> 0.2092 | ... R16: =原始数据!R35 -> -0.9896 | S16: =SUM(C16:R16) -> -0.4715
A17: 税前利润 | C17: =C15-C16 -> -3.4406 | D17: =D15-D16 -> -1.9031 | E17: =E15-E16 -> -2.2866 | F17: =F15-F16 -> -1.5755 | G17: =G15-G16 -> -0.737 | H17: =H15-H16 -> 0.023 | I17: =I15-I16 -> 1.0822 | J17: =J15-J16 -> 2.5395 | ... R17: =R15-R16 -> 65.5615 | S17: =SUM(C17:R17) -> 210.7927
A18: 所得税 | C18: =原始数据!C36 -> 0 | D18: =原始数据!D36 -> 0 | E18: =原始数据!E36 -> 0 | F18: =原始数据!F36 -> 0 | G18: =原始数据!G36 -> 0 | H18: =原始数据!H36 -> 0.0035 | I18: =原始数据!I36 -> 0.1623 | J18: =原始数据!J36 -> 0.3809 | ... R18: =原始数据!R36 -> 9.8342 | S18: =SUM(C18:R18) -> 33.1103
A19: 净利润 | C19: =C17-C18 -> -3.4406 | D19: =D17-D18 -> -1.9031 | E19: =E17-E18 -> -2.2866 | F19: =F17-F18 -> -1.5755 | G19: =G17-G18 -> -0.737 | H19: =H17-H18 -> 0.0195 | I19: =I17-I18 -> 0.9199 | J19: =J17-J18 -> 2.1586 | ... R19: =R17-R18 -> 55.7273 | S19: =SUM(C19:R19) -> 177.6824
A20: 累计净利润 | C20: =C19 -> -3.4406 | D20: =C20+D19 -> -5.3437 | E20: =D20+E19 -> -7.6303 | F20: =E20+F19 -> -9.2058 | G20: =F20+G19 -> -9.9428 | H20: =G20+H19 -> -9.9233 | I20: =H20+I19 -> -9.0034 | J20: =I20+J19 -> -6.8448 | K20: =J20+K19 -> -3.0455 | ... R20: =Q20+R19 -> 177.6824 | S20: =R20 -> 177.6824
A22: 核对（公式结果 − 引擎数字，应为 0）
A23: 营业收入差额 | B23: 应为0 | C23: =C7-原始数据!C26 -> 0 | D23: =D7-原始数据!D26 -> 0 | E23: =E7-原始数据!E26 -> 0 | F23: =F7-原始数据!F26 -> 0 | G23: =G7-原始数据!G26 -> 0 | H23: =H7-原始数据!H26 -> 0 | I23: =I7-原始数据!I26 -> 0 | J23: =J7-原始数据!J26 -> 0 | ... R23: =R7-原始数据!R26 -> 0
A24: 毛利差额 | B24: 应为0 | C24: =C10-原始数据!C31 -> 0 | D24: =D10-原始数据!D31 -> 0 | E24: =E10-原始数据!E31 -> 0 | F24: =F10-原始数据!F31 -> 0 | G24: =G10-原始数据!G31 -> 0 | H24: =H10-原始数据!H31 -> 0 | I24: =I10-原始数据!I31 -> 0 | J24: =J10-原始数据!J31 -> 0 | ... R24: =R10-原始数据!R31 -> 0
A25: 营业利润差额 | B25: 应为0 | C25: =C15-原始数据!C34 -> 0 | D25: =D15-原始数据!D34 -> 0 | E25: =E15-原始数据!E34 -> 0 | F25: =F15-原始数据!F34 -> 0 | G25: =G15-原始数据!G34 -> 0 | H25: =H15-原始数据!H34 -> 0 | I25: =I15-原始数据!I34 -> 0 | J25: =J15-原始数据!J34 -> 0 | ... R25: =R15-原始数据!R34 -> 0
A26: 净利润差额 | B26: 应为0 | C26: =C19-原始数据!C37 -> 0 | D26: =D19-原始数据!D37 -> 0 | E26: =E19-原始数据!E37 -> 0 | F26: =F19-原始数据!F37 -> 0 | G26: =G19-原始数据!G37 -> 0 | H26: =H19-原始数据!H37 -> -0.0001 | I26: =I19-原始数据!I37 -> 0 | J26: =J19-原始数据!J37 -> 0 | ... R26: =R19-原始数据!R37 -> 0
A27: 所得税 − 税率×MAX(0,税前利润) | B27: 应为0 | C27: =C18-TAX_RATE*MAX(0,C17) -> 0 | D27: =D18-TAX_RATE*MAX(0,D17) -> 0 | E27: =E18-TAX_RATE*MAX(0,E17) -> 0 | F27: =F18-TAX_RATE*MAX(0,F17) -> 0 | G27: =G18-TAX_RATE*MAX(0,G17) -> 0 | H27: =H18-TAX_RATE*MAX(0,H17) -> 5e-05 | I27: =I18-TAX_RATE*MAX(0,I17) -> -3e-05 | J27: =J18-TAX_RATE*MAX(0,J17) -> -2.5e-05 | ... R27: =R18-TAX_RATE*MAX(0,R17) -> -2.5e-05

Sheet 资产负债表
A1: 资产负债表（逐季期末）
A2: 单位：十亿美元。B列期初数来自 state_before_Q01.json（输入格）；之后各季：现金取自现金流量表，固定资产=上期+资本开支−折旧，借款=上期+新增借款，股东权益=上期+净利润。
A4: 项目 | B4: 期初 | C4: Q1 | D4: Q2 | E4: Q3 | F4: Q4 | G4: Q5 | H4: Q6 | I4: Q7 | J4: Q8 | K4: Q9 | L4: Q10 | M4: Q11 | N4: Q12 | O4: Q13 | P4: Q14 | Q4: Q15 | R4: Q16
A5: 现金 | B5: 10 | C5: =现金流量表!C19 -> 6.773 | D5: =现金流量表!D19 -> 4.5096 | E5: =现金流量表!E19 -> 3.8657 | F5: =现金流量表!F19 -> 3.7302 | G5: =现金流量表!G19 -> 2.9048 | H5: =现金流量表!H19 -> 2.0856 | I5: =现金流量表!I19 -> 1.9774 | J5: =现金流量表!J19 -> 1.7909 | ... R5: =现金流量表!R19 -> 181.8224
A6: 存货 | B6: 0.96 | C6: =原始数据!C46 -> 1.2464 | D6: =原始数据!D46 -> 2.1067 | E6: =原始数据!E46 -> 2.964 | F6: =原始数据!F46 -> 4.024 | G6: =原始数据!G46 -> 5.1874 | H6: =原始数据!H46 -> 5.7761 | I6: =原始数据!I46 -> 5.7292 | J6: =原始数据!J46 -> 5.1743 | ... R6: =原始数据!R46 -> 0
A7: 固定资产净值 | B7: 30 | C7: =B7+原始数据!C8-原始数据!C42 -> 29.5 | D7: =C7+原始数据!D8-原始数据!D42 -> 29 | E7: =D7+原始数据!E8-原始数据!E42 -> 28.5 | F7: =E7+原始数据!F8-原始数据!F42 -> 28 | G7: =F7+原始数据!G8-原始数据!G42 -> 30.425 | H7: =G7+原始数据!H8-原始数据!H42 -> 32.175 | I7: =H7+原始数据!I8-原始数据!I42 -> 33.25 | J7: =I7+原始数据!J8-原始数据!J42 -> 36.65 | ... R7: =Q7+原始数据!R8-原始数据!R42 -> 30.82
A8: 资产合计 | B8: =B5+B6+B7 -> 40.96 | C8: =C5+C6+C7 -> 37.5194 | D8: =D5+D6+D7 -> 35.6163 | E8: =E5+E6+E7 -> 35.3297 | F8: =F5+F6+F7 -> 35.7542 | G8: =G5+G6+G7 -> 38.5172 | H8: =H5+H6+H7 -> 40.0367 | I8: =I5+I6+I7 -> 40.9566 | ... R8: =R5+R6+R7 -> 212.6424
A10: 借款 | B10: 6 | C10: =B10+原始数据!C11 -> 6 | D10: =C10+原始数据!D11 -> 6 | E10: =D10+原始数据!E11 -> 8 | F10: =E10+原始数据!F11 -> 10 | G10: =F10+原始数据!G11 -> 13.5 | H10: =G10+原始数据!H11 -> 15 | I10: =H10+原始数据!I11 -> 15 | J10: =I10+原始数据!J11 -> 15.5 | ... R10: =Q10+原始数据!R11 -> 0
A11: 紧急授信 | B11: 0 | C11: =B11+原始数据!C43 -> 0 | D11: =C11+原始数据!D43 -> 0 | E11: =D11+原始数据!E43 -> 0 | F11: =E11+原始数据!F43 -> 0 | G11: =F11+原始数据!G43 -> 0 | H11: =G11+原始数据!H43 -> 0 | I11: =H11+原始数据!I43 -> 0 | J11: =I11+原始数据!J43 -> 0 | ... R11: =Q11+原始数据!R43 -> 0
A12: 负债合计 | B12: =B10+B11 -> 6 | C12: =C10+C11 -> 6 | D12: =D10+D11 -> 6 | E12: =E10+E11 -> 8 | F12: =F10+F11 -> 10 | G12: =G10+G11 -> 13.5 | H12: =H10+H11 -> 15 | I12: =I10+I11 -> 15 | ... R12: =R10+R11 -> 0
A13: 股东权益 | B13: 34.96 | C13: =B13+利润表!C19 -> 31.5194 | D13: =C13+利润表!D19 -> 29.6163 | E13: =D13+利润表!E19 -> 27.3297 | F13: =E13+利润表!F19 -> 25.7542 | G13: =F13+利润表!G19 -> 25.0172 | H13: =G13+利润表!H19 -> 25.0367 | I13: =H13+利润表!I19 -> 25.9566 | J13: =I13+利润表!J19 -> 28.1152 | ... R13: =Q13+利润表!R19 -> 212.6424
A14: 负债和股东权益合计 | B14: =B12+B13 -> 40.96 | C14: =C12+C13 -> 37.5194 | D14: =D12+D13 -> 35.6163 | E14: =E12+E13 -> 35.3297 | F14: =F12+F13 -> 35.7542 | G14: =G12+G13 -> 38.5172 | H14: =H12+H13 -> 40.0367 | I14: =I12+I13 -> 40.9566 | ... R14: =R12+R13 -> 212.6424
A16: 备查（片数与单位价值）
A17: 库存（千片） | B17: 60 | C17: =原始数据!C52 -> 75 | D17: =原始数据!D52 -> 165 | E17: =原始数据!E52 -> 260 | F17: =原始数据!F52 -> 333 | G17: =原始数据!G52 -> 383 | H17: =原始数据!H52 -> 402 | I17: =原始数据!I52 -> 384 | J17: =原始数据!J52 -> 337 | ... R17: =原始数据!R52 -> 0
A18: 每千片库存账面价值 | B18: =IF(B17>0,B6/B17*1000,0) -> 16 | C18: =IF(C17>0,C6/C17*1000,0) -> 16.618667 | D18: =IF(D17>0,D6/D17*1000,0) -> 12.767879 | E18: =IF(E17>0,E6/E17*1000,0) -> 11.4 | F18: =IF(F17>0,F6/F17*1000,0) -> 12.084084 | G18: =IF(G17>0,G6/G17*1000,0) -> 13.544125 | H18: =IF(H17>0,H6/H17*1000,0) -> 14.368408 | I18: =IF(I17>0,I6/I17*1000,0) -> 14.919792 | ... R18: =IF(R17>0,R6/R17*1000,0) -> 0
A19: 产能（千片/季） | B19: 300 | C19: =原始数据!C18 -> 300 | D19: =原始数据!D18 -> 300 | E19: =原始数据!E18 -> 300 | F19: =原始数据!F18 -> 300 | G19: =原始数据!G18 -> 300 | H19: =原始数据!H18 -> 300 | I19: =原始数据!I18 -> 300 | J19: =原始数据!J18 -> 300 | ... R19: =原始数据!R18 -> 465
A21: 核对（应为 0）
A22: 资产 − 负债 − 股东权益 | B22: 应为0 | C22: =C8-C14 -> 0 | D22: =D8-D14 -> 0 | E22: =E8-E14 -> 0 | F22: =F8-F14 -> 0 | G22: =G8-G14 -> 0 | H22: =H8-H14 -> 0 | I22: =I8-I14 -> 0 | J22: =J8-J14 -> 0 | ... R22: =R8-R14 -> 0
A23: 现金 − 引擎期末现金 | B23: 应为0 | C23: =C5-原始数据!C45 -> 0 | D23: =D5-原始数据!D45 -> 0 | E23: =E5-原始数据!E45 -> 0 | F23: =F5-原始数据!F45 -> 0 | G23: =G5-原始数据!G45 -> 0 | H23: =H5-原始数据!H45 -> -0.0001 | I23: =I5-原始数据!I45 -> -0.0001 | J23: =J5-原始数据!J45 -> -0.0001 | ... R23: =R5-原始数据!R45 -> 0.0001
A24: 固定资产 − 引擎数 | B24: 应为0 | C24: =C7-原始数据!C47 -> 0 | D24: =D7-原始数据!D47 -> 0 | E24: =E7-原始数据!E47 -> 0 | F24: =F7-原始数据!F47 -> 0 | G24: =G7-原始数据!G47 -> 0 | H24: =H7-原始数据!H47 -> 0 | I24: =I7-原始数据!I47 -> 0 | J24: =J7-原始数据!J47 -> 0 | ... R24: =R7-原始数据!R47 -> 0
A25: 资产合计 − 引擎数 | B25: 应为0 | C25: =C8-原始数据!C48 -> 0 | D25: =D8-原始数据!D48 -> 0 | E25: =E8-原始数据!E48 -> 0 | F25: =F8-原始数据!F48 -> 0 | G25: =G8-原始数据!G48 -> 0 | H25: =H8-原始数据!H48 -> -0.0001 | I25: =I8-原始数据!I48 -> -0.0001 | J25: =J8-原始数据!J48 -> 0 | ... R25: =R8-原始数据!R48 -> 0.0001
A26: 借款 − 引擎数 | B26: 应为0 | C26: =C10-原始数据!C49 -> 0 | D26: =D10-原始数据!D49 -> 0 | E26: =E10-原始数据!E49 -> 0 | F26: =F10-原始数据!F49 -> 0 | G26: =G10-原始数据!G49 -> 0 | H26: =H10-原始数据!H49 -> 0 | I26: =I10-原始数据!I49 -> 0 | J26: =J10-原始数据!J49 -> 0 | ... R26: =R10-原始数据!R49 -> 0
A27: 股东权益 − 引擎数 | B27: 应为0 | C27: =C13-原始数据!C51 -> 0 | D27: =D13-原始数据!D51 -> 0 | E27: =E13-原始数据!E51 -> 0 | F27: =F13-原始数据!F51 -> 0 | G27: =G13-原始数据!G51 -> 0 | H27: =H13-原始数据!H51 -> -0.0001 | I27: =I13-原始数据!I51 -> -0.0001 | J27: =J13-原始数据!J51 -> 0 | ... R27: =R13-原始数据!R51 -> 0.0001

Sheet 现金流量表
A1: 现金流量表（逐季，间接法）
A2: 单位：十亿美元。经营现金流=净利润+折旧−存货增加（本模拟没有应收应付）；期末现金滚动计算后与引擎核对。
A4: 项目 | B4: 单位/口径 | C4: Q1 | D4: Q2 | E4: Q3 | F4: Q4 | G4: Q5 | H4: Q6 | I4: Q7 | J4: Q8 | K4: Q9 | L4: Q10 | M4: Q11 | N4: Q12 | O4: Q13 | P4: Q14 | Q4: Q15 | R4: Q16 | S4: 16季合计
A5: 净利润 | C5: =利润表!C19 -> -3.4406 | D5: =利润表!D19 -> -1.9031 | E5: =利润表!E19 -> -2.2866 | F5: =利润表!F19 -> -1.5755 | G5: =利润表!G19 -> -0.737 | H5: =利润表!H19 -> 0.0195 | I5: =利润表!I19 -> 0.9199 | J5: =利润表!J19 -> 2.1586 | ... R5: =利润表!R19 -> 55.7273 | S5: =SUM(C5:R5) -> 177.6824
A6: 加：折旧 | C6: =原始数据!C42 -> 2 | D6: =原始数据!D42 -> 2 | E6: =原始数据!E42 -> 2 | F6: =原始数据!F42 -> 2 | G6: =原始数据!G42 -> 2.075 | H6: =原始数据!H42 -> 2.15 | I6: =原始数据!I42 -> 2.225 | J6: =原始数据!J42 -> 2.3 | ... R6: =原始数据!R42 -> 3.89 | S6: =SUM(C6:R6) -> 42.98
A7: 减：存货增加（减少为正） | C7: =-(资产负债表!C6-资产负债表!B6) -> -0.2864 | D7: =-(资产负债表!D6-资产负债表!C6) -> -0.8603 | E7: =-(资产负债表!E6-资产负债表!D6) -> -0.8573 | F7: =-(资产负债表!F6-资产负债表!E6) -> -1.06 | G7: =-(资产负债表!G6-资产负债表!F6) -> -1.1634 | H7: =-(资产负债表!H6-资产负债表!G6) -> -0.5887 | I7: =-(资产负债表!I6-资产负债表!H6) -> 0.0469 | J7: =-(资产负债表!J6-资产负债表!I6) -> 0.5549 | ... R7: =-(资产负债表!R6-资产负债表!Q6) -> 0 | S7: =SUM(C7:R7) -> 0.96
A8: 经营活动现金流 | C8: =SUM(C5:C7) -> -1.727 | D8: =SUM(D5:D7) -> -0.7634 | E8: =SUM(E5:E7) -> -1.1439 | F8: =SUM(F5:F7) -> -0.6355 | G8: =SUM(G5:G7) -> 0.1746 | H8: =SUM(H5:H7) -> 1.5808 | I8: =SUM(I5:I7) -> 3.1918 | J8: =SUM(J5:J7) -> 5.0135 | ... R8: =SUM(R5:R7) -> 59.6173 | S8: =SUM(C8:R8) -> 221.6224
A10: 资本开支 | C10: =-原始数据!C8 -> -1.5 | D10: =-原始数据!D8 -> -1.5 | E10: =-原始数据!E8 -> -1.5 | F10: =-原始数据!F8 -> -1.5 | G10: =-原始数据!G8 -> -4.5 | H10: =-原始数据!H8 -> -3.9 | I10: =-原始数据!I8 -> -3.3 | J10: =-原始数据!J8 -> -5.7 | ... R10: =-原始数据!R8 -> -1.5 | S10: =SUM(C10:R10) -> -43.8
A11: 投资活动现金流 | C11: =C10 -> -1.5 | D11: =D10 -> -1.5 | E11: =E10 -> -1.5 | F11: =F10 -> -1.5 | G11: =G10 -> -4.5 | H11: =H10 -> -3.9 | I11: =I10 -> -3.3 | J11: =J10 -> -5.7 | ... R11: =R10 -> -1.5 | S11: =SUM(C11:R11) -> -43.8
A13: 新增借款（还款为负） | C13: =原始数据!C11 -> 0 | D13: =原始数据!D11 -> 0 | E13: =原始数据!E11 -> 2 | F13: =原始数据!F11 -> 2 | G13: =原始数据!G11 -> 3.5 | H13: =原始数据!H11 -> 1.5 | I13: =原始数据!I11 -> 0 | J13: =原始数据!J11 -> 0.5 | ... R13: =原始数据!R11 -> 0 | S13: =SUM(C13:R13) -> -6
A14: 紧急授信提取 | C14: =原始数据!C43 -> 0 | D14: =原始数据!D43 -> 0 | E14: =原始数据!E43 -> 0 | F14: =原始数据!F43 -> 0 | G14: =原始数据!G43 -> 0 | H14: =原始数据!H43 -> 0 | I14: =原始数据!I43 -> 0 | J14: =原始数据!J43 -> 0 | ... R14: =原始数据!R43 -> 0 | S14: =SUM(C14:R14) -> 0
A15: 筹资活动现金流 | C15: =C13+C14 -> 0 | D15: =D13+D14 -> 0 | E15: =E13+E14 -> 2 | F15: =F13+F14 -> 2 | G15: =G13+G14 -> 3.5 | H15: =H13+H14 -> 1.5 | I15: =I13+I14 -> 0 | J15: =J13+J14 -> 0.5 | ... R15: =R13+R14 -> 0 | S15: =SUM(C15:R15) -> -6
A17: 现金净增加 | C17: =C8+C11+C15 -> -3.227 | D17: =D8+D11+D15 -> -2.2634 | E17: =E8+E11+E15 -> -0.6439 | F17: =F8+F11+F15 -> -0.1355 | G17: =G8+G11+G15 -> -0.8254 | H17: =H8+H11+H15 -> -0.8192 | I17: =I8+I11+I15 -> -0.1082 | J17: =J8+J11+J15 -> -0.1865 | ... R17: =R8+R11+R15 -> 58.1173 | S17: =SUM(C17:R17) -> 171.8224
A18: 期初现金 | C18: =资产负债表!B5 -> 10 | D18: =C19 -> 6.773 | E18: =D19 -> 4.5096 | F18: =E19 -> 3.8657 | G18: =F19 -> 3.7302 | H18: =G19 -> 2.9048 | I18: =H19 -> 2.0856 | J18: =I19 -> 1.9774 | K18: =J19 -> 1.7909 | ... R18: =Q19 -> 123.7051 | S18: =C18 -> 10
A19: 期末现金 | C19: =C18+C17 -> 6.773 | D19: =D18+D17 -> 4.5096 | E19: =E18+E17 -> 3.8657 | F19: =F18+F17 -> 3.7302 | G19: =G18+G17 -> 2.9048 | H19: =H18+H17 -> 2.0856 | I19: =I18+I17 -> 1.9774 | J19: =J18+J17 -> 1.7909 | ... R19: =R18+R17 -> 181.8224 | S19: =R19 -> 181.8224
A21: 自由现金流（经营+投资） | C21: =C8+C11 -> -3.227 | D21: =D8+D11 -> -2.2634 | E21: =E8+E11 -> -2.6439 | F21: =F8+F11 -> -2.1355 | G21: =G8+G11 -> -4.3254 | H21: =H8+H11 -> -2.3192 | I21: =I8+I11 -> -0.1082 | J21: =J8+J11 -> -0.6865 | ... R21: =R8+R11 -> 58.1173 | S21: =SUM(C21:R21) -> 177.8224
A23: 核对（公式结果 − 引擎数字，应为 0）
A24: 经营活动现金流差额 | B24: 应为0 | C24: =C8-原始数据!C39 -> 0 | D24: =D8-原始数据!D39 -> 0 | E24: =E8-原始数据!E39 -> 0 | F24: =F8-原始数据!F39 -> 0 | G24: =G8-原始数据!G39 -> 0 | H24: =H8-原始数据!H39 -> -0.0001 | I24: =I8-原始数据!I39 -> 0 | J24: =J8-原始数据!J39 -> 0 | ... R24: =R8-原始数据!R39 -> 0
A25: 投资活动现金流差额 | B25: 应为0 | C25: =C11-原始数据!C40 -> 0 | D25: =D11-原始数据!D40 -> 0 | E25: =E11-原始数据!E40 -> 0 | F25: =F11-原始数据!F40 -> 0 | G25: =G11-原始数据!G40 -> 0 | H25: =H11-原始数据!H40 -> 0 | I25: =I11-原始数据!I40 -> 0 | J25: =J11-原始数据!J40 -> 0 | ... R25: =R11-原始数据!R40 -> 0
A26: 筹资活动现金流差额（引擎筹资不含紧急授信） | B26: 应为0 | C26: =C13-原始数据!C41 -> 0 | D26: =D13-原始数据!D41 -> 0 | E26: =E13-原始数据!E41 -> 0 | F26: =F13-原始数据!F41 -> 0 | G26: =G13-原始数据!G41 -> 0 | H26: =H13-原始数据!H41 -> 0 | I26: =I13-原始数据!I41 -> 0 | J26: =J13-原始数据!J41 -> 0 | ... R26: =R13-原始数据!R41 -> 0
A27: 期末现金差额 | B27: 应为0 | C27: =C19-原始数据!C45 -> 0 | D27: =D19-原始数据!D45 -> 0 | E27: =E19-原始数据!E45 -> 0 | F27: =F19-原始数据!F45 -> 0 | G27: =G19-原始数据!G45 -> 0 | H27: =H19-原始数据!H45 -> -0.0001 | I27: =I19-原始数据!I45 -> -0.0001 | J27: =J19-原始数据!J45 -> -0.0001 | ... R27: =R19-原始数据!R45 -> 0.0001

Sheet 分析
A1: 经营分析（全部为公式）
A2: 引用三张表、原始数据和「假设」页参数（每季天数、年化倍数、价格基准等）。改假设，指标和图表自动更新。
A4: 指标 | B4: 口径 | C4: Q1 | D4: Q2 | E4: Q3 | F4: Q4 | G4: Q5 | H4: Q6 | I4: Q7 | J4: Q8 | K4: Q9 | L4: Q10 | M4: Q11 | N4: Q12 | O4: Q13 | P4: Q14 | Q4: Q15 | R4: Q16 | S4: 全程
A5: 盈利能力
A6: 营业收入 | B6: 十亿美元 | C6: =利润表!C7 -> 4.608 | D6: =利润表!D7 -> 2.8224 | E6: =利润表!E7 -> 2.46 | F6: =利润表!F7 -> 3.0036 | G6: =利润表!G7 -> 3.8448 | H6: =利润表!H7 -> 5.3136 | I6: =利润表!I7 -> 7.1124 | J6: =利润表!J7 -> 9.1536 | ... R6: =利润表!R7 -> 72.8369 | S6: =SUM(C6:R6) -> 318.1111
A7: 营业收入环比增速 | B7: % | C7: — | D7: =D6/C6-1 -> -0.3875 | E7: =E6/D6-1 -> -0.12840136 | F7: =F6/E6-1 -> 0.22097561 | G7: =G6/F6-1 -> 0.28006392 | H7: =H6/G6-1 -> 0.38202247 | I7: =I6/H6-1 -> 0.33852755 | J7: =J6/I6-1 -> 0.28699173 | K7: =K6/J6-1 -> 0.26691138 | ... R7: =R6/Q6-1 -> 0.18150806 | S7: —
A8: 毛利率 | B8: 毛利÷营收 | C8: =利润表!C10/利润表!C7 -> 0.1344184 | D8: =利润表!D10/利润表!D7 -> -0.28957625 | E8: =利润表!E10/利润表!E7 -> -0.48077236 | F8: =利润表!F10/利润表!F7 -> -0.14529232 | G8: =利润表!G10/利润表!G7 -> 0.11267166 | H8: =利润表!H10/利润表!H7 -> 0.23567826 | I8: =利润表!I10/利润表!I7 -> 0.32907317 | J8: =利润表!J10/利润表!J7 -> 0.41499519 | ... S8: =利润表!S10/利润表!S7 -> 0.72339884
A9: 营业利润率 | B9: 营业利润÷营收 | C9: =利润表!C15/利润表!C7 -> -0.74448785 | D9: =利润表!D15/利润表!D7 -> -0.66160006 | E9: =利润表!E15/利润表!E7 -> -0.90760163 | F9: =利润表!F15/利润表!F7 -> -0.49487282 | G9: =利润表!G15/利润表!G7 -> -0.16042447 | H9: =利润表!H15/利润表!H7 -> 0.038072117 | I9: =利润表!I15/利润表!I7 -> 0.18144368 | J9: =利润表!J15/利润表!J7 -> 0.30028623 | ... S9: =利润表!S15/利润表!S7 -> 0.66115643
A10: 净利率 | B10: 净利润÷营收 | C10: =利润表!C19/利润表!C7 -> -0.74665799 | D10: =利润表!D19/利润表!D7 -> -0.6742843 | E10: =利润表!E19/利润表!E7 -> -0.9295122 | F10: =利润表!F19/利润表!F7 -> -0.52453722 | G10: =利润表!G19/利润表!G7 -> -0.19168747 | H10: =利润表!H19/利润表!H7 -> 0.0036698284 | I10: =利润表!I19/利润表!I7 -> 0.1293375 | J10: =利润表!J19/利润表!J7 -> 0.23581979 | ... S10: =利润表!S19/利润表!S7 -> 0.55855454
A11: EBITDA | B11: 营业利润+折旧 | C11: =利润表!C15+现金流量表!C6 -> -1.4306 | D11: =利润表!D15+现金流量表!D6 -> 0.1327 | E11: =利润表!E15+现金流量表!E6 -> -0.2327 | F11: =利润表!F15+现金流量表!F6 -> 0.5136 | G11: =利润表!G15+现金流量表!G6 -> 1.4582 | H11: =利润表!H15+现金流量表!H6 -> 2.3523 | I11: =利润表!I15+现金流量表!I6 -> 3.5155 | J11: =利润表!J15+现金流量表!J6 -> 5.0487 | ... R11: =利润表!R15+现金流量表!R6 -> 68.4619 | S11: =SUM(C11:R11) -> 253.3012
A12: HBM 收入占比 | B12: HBM收入÷营收 | C12: =利润表!C6/利润表!C7 -> 0 | D12: =利润表!D6/利润表!D7 -> 0 | E12: =利润表!E6/利润表!E7 -> 0 | F12: =利润表!F6/利润表!F7 -> 0.089492609 | G12: =利润表!G6/利润表!G7 -> 0.11985019 | H12: =利润表!H6/利润表!H7 -> 0.15447154 | I12: =利润表!I6/利润表!I7 -> 0.20178843 | J12: =利润表!J6/利润表!J7 -> 0.26428946 | ... S12: =利润表!S6/利润表!S7 -> 0.48049628
A13: 单位经济（每千片，百万美元）
A14: 普通内存售价 | B14: 价格指数×基准价×1000 | C14: =原始数据!C13*P_BASE*1000 -> 19.2 | D14: =原始数据!D13*P_BASE*1000 -> 13.44 | E14: =原始数据!E13*P_BASE*1000 -> 12 | F14: =原始数据!F13*P_BASE*1000 -> 12.72 | G14: =原始数据!G13*P_BASE*1000 -> 14.4 | H14: =原始数据!H13*P_BASE*1000 -> 17.28 | I14: =原始数据!I13*P_BASE*1000 -> 19.92 | J14: =原始数据!J13*P_BASE*1000 -> 22.08 | ... R14: =原始数据!R13*P_BASE*1000 -> 109.2 | S14: —
A15: HBM 售价 | B15: HBM价格指数×基准价×1000 | C15: =原始数据!C14*P_BASE*1000 -> 38.4 | D15: =原始数据!D14*P_BASE*1000 -> 33.6 | E15: =原始数据!E14*P_BASE*1000 -> 31.2 | F15: =原始数据!F14*P_BASE*1000 -> 33.6 | G15: =原始数据!G14*P_BASE*1000 -> 38.4 | H15: =原始数据!H14*P_BASE*1000 -> 45.6 | I15: =原始数据!I14*P_BASE*1000 -> 55.2 | J15: =原始数据!J14*P_BASE*1000 -> 67.2 | ... R15: =原始数据!R14*P_BASE*1000 -> 230.4 | S15: —
A16: 单位生产成本（含折旧） | B16: 引擎单位成本 | C16: =原始数据!C23 -> 16.765 | D16: =原始数据!D23 -> 15 | E16: =原始数据!E23 -> 15 | F16: =原始数据!F23 -> 15 | G16: =原始数据!G23 -> 15.25 | H16: =原始数据!H23 -> 15.5 | I16: =原始数据!I23 -> 15.75 | J16: =原始数据!J23 -> 16 | ... R16: =原始数据!R23 -> 15.516 | S16: —
A17: 单位变动成本 | B17: 假设页参数 | C17: =V_COST*1000 -> 5 | D17: =V_COST*1000 -> 5 | E17: =V_COST*1000 -> 5 | F17: =V_COST*1000 -> 5 | G17: =V_COST*1000 -> 5 | H17: =V_COST*1000 -> 5 | I17: =V_COST*1000 -> 5 | J17: =V_COST*1000 -> 5 | ... R17: =V_COST*1000 -> 5 | S17: —
A18: 单位现金成本 | B18: (工厂费用+变动成本+固定研发+管理费)÷产量 | C18: =(PLANT_FIXED+V_COST*原始数据!C19+RND_BASE+SGA_Q)/原始数据!C19*1000 -> 13.039216 | D18: =(PLANT_FIXED+V_COST*原始数据!D19+RND_BASE+SGA_Q)/原始数据!D19*1000 -> 11.833333 | E18: =(PLANT_FIXED+V_COST*原始数据!E19+RND_BASE+SGA_Q)/原始数据!E19*1000 -> 11.833333 | F18: =(PLANT_FIXED+V_COST*原始数据!F19+RND_BASE+SGA_Q)/原始数据!F19*1000 -> 11.833333 | G18: =(PLANT_FIXED+V_COST*原始数据!G19+RND_BASE+SGA_Q)/原始数据!G19*1000 -> 11.833333 | H18: =(PLANT_FIXED+V_COST*原始数据!H19+RND_BASE+SGA_Q)/原始数据!H19*1000 -> 11.833333 | I18: =(PLANT_FIXED+V_COST*原始数据!I19+RND_BASE+SGA_Q)/原始数据!I19*1000 -> 11.833333 | J18: =(PLANT_FIXED+V_COST*原始数据!J19+RND_BASE+SGA_Q)/原始数据!J19*1000 -> 11.833333 | ... R18: =(PLANT_FIXED+V_COST*原始数据!R19+RND_BASE+SGA_Q)/原始数据!R19*1000 -> 9.4086022 | S18: —
A19: 普通内存单片毛利 | B19: 售价−单位生产成本 | C19: =C14-C16 -> 2.435 | D19: =D14-D16 -> -1.56 | E19: =E14-E16 -> -3 | F19: =F14-F16 -> -2.28 | G19: =G14-G16 -> -0.85 | H19: =H14-H16 -> 1.78 | I19: =I14-I16 -> 4.17 | J19: =J14-J16 -> 6.08 | ... R19: =R14-R16 -> 93.684 | S19: —
A20: HBM 售价 ÷ 普通内存售价 | B20: 倍 | C20: =C15/C14 -> 2 | D20: =D15/D14 -> 2.5 | E20: =E15/E14 -> 2.6 | F20: =F15/F14 -> 2.6415094 | G20: =G15/G14 -> 2.6666667 | H20: =H15/H14 -> 2.6388889 | I20: =I15/I14 -> 2.7710843 | J20: =J15/J14 -> 3.0434783 | ... R20: =R15/R14 -> 2.1098901 | S20: —
A21: 运营
A22: 产能利用率 | B22: 产量÷产能 | C22: =原始数据!C19/原始数据!C18 -> 0.85 | D22: =原始数据!D19/原始数据!D18 -> 1 | E22: =原始数据!E19/原始数据!E18 -> 1 | F22: =原始数据!F19/原始数据!F18 -> 1 | G22: =原始数据!G19/原始数据!G18 -> 1 | H22: =原始数据!H19/原始数据!H18 -> 1 | I22: =原始数据!I19/原始数据!I18 -> 1 | J22: =原始数据!J19/原始数据!J18 -> 1 | ... R22: =原始数据!R19/原始数据!R18 -> 1 | S22: —
A23: 普通内存需求满足率 | B23: 销量÷需求 | C23: =原始数据!C21/原始数据!C15 -> 1 | D23: =原始数据!D21/原始数据!D15 -> 1 | E23: =原始数据!E21/原始数据!E15 -> 1 | F23: =原始数据!F21/原始数据!F15 -> 1 | G23: =原始数据!G21/原始数据!G15 -> 1 | H23: =原始数据!H21/原始数据!H15 -> 1 | I23: =原始数据!I21/原始数据!I15 -> 1 | J23: =原始数据!J21/原始数据!J15 -> 1 | ... R23: =原始数据!R21/原始数据!R15 -> 0.5424902 | S23: =SUM(原始数据!C21:R21)/SUM(原始数据!C15:R15) -> 0.9035809
A24: 普通内存需求缺口（千片） | B24: 需求−销量 | C24: =原始数据!C15-原始数据!C21 -> 0 | D24: =原始数据!D15-原始数据!D21 -> 0 | E24: =原始数据!E15-原始数据!E21 -> 0 | F24: =原始数据!F15-原始数据!F21 -> 0 | G24: =原始数据!G15-原始数据!G21 -> 0 | H24: =原始数据!H15-原始数据!H21 -> 0 | I24: =原始数据!I15-原始数据!I21 -> 0 | J24: =原始数据!J15-原始数据!J21 -> 0 | ... R24: =原始数据!R15-原始数据!R21 -> 233.33 | S24: =SUM(C24:R24) -> 494.63
A25: HBM 作废量（千片） | B25: HBM产量−HBM销量 | C25: =原始数据!C20-原始数据!C22 -> 0 | D25: =原始数据!D20-原始数据!D22 -> 0 | E25: =原始数据!E20-原始数据!E22 -> 0 | F25: =原始数据!F20-原始数据!F22 -> 4 | G25: =原始数据!G20-原始数据!G22 -> 3 | H25: =原始数据!H20-原始数据!H22 -> 3 | I25: =原始数据!I20-原始数据!I22 -> 7 | J25: =原始数据!J20-原始数据!J22 -> 6 | ... R25: =原始数据!R20-原始数据!R22 -> 3.33 | S25: =SUM(C25:R25) -> 72.62
A26: 存货周转天数（金额口径） | B26: 平均存货÷营业成本×每季天数 | C26: =AVERAGE(资产负债表!B6,资产负债表!C6)/利润表!C8*DAYS_Q -> 25.23868 | D26: =AVERAGE(资产负债表!C6,资产负债表!D6)/利润表!D8*DAYS_Q -> 42.032362 | E26: =AVERAGE(资产负债表!D6,资产负债表!E6)/利润表!E8*DAYS_Q -> 63.510772 | F26: =AVERAGE(资产负债表!E6,资产负债表!F6)/利润表!F8*DAYS_Q -> 92.682413 | G26: =AVERAGE(资产负债表!F6,资产负债表!G6)/利润表!G8*DAYS_Q -> 123.18857 | H26: =AVERAGE(资产负债表!G6,资产负债表!H6)/利润表!H8*DAYS_Q -> 123.16492 | I26: =AVERAGE(资产负债表!H6,资产负债表!I6)/利润表!I8*DAYS_Q -> 110.00426 | J26: =AVERAGE(资产负债表!I6,资产负债表!J6)/利润表!J8*DAYS_Q -> 92.900369 | ... R26: =AVERAGE(资产负债表!Q6,资产负债表!R6)/利润表!R8*DAYS_Q -> 0 | S26: —
A27: 库存可售天数（片数口径） | B27: 期末库存千片÷普通内存销量×每季天数 | C27: =原始数据!C52/原始数据!C21*DAYS_Q -> 28.515625 | D27: =原始数据!D52/原始数据!D21*DAYS_Q -> 71.696429 | E27: =原始数据!E52/原始数据!E21*DAYS_Q -> 115.73171 | F27: =原始数据!F52/原始数据!F21*DAYS_Q -> 141.3314 | G27: =原始数据!G52/原始数据!G21*DAYS_Q -> 148.71809 | H27: =原始数据!H52/原始数据!H21*DAYS_Q -> 141.08654 | I27: =原始数据!I52/原始数据!I21*DAYS_Q -> 122.94737 | J27: =原始数据!J52/原始数据!J21*DAYS_Q -> 100.82377 | ... R27: =原始数据!R52/原始数据!R21*DAYS_Q -> 0 | S27: —
A28: 现金与杠杆
A29: 经营活动现金流 | B29: 现金流量表 | C29: =现金流量表!C8 -> -1.727 | D29: =现金流量表!D8 -> -0.7634 | E29: =现金流量表!E8 -> -1.1439 | F29: =现金流量表!F8 -> -0.6355 | G29: =现金流量表!G8 -> 0.1746 | H29: =现金流量表!H8 -> 1.5808 | I29: =现金流量表!I8 -> 3.1918 | J29: =现金流量表!J8 -> 5.0135 | ... R29: =现金流量表!R8 -> 59.6173 | S29: =SUM(C29:R29) -> 221.6224
A30: 自由现金流 | B30: 经营+投资 | C30: =现金流量表!C21 -> -3.227 | D30: =现金流量表!D21 -> -2.2634 | E30: =现金流量表!E21 -> -2.6439 | F30: =现金流量表!F21 -> -2.1355 | G30: =现金流量表!G21 -> -4.3254 | H30: =现金流量表!H21 -> -2.3192 | I30: =现金流量表!I21 -> -0.1082 | J30: =现金流量表!J21 -> -0.6865 | ... R30: =现金流量表!R21 -> 58.1173 | S30: =SUM(C30:R30) -> 177.8224
A31: 经营现金流 ÷ 净利润 | B31: 倍 | C31: =IF(利润表!C19>0,现金流量表!C8/利润表!C19,0) -> 0 | D31: =IF(利润表!D19>0,现金流量表!D8/利润表!D19,0) -> 0 | E31: =IF(利润表!E19>0,现金流量表!E8/利润表!E19,0) -> 0 | F31: =IF(利润表!F19>0,现金流量表!F8/利润表!F19,0) -> 0 | G31: =IF(利润表!G19>0,现金流量表!G8/利润表!G19,0) -> 0 | H31: =IF(利润表!H19>0,现金流量表!H8/利润表!H19,0) -> 81.066667 | I31: =IF(利润表!I19>0,现金流量表!I8/利润表!I19,0) -> 3.469725 | J31: =IF(利润表!J19>0,现金流量表!J8/利润表!J19,0) -> 2.3225702 | ... R31: =IF(利润表!R19>0,现金流量表!R8/利润表!R19,0) -> 1.0698042 | S31: —
A32: 净负债 | B32: 借款+紧急授信−现金 | C32: =资产负债表!C12-资产负债表!C5 -> -0.773 | D32: =资产负债表!D12-资产负债表!D5 -> 1.4904 | E32: =资产负债表!E12-资产负债表!E5 -> 4.1343 | F32: =资产负债表!F12-资产负债表!F5 -> 6.2698 | G32: =资产负债表!G12-资产负债表!G5 -> 10.5952 | H32: =资产负债表!H12-资产负债表!H5 -> 12.9144 | I32: =资产负债表!I12-资产负债表!I5 -> 13.0226 | J32: =资产负债表!J12-资产负债表!J5 -> 13.7091 | ... R32: =资产负债表!R12-资产负债表!R5 -> -181.8224 | S32: —
A33: 净负债 ÷ 股东权益 | B33: % | C33: =C32/资产负债表!C13 -> -0.024524579 | D33: =D32/资产负债表!D13 -> 0.050323639 | E33: =E32/资产负债表!E13 -> 0.15127499 | F33: =F32/资产负债表!F13 -> 0.24344767 | G33: =G32/资产负债表!G13 -> 0.42351662 | H33: =H32/资产负债表!H13 -> 0.51581878 | I33: =I32/资产负债表!I13 -> 0.5017067 | J33: =J32/资产负债表!J13 -> 0.48760457 | ... R33: =R32/资产负债表!R13 -> -0.85506183 | S33: —
A34: 资产负债率 | B34: 负债合计÷资产合计 | C34: =资产负债表!C12/资产负债表!C8 -> 0.15991727 | D34: =资产负债表!D12/资产负债表!D8 -> 0.16846219 | E34: =资产负债表!E12/资产负债表!E8 -> 0.22643838 | F34: =资产负债表!F12/资产负债表!F8 -> 0.27968742 | G34: =资产负债表!G12/资产负债表!G8 -> 0.35049277 | H34: =资产负债表!H12/资产负债表!H8 -> 0.37465625 | I34: =资产负债表!I12/资产负债表!I8 -> 0.36624134 | J34: =资产负债表!J12/资产负债表!J8 -> 0.35538069 | ... R34: =资产负债表!R12/资产负债表!R8 -> 0 | S34: —
A35: 借款上限（按期末权益） | B35: MAX(下限,比例×权益) | C35: =MAX(DEBT_FLOOR,DEBT_RATIO*资产负债表!C13) -> 18.91164 | D35: =MAX(DEBT_FLOOR,DEBT_RATIO*资产负债表!D13) -> 17.76978 | E35: =MAX(DEBT_FLOOR,DEBT_RATIO*资产负债表!E13) -> 16.39782 | F35: =MAX(DEBT_FLOOR,DEBT_RATIO*资产负债表!F13) -> 15.45252 | G35: =MAX(DEBT_FLOOR,DEBT_RATIO*资产负债表!G13) -> 15.01032 | H35: =MAX(DEBT_FLOOR,DEBT_RATIO*资产负债表!H13) -> 15.02202 | I35: =MAX(DEBT_FLOOR,DEBT_RATIO*资产负债表!I13) -> 15.57396 | J35: =MAX(DEBT_FLOOR,DEBT_RATIO*资产负债表!J13) -> 16.86912 | ... R35: =MAX(DEBT_FLOOR,DEBT_RATIO*资产负债表!R13) -> 127.58544 | S35: —
A36: 借款占上限比例 | B36: 借款÷借款上限 | C36: =资产负债表!C10/C35 -> 0.31726492 | D36: =资产负债表!D10/D35 -> 0.3376519 | E36: =资产负债表!E10/E35 -> 0.48786973 | F36: =资产负债表!F10/F35 -> 0.64714364 | G36: =资产负债表!G10/G35 -> 0.89938123 | H36: =资产负债表!H10/H35 -> 0.99853415 | I36: =资产负债表!I10/I35 -> 0.96314617 | J36: =资产负债表!J10/J35 -> 0.91883868 | ... R36: =资产负债表!R10/R35 -> 0 | S36: —
A37: 回报
A38: 平均股东权益 | B38: (期初+期末)÷2 | C38: =AVERAGE(资产负债表!B13,资产负债表!C13) -> 33.2397 | D38: =AVERAGE(资产负债表!C13,资产负债表!D13) -> 30.56785 | E38: =AVERAGE(资产负债表!D13,资产负债表!E13) -> 28.473 | F38: =AVERAGE(资产负债表!E13,资产负债表!F13) -> 26.54195 | G38: =AVERAGE(资产负债表!F13,资产负债表!G13) -> 25.3857 | H38: =AVERAGE(资产负债表!G13,资产负债表!H13) -> 25.02695 | I38: =AVERAGE(资产负债表!H13,资产负债表!I13) -> 25.49665 | J38: =AVERAGE(资产负债表!I13,资产负债表!J13) -> 27.0359 | ... R38: =AVERAGE(资产负债表!Q13,资产负债表!R13) -> 184.77875 | S38: —
A39: ROE（季度） | B39: 净利润÷平均权益 | C39: =利润表!C19/C38 -> -0.10350876 | D39: =利润表!D19/D38 -> -0.062258222 | E39: =利润表!E19/E38 -> -0.08030766 | F39: =利润表!F19/F38 -> -0.059358864 | G39: =利润表!G19/G38 -> -0.029032093 | H39: =利润表!H19/H38 -> 0.00077916007 | I39: =利润表!I19/I38 -> 0.03607925 | J39: =利润表!J19/J38 -> 0.079841988 | ... R39: =利润表!R19/R38 -> 0.30158933 | S39: —
A40: ROE（年化） | B40: 季度ROE×年化倍数 | C40: =C39*ANNUAL -> -0.41403502 | D40: =D39*ANNUAL -> -0.24903289 | E40: =E39*ANNUAL -> -0.32123064 | F40: =F39*ANNUAL -> -0.23743546 | G40: =G39*ANNUAL -> -0.11612837 | H40: =H39*ANNUAL -> 0.0031166403 | I40: =I39*ANNUAL -> 0.144317 | J40: =J39*ANNUAL -> 0.31936795 | ... R40: =R39*ANNUAL -> 1.2063573 | S40: —
A41: 累计回报（相对期初权益） | B41: 累计净利润÷期初权益 | C41: =利润表!C20/资产负债表!$B$13 -> -0.098415332 | D41: =利润表!D20/资产负债表!$B$13 -> -0.15285183 | E41: =利润表!E20/资产负债表!$B$13 -> -0.21825801 | F41: =利润表!F20/资产负债表!$B$13 -> -0.2633238 | G41: =利润表!G20/资产负债表!$B$13 -> -0.28440503 | H41: =利润表!H20/资产负债表!$B$13 -> -0.28384725 | I41: =利润表!I20/资产负债表!$B$13 -> -0.25753432 | J41: =利润表!J20/资产负债表!$B$13 -> -0.19578947 | ... R41: =利润表!R20/资产负债表!$B$13 -> 5.0824485 | S41: —
...

Sheet 模型复现与情景
A1: 模型复现与情景（按推断参数从头重算）
A2: 黄色情景格留空=使用实际决策；填入数字即覆盖该季决策。价格系数在「假设」页。HBM 产量=产量×HBM占比（假设开工率同样作用于HBM）；现金低于下限时紧急授信补足到下限（假设）。
A4: 项目〔算法〕 | B4: 期初 | C4: Q1 | D4: Q2 | E4: Q3 | F4: Q4 | G4: Q5 | H4: Q6 | I4: Q7 | J4: Q8 | K4: Q9 | L4: Q10 | M4: Q11 | N4: Q12 | O4: Q13 | P4: Q14 | Q4: Q15 | R4: Q16
A5: 情景输入（留空=实际决策）
A6: 开工率（情景） 〔留空=实际〕
A7: 出货比例（情景） 〔留空=实际〕
A8: 资本开支（情景） 〔留空=实际〕
A9: HBM 产能占比（情景） 〔留空=实际〕
A10: 新增借款（情景） 〔留空=实际〕
A11: 实际生效的决策
A12: 开工率 | C12: =IF(C6="",原始数据!C6,C6) -> 0.85 | D12: =IF(D6="",原始数据!D6,D6) -> 1 | E12: =IF(E6="",原始数据!E6,E6) -> 1 | F12: =IF(F6="",原始数据!F6,F6) -> 1 | G12: =IF(G6="",原始数据!G6,G6) -> 1 | H12: =IF(H6="",原始数据!H6,H6) -> 1 | I12: =IF(I6="",原始数据!I6,I6) -> 1 | J12: =IF(J6="",原始数据!J6,J6) -> 1 | ... R12: =IF(R6="",原始数据!R6,R6) -> 1
A13: 出货比例 | C13: =IF(C7="",原始数据!C7,C7) -> 1 | D13: =IF(D7="",原始数据!D7,D7) -> 1 | E13: =IF(E7="",原始数据!E7,E7) -> 1 | F13: =IF(F7="",原始数据!F7,F7) -> 1 | G13: =IF(G7="",原始数据!G7,G7) -> 1 | H13: =IF(H7="",原始数据!H7,H7) -> 1 | I13: =IF(I7="",原始数据!I7,I7) -> 1 | J13: =IF(J7="",原始数据!J7,J7) -> 1 | ... R13: =IF(R7="",原始数据!R7,R7) -> 1
A14: 资本开支 | C14: =IF(C8="",原始数据!C8,C8) -> 1.5 | D14: =IF(D8="",原始数据!D8,D8) -> 1.5 | E14: =IF(E8="",原始数据!E8,E8) -> 1.5 | F14: =IF(F8="",原始数据!F8,F8) -> 1.5 | G14: =IF(G8="",原始数据!G8,G8) -> 4.5 | H14: =IF(H8="",原始数据!H8,H8) -> 3.9 | I14: =IF(I8="",原始数据!I8,I8) -> 3.3 | J14: =IF(J8="",原始数据!J8,J8) -> 5.7 | ... R14: =IF(R8="",原始数据!R8,R8) -> 1.5
A15: HBM 产能占比 | C15: =IF(C9="",原始数据!C10,C9) -> 0 | D15: =IF(D9="",原始数据!D10,D9) -> 0 | E15: =IF(E9="",原始数据!E10,E9) -> 0 | F15: =IF(F9="",原始数据!F10,F9) -> 0.04 | G15: =IF(G9="",原始数据!G10,G9) -> 0.05 | H15: =IF(H9="",原始数据!H10,H9) -> 0.07 | I15: =IF(I9="",原始数据!I10,I9) -> 0.11 | J15: =IF(J9="",原始数据!J10,J9) -> 0.14 | ... R15: =IF(R9="",原始数据!R10,R9) -> 0.405
A16: 新增借款 | C16: =IF(C10="",原始数据!C11,C10) -> 0 | D16: =IF(D10="",原始数据!D11,D10) -> 0 | E16: =IF(E10="",原始数据!E11,E10) -> 2 | F16: =IF(F10="",原始数据!F11,F10) -> 2 | G16: =IF(G10="",原始数据!G11,G10) -> 3.5 | H16: =IF(H10="",原始数据!H11,H10) -> 1.5 | I16: =IF(I10="",原始数据!I11,I10) -> 0 | J16: =IF(J10="",原始数据!J11,J10) -> 0.5 | ... R16: =IF(R10="",原始数据!R11,R10) -> 0
A17: 产能、产量与成本
A18: 产能（千片/季） 〔300+已投产扩产〕 | B18: =资产负债表!B19 -> 300 | C18: =$B$18 -> 300 | D18: =$B$18 -> 300 | E18: =$B$18 -> 300 | F18: =$B$18 -> 300 | G18: =$B$18+(SUM($C$14:C14)-MAINT*1)/CAP_COST -> 300 | H18: =$B$18+(SUM($C$14:D14)-MAINT*2)/CAP_COST -> 300 | I18: =$B$18+(SUM($C$14:E14)-MAINT*3)/CAP_COST -> 300 | J18: =$B$18+(SUM($C$14:F14)-MAINT*4)/CAP_COST -> 300 | K18: =$B$18+(SUM($C$14:G14)-MAINT*5)/CAP_COST -> 325 | L18: =$B$18+(SUM($C$14:H14)-MAINT*6)/CAP_COST -> 345 | M18: =$B$18+(SUM($C$14:I14)-MAINT*7)/CAP_COST -> 360 | N18: =$B$18+(SUM($C$14:J14)-MAINT*8)/CAP_COST -> 395 | O18: =$B$18+(SUM($C$14:K14)-MAINT*9)/CAP_COST -> 435 | P18: =$B$18+(SUM($C$14:L14)-MAINT*10)/CAP_COST -> 465 | Q18: =$B$18+(SUM($C$14:M14)-MAINT*11)/CAP_COST -> 465 | R18: =$B$18+(SUM($C$14:N14)-MAINT*12)/CAP_COST -> 465
A19: 折旧 〔基础+已投产资本开支÷折旧期〕 | C19: =DEP_BASE -> 2 | D19: =DEP_BASE -> 2 | E19: =DEP_BASE -> 2 | F19: =DEP_BASE -> 2 | G19: =DEP_BASE+SUM($C$14:C14)/DEP_LIFE -> 2.075 | H19: =DEP_BASE+SUM($C$14:D14)/DEP_LIFE -> 2.15 | I19: =DEP_BASE+SUM($C$14:E14)/DEP_LIFE -> 2.225 | J19: =DEP_BASE+SUM($C$14:F14)/DEP_LIFE -> 2.3 | K19: =DEP_BASE+SUM($C$14:G14)/DEP_LIFE -> 2.525 | L19: =DEP_BASE+SUM($C$14:H14)/DEP_LIFE -> 2.72 | M19: =DEP_BASE+SUM($C$14:I14)/DEP_LIFE -> 2.885 | N19: =DEP_BASE+SUM($C$14:J14)/DEP_LIFE -> 3.17 | ... R19: =DEP_BASE+SUM($C$14:N14)/DEP_LIFE -> 3.89
A20: 产量（千片） 〔产能×开工率〕 | C20: =C18*C12 -> 255 | D20: =D18*D12 -> 300 | E20: =E18*E12 -> 300 | F20: =F18*F12 -> 300 | G20: =G18*G12 -> 300 | H20: =H18*H12 -> 300 | I20: =I18*I12 -> 300 | J20: =J18*J12 -> 300 | ... R20: =R18*R12 -> 465
A21: HBM 量产资格 〔取实际〕 | C21: =原始数据!C24 -> 0 | D21: =原始数据!D24 -> 0 | E21: =原始数据!E24 -> 0 | F21: =原始数据!F24 -> 1 | G21: =原始数据!G24 -> 1 | H21: =原始数据!H24 -> 1 | I21: =原始数据!I24 -> 1 | J21: =原始数据!J24 -> 1 | ... R21: =原始数据!R24 -> 1
A22: HBM 产量（千片） 〔产量×HBM占比×资格〕 | C22: =C20*C15*C21 -> 0 | D22: =D20*D15*D21 -> 0 | E22: =E20*E15*E21 -> 0 | F22: =F20*F15*F21 -> 12 | G22: =G20*G15*G21 -> 15 | H22: =H20*H15*H21 -> 21 | I22: =I20*I15*I21 -> 33 | J22: =J20*J15*J21 -> 42 | ... R22: =R20*R15*R21 -> 188.325
A23: 普通内存产量（千片） 〔产量−HBM〕 | C23: =C20-C22 -> 255 | D23: =D20-D22 -> 300 | E23: =E20-E22 -> 300 | F23: =F20-F22 -> 288 | G23: =G20-G22 -> 285 | H23: =H20-H22 -> 279 | I23: =I20-I22 -> 267 | J23: =J20-J22 -> 258 | ... R23: =R20-R22 -> 276.675
A24: 单位成本（十亿美元/千片） 〔(折旧+工厂费用+变动成本×产量)÷产量〕 | C24: =(C19+PLANT_FIXED+V_COST*C20)/C20 -> 0.016764706 | D24: =(D19+PLANT_FIXED+V_COST*D20)/D20 -> 0.015 | E24: =(E19+PLANT_FIXED+V_COST*E20)/E20 -> 0.015 | F24: =(F19+PLANT_FIXED+V_COST*F20)/F20 -> 0.015 | G24: =(G19+PLANT_FIXED+V_COST*G20)/G20 -> 0.01525 | H24: =(H19+PLANT_FIXED+V_COST*H20)/H20 -> 0.0155 | I24: =(I19+PLANT_FIXED+V_COST*I20)/I20 -> 0.01575 | J24: =(J19+PLANT_FIXED+V_COST*J20)/J20 -> 0.016 | ... R24: =(R19+PLANT_FIXED+V_COST*R20)/R20 -> 0.015516129
A25: 存货与销售
A26: 期初库存（千片） | C26: =B33 -> 60 | D26: =C33 -> 75 | E26: =D33 -> 165 | F26: =E33 -> 260 | G26: =F33 -> 333 | H26: =G33 -> 383 | I26: =H33 -> 402 | J26: =I33 -> 384 | ... R26: =Q33 -> 0
A27: 期初存货金额 | C27: =B36 -> 0.96 | D27: =C36 -> 1.2464286 | E27: =D36 -> 2.10672 | F27: =E36 -> 2.964 | G27: =F36 -> 4.023972 | H27: =G36 -> 5.1873706 | I27: =H36 -> 5.7760906 | J27: =I36 -> 5.7292 | ... R27: =Q36 -> 0
A28: 可售片数 〔期初+普通产量〕 | C28: =C26+C23 -> 315 | D28: =D26+D23 -> 375 | E28: =E26+E23 -> 465 | F28: =F26+F23 -> 548 | G28: =G26+G23 -> 618 | H28: =H26+H23 -> 662 | I28: =I26+I23 -> 669 | J28: =J26+J23 -> 642 | ... R28: =R26+R23 -> 276.675
A29: 可售成本池 〔期初金额+普通产量×单位成本〕 | C29: =C27+C23*C24 -> 5.235 | D29: =D27+D23*D24 -> 5.7464286 | E29: =E27+E23*E24 -> 6.60672 | F29: =F27+F23*F24 -> 7.284 | G29: =G27+G23*G24 -> 8.370222 | H29: =H27+H23*H24 -> 9.5118706 | I29: =I27+I23*I24 -> 9.9813406 | J29: =J27+J23*J24 -> 9.8572 | ... R29: =R27+R23*R24 -> 4.292925
A30: 加权平均成本（十亿美元/千片） | C30: =IF(C28>0,C29/C28,0) -> 0.016619048 | D30: =IF(D28>0,D29/D28,0) -> 0.01532381 | E30: =IF(E28>0,E29/E28,0) -> 0.014208 | F30: =IF(F28>0,F29/F28,0) -> 0.013291971 | G30: =IF(G28>0,G29/G28,0) -> 0.013544049 | H30: =IF(H28>0,H29/H28,0) -> 0.014368385 | I30: =IF(I28>0,I29/I28,0) -> 0.014919792 | J30: =IF(J28>0,J29/J28,0) -> 0.015353894 | ... R30: =IF(R28>0,R29/R28,0) -> 0.015516129
A31: 普通内存销量（千片） 〔MIN(出货比例×可售,需求)〕 | C31: =MIN(C13*C28,原始数据!C15) -> 240 | D31: =MIN(D13*D28,原始数据!D15) -> 210 | E31: =MIN(E13*E28,原始数据!E15) -> 205 | F31: =MIN(F13*F28,原始数据!F15) -> 215 | G31: =MIN(G13*G28,原始数据!G15) -> 235 | H31: =MIN(H13*H28,原始数据!H15) -> 260 | I31: =MIN(I13*I28,原始数据!I15) -> 285 | J31: =MIN(J13*J28,原始数据!J15) -> 305 | ... R31: =MIN(R13*R28,原始数据!R15) -> 276.675
A32: HBM 销量（千片） 〔MIN(HBM产量,HBM需求)〕 | C32: =MIN(C22,原始数据!C16) -> 0 | D32: =MIN(D22,原始数据!D16) -> 0 | E32: =MIN(E22,原始数据!E16) -> 0 | F32: =MIN(F22,原始数据!F16) -> 8 | G32: =MIN(G22,原始数据!G16) -> 12 | H32: =MIN(H22,原始数据!H16) -> 18 | I32: =MIN(I22,原始数据!I16) -> 26 | J32: =MIN(J22,原始数据!J16) -> 36 | ... R32: =MIN(R22,原始数据!R16) -> 185
A33: 期末库存（千片） | B33: =资产负债表!B17 -> 60 | C33: =C28-C31 -> 75 | D33: =D28-D31 -> 165 | E33: =E28-E31 -> 260 | F33: =F28-F31 -> 333 | G33: =G28-G31 -> 383 | H33: =H28-H31 -> 402 | I33: =I28-I31 -> 384 | J33: =J28-J31 -> 337 | ... R33: =R28-R31 -> 0
A34: 可变现净值（十亿美元/千片） 〔(1−销售费用率)×价格〕 | C34: =(1-SELL_COST)*原始数据!C13*PRICE_SCEN*P_BASE -> 0.01824 | D34: =(1-SELL_COST)*原始数据!D13*PRICE_SCEN*P_BASE -> 0.012768 | E34: =(1-SELL_COST)*原始数据!E13*PRICE_SCEN*P_BASE -> 0.0114 | F34: =(1-SELL_COST)*原始数据!F13*PRICE_SCEN*P_BASE -> 0.012084 | G34: =(1-SELL_COST)*原始数据!G13*PRICE_SCEN*P_BASE -> 0.01368 | H34: =(1-SELL_COST)*原始数据!H13*PRICE_SCEN*P_BASE -> 0.016416 | I34: =(1-SELL_COST)*原始数据!I13*PRICE_SCEN*P_BASE -> 0.018924 | J34: =(1-SELL_COST)*原始数据!J13*PRICE_SCEN*P_BASE -> 0.020976 | ... R34: =(1-SELL_COST)*原始数据!R13*PRICE_SCEN*P_BASE -> 0.10374
A35: 存货跌价 〔MAX(0,期末片×(平均成本−净值))〕 | C35: =IF(C33>0.000001,MAX(0,C33*(C30-C34)),0) -> 0 | D35: =IF(D33>0.000001,MAX(0,D33*(D30-D34)),0) -> 0.42170857 | E35: =IF(E33>0.000001,MAX(0,E33*(E30-E34)),0) -> 0.73008 | F35: =IF(F33>0.000001,MAX(0,F33*(F30-F34)),0) -> 0.40225428 | G35: =IF(G33>0.000001,MAX(0,G33*(G30-G34)),0) -> 0 | H35: =IF(H33>0.000001,MAX(0,H33*(H30-H34)),0) -> 0 | I35: =IF(I33>0.000001,MAX(0,I33*(I30-I34)),0) -> 0 | J35: =IF(J33>0.000001,MAX(0,J33*(J30-J34)),0) -> 0 | ... R35: =IF(R33>0.000001,MAX(0,R33*(R30-R34)),0) -> 0
A36: 期末存货金额 | B36: =资产负债表!B6 -> 0.96 | C36: =C33*C30-C35 -> 1.2464286 | D36: =D33*D30-D35 -> 2.10672 | E36: =E33*E30-E35 -> 2.964 | F36: =F33*F30-F35 -> 4.023972 | G36: =G33*G30-G35 -> 5.1873706 | H36: =H33*H30-H35 -> 5.7760906 | I36: =I33*I30-I35 -> 5.7292 | J36: =J33*J30-J35 -> 5.1742623 | ... R36: =R33*R30-R35 -> 0
A37: 利润
A38: 营业收入 | C38: =C31*原始数据!C13*PRICE_SCEN*P_BASE+C32*原始数据!C14*HBM_PRICE_SCEN*P_BASE -> 4.608 | D38: =D31*原始数据!D13*PRICE_SCEN*P_BASE+D32*原始数据!D14*HBM_PRICE_SCEN*P_BASE -> 2.8224 | E38: =E31*原始数据!E13*PRICE_SCEN*P_BASE+E32*原始数据!E14*HBM_PRICE_SCEN*P_BASE -> 2.46 | F38: =F31*原始数据!F13*PRICE_SCEN*P_BASE+F32*原始数据!F14*HBM_PRICE_SCEN*P_BASE -> 3.0036 | G38: =G31*原始数据!G13*PRICE_SCEN*P_BASE+G32*原始数据!G14*HBM_PRICE_SCEN*P_BASE -> 3.8448 | H38: =H31*原始数据!H13*PRICE_SCEN*P_BASE+H32*原始数据!H14*HBM_PRICE_SCEN*P_BASE -> 5.3136 | I38: =I31*原始数据!I13*PRICE_SCEN*P_BASE+I32*原始数据!I14*HBM_PRICE_SCEN*P_BASE -> 7.1124 | J38: =J31*原始数据!J13*PRICE_SCEN*P_BASE+J32*原始数据!J14*HBM_PRICE_SCEN*P_BASE -> 9.1536 | ... R38: =R31*原始数据!R13*PRICE_SCEN*P_BASE+R32*原始数据!R14*HBM_PRICE_SCEN*P_BASE -> 72.83691
A39: 营业成本（含跌价） | C39: =C31*C30+C22*C24+C35 -> 3.9885714 | D39: =D31*D30+D22*D24+D35 -> 3.6397086 | E39: =E31*E30+E22*E24+E35 -> 3.64272 | F39: =F31*F30+F22*F24+F35 -> 3.440028 | G39: =G31*G30+G22*G24+G35 -> 3.4116014 | H39: =H31*H30+H22*H24+H35 -> 4.06128 | I39: =I31*I30+I22*I24+I35 -> 4.7718906 | J39: =J31*J30+J22*J24+J35 -> 5.3549377 | ... R39: =R31*R30+R22*R24+R35 -> 7.215
A40: 研发费用 〔固定+HBM研发〕 | C40: =RND_BASE+原始数据!C9 -> 3.8 | D40: =RND_BASE+原始数据!D9 -> 0.8 | E40: =RND_BASE+原始数据!E9 -> 0.8 | F40: =RND_BASE+原始数据!F9 -> 0.8 | G40: =RND_BASE+原始数据!G9 -> 0.8 | H40: =RND_BASE+原始数据!H9 -> 0.8 | I40: =RND_BASE+原始数据!I9 -> 0.8 | J40: =RND_BASE+原始数据!J9 -> 0.8 | ... R40: =RND_BASE+原始数据!R9 -> 0.8
A41: 营业利润 | C41: =C38-C39-C40-SGA_Q -> -3.4305714 | D41: =D38-D39-D40-SGA_Q -> -1.8673086 | E41: =E38-E39-E40-SGA_Q -> -2.23272 | F41: =F38-F39-F40-SGA_Q -> -1.486428 | G41: =G38-G39-G40-SGA_Q -> -0.61680141 | H41: =H38-H39-H40-SGA_Q -> 0.20232001 | I41: =I38-I39-I40-SGA_Q -> 1.2905094 | J41: =J38-J39-J40-SGA_Q -> 2.7486623 | ... R41: =R38-R39-R40-SGA_Q -> 64.57191
...

Sheet 决策备注
A1: 每季决策与备注原文
A2: 来源：export_final.json → history[i].decision；数字为输入格（原样）。
A4: 季度 | B4: 开工率 | C4: 出货比例 | D4: 资本开支 | E4: HBM研发 | F4: HBM占比 | G4: 借款 | H4: 提交给引擎的备注原文
A5: Q1 | B5: 0.85 | C5: 1 | D5: 1.5 | E5: 3 | F5: 0 | G5: 0 | H5: Q1：景气刚过顶，一致预期本季合约价跌15%-25%，客户下单谨慎。判断：下行周期刚开始，库存越早卖越好，价格大概率还会继续走低。决定：开工率降到85%，避免在需求转弱时堆库存；可售库存全部挂出去卖（60千片期初库存+本季产出）；资本开支只做15亿美元维持，不扩产，等看清单位成本和需求再说；HBM研发一次投满30亿美元，抢在AI需求起来前拿到量产资格（最早约第3-4季可量产）；不新增借款，现金100亿美元足够覆盖研发和维持开支。
A6: Q2 | B6: 1 | C6: 1 | D6: 1.5 | E6: 0 | F6: 0 | G6: 0 | H6: Q2：Q1价格指数0.80（每千片1920万美元），需求只有240千片，我们挂了315千片，剩75千片库存。反推成本：每季固定成本约30亿美元（折旧20亿+工厂费用约10亿，假设），每千片变动成本约500万美元（假设，本季用不同开工率验证）。判断：售价远高于变动成本，少开工只省500万/千片的现金，却把固定成本摊到更少的片子上；多出来的片子可以留到复苏时卖，HBM量产后普通内存产能还会被挤占。决定：开工率提到100%，可售库存全部挂出；资本开支维持15亿；HBM研发已满30亿，第4季起可量产；本季不借款，预计季末现金约45-50亿美元。一致预期下季再跌20%-30%，同业削减资本开支，扩产等下季看清需求再定。
A7: Q3 | B7: 1 | C7: 1 | D7: 1.5 | E7: 0 | F7: 0 | G7: 2 | H7: Q3：Q2价格指数0.56（每千片1344万美元），需求降到210千片，库存升到165千片并按可变现净值减记4.2亿美元。验证了成本结构：满开工单位成本1500万美元/千片=固定30亿/300千片+变动500万。一致预期下季只再跌5%-15%，新闻说价格跌破多数厂商现金成本、同业开始减产——跌幅收窄、供给收缩，底部临近。判断：继续满开工，每多产1千片只花500万现金，按减记后的价值入账还高于现金成本，库存留给复苏和HBM挤占产能后的缺口；扩产先不做，下行期每季烧现金约27亿美元，借款上限随权益下降，流动性优先；借20亿美元保持现金缓冲，避免触发3%的紧急授信。
A8: Q4 | B8: 1 | C8: 1 | D8: 1.5 | E8: 0 | F8: 0.04 | G8: 2 | H8: Q4：Q3价格指数0.50（每千片1200万美元），需求205千片，库存260千片、账面按可变现净值每千片1140万美元。一致预期下季持平到小幅上涨，两家同业减产超20%，跌幅收窄——判断这里就是底部区域。HBM本季起可量产，但HBM需求只有5-6千片、价格指数从1.6滑到1.3，先小量试产：划4%产能（约12千片），宁可略多、多出的片子成本只有变动成本。普通内存继续满开工，库存已够1.3个季度销量，边际一片更可能很久以后才卖得掉，所以本季仍按需求全部出货、不惜售。扩产暂缓：每季仍在烧现金约24亿美元，借款上限随权益下降到约164亿美元，等复苏信号和HBM需求更明确再投。借20亿美元维持约35亿美元现金缓冲。
A9: Q5 | B9: 1 | C9: 1 | D9: 4.5 | E9: 0 | F9: 0.05 | G9: 3.5 | H9: Q5：Q4价格指数0.53，需求回升到215千片；HBM首季量产，需求8千片、每千片售价3360万美元（=2400万×HBM价格指数1.4），产12卖8。新闻：渠道开始补库、客户愿签长约、云厂商测试新一代AI服务器；一致预期下季涨5%-10%。判断：普通内存已过底，AI服务器会在几个季度后拉动HBM需求；HBM每千片毛利远高于普通内存，产能将成为瓶颈。决定：在底部做逆周期扩产，资本开支45亿美元（维持15亿+扩产30亿，约增加25千片/季，第9季投产）；HBM划5%产能（约15千片），按报童模型宁多勿少；普通内存满开工、按需求全部出货，现金优先给扩产；借35亿美元，预计季末现金约25亿、负债135亿，低于约148亿的上限。
A10: Q6 | B10: 1 | C10: 1 | D10: 3.9 | E10: 0 | F10: 0.07 | G10: 1.5 | H10: Q6：Q5价格指数0.60，需求235千片；HBM价格指数回到1.6（每千片3840万美元），需求12千片，连续加速（5→5→6→8→12）。新闻：合约价连续回升、同业开工率回到八成、AI加速卡订单传闻增多；一致预期下季涨10%-20%。本季首次毛利转正，存货不再减记。判断：复苏确认，HBM需求进入加速期，未来瓶颈在产能而不是需求；普通内存库存383千片足够应付复苏初期的缺口。决定：继续逆周期扩产，资本开支39亿美元（扩产24亿，约20千片/季，第10季投产）；HBM划7%产能（约21千片），按报童模型取需求分布的六成分位；普通内存满开工、按需求出货；借15亿美元到150亿，几乎用满上限，预计季末现金约16亿美元，下季开始经营现金流转正。
A11: Q7 | B11: 1 | C11: 1 | D11: 3.3 | E11: 0 | F11: 0.11 | G11: 0 | H11: Q7：Q6价格指数0.72，需求260千片；HBM价格指数1.9（每千片4560万美元），需求18千片，每季约增长50%。本季净利润首次转正（0.2亿美元）。新闻：服务器内存需求转强，HBM认证名额紧张、只有少数厂商通过——我们已在第4季通过认证。一致预期下季涨10%-15%。判断：HBM需求会继续高速增长，几个季度后HBM会占用大量产能，普通内存反而会出现缺口，产能是最稀缺的资源。决定：继续扩产，资本开支33亿美元（扩产18亿，约15千片/季，第11季投产），这是在借款已到上限（150亿）情况下用经营现金能承受的最大规模；HBM划11%产能（约33千片），按需求约27-30千片、宁多勿少；普通内存满开工、按需求全部出货，把现金留给扩产；本季不借款。
A12: Q8 | B12: 1 | C12: 1 | D12: 5.7 | E12: 0 | F12: 0.14 | G12: 0.5 | H12: Q8：Q7价格指数0.83，需求285千片；HBM价格指数2.3（每千片5520万美元，是普通内存的2.8倍），需求26千片，仍以每季约45%的速度增长；本季净利润9.2亿美元。新闻：主要云厂商上调全年资本开支、AI服务器出货预期上修；一致预期下季涨约10%。判断：按目前增速，HBM需求到第12-13季可能超过200千片，碰到60%产能上限，普通内存同时会缺货，产能是最值钱的东西；每千片HBM产能投入1.2亿美元、每季可赚约5000万美元毛利，两三个季度回本。决定：加大扩产，资本开支57亿美元（扩产42亿，约35千片/季，第12季投产）；HBM划14%产能（约42千片），按报童模型取需求分布约七成分位；普通内存满开工、按需求出货，库存开始下降；借5亿美元用满上限。
A13: Q9 | B13: 1 | C13: 1 | D13: 6.3 | E13: 0 | F13: 0.17 | G13: 1.3 | H13: Q9：Q8价格指数0.92，需求305千片；HBM价格指数2.8（每千片6720万美元），需求36千片，本季HBM收入24亿美元；净利润21.6亿美元。新闻：普通内存涨势放缓，HBM供不应求、排产到明年；一致预期普通内存持平到小涨、HBM继续涨。判断：普通内存接近这一轮的顶部，库存337千片应在高价区尽量卖掉；HBM需求还会以每季约40%增长，第13季起产能会成为HBM和普通内存共同的瓶颈。本季下单的产能第13季投产，只剩4个季度可用，按每千片HBM毛利约6000万美元测算仍明显划算，但这是扩产的最后窗口，之后不再大规模扩产。决定：资本开支63亿美元（扩产48亿，约40千片/季）；HBM划17%产能（第9季产能325千片，约55千片）；普通内存满开工、按需求全部出货；借13亿美元，负债168亿，贴近上限。
A14: Q10 | B14: 1 | C14: 1 | D14: 5.1 | E14: 0 | F14: 0.2 | G14: -2 | H14: Q10：Q9普通内存价格指数1.00、需求320千片；HBM价格指数3.4（每千片8160万美元），需求48千片，HBM收入39亿美元；净利润38亿美元，经营现金流70亿美元。从报表还看出：扩产投资在投产当季才开始折旧，工厂费用不随产能增加。新闻：消费电子平淡，普通内存短暂回调；HBM订单继续增加；一致预期普通内存小幅波动、HBM上涨。判断：普通内存到顶，不再为它扩产；HBM需求增量每季多2千片左右（6、8、10、12），按此推算第16季约190千片，现有在建产能基本够用，但若AI需求更快，第15-16季HBM会碰到60%上限。决定：最后一笔中等规模扩产36亿美元（约30千片，第14季投产）作为HBM上行情景的保险，资本开支合计51亿；HBM划20%产能（约69千片），HBM单片毛利远高于普通内存，按报童模型取高分位；普通内存满开工、按需求出货；经营现金充裕，先还20亿美元借款。
A15: Q11 | B15: 1 | C15: 1 | D15: 1.5 | E15: 0 | F15: 0.235 | G15: -10 | H15: Q11：Q10普通内存价格指数0.97、需求320千片；HBM价格指数4.0（每千片9600万美元），需求60千片，HBM收入58亿美元，已占营收44%；净利润50亿美元，经营现金流83亿美元。新闻：新一代AI芯片发布带动服务器内存需求，同业扩产谨慎、新产能一年后才出来；一致预期下季涨5%-15%。判断：未来3-4个季度供给偏紧、价格向上，但同业新产能约在第14-15季释放，届时普通内存可能转弱。按在建产能推算（第14季起465千片），HBM需求和普通内存需求基本都能满足，库存还剩约170-240千片缓冲；现在下单的产能第15季才投产，只能用2个季度，不再扩产，资本开支只做15亿维持。决定：HBM划23.5%产能（约85千片），按需求约75千片取高分位；普通内存满开工、按需求出货；经营现金充裕，还款100亿美元，借款降到48亿，省利息，需要时仍可在上限内再借。
A16: Q12 | B16: 1 | C16: 1 | D16: 1.5 | E16: 0 | F16: 0.245 | G16: -4.8 | H16: Q12：Q11普通内存价格指数1.06、需求升到340千片；HBM价格指数4.6（每千片1.1亿美元），需求74千片；净利润76亿美元，股东权益444亿美元。新闻：多家云厂商再次上调资本开支，市场担心明年内存缺货；一致预期下季涨15%-25%。判断：景气进入加速段，库存178千片按当前节奏约在第14-15季卖完，之后普通内存会供不应求。但现在下单的产能要第16季才投产，正好撞上同业一年后释放的新产能，这是周期顶部扩产的老坑，坚持不在顶部扩产。决定：资本开支只做15亿维持；HBM划24.5%产能（第12季产能395千片，约97千片），需求约90千片，普通内存将来也缺货，所以多产HBM的机会成本上升，分位数比上季略低；普通内存满开工、按需求出货；经营现金预计约160亿美元，全部还清48亿美元正常借款。
... A20: Q16 | B20: 1 | C20: 1 | D20: 1.5 | E20: 0 | F20: 0.405 | G20: 0 | H20: Q16（最后一季）：Q15普通内存价格指数3.90（每千片9360万美元），需求480千片，我们供298千片；HBM价格指数8.8（每千片2.11亿美元），需求160千片；单季净利润460亿美元，股东权益1569亿美元，现金1237亿美元、无借款。新闻：涨幅开始收窄、客户抱怨价格、新产能陆续投产的消息增多；一致预期下季涨10%-20%，明年可能转平。判断：这是周期见顶前的最后一季，需求仍大于我们的供给。最后一季的原则：不留库存（期末库存只按成本入账），不为16季以后加杠杆或扩产。决定：开工率100%，普通内存全部出货；HBM需求近四季每季增长约20%，推算约185-190千片，普通内存每千片约1.06亿美元的机会成本和HBM每千片约2.3亿美元售价接近对半，按中位数划40.5%产能（约188千片）；资本开支15亿只做维持，保证公司交接时产能完好；不借款。
