Workbook
Name A_h2: '假设与参数'!$B$7
Name A_rate: '假设与参数'!$B$8
Name A_tax: '假设与参数'!$B$9
Name P_conv: '假设与参数'!$B$6
Name P_mincash: '假设与参数'!$B$10

Sheet 说明
B1: 伯克希尔账本（2021 — 2026 上半年）
B2: 巴菲特交班之后，伯克希尔的账 —— 研究用数据底稿与变化分析。编制日期 2026-10-22；数据截至 2026-06-30（另含 2026-08-08 业绩公告）。
B4: 用途 | C4: 把 2021—2025 年及 2026 年上半年伯克希尔·哈撒韦的分部利润、浮存金、现金与短期国债、股票组合、回购、每股账面价值放在一张可追溯、可联动的表里，供研究与教学展示。
B5: 重要声明 | C5: 仅为研究和展示用的分析，不构成投资建议；不给出买入、卖出、持有或目标价，也不评价股价高低。
B6: 单位 | C6: 除特别注明外，金额为百万美元（USD m）；每股数据为美元；股数为股。
B7: 颜色约定 | C7: 蓝底蓝字 = 披露数据（手工录入，单元格批注写明文件、章节、页码与原文锚点）；黄底 = 假设（可改）；白底 = 公式；橙底斜体 = 受假设影响的公式结果；绿底 = 核对。
B8: 联动方式 | C8: 所有汇总、比率、同比、占比、每股数均为公式；“假设与参数”表中的名称（P_conv、A_h2、A_rate、A_tax、P_mincash）被各表公式引用，改一个数，相关结果与图表自动更新。
B9: 口径要点 | C9: ① 分部利润采用 2025 年年报 MD&A 的税后利润分解（保险承保、保险投资收益、BNSF、BHE、制造服务零售、其他）；② 2021–2022 年取自 2023 年年报（LDTI 追溯调整后），“其他”= 非控股企业 + 其他；③ 经营利润 = 净利润 − 投资收益 − 权益法投资减值；④ 现金及国债的“保险及其他（净额）”口径与公司 MD&A 一致。
B10: 出处 | C10: 见“出处索引”表。材料内文件以代码 S01–S03、L2021–L2025 表示；联网补充的 2021–2022 年数据来自伯克希尔官网年度报告 PDF（W01、W02，访问日期 2026-10-22）。
B11: 自检 | C11: “核对”表汇总了 8 类勾稽关系（净利润、经营利润、组合合计、股数等）以及网页数字一致性检查，全部应显示 TRUE。
B13: 工作表目录
B14: 假设与参数 | C14: 可修改的假设与披露参数
B15: 分部利润 | C15: 六大板块税后利润、经营利润、净利润及核对；“其他”拆分
B16: 业务明细 | C16: 保险承保（GEICO/Primary/再保险）、GEICO 成本率、BNSF 运营比率、BHE 构成、制造服务零售
B17: 浮存金与现金 | C17: 浮存金、现金与短期国债、总资产、浮存金成本
B18: 现金流节选 | C18: 经营现金流、股票买卖、收购、资本开支
B19: 股票组合 | C19: 按行业成本/公允价值、集中度、主要持仓
B20: 回购与每股账面 | C20: 股东权益、A/B 股数、每股账面价值、回购金额与均价
B21: 变化 | C21: 同比、占比、结构与 7 张图表（分析页）
B22: 网页数字对照 | C22: 小游戏与备忘录中引用的数字与本表逐项对照
B23: 出处索引 | C23: 文件代码与网址
B24: 核对 | C24: 勾稽关系汇总
B26: 颜色图例
B27: 披露数据 | C27: 来自年报/季报/公告/股东信的原始数字；单元格批注写明出处
B28: 假设输入 | C28: 可修改的假设（“假设与参数”表及少量标注单元格）
B29: 公式 | C29: 由公式计算，不手填
B30: 受假设影响 | C30: 公式结果，但会随假设改变
B31: 核对 | C31: 勾稽检查，应为 0 或 TRUE

Sheet 假设与参数
A1: 假设与参数（改这里，相关结果自动联动）
A2: 黄色 = 假设（可改）；蓝色 = 披露的参数（事实，通常不改）。所有引用均通过名称（如 P_conv、A_rate）进入公式。
A3: 图例： | B3: 披露数据 | C3: 假设输入 | D3: 公式 | E3: 受假设影响 | F3: 核对
A5: 名称 | B5: 数值 | C5: 类型 | D5: 说明 / 出处
A6: 1 股 A 类股可转换的 B 类股数量 | B6: 1500 | C6: 参数 | D6: 披露事实：每股 A 类股可转换为 1,500 股 B 类股（10-K 附注 22 Common stock）
A7: 2026 下半年经营利润 = 上半年 × 系数 | B7: 1 | C7: 假设 | D7: 仅用于“2026 全年化（示意）”列；1.0 表示假设下半年与上半年持平。不是预测。
A8: 短期利率变动（百分点，负数=下降） | B8: -1 | C8: 假设 | D8: 用于估算现金及国债利息收入对利率的敏感度；示意性情景，不是预测。
A9: 利息收入适用税率 | B9: 0.21 | C9: 假设 | D9: 按美国联邦法定公司税率 21% 简化估算，未考虑州税等因素。
A10: 公司承诺的最低现金及国债持有量（百万美元） | B10: 30000 | C10: 参数 | D10: 披露事实：回购不得使现金、现金等价物及国债低于 300 亿美元（10-K Item 5）
A12: 其他口径说明与假设（文字）
A13: 1. 2021–2023 年末资产负债表未单列“待付国债购买款”，按 0 处理（假设）。
A14: 2. 2021 年末伯克希尔股东权益采用 2023 年年报中按 LDTI（长期保险合同会计准则 ASU 2018-12）追溯调整后的数字；原始披露为 5,061.99 亿美元，另列对照。
A15: 3. 浮存金为公司以“约 X 十亿美元”披露的约数；浮存金成本 = −税前承保利润 ÷ 平均浮存金（期初期末平均，方法假设）。
A16: 4. 回购均价 ÷ 期末每股账面价值，仅为近似的“回购市净率”，用期末每股账面价值代替回购当时的数值（近似假设）。
A17: 5. “前五大持仓合计金额” = 披露的占比（四舍五入到整数百分比）× 股票投资公允价值，属于推算的近似值。
A18: 6. 2026 全年化列 = 上半年 × (1 + 系数)，系数为假设，仅作示意，不构成预测。

Sheet 分部利润
A1: 各业务板块税后利润（归属伯克希尔股东，百万美元）
A2: 口径：2025 年年报（10-K）MD&A 的税后利润分解。2021–2022 年取自 2023 年年报（已按 LDTI 追溯调整），其“其他”由两行合并；Pilot 自 2023 年起并表，计入制造服务零售。
A3: 图例： | B3: 披露数据 | C3: 假设输入 | D3: 公式 | E3: 受假设影响 | F3: 核对
A5: 项目 | B5: 2021 年 | C5: 2022 年 | D5: 2023 年 | E5: 2024 年 | F5: 2025 年 | G5: 2025 上半年 | H5: 2026 上半年 | I5: 2026 全年化（示意·受假设影响） | J5: 出处（文件代码 + 页码；单元格批注有完整出处）
A6: 保险承保（Insurance–underwriting） | B6: 870 | C6: -30 | D6: 5428 | E6: 9020 | F6: 7258 | G6: 3328 | H6: 3448 | I6: =H6*(1+A_h2) -> 6896 | J6: 2021–2022：W01 PDF 第59页（页脚 K-35）；2023–2025：S01 p.K-34；2025H1–2026H1：S02 p.33
A7: 保险投资收益（Insurance–investment income） | B7: 4807 | C7: 6484 | D7: 9567 | E7: 13670 | F7: 12513 | G7: 6260 | H7: 5738 | I7: =H7*(1+A_h2) -> 11476 | J7: 2021–2022：W01 PDF 第59页（页脚 K-35）；2023–2025：S01 p.K-34；2025H1–2026H1：S02 p.33
A8: 铁路 BNSF | B8: 5990 | C8: 5946 | D8: 5087 | E8: 5031 | F8: 5476 | G8: 2680 | H8: 2935 | I8: =H8*(1+A_h2) -> 5870 | J8: 2021–2022：W01 PDF 第59页（页脚 K-35）；2023–2025：S01 p.K-34；2025H1–2026H1：S02 p.33
A9: 能源 BHE（伯克希尔哈撒韦能源） | B9: 3572 | C9: 3904 | D9: 2331 | E9: 3730 | F9: 3979 | G9: 1799 | H9: 2005 | I9: =H9*(1+A_h2) -> 4010 | J9: 2021–2022：W01 PDF 第59页（页脚 K-35）；2023–2025：S01 p.K-34；2025H1–2026H1：S02 p.33
A10: 制造、服务与零售（MSR，2023 起含 Pilot） | B10: 11120 | C10: 12512 | D10: 13362 | E10: 13072 | F10: 13647 | G10: 6661 | H10: 7669 | I10: =H10*(1+A_h2) -> 15338 | J10: 2021–2022：W01 PDF 第59页（页脚 K-35）；2023–2025：S01 p.K-34；2025H1–2026H1：S02 p.33
A11: 其他（含权益法投资收益、公司层面投资收益、汇兑等） | B11: =B23+B24 -> 1238 | C11: =C23+C24 -> 2037 | D11: 1575 | E11: 2914 | F11: 1613 | G11: 73 | H11: 2534 | I11: =H11*(1+A_h2) -> 5068 | J11: 2021–2022：= 下方附表两行之和（公式）；2023–2025：S01 p.K-34；2025H1–2026H1：S02 p.33
A12: 经营利润（Operating earnings）= 以上合计 | B12: =SUM(B6:B11) -> 27597 | C12: =SUM(C6:C11) -> 30853 | D12: =SUM(D6:D11) -> 37350 | E12: =SUM(E6:E11) -> 47437 | F12: =SUM(F6:F11) -> 44486 | G12: =SUM(G6:G11) -> 20801 | H12: =SUM(H6:H11) -> 24329 | I12: =H12*(1+A_h2) -> 48658 | J12: 公式：六个板块加总
A13: 投资收益（亏损）（含未实现，波动大） | B13: 62340 | C13: -53612 | D13: 58873 | E13: 41558 | F13: 30737 | G13: -68 | H13: 11444 | J13: 2021–2022：W01 PDF 第59页（页脚 K-35）；2023–2025：S01 p.K-34；2025H1–2026H1：S02 p.33
A14: 权益法投资非暂时性减值（卡夫亨氏、西方石油） | B14: 0 | C14: 0 | D14: 0 | E14: 0 | F14: -8255 | G14: -3760 | H14: 0 | J14: 2021–2024：无此项；2025：S01 p.K-34；2025H1：S02 p.33；2026H1：无此项
A15: 归属伯克希尔股东净利润 = 经营利润 + 投资收益 + 减值 | B15: =B12+B13+B14 -> 89937 | C15: =C12+C13+C14 -> -22759 | D15: =D12+D13+D14 -> 96223 | E15: =E12+E13+E14 -> 88995 | F15: =F12+F13+F14 -> 66968 | G15: =G12+G13+G14 -> 16973 | H15: =H12+H13+H14 -> 35773 | J15: 公式
A16: 核对：公司披露的净利润 | B16: 89937 | C16: -22759 | D16: 96223 | E16: 88995 | F16: 66968 | G16: 16973 | H16: 35773 | J16: 2021–2022：W01 PDF 第59页（页脚 K-35）；2023–2025：S01 p.K-34；2025H1–2026H1：S02 p.4
A17: 核对差异（应为 0） | B17: =B15-B16 -> 0 | C17: =C15-C16 -> 0 | D17: =D15-D16 -> 0 | E17: =E15-E16 -> 0 | F17: =F15-F16 -> 0 | G17: =G15-G16 -> 0 | H17: =H15-H16 -> 0
A18: 核对：公司披露的经营利润（股东信/业绩公告） | B18: 见下行 | C18: 30853 | D18: 37350 | E18: 47437 | F18: 见下行 | G18: 20801 | H18: 24329 | J18: 2022：L2023 PDF 第10页（页脚 11）；2023–2024：L2024 PDF 第5页（页脚 5）；2025H1–2026H1：S03
A19: 核对：股东信文字披露的经营利润（十亿美元，约数） | B19: 27.6 | F19: 44.5 | J19: 2021：L2023 PDF 第3页（页脚 4）；2025：L2025 PDF 第8页（页脚 8）
A20: 核对差异（应为 0；约数按十亿美元一位小数比较） | B20: =ROUND(B12/1000,1)-B19 -> 0 | C20: =C12-C18 -> 0 | D20: =D12-D18 -> 0 | E20: =E12-E18 -> 0 | F20: =ROUND(F12/1000,1)-F19 -> 0 | G20: =G12-G18 -> 0 | H20: =H12-H18 -> 0
A21: 附表 A：2021–2022 年“其他”的构成（2023 年年报口径）
A22: 项目 | B22: 2021 年 | C22: 2022 年 | D22: 2023 年 | E22: 2024 年 | F22: 2025 年 | G22: 2025 上半年 | H22: 2026 上半年 | I22: 出处
A23: 非控股企业（权益法，如卡夫亨氏、西方石油、Pilot〔2022 年前〕） | B23: 804 | C23: 1528 | J23: 2021–2022：W01 PDF 第59页（页脚 K-35）
A24: 其他（公司层面投资收益、汇兑、收购会计费用等） | B24: 434 | C24: 509 | J24: 2021–2022：W01 PDF 第59页（页脚 K-35）
A26: 附表 B：2023 年起“其他”的构成（2025 年报 p.K-54 / 2026Q2 10-Q p.47）
A27: 项目 | B27: 2021 年 | C27: 2022 年 | D27: 2023 年 | E27: 2024 年 | F27: 2025 年 | G27: 2025 上半年 | H27: 2026 上半年 | I27: 出处
A28: 公司层面投资收益（主要为母公司持有的短期国债利息） | D28: 959 | E28: 1445 | F28: 3566 | G28: 1735 | H28: 1924 | J28: 2023–2025：S01 p.K-54；2025H1–2026H1：S02 p.47
A29: 非美元债务汇兑损益 | D29: 211 | E29: 1151 | F29: -642 | G29: -1590 | H29: 575 | J29: 2023–2025：S01 p.K-54；2025H1–2026H1：S02 p.47
A30: 商誉减值 | D30: 0 | E30: -399 | F30: -1555 | G30: 0 | H30: 0 | J30: 2023–2025：S01 p.K-54；2025H1–2026H1：无此项
A31: 权益法投资收益（卡夫亨氏、西方石油、Berkadia 等；不含减值） | D31: 1750 | E31: 1519 | F31: 900 | G31: 300 | H31: 366 | J31: 2023–2025：S01 p.K-54；2025H1–2026H1：S02 p.47
A32: 收购会计费用（无形资产摊销等） | D32: -693 | E32: -531 | F32: -528 | G32: -248 | H32: -227 | J32: 2023–2025：S01 p.K-54；2025H1–2026H1：S02 p.47
A33: 其余（公司管理费用、利息等） | D33: -652 | E33: -271 | F33: -128 | G33: -124 | H33: -104 | J33: 2023–2025：S01 p.K-54；2025H1–2026H1：S02 p.47
A34: 合计（公式） | D34: =SUM(D28:D33) -> 1575 | E34: =SUM(E28:E33) -> 2914 | F34: =SUM(F28:F33) -> 1613 | G34: =SUM(G28:G33) -> 73 | H34: =SUM(H28:H33) -> 2534
A35: 核对：与上表“其他”之差（应为 0） | D35: =D34-D11 -> 0 | E35: =E34-E11 -> 0 | F35: =F34-F11 -> 0 | G35: =G34-G11 -> 0 | H35: =H34-H11 -> 0
A37: 附表 C：投资收益合计（保险投资收益 + 公司层面投资收益，2023 起）
A38: 项目 | B38: 2021 年 | C38: 2022 年 | D38: 2023 年 | E38: 2024 年 | F38: 2025 年 | G38: 2025 上半年 | H38: 2026 上半年 | I38: 说明
A39: 保险投资收益 + 公司层面投资收益（公式） | D39: =D7+D28 -> 10526 | E39: =E7+E28 -> 15115 | F39: =F7+F28 -> 16079 | G39: =G7+G28 -> 7995 | H39: =H7+H28 -> 7662 | J39: 2024 年底保险子公司向母公司大额分配资本，部分利息收入从“保险投资收益”转入“其他”（10-K p.K-34、K-40），合并看更能反映全部投资收益变化。

Sheet 业务明细
A1: 保险、铁路、能源、制造服务零售：经营明细（百万美元）
A2: 保险承保与 BNSF 为税前口径；BHE 明细为“归属 BHE 的税后利润”；比率均为公式。
A3: 图例： | B3: 披露数据 | C3: 假设输入 | D3: 公式 | E3: 受假设影响 | F3: 核对
A5: 保险：税前承保利润（Pre-tax underwriting earnings）
A6: 项目 | B6: 2021 年 | C6: 2022 年 | D6: 2023 年 | E6: 2024 年 | F6: 2025 年 | G6: 2025 上半年 | H6: 2026 上半年 | I6: 出处（文件代码 + 页码；单元格批注有完整出处）
A7: GEICO 税前承保利润 | B7: 1259 | C7: -1880 | D7: 3635 | E7: 7813 | F7: 6824 | G7: 3994 | H7: 2410 | I7: 2021–2022：W01 PDF 第61页（页脚 K-37）；2023–2025：S01 p.K-35；2025H1–2026H1：S02 p.34
A8: BH Primary 税前承保利润 | B8: 607 | C8: 393 | D8: 1374 | E8: 855 | F8: 785 | G8: -81 | H8: 749 | I8: 2021–2022：W01 PDF 第61页（页脚 K-37）；2023–2025：S01 p.K-35；2025H1–2026H1：S02 p.34
A9: BHRG 再保险集团 税前承保利润 | B9: -755 | C9: 1465 | D9: 1904 | E9: 2737 | F9: 1851 | G9: 343 | H9: 1286 | I9: 2021–2022：W01 PDF 第61页（页脚 K-37）；2023–2025：S01 p.K-35；2025H1–2026H1：S02 p.34
A10: 税前承保利润合计（公式） | B10: =SUM(B7:B9) -> 1111 | C10: =SUM(C7:C9) -> -22 | D10: =SUM(D7:D9) -> 6913 | E10: =SUM(E7:E9) -> 11405 | F10: =SUM(F7:F9) -> 9460 | G10: =SUM(G7:G9) -> 4256 | H10: =SUM(H7:H9) -> 4445
A11: 核对：公司披露的税前承保利润合计 | B11: 1111 | C11: -22 | D11: 6913 | E11: 11405 | F11: 9460 | G11: 4256 | H11: 4445 | I11: 2021–2022：W01 PDF 第61页（页脚 K-37）；2023–2025：S01 p.K-35；2025H1–2026H1：S02 p.34
A12: 核对差异（应为 0） | B12: =B10-B11 -> 0 | C12: =C10-C11 -> 0 | D12: =D10-D11 -> 0 | E12: =E10-E11 -> 0 | F12: =F10-F11 -> 0 | G12: =G10-G11 -> 0 | H12: =H10-H11 -> 0
A14: GEICO：保费与成本率
A15: 项目 | B15: 2021 年 | C15: 2022 年 | D15: 2023 年 | E15: 2024 年 | F15: 2025 年 | G15: 2025 上半年 | H15: 2026 上半年 | I15: 出处（文件代码 + 页码；单元格批注有完整出处）
A16: GEICO 已赚保费 | B16: 37706 | C16: 38984 | D16: 39264 | E16: 42252 | F16: 44481 | G16: 21816 | H16: 22477 | I16: 2021–2022：W01 PDF 第61页（页脚 K-37）；2023–2025：S01 p.K-36；2025H1–2026H1：S02 p.34
A17: GEICO 赔付及理赔费用（Losses and LAE） | B17: 30999 | C17: 36297 | D17: 31814 | E17: 30331 | F17: 32144 | G17: 15369 | H17: 16921 | I17: 2021–2022：W01 PDF 第61页（页脚 K-37）；2023–2025：S01 p.K-36；2025H1–2026H1：S02 p.34
A18: GEICO 承保费用 | B18: 5448 | C18: 4567 | D18: 3815 | E18: 4108 | F18: 5513 | G18: 2453 | H18: 3146 | I18: 2021–2022：W01 PDF 第61页（页脚 K-37）；2023–2025：S01 p.K-36；2025H1–2026H1：S02 p.34
A19: 赔付率 = 赔付及理赔费用 ÷ 已赚保费 | B19: =B17/B16 -> 0.8221238 | C19: =C17/C16 -> 0.93107429 | D19: =D17/D16 -> 0.81025876 | E19: =E17/E16 -> 0.71785951 | F19: =F17/F16 -> 0.72264562 | G19: =G17/G16 -> 0.70448295 | H19: =H17/H16 -> 0.75281399
A20: 费用率 = 承保费用 ÷ 已赚保费 | B20: =B18/B16 -> 0.14448629 | C20: =C18/C16 -> 0.11715063 | D20: =D18/D16 -> 0.097162795 | E20: =E18/E16 -> 0.097226167 | F20: =F18/F16 -> 0.12394056 | G20: =G18/G16 -> 0.11244041 | H20: =H18/H16 -> 0.1399653
A21: 综合成本率 = 赔付率 + 费用率（<100% 即承保盈利） | B21: =B19+B20 -> 0.96661009 | C21: =C19+C20 -> 1.0482249 | D21: =D19+D20 -> 0.90742156 | E21: =E19+E20 -> 0.81508568 | F21: =F19+F20 -> 0.84658618 | G21: =G19+G20 -> 0.81692336 | H21: =H19+H20 -> 0.89277929
A23: BNSF 铁路：收入、费用与运营比率
A24: 项目 | B24: 2021 年 | C24: 2022 年 | D24: 2023 年 | E24: 2024 年 | F24: 2025 年 | G24: 2025 上半年 | H24: 2026 上半年 | I24: 出处（文件代码 + 页码；单元格批注有完整出处）
A25: 铁路营业收入 | B25: 22513 | C25: 25203 | D25: 23474 | E25: 23355 | F25: 23350 | G25: 11402 | H25: 12521 | I25: 2021–2022：W01 PDF 第67页（页脚 K-43）；2023–2025：S01 p.K-41；2025H1–2026H1：S02 p.39
A26: 铁路营业费用 | B26: 13702 | C26: 16600 | D26: 16059 | E26: 15886 | F26: 15295 | G26: 7568 | H26: 8203 | I26: 2021–2022：W01 PDF 第67页（页脚 K-43）；2023–2025：S01 p.K-41；2025H1–2026H1：S02 p.39
A27: 货运量（千车/箱） | B27: 10135 | C27: 9549 | D27: 9003 | E27: 9589 | F27: 9622 | G27: 4684 | H27: 4887 | I27: 2021–2022：W01 PDF 第67页（页脚 K-43）；2023–2025：S01 p.K-42；2025H1–2026H1：S02 p.39
A28: 铁路营业利润 = 收入 − 费用 | B28: =B25-B26 -> 8811 | C28: =C25-C26 -> 8603 | D28: =D25-D26 -> 7415 | E28: =E25-E26 -> 7469 | F28: =F25-F26 -> 8055 | G28: =G25-G26 -> 3834 | H28: =H25-H26 -> 4318
A29: 运营比率（Operating ratio）= 费用 ÷ 收入（越低越好） | B29: =B26/B25 -> 0.60862613 | C29: =C26/C25 -> 0.65865175 | D29: =D26/D25 -> 0.6841186 | E29: =E26/E25 -> 0.68019696 | F29: =F26/F25 -> 0.65503212 | G29: =G26/G25 -> 0.6637432 | H29: =H26/H25 -> 0.65513937
A30: 营业利润率 = 1 − 运营比率 | B30: =1-B29 -> 0.39137387 | C30: =1-C29 -> 0.34134825 | D30: =1-D29 -> 0.3158814 | E30: =1-E29 -> 0.31980304 | F30: =1-F29 -> 0.34496788 | G30: =1-G29 -> 0.3362568 | H30: =1-H29 -> 0.34486063
A32: BHE 能源：归属 BHE 的税后利润构成（2023 年起）
A33: 项目 | B33: 2021 年 | C33: 2022 年 | D33: 2023 年 | E33: 2024 年 | F33: 2025 年 | G33: 2025 上半年 | H33: 2026 上半年 | I33: 出处（文件代码 + 页码；单元格批注有完整出处）
A34: 美国公用事业（PacifiCorp、MidAmerican、NV Energy） | B34: 未录入 | C34: 未录入 | D34: 906 | E34: 1961 | F34: 2097 | G34: 862 | H34: 956 | I34: 2023–2025：S01 p.K-44；2025H1–2026H1：S02 p.41
A35: 天然气管道 | B35: 未录入 | C35: 未录入 | D35: 1079 | E35: 1232 | F35: 1151 | G35: 671 | H35: 848 | I35: 2023–2025：S01 p.K-44；2025H1–2026H1：S02 p.41
A36: 其他能源业务（Northern Powergrid、可再生能源等） | B36: 未录入 | C36: 未录入 | D36: 1024 | E36: 1334 | F36: 1175 | G36: 650 | H36: 546 | I36: 2023–2025：S01 p.K-44；2025H1–2026H1：S02 p.41
A37: 房地产经纪 | B37: 未录入 | C37: 未录入 | D37: 13 | E37: -107 | F37: 24 | G37: 30 | H37: 8 | I37: 2023–2025：S01 p.K-44；2025H1–2026H1：S02 p.41
A38: BHE 公司层面利息及其他 | B38: 未录入 | C38: 未录入 | D38: -412 | E38: -394 | F38: -465 | G38: -411 | H38: -353 | I38: 2023–2025：S01 p.K-44；2025H1–2026H1：S02 p.41
A39: 归属 BHE 的税后利润合计（公式） | B39: 未录入 | C39: 未录入 | D39: =SUM(D34:D38) -> 2610 | E39: =SUM(E34:E38) -> 4026 | F39: =SUM(F34:F38) -> 3982 | G39: =SUM(G34:G38) -> 1802 | H39: =SUM(H34:H38) -> 2005
A40: PacifiCorp 山火损失计提（税前） | B40: 未录入 | C40: 未录入 | D40: 1700 | E40: 346 | F40: 100 | G40: 未录入 | H40: 未录入 | I40: 2023–2025：S01 p.K-45；2023 年为扣除预期保险赔付后的计提
A42: 制造、服务与零售：税前利润与收入（2023 年起）
A43: 项目 | B43: 2021 年 | C43: 2022 年 | D43: 2023 年 | E43: 2024 年 | F43: 2025 年 | G43: 2025 上半年 | H43: 2026 上半年 | I43: 出处（文件代码 + 页码；单元格批注有完整出处）
A44: 制造业 税前利润 | B44: 未录入 | C44: 未录入 | D44: 11445 | E44: 11895 | F44: 12571 | G44: 5963 | H44: 7176 | I44: 2023–2025：S01 p.K-46；2025H1–2026H1：S02 p.42
A45: 服务与零售（含 McLane、Pilot）税前利润 | B45: 未录入 | C45: 未录入 | D45: 6144 | E45: 4948 | F45: 4905 | G45: 2690 | H45: 2904 | I45: 2023–2025：S01 p.K-46；2025H1–2026H1：S02 p.42
...

Sheet 浮存金与现金
A1: 保险浮存金、现金与短期国债（期末余额，百万美元）
A2: “现金及国债（保险及其他，净额）”与公司 MD&A 的口径一致：现金及等价物 + 短期国债 − 待付国债款；合并口径再加铁路/公用事业/能源板块现金。
A3: 图例： | B3: 披露数据 | C3: 假设输入 | D3: 公式 | E3: 受假设影响 | F3: 核对
A5: 项目 | B5: 2020末 | C5: 2021末 | D5: 2022末 | E5: 2023末 | F5: 2024末 | G5: 2025末 | H5: 2026-06-30 | I5: 出处（文件代码 + 页码；单元格批注有完整出处）
A6: 保险浮存金（约数） | B6: 138000 | C6: 147000 | D6: 164000 | E6: 169000 | F6: 171000 | G6: 176000 | H6: 177500 | I6: 2020末：S01 p.K-6；2021末–2022末：W01 PDF 第66页（页脚 K-42）；2023末–2025末：S01 p.K-41；2026-06-30：S02 p.38；原文为“约 X 十亿美元”
A7: 保险及其他：现金及现金等价物 | B7: — | C7: 85319 | D7: 32260 | E7: 33672 | F7: 44333 | G7: 47719 | H7: 35096 | I7: 2021末：W02 PDF 第86页（页脚 K-70）；2022末–2023末：W01 PDF 第94页（页脚 K-70）；2024末–2025末：S01 p.K-66；2026-06-30：S02 p.2
A8: 保险及其他：短期美国国债（Short-term investments in U.S. Treasury Bills） | B8: — | C8: 58535 | D8: 92774 | E8: 129619 | F8: 286472 | G8: 321434 | H8: 324905 | I8: 2021末：W02 PDF 第86页（页脚 K-70）；2022末–2023末：W01 PDF 第94页（页脚 K-70）；2024末–2025末：S01 p.K-66；2026-06-30：S02 p.2
A9: 减：待付国债购买款（Payable for purchase of U.S. Treasury Bills） | B9: — | C9: 0 | D9: 0 | E9: 0 | F9: 12769 | G9: 167 | H9: 771 | I9: 2021末–2023末：假设；2024末–2025末：S01 p.K-67；2026-06-30：S02 p.3
A10: 铁路、公用事业与能源：现金及现金等价物 | B10: — | C10: 2865 | D10: 3551 | E10: 4350 | F10: 3396 | G10: 4158 | H10: 5513 | I10: 2021末：W02 PDF 第86页（页脚 K-70）；2022末–2023末：W01 PDF 第94页（页脚 K-70）；2024末–2025末：S01 p.K-66；2026-06-30：S02 p.2
A11: 现金及短期国债（保险及其他，净额）= 现金 + 国债 − 待付款 | B11: — | C11: =C7+C8-C9 -> 143854 | D11: =D7+D8-D9 -> 125034 | E11: =E7+E8-E9 -> 163291 | F11: =F7+F8-F9 -> 318036 | G11: =G7+G8-G9 -> 368986 | H11: =H7+H8-H9 -> 359230 | I11: 公式；2021–2023 年受“待付款=0”假设影响（橙色）
A12: 现金及短期国债（合并口径）= 上行 + 铁路/公用事业/能源现金 | B12: — | C12: =C11+C10 -> 146719 | D12: =D11+D10 -> 128585 | E12: =E11+E10 -> 167641 | F12: =F11+F10 -> 321432 | G12: =G11+G10 -> 373144 | H12: =H11+H10 -> 364743 | I12: 公式
A13: 核对：MD&A 披露的“保险及其他现金及国债（净额）”（十亿美元） | G13: 369 | H13: 359.2 | I13: 2025末：S01 p.K-55；2026-06-30：S02 p.48
A14: 核对差异（十亿美元，一位小数，应为 0） | G14: =ROUND(G11/1000,1)-G13 -> 0 | H14: =ROUND(H11/1000,1)-H13 -> 0
A15: 总资产 | B15: — | C15: 958784 | D15: 948465 | E15: 1069978 | F15: 1153881 | G15: 1222176 | H15: 1263071 | I15: 2021末：W02 PDF 第86页（页脚 K-70）；2022末–2023末：W01 PDF 第94页（页脚 K-70）；2024末–2025末：S01 p.K-66；2026-06-30：S02 p.2；2021 年末为 LDTI 追溯调整前口径
A16: 股票投资（资产负债表 Investments in equity securities，公允价值） | B16: — | C16: 350719 | D16: 308793 | E16: 353842 | F16: 271588 | G16: 297778 | H16: 323779 | I16: 2021末：W02 PDF 第86页（页脚 K-70）；2022末–2023末：W01 PDF 第94页（页脚 K-70）；2024末–2025末：S01 p.K-66；2026-06-30：S02 p.2
A17: 权益法投资（卡夫亨氏、西方石油、Berkadia 等，账面值） | B17: — | C17: 16045 | D17: 28050 | E17: 29066 | F17: 31134 | G17: 19978 | H17: 19948 | I17: 2021末：W02 PDF 第86页（页脚 K-70）；2022末–2023末：W01 PDF 第94页（页脚 K-70）；2024末–2025末：S01 p.K-66；2026-06-30：S02 p.2
A19: 比率与浮存金成本（公式）
A20: 项目 | B20: 2020末 | C20: 2021末 | D20: 2022末 | E20: 2023末 | F20: 2024末 | G20: 2025末 | H20: 2026-06-30 | I20: 说明
A21: 现金及国债（合并）÷ 总资产 | B21: — | C21: =C12/C15 -> 0.15302612 | D21: =D12/D15 -> 0.13557169 | E21: =E12/E15 -> 0.15667705 | F21: =F12/F15 -> 0.27856599 | G21: =G12/G15 -> 0.30531118 | H21: =H12/H15 -> 0.28877474
A22: 浮存金 ÷ 现金及国债（保险及其他，净额） | B22: — | C22: =C6/C11 -> 1.0218694 | D22: =D6/D11 -> 1.3116432 | E22: =E6/E11 -> 1.0349621 | F22: =F6/F11 -> 0.53767498 | G22: =G6/G11 -> 0.47698287 | H22: =H6/H11 -> 0.49411241
A23: 现金及国债（合并）− 最低持有承诺 300 亿美元（百万美元） | B23: — | C23: =C12-P_mincash -> 116719 | D23: =D12-P_mincash -> 98585 | E23: =E12-P_mincash -> 137641 | F23: =F12-P_mincash -> 291432 | G23: =G12-P_mincash -> 343144 | H23: =H12-P_mincash -> 334743 | I23: P_mincash 为披露参数（见“假设与参数”）
A24: 平均浮存金 =（期初 + 期末）÷ 2 | B24: — | C24: =(B6+C6)/2 -> 142500 | D24: =(C6+D6)/2 -> 155500 | E24: =(D6+E6)/2 -> 166500 | F24: =(E6+F6)/2 -> 170000 | G24: =(F6+G6)/2 -> 173500 | H24: =(G6+H6)/2 -> 176750 | I24: 2026-06-30 列为 2025 年末与 2026 年 6 月末平均
A25: 当期税前承保利润（链接“业务明细”） | B25: — | C25: ='业务明细'!$B$10 -> 1111 | D25: ='业务明细'!$C$10 -> -22 | E25: ='业务明细'!$D$10 -> 6913 | F25: ='业务明细'!$E$10 -> 11405 | G25: ='业务明细'!$F$10 -> 9460 | H25: ='业务明细'!$H$10 -> 4445 | I25: 2026-06-30 列为 2026 上半年（未年化）
A26: 浮存金成本 = −税前承保利润 ÷ 平均浮存金（负数 = 浮存金“倒贴钱”给伯克希尔） | B26: — | C26: =-C25/C24 -> -0.0077964912 | D26: =-D25/D24 -> 0.0001414791 | E26: =-E25/E24 -> -0.04151952 | F26: =-F25/F24 -> -0.067088235 | G26: =-G25/G24 -> -0.054524496 | H26: =-H25/H24 -> -0.025148515 | I26: 2026-06-30 列为上半年数，未年化

Sheet 股票组合
A1: 股票投资组合（按披露的行业与主要持仓，公允价值，百万美元）
A2: 口径：年报附注“Investments in equity securities”按被投资企业主要行业划分；不含按权益法核算的卡夫亨氏、西方石油普通股。
A3: 图例： | B3: 披露数据 | C3: 假设输入 | D3: 公式 | E3: 受假设影响 | F3: 核对
A5: A. 按行业：成本与公允价值
A6: 项目 | B6: 2021末 | C6: 2022末 | D6: 2023末 | E6: 2024末 | F6: 2025末 | G6: 2026-06-30 | H6: 出处（文件代码 + 页码；单元格批注有完整出处）
A7: 银行、保险与金融：成本 | B7: 26822 | C7: 25893 | D7: 27136 | E7: 15707 | F7: 15454 | G7: 15729 | H7: 2021末：W02 PDF 第100页（页脚 K-84）；2022末–2023末：W01 PDF 第109页（页脚 K-85）；2024末–2025末：S01 p.K-79；2026-06-30：S02 p.9
A8: 银行、保险与金融：公允价值 | B8: 89058 | C8: 69556 | D8: 78312 | E8: 91643 | F8: 104129 | G8: 94477 | H8: 2021末：W02 PDF 第100页（页脚 K-84）；2022末–2023末：W01 PDF 第109页（页脚 K-85）；2024末–2025末：S01 p.K-79；2026-06-30：S02 p.9
A9: 银行、保险与金融：未实现收益 = 公允价值 − 成本 | B9: =B8-B7 -> 62236 | C9: =C8-C7 -> 43663 | D9: =D8-D7 -> 51176 | E9: =E8-E7 -> 75936 | F9: =F8-F7 -> 88675 | G9: =G8-G7 -> 78748
A10: 消费品：成本 | B10: 36076 | C10: 40508 | D10: 34248 | E10: 12658 | F10: 11899 | G10: 8650 | H10: 2021末：W02 PDF 第100页（页脚 K-84）；2022末–2023末：W01 PDF 第109页（页脚 K-85）；2024末–2025末：S01 p.K-79；2026-06-30：S02 p.9
A11: 消费品：公允价值 | B11: 191021 | C11: 152892 | D11: 201143 | E11: 104749 | F11: 94954 | G11: 100486 | H11: 2021末：W02 PDF 第100页（页脚 K-84）；2022末–2023末：W01 PDF 第109页（页脚 K-85）；2024末–2025末：S01 p.K-79；2026-06-30：S02 p.9
A12: 消费品：未实现收益 = 公允价值 − 成本 | B12: =B11-B10 -> 154945 | C12: =C11-C10 -> 112384 | D12: =D11-D10 -> 166895 | E12: =E11-E10 -> 92091 | F12: =F11-F10 -> 83055 | G12: =G11-G10 -> 91836
A13: 商业、工业及其他：成本 | B13: 41707 | C13: 65209 | D13: 48032 | E13: 47141 | F13: 58036 | G13: 82142 | H13: 2021末：W02 PDF 第100页（页脚 K-84）；2022末–2023末：W01 PDF 第109页（页脚 K-85）；2024末–2025末：S01 p.K-79；2026-06-30：S02 p.9
A14: 商业、工业及其他：公允价值 | B14: 70640 | C14: 86345 | D14: 74387 | E14: 75196 | F14: 98695 | G14: 128816 | H14: 2021末：W02 PDF 第100页（页脚 K-84）；2022末–2023末：W01 PDF 第109页（页脚 K-85）；2024末–2025末：S01 p.K-79；2026-06-30：S02 p.9
A15: 商业、工业及其他：未实现收益 = 公允价值 − 成本 | B15: =B14-B13 -> 28933 | C15: =C14-C13 -> 21136 | D15: =D14-D13 -> 26355 | E15: =E14-E13 -> 28055 | F15: =F14-F13 -> 40659 | G15: =G14-G13 -> 46674
A16: 合计：成本（公式） | B16: =B7+B10+B13 -> 104605 | C16: =C7+C10+C13 -> 131610 | D16: =D7+D10+D13 -> 109416 | E16: =E7+E10+E13 -> 75506 | F16: =F7+F10+F13 -> 85389 | G16: =G7+G10+G13 -> 106521
A17: 合计：公允价值（公式） | B17: =B8+B11+B14 -> 350719 | C17: =C8+C11+C14 -> 308793 | D17: =D8+D11+D14 -> 353842 | E17: =E8+E11+E14 -> 271588 | F17: =F8+F11+F14 -> 297778 | G17: =G8+G11+G14 -> 323779
A18: 核对：与资产负债表“股票投资”之差（应为 0） | B18: =B17-'浮存金与现金'!$C$16 -> 0 | C18: =C17-'浮存金与现金'!$D$16 -> 0 | D18: =D17-'浮存金与现金'!$E$16 -> 0 | E18: =E17-'浮存金与现金'!$F$16 -> 0 | F18: =F17-'浮存金与现金'!$G$16 -> 0 | G18: =G17-'浮存金与现金'!$H$16 -> 0
A19: 未实现收益合计 ÷ 公允价值 | B19: =(B17-B16)/B17 -> 0.70174128 | C19: =(C17-C16)/C17 -> 0.57379215 | D19: =(D17-D16)/D17 -> 0.69077724 | E19: =(E17-E16)/E17 -> 0.7219833 | F19: =(F17-F16)/F17 -> 0.71324611 | G19: =(G17-G16)/G17 -> 0.67100708
A21: B. 行业占比（公允价值口径，公式）
A22: 项目 | B22: 2021末 | C22: 2022末 | D22: 2023末 | E22: 2024末 | F22: 2025末 | G22: 2026-06-30 | H22: 说明
A23: 银行、保险与金融 | B23: =B8/B17 -> 0.25392978 | C23: =C8/C17 -> 0.22525122 | D23: =D8/D17 -> 0.22131912 | E23: =E8/E17 -> 0.33743391 | F23: =F8/F17 -> 0.34968668 | G23: =G8/G17 -> 0.29179471
A24: 消费品 | B24: =B11/B17 -> 0.54465541 | C24: =C11/C17 -> 0.4951278 | D24: =D11/D17 -> 0.56845428 | E24: =E11/E17 -> 0.38569083 | F24: =F11/F17 -> 0.31887514 | G24: =G11/G17 -> 0.31035367
A25: 商业、工业及其他 | B25: =B14/B17 -> 0.20141481 | C25: =C14/C17 -> 0.27962098 | D25: =D14/D17 -> 0.2102266 | E25: =E14/E17 -> 0.27687527 | F25: =F14/F17 -> 0.33143819 | G25: =G14/G17 -> 0.39785162
A27: C. 集中度：前五大持仓
A28: 项目 | B28: 2021末 | C28: 2022末 | D28: 2023末 | E28: 2024末 | F28: 2025末 | G28: 2026-06-30 | H28: 出处（文件代码 + 页码；单元格批注有完整出处）
A29: 前五大持仓占股票投资公允价值比例（2021 年为前四大） | B29: 0.73 | C29: 0.75 | D29: 0.79 | E29: 0.71 | F29: 0.65 | G29: 0.66 | H29: 2021末：W02 PDF 第100页（页脚 K-84）；2022末–2023末：W01 PDF 第109页（页脚 K-85）；2024末–2025末：S01 p.K-80；2026-06-30：S02 p.9
A30: 前五大合计金额（近似 = 占比 × 公允价值，公式） | B30: =B29*B17 -> 256024.87 | C30: =C29*C17 -> 231594.75 | D30: =D29*D17 -> 279535.18 | E30: =E29*E17 -> 192827.48 | F30: =F29*F17 -> 193555.7 | G30: =G29*G17 -> 213694.14 | H30: 占比为四舍五入后的整数百分比，金额为近似值（见“假设与参数”口径说明 5）
A31: 前五大名单 | B31: 美国运通、苹果、美国银行、可口可乐（前四） | C31: 美国运通、苹果、美国银行、可口可乐、雪佛龙 | D31: 美国运通、苹果、美国银行、可口可乐、雪佛龙 | E31: 美国运通、苹果、美国银行、可口可乐、雪佛龙 | F31: 美国运通、苹果、美国银行、可口可乐、雪佛龙 | G31: Alphabet、美国运通、苹果、美国银行、可口可乐
A33: D. 主要持仓公允价值（仅录入逐家披露的数）
A34: 项目 | B34: 2021末 | C34: 2022末 | D34: 2023末 | E34: 2024末 | F34: 2025末 | G34: 2026-06-30 | H34: 出处（文件代码 + 页码；单元格批注有完整出处）
A35: 苹果 Apple | B35: 161155 | C35: 119000 | D35: 174300 | E35: 未披露 | F35: 61962 | G35: 未披露 | H35: 2021末：L2021 PDF 第6页（页脚 7）；2022末–2023末：W01 PDF 第109页（页脚 K-85）；2025末：L2025 PDF 第15页（页脚 15）
A36: 美国运通 American Express | B36: 24804 | C36: 22400 | D36: 28400 | E36: 未披露 | F36: 56088 | G36: 未披露 | H36: 2021末：L2021 PDF 第6页（页脚 7）；2022末–2023末：W01 PDF 第109页（页脚 K-85）；2025末：L2025 PDF 第15页（页脚 15）
A37: 美国银行 Bank of America | B37: 45952 | C37: 34200 | D37: 34800 | E37: 未披露 | F37: 未披露 | G37: 未披露 | H37: 2021末：L2021 PDF 第6页（页脚 7）；2022末–2023末：W01 PDF 第109页（页脚 K-85）
A38: 可口可乐 Coca-Cola | B38: 23684 | C38: 25400 | D38: 23600 | E38: 未披露 | F38: 27964 | G38: 未披露 | H38: 2021末：L2021 PDF 第6页（页脚 7）；2022末–2023末：W01 PDF 第109页（页脚 K-85）；2025末：L2025 PDF 第15页（页脚 15）
A39: 雪佛龙 Chevron | B39: 4488 | C39: 30000 | D39: 18800 | E39: 未披露 | F39: 未披露 | G39: 未披露 | H39: 2021末：L2021 PDF 第6页（页脚 7）；2022末–2023末：W01 PDF 第109页（页脚 K-85）
A40: 穆迪 Moody's | B40: 9636 | C40: 未披露 | D40: 未披露 | E40: 未披露 | F40: 12603 | G40: 未披露 | H40: 2021末：L2021 PDF 第6页（页脚 7）；2025末：L2025 PDF 第15页（页脚 15）
A41: 日本五大商社合计 | B41: 未披露 | C41: 未披露 | D41: 未披露 | E41: 23500 | F41: 35368 | G41: 未披露 | H41: 2024末：L2024 PDF 第11页（页脚 11）；2025末：L2025 PDF 第16页（页脚 16）
A42: 注：2022–2023 年数字取自年报附注脚注，原文以十亿美元列示（已四舍五入）；2024 年末逐家公允价值未在所用材料中披露，留空。 2025 年末苹果、美国运通、可口可乐、穆迪与日本五大商社合计约 1,940 亿美元，约占 2,978 亿美元组合的近三分之二（2025 年致股东信 p.16）。
A43: 苹果占组合比例（公式） | B43: =B35/B17 -> 0.45949892 | C43: =C35/C17 -> 0.38537143 | D43: =D35/D17 -> 0.49259274 | E43: — | F43: =F35/F17 -> 0.20808119 | G43: —
A45: E. 可口可乐：1988 年买入的持仓，2025 年的股息回报（游戏第 4 题引用）
...

Sheet 回购与每股账面
A1: 股东权益、股数、每股账面价值与回购
A2: 每股账面价值 = 伯克希尔股东权益 ÷ A 类等值股数；A 类等值股 = A 类股 + B 类股 ÷ 1,500（P_conv）。
A3: 图例： | B3: 披露数据 | C3: 假设输入 | D3: 公式 | E3: 受假设影响 | F3: 核对
A5: A. 股东权益与每股账面价值（期末）
A6: 项目 | B6: 2021末 | C6: 2022末 | D6: 2023末 | E6: 2024末 | F6: 2025末 | G6: 2026-06-30 | I6: 出处（文件代码 + 页码；单元格批注有完整出处）
A7: 2021 年末：权益合计（含少数股东，LDTI 调整后） | B7: 510299 | I7: W01 PDF 第97页（页脚 K-73）（合并股东权益变动表 Balance at December 31, 2021 · Total）
A8: 2021 年末：少数股东权益 | B8: 8731 | I8: W01 PDF 第97页（页脚 K-73）（同上 · Non-controlling interests）
A9: 伯克希尔股东权益（百万美元） | B9: =B7-B8 -> 501568 | C9: 473424 | D9: 561273 | E9: 649368 | F9: 717419 | G9: 747910 | I9: 2021 年末 = 上两行相减（公式）；2022末–2023末：W01 PDF 第95页（页脚 K-71）；2024末–2025末：S01 p.K-67；2026-06-30：S02 p.3
A10: 对照：LDTI 追溯调整前的原始披露 | B10: 506199 | C10: 472360 | I10: 2021末–2022末：W02 PDF 第87页（页脚 K-71）
A11: A 类股流通股数（股） | B11: 617113 | C11: 591564 | D11: 567775 | E11: 547562 | F11: 515835 | G11: 501101 | I11: 2021末：W01 PDF 第131页（页脚 K-107）；2022末–2025末：S01 p.K-102；2026-06-30：S02 p.21
A12: B 类股流通股数（股） | B12: 1290474503 | C12: 1302254076 | D12: 1310561508 | E12: 1335992139 | F12: 1383582639 | G12: 1395887484 | I12: 2021末：W01 PDF 第131页（页脚 K-107）；2022末–2025末：S01 p.K-102；2026-06-30：S02 p.21
A13: A 类等值股数 = A 类 + B 类 ÷ P_conv（公式） | B13: =B11+B12/P_conv -> 1477429.3 | C13: =C11+C12/P_conv -> 1459733.4 | D13: =D11+D12/P_conv -> 1441482.7 | E13: =E11+E12/P_conv -> 1438223.4 | F13: =F11+F12/P_conv -> 1438223.4 | G13: =G11+G12/P_conv -> 1431692.7 | I13: 公式；P_conv 见“假设与参数”
A14: 核对：公司披露的 A 类等值股数 | B14: 1477429 | C14: 1459733 | D14: 1441483 | E14: 1438223 | F14: 1438223 | G14: 1431693 | I14: 2021末：W02 PDF 第121页（页脚 K-105）；2022末–2023末：W01 PDF 第131页（页脚 K-107）；2024末–2025末：S01 p.K-102；2026-06-30：S03
A15: 核对差异（四舍五入到整股，应为 0） | B15: =ROUND(B13,0)-B14 -> 0 | C15: =ROUND(C13,0)-C14 -> 0 | D15: =ROUND(D13,0)-D14 -> 0 | E15: =ROUND(E13,0)-E14 -> 0 | F15: =ROUND(F13,0)-F14 -> 0 | G15: =ROUND(G13,0)-G14 -> 0
A16: 每股账面价值（每 A 类等值股，美元） | B16: =B9*1000000/B13 -> 339486.96 | C16: =C9*1000000/C13 -> 324322.24 | D16: =D9*1000000/D13 -> 389372.01 | E16: =E9*1000000/E13 -> 451507.04 | F16: =F9*1000000/F13 -> 498823.05 | G16: =G9*1000000/G13 -> 522395.64 | I16: 公式（权益单位为百万美元，故 ×1,000,000）
A17: 每股账面价值（每 B 类股，美元）= 上行 ÷ P_conv | B17: =B16/P_conv -> 226.32464 | C17: =C16/P_conv -> 216.21483 | D17: =D16/P_conv -> 259.58134 | E17: =E16/P_conv -> 301.00469 | F17: =F16/P_conv -> 332.5487 | G17: =G16/P_conv -> 348.26376
A18: 每股账面价值变化（较上期末） | B18: — | C18: =C16/B16-1 -> -0.044669535 | D18: =D16/C16-1 -> 0.2005714 | E18: =E16/D16-1 -> 0.15957755 | F18: =F16/E16-1 -> 0.10479574 | G18: =G16/F16-1 -> 0.047256409 | I18: 2026-06-30 列为较 2025 年末（半年，未年化）
A20: B. 回购（当期金额，百万美元）
A21: 项目 | B21: 2021 年 | C21: 2022 年 | D21: 2023 年 | E21: 2024 年 | F21: 2025 年 | G21: 2025 上半年 | H21: 2026 上半年 | I21: 出处（文件代码 + 页码；单元格批注有完整出处）
A22: 其中：2026 年一季度回购（权益变动表） | B22: — | C22: — | D22: — | E22: — | F22: — | G22: — | H22: 235 | I22: S02 p.6
A23: 其中：2026 年二季度回购（权益变动表） | B23: — | C23: — | D23: — | E23: — | F23: — | G23: — | H23: 4527 | I23: S02 p.6
A24: 回购金额（权益变动表“Acquisition(s) of common stock”） | B24: 26942 | C24: 8031 | D24: 8976 | E24: 2918 | F24: 0 | G24: 0 | H24: =H22+H23 -> 4762 | I24: 2021–2022：W01 PDF 第97页（页脚 K-73）；2023–2024：S01 p.K-69；2025：S01 p.K-55；2025H1：S02 p.6；2026 上半年 = 一季度 + 二季度（公式），与业绩公告“约 48 亿美元”一致
A25: 回购付现（现金流量表“Acquisitions of treasury stock”） | B25: 27061 | C25: 7854 | D25: 9171 | E25: 2918 | F25: 0 | G25: 0 | H25: 4444 | I25: 2021–2022：W01 PDF 第98页（页脚 K-74）；2023–2025：S01 p.K-70；2025H1–2026H1：S02 p.7；与上行差异来自期末未结算交易
A26: 回购 A 类股（股） | B26: 14196 | C26: 11098 | D26: 11667 | E26: 4787 | F26: 0 | G26: 0 | H26: 511 | I26: 2021–2022：W01 PDF 第131页（页脚 K-107）；2023–2025：S01 p.K-102；2025H1：S02 p.6；2026H1：S02 p.21
A27: 回购 B 类股（股） | B27: 78501968 | C27: 9896927 | D27: 9875568 | E27: 0 | F27: 0 | G27: 0 | H27: 9029655 | I27: 2021–2022：W01 PDF 第131页（页脚 K-107）；2023–2025：S01 p.K-102；2025H1：S02 p.6；2026H1：S02 p.21
A28: 回购的 A 类等值股数（公式） | B28: =B26+B27/P_conv -> 66530.645 | C28: =C26+C27/P_conv -> 17695.951 | D28: =D26+D27/P_conv -> 18250.712 | E28: =E26+E27/P_conv -> 4787 | F28: =F26+F27/P_conv -> 0 | G28: =G26+G27/P_conv -> 0 | H28: =H26+H27/P_conv -> 6530.77
A29: 回购均价（每 A 类等值股，美元）= 回购金额 ÷ 回购股数 | B29: =IF(B28>0,B24*1000000/B28,"无回购") -> 404956.24 | C29: =IF(C28>0,C24*1000000/C28,"无回购") -> 453832.62 | D29: =IF(D28>0,D24*1000000/D28,"无回购") -> 491816.43 | E29: =IF(E28>0,E24*1000000/E28,"无回购") -> 609567.58 | F29: =IF(F28>0,F24*1000000/F28,"无回购") -> 无回购 | G29: =IF(G28>0,G24*1000000/G28,"无回购") -> 无回购 | H29: =IF(H28>0,H24*1000000/H28,"无回购") -> 729163.64
A30: 回购均价 ÷ 期末每股账面价值（近似“回购市净率”，受近似假设影响） | B30: =IF(ISNUMBER(B29),B29/'回购与每股账面'!$B$16,"—") -> 1.1928477 | C30: =IF(ISNUMBER(C29),C29/'回购与每股账面'!$C$16,"—") -> 1.3993262 | D30: =IF(ISNUMBER(D29),D29/'回购与每股账面'!$D$16,"—") -> 1.2631017 | E30: =IF(ISNUMBER(E29),E29/'回购与每股账面'!$E$16,"—") -> 1.3500733 | F30: =IF(ISNUMBER(F29),F29/'回购与每股账面'!$F$16,"—") -> — | G30: — | H30: =IF(ISNUMBER(H29),H29/'回购与每股账面'!$G$16,"—") -> 1.3958073 | I30: 用期末每股账面价值代替回购当时的数值（近似）；2026Q2 10-Q p.51 披露 5–6 月 A 类回购均价约 71.6–73.4 万美元
A31: 回购金额 ÷ 当期经营利润 | B31: =B24/'分部利润'!$B$12 -> 0.97626554 | C31: =C24/'分部利润'!$C$12 -> 0.26029884 | D31: =D24/'分部利润'!$D$12 -> 0.24032129 | E31: =E24/'分部利润'!$E$12 -> 0.061513165 | F31: =F24/'分部利润'!$F$12 -> 0 | G31: =G24/'分部利润'!$G$12 -> 0 | H31: =H24/'分部利润'!$H$12 -> 0.19573349

Sheet 现金流节选
A1: 现金流量表节选：钱从哪里来、花到哪里去（百万美元）
A2: 流出项以正数列示；“净买入股票” = 购买 − 出售（负数表示净卖出）。
A3: 图例： | B3: 披露数据 | C3: 假设输入 | D3: 公式 | E3: 受假设影响 | F3: 核对
A5: 合并现金流量表（节选）
A6: 项目 | B6: 2021 年 | C6: 2022 年 | D6: 2023 年 | E6: 2024 年 | F6: 2025 年 | G6: 2025 上半年 | H6: 2026 上半年 | I6: 出处（文件代码 + 页码；单元格批注有完整出处）
A7: 经营活动现金流量净额 | B7: 39427 | C7: 37350 | D7: 49196 | E7: 30592 | F7: 45969 | G7: 20988 | H7: 21653 | I7: 2021–2022：W01 PDF 第98页（页脚 K-74）；2023–2025：S01 p.K-70；2025H1–2026H1：S02 p.7
A8: 购买股票（Purchases of equity securities） | B8: 8448 | C8: 67930 | D8: 16462 | E8: 9237 | F8: 16923 | G8: 7092 | H8: 39405 | I8: 2021–2022：W01 PDF 第98页（页脚 K-74）；2023–2025：S01 p.K-70；2025H1–2026H1：S02 p.7
A9: 出售股票（Sales of equity securities） | B9: 15849 | C9: 33664 | D9: 40631 | E9: 143359 | F9: 30686 | G9: 11592 | H9: 27780 | I9: 2021–2022：W01 PDF 第98页（页脚 K-74）；2023–2025：S01 p.K-70；2025H1–2026H1：S02 p.7
A10: 收购业务（扣除取得的现金） | B10: 456 | C10: 10594 | D10: 8604 | E10: 396 | F10: 1074 | G10: 101 | H10: 9704 | I10: 2021–2022：W01 PDF 第98页（页脚 K-74）；2023–2025：S01 p.K-70；2025H1–2026H1：S02 p.7
A11: 资本开支（物业厂房设备及租赁设备） | B11: 13276 | C11: 15464 | D11: 19409 | E11: 18976 | F11: 20927 | G11: 9139 | H11: 10631 | I11: 2021–2022：W01 PDF 第98页（页脚 K-74）；2023–2025：S01 p.K-70；2025H1–2026H1：S02 p.7
A12: 净买入股票 = 购买 − 出售（公式） | B12: =B8-B9 -> -7401 | C12: =C8-C9 -> 34266 | D12: =D8-D9 -> -24169 | E12: =E8-E9 -> -134122 | F12: =F8-F9 -> -13763 | G12: =G8-G9 -> -4500 | H12: =H8-H9 -> 11625
A13: 回购付现（链接“回购与每股账面”） | B13: ='回购与每股账面'!$B$25 -> 27061 | C13: ='回购与每股账面'!$C$25 -> 7854 | D13: ='回购与每股账面'!$D$25 -> 9171 | E13: ='回购与每股账面'!$E$25 -> 2918 | F13: ='回购与每股账面'!$F$25 -> 0 | G13: ='回购与每股账面'!$G$25 -> 0 | H13: ='回购与每股账面'!$H$25 -> 4444
A14: 经营现金流 − 资本开支（公式，粗略的“自由现金流”口径） | B14: =B7-B11 -> 26151 | C14: =C7-C11 -> 21886 | D14: =D7-D11 -> 29787 | E14: =E7-E11 -> 11616 | F14: =F7-F11 -> 25042 | G14: =G7-G11 -> 11849 | H14: =H7-H11 -> 11022

Sheet 变化
A1: 变化分析：同比、占比与结构（全部为公式，联动前面各表）
A2: 同比 = 本期 ÷ 上期 − 1；上期为负或为零时显示“n/m”（不具可比意义）。半年度与上年同期比较；余额项目 2026-06-30 与 2025 年末比较。
A3: 图例： | B3: 披露数据 | C3: 假设输入 | D3: 公式 | E3: 受假设影响 | F3: 核对
A5: A. 一眼看懂（文字随数据自动更新） | D5: ↓ 图表在本页第 84 行起（7 张）
A6: ="2026 上半年经营利润 "&TEXT('分部利润'!$H$12/100,"#,##0.0")&" 亿美元，较 2025 上半年 "&TEXT('分部利润'!$H$12/'分部利润'!$G$12-1,"+0.0%;-0.0%")&"；其中制造服务零售 "&TEXT('分部利润'!$H$10/'分部利润'!$G$10-1,"+0.0%;-0.0%")&"、BNSF "&TEXT('分部利润'!$H$8/'分部利润'!$G$8-1,"+0.0%;-0.0%")&"、BHE "&TEXT('分部利润'!$H$9/'分部利润'!$G$9-1,"+0.0%;-0.0%")&"。" -> 2026 上半年经营利润 243.3 亿美元，较 2025 上半年 +17.0%；其中制造服务零售 +15.1%、BNSF +9.5%、BHE +11.5%。
A7: ="保险投资收益 2026 上半年同比 "&TEXT('分部利润'!$H$7/'分部利润'!$G$7-1,"+0.0%;-0.0%")&"（利率下行）；与公司层面投资收益合并看为 "&TEXT('分部利润'!$H$39/'分部利润'!$G$39-1,"+0.0%;-0.0%")&"。承保利润同比 "&TEXT('分部利润'!$H$6/'分部利润'!$G$6-1,"+0.0%;-0.0%")&"，但 GEICO 综合成本率由 "&TEXT('业务明细'!$G$21,"0.0%")&" 升至 "&TEXT('业务明细'!$H$21,"0.0%")&"。" -> 保险投资收益 2026 上半年同比 -8.3%（利率下行）；与公司层面投资收益合并看为 -4.2%。承保利润同比 +3.6%，但 GEICO 综合成本率由 81.7% 升至 89.3%。
A8: ="2026 年 6 月末浮存金约 "&TEXT('浮存金与现金'!$H$6/100,"#,##0")&" 亿美元；保险及其他业务现金及短期国债（净额）"&TEXT('浮存金与现金'!$H$11/100,"#,##0")&" 亿美元，较 2025 年末 "&TEXT('浮存金与现金'!$H$11/'浮存金与现金'!$G$11-1,"+0.0%;-0.0%")&"。" -> 2026 年 6 月末浮存金约 1,775 亿美元；保险及其他业务现金及短期国债（净额）3,592 亿美元，较 2025 年末 -2.6%。
A9: ="股票组合公允价值 "&TEXT('股票组合'!$G$17/100,"#,##0")&" 亿美元，较 2025 年末 "&TEXT('股票组合'!$G$17/'股票组合'!$F$17-1,"+0.0%;-0.0%")&"；“商业、工业及其他”占比由 "&TEXT('股票组合'!$F$25,"0.0%")&" 升至 "&TEXT('股票组合'!$G$25,"0.0%")&"，前五大集中度 "&TEXT('股票组合'!$G$29,"0%")&"。" -> 股票组合公允价值 3,238 亿美元，较 2025 年末 +8.7%；“商业、工业及其他”占比由 33.1% 升至 39.8%，前五大集中度 66%。
A10: ="交班后重启回购：2026 上半年回购 "&TEXT('回购与每股账面'!$H$24/100,"#,##0.0")&" 亿美元（2025 全年为 0），均价约为期末每股账面价值的 "&TEXT('回购与每股账面'!$H$30,"0.00")&" 倍；每股账面价值 "&TEXT('回购与每股账面'!$G$16,"$#,##0")&"，较 2025 年末 "&TEXT('回购与每股账面'!$G$18,"+0.0%;-0.0%")&"。" -> 交班后重启回购：2026 上半年回购 47.6 亿美元（2025 全年为 0），均价约为期末每股账面价值的 1.40 倍；每股账面价值 $522,396，较 2025 年末 +4.7%。
A12: B. 分部税后利润：同比变化
A13: 板块 | B13: 2022 vs 2021 | C13: 2023 vs 2022 | D13: 2024 vs 2023 | E13: 2025 vs 2024 | F13: 2026H1 vs 2025H1 | G13: 2021→2025 年复合增速 | H13: 2025 vs 2021 增减（百万美元）
A14: 保险承保 | B14: =IF('分部利润'!$B$6<=0,"n/m",'分部利润'!$C$6/'分部利润'!$B$6-1) -> -1.0344828 | C14: =IF('分部利润'!$C$6<=0,"n/m",'分部利润'!$D$6/'分部利润'!$C$6-1) -> n/m | D14: =IF('分部利润'!$D$6<=0,"n/m",'分部利润'!$E$6/'分部利润'!$D$6-1) -> 0.66175387 | E14: =IF('分部利润'!$E$6<=0,"n/m",'分部利润'!$F$6/'分部利润'!$E$6-1) -> -0.19534368 | F14: =IF('分部利润'!$G$6<=0,"n/m",'分部利润'!$H$6/'分部利润'!$G$6-1) -> 0.036057692 | G14: =IF(OR('分部利润'!$B$6<=0,'分部利润'!$F$6<=0),"n/m",('分部利润'!$F$6/'分部利润'!$B$6)^(1/4)-1) -> 0.69951275 | H14: ='分部利润'!$F$6-'分部利润'!$B$6 -> 6388
A15: 保险投资收益 | B15: =IF('分部利润'!$B$7<=0,"n/m",'分部利润'!$C$7/'分部利润'!$B$7-1) -> 0.34886624 | C15: =IF('分部利润'!$C$7<=0,"n/m",'分部利润'!$D$7/'分部利润'!$C$7-1) -> 0.4754781 | D15: =IF('分部利润'!$D$7<=0,"n/m",'分部利润'!$E$7/'分部利润'!$D$7-1) -> 0.42887007 | E15: =IF('分部利润'!$E$7<=0,"n/m",'分部利润'!$F$7/'分部利润'!$E$7-1) -> -0.084637893 | F15: =IF('分部利润'!$G$7<=0,"n/m",'分部利润'!$H$7/'分部利润'!$G$7-1) -> -0.083386581 | G15: =IF(OR('分部利润'!$B$7<=0,'分部利润'!$F$7<=0),"n/m",('分部利润'!$F$7/'分部利润'!$B$7)^(1/4)-1) -> 0.27019919 | H15: ='分部利润'!$F$7-'分部利润'!$B$7 -> 7706
A16: 铁路 BNSF | B16: =IF('分部利润'!$B$8<=0,"n/m",'分部利润'!$C$8/'分部利润'!$B$8-1) -> -0.007345576 | C16: =IF('分部利润'!$C$8<=0,"n/m",'分部利润'!$D$8/'分部利润'!$C$8-1) -> -0.14446687 | D16: =IF('分部利润'!$D$8<=0,"n/m",'分部利润'!$E$8/'分部利润'!$D$8-1) -> -0.011008453 | E16: =IF('分部利润'!$E$8<=0,"n/m",'分部利润'!$F$8/'分部利润'!$E$8-1) -> 0.0884516 | F16: =IF('分部利润'!$G$8<=0,"n/m",'分部利润'!$H$8/'分部利润'!$G$8-1) -> 0.095149254 | G16: =IF(OR('分部利润'!$B$8<=0,'分部利润'!$F$8<=0),"n/m",('分部利润'!$F$8/'分部利润'!$B$8)^(1/4)-1) -> -0.022179463 | H16: ='分部利润'!$F$8-'分部利润'!$B$8 -> -514
A17: 能源 BHE | B17: =IF('分部利润'!$B$9<=0,"n/m",'分部利润'!$C$9/'分部利润'!$B$9-1) -> 0.092945129 | C17: =IF('分部利润'!$C$9<=0,"n/m",'分部利润'!$D$9/'分部利润'!$C$9-1) -> -0.40292008 | D17: =IF('分部利润'!$D$9<=0,"n/m",'分部利润'!$E$9/'分部利润'!$D$9-1) -> 0.6001716 | E17: =IF('分部利润'!$E$9<=0,"n/m",'分部利润'!$F$9/'分部利润'!$E$9-1) -> 0.066756032 | F17: =IF('分部利润'!$G$9<=0,"n/m",'分部利润'!$H$9/'分部利润'!$G$9-1) -> 0.11450806 | G17: =IF(OR('分部利润'!$B$9<=0,'分部利润'!$F$9<=0),"n/m",('分部利润'!$F$9/'分部利润'!$B$9)^(1/4)-1) -> 0.027343369 | H17: ='分部利润'!$F$9-'分部利润'!$B$9 -> 407
A18: 制造、服务与零售 | B18: =IF('分部利润'!$B$10<=0,"n/m",'分部利润'!$C$10/'分部利润'!$B$10-1) -> 0.12517986 | C18: =IF('分部利润'!$C$10<=0,"n/m",'分部利润'!$D$10/'分部利润'!$C$10-1) -> 0.067934783 | D18: =IF('分部利润'!$D$10<=0,"n/m",'分部利润'!$E$10/'分部利润'!$D$10-1) -> -0.021703338 | E18: =IF('分部利润'!$E$10<=0,"n/m",'分部利润'!$F$10/'分部利润'!$E$10-1) -> 0.043987148 | F18: =IF('分部利润'!$G$10<=0,"n/m",'分部利润'!$H$10/'分部利润'!$G$10-1) -> 0.15132863 | G18: =IF(OR('分部利润'!$B$10<=0,'分部利润'!$F$10<=0),"n/m",('分部利润'!$F$10/'分部利润'!$B$10)^(1/4)-1) -> 0.05252665 | H18: ='分部利润'!$F$10-'分部利润'!$B$10 -> 2527
A19: 其他 | B19: =IF('分部利润'!$B$11<=0,"n/m",'分部利润'!$C$11/'分部利润'!$B$11-1) -> 0.6453958 | C19: =IF('分部利润'!$C$11<=0,"n/m",'分部利润'!$D$11/'分部利润'!$C$11-1) -> -0.22680412 | D19: =IF('分部利润'!$D$11<=0,"n/m",'分部利润'!$E$11/'分部利润'!$D$11-1) -> 0.85015873 | E19: =IF('分部利润'!$E$11<=0,"n/m",'分部利润'!$F$11/'分部利润'!$E$11-1) -> -0.44646534 | F19: =IF('分部利润'!$G$11<=0,"n/m",'分部利润'!$H$11/'分部利润'!$G$11-1) -> 33.712329 | G19: =IF(OR('分部利润'!$B$11<=0,'分部利润'!$F$11<=0),"n/m",('分部利润'!$F$11/'分部利润'!$B$11)^(1/4)-1) -> 0.068386596 | H19: ='分部利润'!$F$11-'分部利润'!$B$11 -> 375
A20: 经营利润合计 | B20: =IF('分部利润'!$B$12<=0,"n/m",'分部利润'!$C$12/'分部利润'!$B$12-1) -> 0.11798384 | C20: =IF('分部利润'!$C$12<=0,"n/m",'分部利润'!$D$12/'分部利润'!$C$12-1) -> 0.2105792 | D20: =IF('分部利润'!$D$12<=0,"n/m",'分部利润'!$E$12/'分部利润'!$D$12-1) -> 0.27006693 | E20: =IF('分部利润'!$E$12<=0,"n/m",'分部利润'!$F$12/'分部利润'!$E$12-1) -> -0.062208824 | F20: =IF('分部利润'!$G$12<=0,"n/m",'分部利润'!$H$12/'分部利润'!$G$12-1) -> 0.16960723 | G20: =IF(OR('分部利润'!$B$12<=0,'分部利润'!$F$12<=0),"n/m",('分部利润'!$F$12/'分部利润'!$B$12)^(1/4)-1) -> 0.12678322 | H20: ='分部利润'!$F$12-'分部利润'!$B$12 -> 16889
A21: 归属股东净利润 | B21: =IF('分部利润'!$B$15<=0,"n/m",'分部利润'!$C$15/'分部利润'!$B$15-1) -> -1.2530549 | C21: =IF('分部利润'!$C$15<=0,"n/m",'分部利润'!$D$15/'分部利润'!$C$15-1) -> n/m | D21: =IF('分部利润'!$D$15<=0,"n/m",'分部利润'!$E$15/'分部利润'!$D$15-1) -> -0.075117176 | E21: =IF('分部利润'!$E$15<=0,"n/m",'分部利润'!$F$15/'分部利润'!$E$15-1) -> -0.24750829 | F21: =IF('分部利润'!$G$15<=0,"n/m",'分部利润'!$H$15/'分部利润'!$G$15-1) -> 1.1076415 | G21: =IF(OR('分部利润'!$B$15<=0,'分部利润'!$F$15<=0),"n/m",('分部利润'!$F$15/'分部利润'!$B$15)^(1/4)-1) -> -0.071071616 | H21: ='分部利润'!$F$15-'分部利润'!$B$15 -> -22969
A23: C. 经营利润构成：各板块占比
A24: 板块 | B24: 2021 年 | C24: 2022 年 | D24: 2023 年 | E24: 2024 年 | F24: 2025 年 | G24: 2025 上半年 | H24: 2026 上半年
A25: 保险承保 | B25: ='分部利润'!$B$6/'分部利润'!$B$12 -> 0.031525166 | C25: ='分部利润'!$C$6/'分部利润'!$C$12 -> -0.00097235277 | D25: ='分部利润'!$D$6/'分部利润'!$D$12 -> 0.14532798 | E25: ='分部利润'!$E$6/'分部利润'!$E$12 -> 0.19014693 | F25: ='分部利润'!$F$6/'分部利润'!$F$12 -> 0.16315245 | G25: ='分部利润'!$G$6/'分部利润'!$G$12 -> 0.15999231 | H25: ='分部利润'!$H$6/'分部利润'!$H$12 -> 0.14172387
A26: 保险投资收益 | B26: ='分部利润'!$B$7/'分部利润'!$B$12 -> 0.1741856 | C26: ='分部利润'!$C$7/'分部利润'!$C$12 -> 0.21015785 | D26: ='分部利润'!$D$7/'分部利润'!$D$12 -> 0.25614458 | E26: ='分部利润'!$E$7/'分部利润'!$E$12 -> 0.28817168 | F26: ='分部利润'!$F$7/'分部利润'!$F$12 -> 0.2812795 | G26: ='分部利润'!$G$7/'分部利润'!$G$12 -> 0.30094707 | H26: ='分部利润'!$H$7/'分部利润'!$H$12 -> 0.23585022
A27: 铁路 BNSF | B27: ='分部利润'!$B$8/'分部利润'!$B$12 -> 0.21705258 | C27: ='分部利润'!$C$8/'分部利润'!$C$12 -> 0.19272032 | D27: ='分部利润'!$D$8/'分部利润'!$D$12 -> 0.13619813 | E27: ='分部利润'!$E$8/'分部利润'!$E$12 -> 0.10605645 | F27: ='分部利润'!$F$8/'分部利润'!$F$12 -> 0.12309491 | G27: ='分部利润'!$G$8/'分部利润'!$G$12 -> 0.12883996 | H27: ='分部利润'!$H$8/'分部利润'!$H$12 -> 0.12063792
A28: 能源 BHE | B28: ='分部利润'!$B$9/'分部利润'!$B$12 -> 0.12943436 | C28: ='分部利润'!$C$9/'分部利润'!$C$12 -> 0.12653551 | D28: ='分部利润'!$D$9/'分部利润'!$D$12 -> 0.062409639 | E28: ='分部利润'!$E$9/'分部利润'!$E$12 -> 0.078630605 | F28: ='分部利润'!$F$9/'分部利润'!$F$12 -> 0.08944387 | G28: ='分部利润'!$G$9/'分部利润'!$G$12 -> 0.086486227 | H28: ='分部利润'!$H$9/'分部利润'!$H$12 -> 0.082411936
A29: 制造、服务与零售 | B29: ='分部利润'!$B$10/'分部利润'!$B$12 -> 0.40294235 | C29: ='分部利润'!$C$10/'分部利润'!$C$12 -> 0.40553593 | D29: ='分部利润'!$D$10/'分部利润'!$D$12 -> 0.357751 | E29: ='分部利润'!$E$10/'分部利润'!$E$12 -> 0.27556549 | F29: ='分部利润'!$F$10/'分部利润'!$F$12 -> 0.30677067 | G29: ='分部利润'!$G$10/'分部利润'!$G$12 -> 0.32022499 | H29: ='分部利润'!$H$10/'分部利润'!$H$12 -> 0.31522052
A30: 其他 | B30: ='分部利润'!$B$11/'分部利润'!$B$12 -> 0.044859949 | C30: ='分部利润'!$C$11/'分部利润'!$C$12 -> 0.066022753 | D30: ='分部利润'!$D$11/'分部利润'!$D$12 -> 0.042168675 | E30: ='分部利润'!$E$11/'分部利润'!$E$12 -> 0.061428842 | F30: ='分部利润'!$F$11/'分部利润'!$F$12 -> 0.036258598 | G30: ='分部利润'!$G$11/'分部利润'!$G$12 -> 0.0035094467 | H30: ='分部利润'!$H$11/'分部利润'!$H$12 -> 0.10415553
A31: 合计（应为 100%） | B31: =SUM(B25:B30) -> 1 | C31: =SUM(C25:C30) -> 1 | D31: =SUM(D25:D30) -> 1 | E31: =SUM(E25:E30) -> 1 | F31: =SUM(F25:F30) -> 1 | G31: =SUM(G25:G30) -> 1 | H31: =SUM(H25:H30) -> 1
A33: D. 图表数据：分部税后利润（百万美元，链接“分部利润”表）
A34: 板块 | B34: 2021 年 | C34: 2022 年 | D34: 2023 年 | E34: 2024 年 | F34: 2025 年 | G34: 2025 上半年 | H34: 2026 上半年
A35: 保险承保 | B35: ='分部利润'!$B$6 -> 870 | C35: ='分部利润'!$C$6 -> -30 | D35: ='分部利润'!$D$6 -> 5428 | E35: ='分部利润'!$E$6 -> 9020 | F35: ='分部利润'!$F$6 -> 7258 | G35: ='分部利润'!$G$6 -> 3328 | H35: ='分部利润'!$H$6 -> 3448
A36: 保险投资收益 | B36: ='分部利润'!$B$7 -> 4807 | C36: ='分部利润'!$C$7 -> 6484 | D36: ='分部利润'!$D$7 -> 9567 | E36: ='分部利润'!$E$7 -> 13670 | F36: ='分部利润'!$F$7 -> 12513 | G36: ='分部利润'!$G$7 -> 6260 | H36: ='分部利润'!$H$7 -> 5738
A37: 铁路 BNSF | B37: ='分部利润'!$B$8 -> 5990 | C37: ='分部利润'!$C$8 -> 5946 | D37: ='分部利润'!$D$8 -> 5087 | E37: ='分部利润'!$E$8 -> 5031 | F37: ='分部利润'!$F$8 -> 5476 | G37: ='分部利润'!$G$8 -> 2680 | H37: ='分部利润'!$H$8 -> 2935
A38: 能源 BHE | B38: ='分部利润'!$B$9 -> 3572 | C38: ='分部利润'!$C$9 -> 3904 | D38: ='分部利润'!$D$9 -> 2331 | E38: ='分部利润'!$E$9 -> 3730 | F38: ='分部利润'!$F$9 -> 3979 | G38: ='分部利润'!$G$9 -> 1799 | H38: ='分部利润'!$H$9 -> 2005
A39: 制造、服务与零售 | B39: ='分部利润'!$B$10 -> 11120 | C39: ='分部利润'!$C$10 -> 12512 | D39: ='分部利润'!$D$10 -> 13362 | E39: ='分部利润'!$E$10 -> 13072 | F39: ='分部利润'!$F$10 -> 13647 | G39: ='分部利润'!$G$10 -> 6661 | H39: ='分部利润'!$H$10 -> 7669
A40: 其他 | B40: ='分部利润'!$B$11 -> 1238 | C40: ='分部利润'!$C$11 -> 2037 | D40: ='分部利润'!$D$11 -> 1575 | E40: ='分部利润'!$E$11 -> 2914 | F40: ='分部利润'!$F$11 -> 1613 | G40: ='分部利润'!$G$11 -> 73 | H40: ='分部利润'!$H$11 -> 2534
A41: 经营利润合计 | B41: ='分部利润'!$B$12 -> 27597 | C41: ='分部利润'!$C$12 -> 30853 | D41: ='分部利润'!$D$12 -> 37350 | E41: ='分部利润'!$E$12 -> 47437 | F41: ='分部利润'!$F$12 -> 44486 | G41: ='分部利润'!$G$12 -> 20801 | H41: ='分部利润'!$H$12 -> 24329
A42: D2. 图表数据：主要板块同比（不含波动极大的“其他”）
A43: 板块 | B43: 2025 vs 2024 | C43: 2026H1 vs 2025H1
A44: 保险承保 | B44: ='变化'!$E$14 -> -0.19534368 | C44: ='变化'!$F$14 -> 0.036057692
...

Sheet 网页数字对照
A1: 网页（交付/web）与备忘录中使用的数字：与本表格逐项对照
A2: 网页数值（蓝色）由同一数据源生成；“账本数值”为链接到本工作簿相应单元格的公式；差异应为 0。历史决定中的数字来自致股东信原文，列出处备查。
A4: 网页位置 | B4: 内容 | C4: 网页数值 | D4: 账本数值（公式） | E4: 差异 | F4: 出处 / 说明
A5: 第 3 题·揭晓 | B5: 2025 年末保险浮存金（百万美元） | C5: 176000 | D5: ='浮存金与现金'!$G$6 -> 176000 | E5: =ROUND(C5-D5,2) -> 0 | F5: S01 2025 年报 MD&A p.K-41
A6: 第 3 题·揭晓 | B6: 再保险集团（BHRG）2025 年税前承保利润（百万美元） | C6: 1851 | D6: ='业务明细'!$F$9 -> 1851 | E6: =ROUND(C6-D6,2) -> 0 | F6: S01 2025 年报 MD&A p.K-35
A7: 第 4 题·揭晓 | B7: 可口可乐持仓 2025 年股息（百万美元） | C7: 816 | D7: ='股票组合'!$B$47 -> 816 | E7: =ROUND(C7-D7,2) -> 0 | F7: L2025 2025 年致股东信 PDF 第15页
A8: 第 4 题·揭晓 | B8: 可口可乐持仓原始成本（百万美元） | C8: 1299 | D8: ='股票组合'!$C$47 -> 1299 | E8: =ROUND(C8-D8,2) -> 0 | F8: L2025 2025 年致股东信 PDF 第15页
A9: 第 4 题·揭晓 | B9: 股息 ÷ 成本 | C9: 0.62817552 | D9: ='股票组合'!$D$47 -> 0.62817552 | E9: =ROUND(C9-D9,4) -> 0 | F9: 公式：股票组合!D 列
A10: 第 6 题·揭晓 | B10: GEICO 2025 年已赚保费（百万美元） | C10: 44481 | D10: ='业务明细'!$F$16 -> 44481 | E10: =ROUND(C10-D10,2) -> 0 | F10: S01 2025 年报 MD&A p.K-36
A11: 第 6 题·揭晓 | B11: GEICO 2025 年税前承保利润（百万美元） | C11: 6824 | D11: ='业务明细'!$F$7 -> 6824 | E11: =ROUND(C11-D11,2) -> 0 | F11: S01 2025 年报 MD&A p.K-35
A12: 第 9 题·揭晓 | B12: BNSF 2025 年税后利润（百万美元） | C12: 5476 | D12: ='分部利润'!$F$8 -> 5476 | E12: =ROUND(C12-D12,2) -> 0 | F12: S01 2025 年报 MD&A p.K-34
A13: 第 9 题·揭晓 | B13: BNSF 2026 上半年税后利润（百万美元） | C13: 2935 | D13: ='分部利润'!$H$8 -> 2935 | E13: =ROUND(C13-D13,2) -> 0 | F13: S02 2026Q2 10-Q p.33
A14: 第 10 题·揭晓 | B14: 2026 上半年回购金额（百万美元） | C14: 4762 | D14: ='回购与每股账面'!$H$24 -> 4762 | E14: =ROUND(C14-D14,2) -> 0 | F14: S02 权益变动表 p.6（Q1+Q2，公式）
A15: 结算页·今天的账本 | B15: 2026 上半年经营利润（百万美元） | C15: 24329 | D15: ='分部利润'!$H$12 -> 24329 | E15: =ROUND(C15-D15,2) -> 0 | F15: 公式：分部利润表加总；与业绩公告 24,329 一致
A16: 结算页·今天的账本 | B16: 2025 上半年经营利润（百万美元） | C16: 20801 | D16: ='分部利润'!$G$12 -> 20801 | E16: =ROUND(C16-D16,2) -> 0 | F16: 公式：分部利润表加总；与业绩公告 20,801 一致
A17: 结算页·今天的账本 | B17: 2026-06-30 保险浮存金（百万美元） | C17: 177500 | D17: ='浮存金与现金'!$H$6 -> 177500 | E17: =ROUND(C17-D17,2) -> 0 | F17: S02 10-Q p.38
A18: 结算页·今天的账本 | B18: 2026-06-30 现金及短期国债（保险及其他，净额，百万美元） | C18: 359230 | D18: ='浮存金与现金'!$H$11 -> 359230 | E18: =ROUND(C18-D18,2) -> 0 | F18: 公式：浮存金与现金表
A19: 结算页·今天的账本 | B19: 2026-06-30 股票投资公允价值（百万美元） | C19: 323779 | D19: ='股票组合'!$G$17 -> 323779 | E19: =ROUND(C19-D19,2) -> 0 | F19: 公式：股票组合表行业合计
A20: 结算页·今天的账本 | B20: 2026-06-30 每股账面价值（A 类，美元） | C20: 522395.64 | D20: ='回购与每股账面'!$G$16 -> 522395.64 | E20: =ROUND(C20-D20,2) -> 0 | F20: 公式：回购与每股账面表
A21: 结算页·今天的账本 | B21: 2025 全年经营利润（百万美元） | C21: 44486 | D21: ='分部利润'!$F$12 -> 44486 | E21: =ROUND(C21-D21,2) -> 0 | F21: 公式：分部利润表加总
A22: 第 1 题 | B22: 1983 年买下内布拉斯加家具城 90% 股权支付的支票（百万美元） | C22: 55 | D22: （历史数字，见出处） | F22: 1984 年致股东信（“a check for $55 million”）
A23: 第 1 题 | B23: 内布拉斯加家具城单店年销售额（百万美元，超过） | C23: 100 | D23: （历史数字，见出处） | F23: 1983 年致股东信（“over $100 million of sales annually”）
A24: 第 2 题 | B24: 接手前九年纺织业务累计销售额（百万美元） | C24: 530 | D24: （历史数字，见出处） | F24: 1985 年致股东信
A25: 第 2 题 | B25: 同期累计亏损（百万美元） | C25: 10 | D25: （历史数字，见出处） | F25: 1985 年致股东信
A26: 第 2 题 | B26: 1980 年以来美国关闭的纺织厂数量 | C26: 250 | D26: （历史数字，见出处） | F26: 1985 年致股东信（引 Business Week）
A27: 第 3 题 | B27: 1967 年进入保险业时的浮存金（百万美元） | C27: 19 | D27: （历史数字，见出处） | F27: 2021 年致股东信
A28: 第 4 题 | B28: 1988 年末可口可乐持股（股） | C28: 14172500 | D28: （历史数字，见出处） | F28: 1988 年致股东信持仓表
A29: 第 4 题 | B29: 1988 年末可口可乐持仓成本（千美元） | C29: 592540 | D29: （历史数字，见出处） | F29: 1988 年致股东信持仓表
A30: 第 4 题 | B30: 1989 年末可口可乐持仓成本（千美元） | C30: 1023920 | D30: （历史数字，见出处） | F30: 1989 年致股东信持仓表
A31: 第 4 题 | B31: 1989 年末可口可乐持仓市值（千美元） | C31: 1803787 | D31: （历史数字，见出处） | F31: 1989 年致股东信持仓表
A32: 第 5 题 | B32: 买下富国银行约 10% 股权的总价（百万美元） | C32: 290 | D32: （历史数字，见出处） | F32: 1990 年致股东信
A33: 第 5 题 | B33: 富国银行总资产（十亿美元） | C33: 56 | D33: （历史数字，见出处） | F33: 1990 年致股东信
... A50: 第 10 题 | B50: 2014 年分红提案：投票股份中反对派息的比例（%） | C50: 98 | D50: （历史数字，见出处） | F50: 2014 年致股东信

Sheet 出处索引
A1: 出处索引（单元格批注中的出处代码对应此表）
A2: 页码规则：10-K 用页脚页码（如 p.K-34）；10-Q 用页脚页码；PDF 给出“PDF 第 N 页（页脚）”。有出处的输入数字已用脚本逐条比对原文（430 条，全部在所引位置找到）。
A4: 代码 | B4: 名称 | C4: 文件路径 / 网页地址 | D4: 访问日期
A5: S01 | B5: 伯克希尔 2025 年年报（Form 10-K，截至 2025-12-31） | C5: 材料/Berkshire_2025年报__brka-20251231.htm | D5: 本地材料
A6: S02 | B6: 伯克希尔 2026 年二季度报告（Form 10-Q，截至 2026-06-30） | C6: 材料/Berkshire_2026Q2季报__brka-20260630.htm | D6: 本地材料
A7: S03 | B7: 伯克希尔 2026 年二季度业绩公告（8-K 附件 99.1，2026-08-08） | C7: 材料/Berkshire_2026Q2业绩公告__d159922dex991.htm | D7: 本地材料
A8: L2021 | B8: 2021 年致股东信（巴菲特） | C8: 材料/股东信/2021ltr.pdf | D8: 本地材料
A9: L2022 | B9: 2022 年致股东信（巴菲特） | C9: 材料/股东信/2022ltr.pdf | D9: 本地材料
A10: L2023 | B10: 2023 年致股东信（巴菲特） | C10: 材料/股东信/2023ltr.pdf | D10: 本地材料
A11: L2024 | B11: 2024 年致股东信（巴菲特） | C11: 材料/股东信/2024ltr.pdf | D11: 本地材料
A12: L2025 | B12: 2025 年致股东信（阿贝尔，首封 CEO 信） | C12: 材料/股东信/2025ltr.pdf | D12: 本地材料
A13: W01 | B13: 伯克希尔 2023 年年度报告（含 10-K；2021–2022 年数字已按 LDTI 追溯调整） | C13: https://www.berkshirehathaway.com/2023ar/2023ar.pdf | D13: 2026-10-22
A14: W02 | B14: 伯克希尔 2022 年年度报告（含 10-K；LDTI 追溯调整前口径） | C14: https://www.berkshirehathaway.com/2022ar/2022ar.pdf | D14: 2026-10-22
A16: 说明
A17: • W01/W02 为联网获取的伯克希尔官网年度报告 PDF（含 10-K 全文），用于补齐材料中缺少的 2021–2022 年分部利润、资产负债表与股数；2025 年年报只覆盖 2023–2025 年。
A18: • 2021–2022 年分部利润与 2021 年末股东权益使用 2023 年年报中按 LDTI（ASU 2018-12）追溯调整后的数字，与 2023 年起口径一致。
A19: • “其他”在 2025 年年报中包含权益法投资收益；2021–2022 年由 2023 年年报中的“非控股企业”和“其他”两行合并而来（公式）。
A20: • 股东信中的经营利润、浮存金等文字数字用于交叉核对（见各表“核对”行）。

Sheet 核对
A1: 核对汇总（全部应为 0 / TRUE）
A3: 核对项 | B3: 最大绝对差异 | C3: 是否通过
A4: 分部利润：公式净利润 − 披露净利润 | B4: =MAX(ABS('分部利润'!$B$17),ABS('分部利润'!$C$17),ABS('分部利润'!$D$17),ABS('分部利润'!$E$17),ABS('分部利润'!$F$17),ABS('分部利润'!$G$17),ABS('分部利润'!$H$17)) -> 0 | C4: =B4<0.0001 -> TRUE
A5: 分部利润：公式经营利润 − 披露经营利润 | B5: =MAX(ABS('分部利润'!$B$20),ABS('分部利润'!$C$20),ABS('分部利润'!$D$20),ABS('分部利润'!$E$20),ABS('分部利润'!$F$20),ABS('分部利润'!$G$20),ABS('分部利润'!$H$20)) -> 0 | C5: =B5<0.0001 -> TRUE
A6: “其他”明细合计 − “其他”（2023 起） | B6: =MAX(ABS('分部利润'!$D$35),ABS('分部利润'!$E$35),ABS('分部利润'!$F$35),ABS('分部利润'!$G$35),ABS('分部利润'!$H$35)) -> 0 | C6: =B6<0.0001 -> TRUE
A7: 保险：分部承保利润合计 − 披露合计 | B7: =MAX(ABS('业务明细'!$B$12),ABS('业务明细'!$C$12),ABS('业务明细'!$D$12),ABS('业务明细'!$E$12),ABS('业务明细'!$F$12),ABS('业务明细'!$G$12),ABS('业务明细'!$H$12)) -> 0 | C7: =B7<0.0001 -> TRUE
A8: 现金及国债：公式 − MD&A 披露（十亿美元） | B8: =MAX(ABS('浮存金与现金'!$G$14),ABS('浮存金与现金'!$H$14)) -> 0 | C8: =B8<0.0001 -> TRUE
A9: 股票组合：行业合计 − 资产负债表 | B9: =MAX(ABS('股票组合'!$B$18),ABS('股票组合'!$C$18),ABS('股票组合'!$D$18),ABS('股票组合'!$E$18),ABS('股票组合'!$F$18),ABS('股票组合'!$G$18)) -> 0 | C9: =B9<0.0001 -> TRUE
A10: A 类等值股：公式 − 披露 | B10: =MAX(ABS('回购与每股账面'!$B$15),ABS('回购与每股账面'!$C$15),ABS('回购与每股账面'!$D$15),ABS('回购与每股账面'!$E$15),ABS('回购与每股账面'!$F$15),ABS('回购与每股账面'!$G$15)) -> 0 | C10: =B10<0.0001 -> TRUE
A11: 经营利润构成占比合计 − 100% | B11: =MAX(ABS(('变化'!$B$31-1)),ABS(('变化'!$C$31-1)),ABS(('变化'!$D$31-1)),ABS(('变化'!$E$31-1)),ABS(('变化'!$F$31-1)),ABS(('变化'!$G$31-1)),ABS(('变化'!$H$31-1))) -> 0 | C11: =B11<0.0001 -> TRUE
A12: 网页数字 − 账本数字 | B12: =MAX(ABS(MIN('网页数字对照'!E5:E50)),ABS(MAX('网页数字对照'!E5:E50))) -> 0 | C12: =B12<0.0001 -> TRUE
A14: 全部通过？ | C14: =AND(C4:C12) -> TRUE
