Workbook

Sheet 说明
A1: SPACE × TESLA | 并购讨论模型
A2: 单位：百万美元（股数为百万股；股价为美元/股），除非另有注明 | 取数：2026-10-22
A3: 项目 | B3: 说明
A4: 模型性质 | B4: 研究和展示用途，不构成投资建议。合并尚未确定；此表是账面加总加有限抵销，不是符合监管要求的完整购买法备考财务报表。
A5: 期间 | B5: 最近四季度：2025Q4、2026Q1、Q2、Q3；完整财年：2025；TTM=四季度之和。资产负债项目取各期末，TTM列取2026-09-30。
A6: SpaceX口径 | B6: 招股书对SpaceX、xAI、X按共同控制重组追溯合并；沿用其历史比较口径。AI在Q3称SI。Cursor自2026-08-14并入，历史TTM未做全年收购备考。
A7: 分部利润 | B7: SpaceX按分部经营利润；Tesla正式分部为汽车（含服务及其他）和能源，披露分部毛利。不得直接把两类利润相加；备考另列Tesla总经营费用桥接。
A8: 净利润 | B8: 主表净利润为合并净利润；另列归属股东净利润。SpaceX Q1两者相差671，不能将归属股东数字当合并净利润。
A9: 现金与债务 | B9: 现金及短期投资不含受限现金、数字资产、Tesla长期SpaceX投资；有息负债含融资租赁，不含经营租赁。SpaceX历史可赎回优先股独列，不计普通权益或债务。
A10: 自由现金流 | B10: FCF=经营现金流−披露资本开支。SpaceX资本开支用PP&E采购（不另扣返利、不并入单列资本化利息或频谱支出）；Tesla用披露净资本开支。属分析口径，非全部资金需求。
A11: 单季推导 | B11: SpaceX Q4=FY2025−9M2025；Q2经营现金流/资本开支=6M−Q1；Q3=9M−6M。所有差分由公式计算。
A12: 合并范围 | B12: 只合并Tesla与SpaceX及既有子公司（含xAI/X/Cursor）；不额外纳入TBC、Neuralink、Valor或个人安保公司。关联不等于属于合并范围。
A13: 抵销边界 | B13: Q3与9M26按Tesla披露Megapack销售/成本抵销；对资本化内部毛利按尚未对外实现、无折旧回转假设处理。Q4 2025内部毛利未知，不把调整后的9M冒充完整TTM。
A14: 资产负债备考 | B14: 仅确认可量化交叉投资与2026内部毛利抵销。往来抵销设可编辑的待核对假设，默认0；未对账≠不存在。没有PPA、商誉重估、融资或递延税全面调整。
... A22: 访问日期 | B22: 材料及行情访问/取数日期均为2026-10-22。来源登记含文件全名及章节。所有模型假设集中在假设页。

Sheet 来源登记
A1: 来源与取数索引
A2: 单位：百万美元（股数为百万股；股价为美元/股），除非另有注明 | 取数：2026-10-22
A3: ID | B3: 文件 / 网页 | C3: 章节 / 用途 | D3: 访问日期
A4: S1 | B4: SpaceX_招股书__spaceexplorationtechnologi.htm | C4: 原始材料；逐项章节见原始数据页 | D4: 2026-10-22
A5: S2 | B5: SpaceX_2026Q2季报__spcx-20260630.htm | C5: 原始材料；逐项章节见原始数据页 | D5: 2026-10-22
A6: S3 | B6: SpaceX_2026Q3业绩公告__spaceexplorationtechnologi.htm | C6: 原始材料；逐项章节见原始数据页 | D6: 2026-10-22
A7: T1 | B7: Tesla_2025年报__tsla-20251231.htm | C7: 原始材料；逐项章节见原始数据页 | D7: 2026-10-22
A8: T2 | B8: Tesla_2026Q3季报__tsla-20260930.htm | C8: 原始材料；逐项章节见原始数据页 | D8: 2026-10-22
A9: T3 | B9: Tesla_2026Q3业绩公告__exhibit9914.htm | C9: 原始材料；逐项章节见原始数据页 | D9: 2026-10-22
A10: T4 | B10: Tesla_2026股东大会委托书__tm267596-1_def14a.htm | C10: 原始材料；逐项章节见原始数据页 | D10: 2026-10-22
A11: M1 | B11: https://stockanalysis.com/stocks/spcx/history/ | C11: 20个已完成交易日 Close / Volume；S&P Global数据，网页转录 | D11: 2026-10-22
A12: M2 | B12: https://stockanalysis.com/stocks/tsla/history/ | C12: 20个已完成交易日 Close / Volume；未使用盘中行 | D12: 2026-10-22
A13: M3 | B13: https://chartexchange.com/symbol/nasdaq-spcx/historical/ | C13: 10月21日收盘159.31交叉核对；成交量与M1有差异，统一采用M1口径 | D13: 2026-10-22
A14: 背景 | B14: 任务.md；T2 Item 5 Other Information | C14: Tesla特别委员会成立可由季报核实；交易未保证完成 | D14: 2026-10-22

Sheet 原始数据
A1: 可追溯披露输入
A2: 单位：百万美元（股数为百万股；股价为美元/股），除非另有注明 | 取数：2026-10-22
A3: 数据ID | B3: 公司 | C3: 期间 | D3: 字段 | E3: 披露值 | F3: 来源文件 | G3: 章节 / 表名 | H3: 取数日期
A4: S_FY25_rev | B4: S | C4: FY25 | D4: rev | E4: 18674 | F4: SpaceX_招股书__spaceexplorationtechnologi.htm | G4: F-3/F-4/F-9 Consolidated financial statements; FY2025 restated | H4: 2026-10-22
A5: S_FY25_cost | B5: S | C5: FY25 | D5: cost | E5: 9451 | F5: SpaceX_招股书__spaceexplorationtechnologi.htm | G5: F-3/F-4/F-9 Consolidated financial statements; FY2025 restated | H5: 2026-10-22
A6: S_FY25_op | B6: S | C6: FY25 | D6: op | E6: -2589 | F6: SpaceX_招股书__spaceexplorationtechnologi.htm | G6: F-3/F-4/F-9 Consolidated financial statements; FY2025 restated | H6: 2026-10-22
A7: S_FY25_net | B7: S | C7: FY25 | D7: net | E7: -4937 | F7: SpaceX_招股书__spaceexplorationtechnologi.htm | G7: F-3/F-4/F-9 Consolidated financial statements; FY2025 restated | H7: 2026-10-22
A8: S_FY25_attrib | B8: S | C8: FY25 | D8: attrib | E8: -4937 | F8: SpaceX_招股书__spaceexplorationtechnologi.htm | G8: F-3/F-4/F-9 Consolidated financial statements; FY2025 restated | H8: 2026-10-22
A9: S_FY25_ocf | B9: S | C9: FY25 | D9: ocf | E9: 6785 | F9: SpaceX_招股书__spaceexplorationtechnologi.htm | G9: F-3/F-4/F-9 Consolidated financial statements; FY2025 restated | H9: 2026-10-22
A10: S_FY25_capex | B10: S | C10: FY25 | D10: capex | E10: 20737 | F10: SpaceX_招股书__spaceexplorationtechnologi.htm | G10: F-3/F-4/F-9 Consolidated financial statements; FY2025 restated | H10: 2026-10-22
A11: S_FY25_cash | B11: S | C11: FY25 | D11: cash | E11: 24747 | F11: SpaceX_招股书__spaceexplorationtechnologi.htm | G11: F-3/F-4/F-9 Consolidated financial statements; FY2025 restated | H11: 2026-10-22
A12: S_FY25_st | B12: S | C12: FY25 | D12: st | E12: 0 | F12: SpaceX_招股书__spaceexplorationtechnologi.htm | G12: F-3/F-4/F-9 Consolidated financial statements; FY2025 restated | H12: 2026-10-22
A13: S_FY25_dc | B13: S | C13: FY25 | D13: dc | E13: 928 | F13: SpaceX_招股书__spaceexplorationtechnologi.htm | G13: F-3/F-4/F-9 Consolidated financial statements; FY2025 restated | H13: 2026-10-22
A14: S_FY25_dl | B14: S | C14: FY25 | D14: dl | E14: 21968 | F14: SpaceX_招股书__spaceexplorationtechnologi.htm | G14: F-3/F-4/F-9 Consolidated financial statements; FY2025 restated | H14: 2026-10-22
A15: S_FY25_equity | B15: S | C15: FY25 | D15: equity | E15: 2573 | F15: SpaceX_招股书__spaceexplorationtechnologi.htm | G15: F-3/F-4/F-9 Consolidated financial statements; FY2025 restated | H15: 2026-10-22
... A287: X_9M26_fv_aftertax | B287: X | C287: 9M26 | D287: fv_aftertax | E287: 655 | F287: Tesla_2026Q3业绩公告__exhibit9914.htm | G287: p.30 Reconciliation: SpaceX equity investment gain/loss, net of tax | H287: 2026-10-22

Sheet 假设
A1: 独立于披露事实的建模假设
A2: 单位：百万美元（股数为百万股；股价为美元/股），除非另有注明 | 取数：2026-10-22
A3: 假设名称 | B3: 数值 | C3: 单位 | D3: 说明
A4: 支付给外部SpaceX股东的溢价 | B4: 0 | C4: 比例 | D4: 【假设】以各方法SpaceX基础每股价格加成；Tesla每股价值不加成。
A5: SpaceX EV / TTM营收 | B5: 12 | C5: 倍 | D5: 【假设】纯演示倍数，未作可比公司校准，不是估值意见。
A6: Tesla EV / TTM营收 | B6: 4 | C6: 倍 | D6: 【假设】纯演示倍数；不将负净利润用于P/E。
A7: Q3可实现经营协同 | B7: 0 | C7: 百万美元 | D7: 【假设】尚无已签约可验证协同。
A8: Q3一次性交易费用 | B8: 0 | C8: 百万美元 | D8: 【假设】尚无交易方案，基准不计；可编辑。
A9: 内部毛利/协同净调整税率 | B9: 0 | C9: 比例 | D9: 【假设】无完整税务资料，基准不确认税收利益；非适用法定税率。
A10: Q3内部毛利折旧回转 | B10: 0 | C10: 百万美元 | D10: 【假设】未获资产投用日期/年限；基准0，可能低估利润。
A11: 9M26内部毛利折旧回转 | B11: 0 | C11: 百万美元 | D11: 【假设】不含2025及以前内部毛利余额。
A12: Q3内部资本采购对应已结算现金 | B12: =原始数据!E230-原始数据!E237 -> 151 | C12: 百万美元 | D12: 【假设】以SpaceX关联PP&E现金流差分151估计对应Tesla收款；与221销售不能直接等同，待现金对账。
A13: 9M26内部资本采购对应已结算现金 | B13: =原始数据!E230 -> 480 | C13: 百万美元 | D13: 【假设】以480关联PP&E现金流近似；重分类同时减少经营现金流和资本开支，FCF不变。
A14: 已匹配往来应收/应付抵销 | B14: 0 | C14: 百万美元 | D14: 【假设】双边余额未核对，默认不抵销；不是认定无往来。Tesla账面729含588未交货开票，净141仅为核对起点。
A15: 已匹配预付/递延收入抵销 | B15: 0 | C15: 百万美元 | D15: 【假设】需核实对手预付款；不得自动把648或60全额认作可抵销余额。
A16: 2025及以前未实现内部毛利余额 | B16: 0 | C16: 百万美元 | D16: 【假设】缺少成本/折旧明细；0为未计量占位，不表示实际为0。
A17: Musk SpaceX披露后持股净变动 | B17: 0 | C17: 百万股 | D17: 【假设】5月持股沿用至9月，未取得完整持股变动；按基础无变动。
A18: SpaceX期权行权比例（补充情景） | B18: 1 | C18: 比例 | D18: 【假设】只用于持股补充情景；不纳入主换股股本，未建行权现金/库存股法。
A19: Tesla未达标股份转为Musk可支配比例 | B19: 1 | C19: 比例 | D19: 【假设】仅作上界示意，非合并必然触发归属；未计334.09美元/股抵扣或现金支付影响。
A20: SpaceX其他非经营净资产估值调整 | B20: 0 | C20: 百万美元 | D20: 【假设】除现金/债务外不另估数字资产、少数投资；倍数法简化。
A21: Tesla其他非经营净资产估值调整 | B21: 0 | C21: 百万美元 | D21: 【假设】SpaceX股权单独加入；数字资产、少数股权、经营租赁等暂不另调整。

Sheet SpaceX财务
A1: SpaceX财务 | 单季、财年与TTM
A2: 单位：百万美元（股数为百万股；股价为美元/股），除非另有注明 | 取数：2026-10-22
A3: 项目 | B3: FY2025 | C3: 2025Q4 | D3: 2026Q1 | E3: 2026Q2 | F3: 2026Q3 | G3: TTM至26Q3 | H3: 口径 / 来源
A4: 营收 | B4: =原始数据!E4 -> 18674 | C4: =原始数据!E4-原始数据!E19 -> 4960 | D4: =原始数据!E26 -> 4694 | E4: =原始数据!E41 -> 7814 | F4: =原始数据!E56 -> 14575 | G4: =SUM(C4:F4) -> 32043 | H4: 公式追溯至原始数据页；TTM流量求和/存量取期末。
A5: 营业成本 | B5: =原始数据!E5 -> 9451 | C5: =原始数据!E5-原始数据!E20 -> 2502 | D5: =原始数据!E27 -> 2388 | E5: =原始数据!E42 -> 3495 | F5: =原始数据!E57 -> 5478 | G5: =SUM(C5:F5) -> 13863 | H5: 公式追溯至原始数据页；TTM流量求和/存量取期末。
A6: 毛利 | B6: =B4-B5 -> 9223 | C6: =C4-C5 -> 2458 | D6: =D4-D5 -> 2306 | E6: =E4-E5 -> 4319 | F6: =F4-F5 -> 9097 | G6: =G4-G5 -> 18180 | H6: 公式追溯至原始数据页；TTM流量求和/存量取期末。
A7: 经营利润 | B7: =原始数据!E6 -> -2589 | C7: =原始数据!E6-原始数据!E21 -> -1373 | D7: =原始数据!E28 -> -1943 | E7: =原始数据!E43 -> -143 | F7: =原始数据!E58 -> 2791 | G7: =SUM(C7:F7) -> -668 | H7: 公式追溯至原始数据页；TTM流量求和/存量取期末。
A8: 合并净利润 | B8: =原始数据!E7 -> -4937 | C8: =原始数据!E7-原始数据!E22 -> -2347 | D8: =原始数据!E29 -> -4276 | E8: =原始数据!E44 -> -541 | F8: =原始数据!E59 -> 4404 | G8: =SUM(C8:F8) -> -2760 | H8: 公式追溯至原始数据页；TTM流量求和/存量取期末。
A9: 归属股东净利润 | B9: =原始数据!E8 -> -4937 | C9: =原始数据!E8-原始数据!E23 -> -2347 | D9: =原始数据!E30 -> -4947 | E9: =原始数据!E45 -> -541 | F9: =原始数据!E60 -> 4404 | G9: =SUM(C9:F9) -> -3431 | H9: 公式追溯至原始数据页；TTM流量求和/存量取期末。
A10: 经营现金流 | B10: =原始数据!E9 -> 6785 | C10: =原始数据!E9-原始数据!E24 -> 2665 | D10: =原始数据!E31 -> 1047 | E10: =原始数据!E54-原始数据!E31 -> 2419 | F10: =原始数据!E74-原始数据!E54 -> 9631 | G10: =SUM(C10:F10) -> 15762 | H10: 公式追溯至原始数据页；TTM流量求和/存量取期末。
A11: 资本开支（正数） | B11: =原始数据!E10 -> 20737 | C11: =原始数据!E10-原始数据!E25 -> 6891 | D11: =原始数据!E32 -> 10107 | E11: =原始数据!E55-原始数据!E32 -> 18369 | F11: =原始数据!E75-原始数据!E55 -> 19593 | G11: =SUM(C11:F11) -> 54960 | H11: 公式追溯至原始数据页；TTM流量求和/存量取期末。
A12: 自由现金流 | B12: =B10-B11 -> -13952 | C12: =C10-C11 -> -4226 | D12: =D10-D11 -> -9060 | E12: =E10-E11 -> -15950 | F12: =F10-F11 -> -9962 | G12: =G10-G11 -> -39198 | H12: 公式追溯至原始数据页；TTM流量求和/存量取期末。
A13: 现金及短期投资 | B13: =原始数据!E11+原始数据!E12 -> 24747 | C13: =原始数据!E11+原始数据!E12 -> 24747 | D13: =原始数据!E33+原始数据!E34 -> 23675 | E13: =原始数据!E46+原始数据!E47 -> 100009 | F13: =原始数据!E61+原始数据!E62 -> 89855 | G13: =原始数据!E61+原始数据!E62 -> 89855 | H13: 公式追溯至原始数据页；TTM流量求和/存量取期末。
A14: 有息负债含融资租赁 | B14: =原始数据!E13+原始数据!E14 -> 22896 | C14: =原始数据!E13+原始数据!E14 -> 22896 | D14: =原始数据!E35+原始数据!E36 -> 30265 | E14: =原始数据!E48+原始数据!E49 -> 39364 | F14: =原始数据!E63+原始数据!E64 -> 38844 | G14: =原始数据!E63+原始数据!E64 -> 38844 | H14: 公式追溯至原始数据页；TTM流量求和/存量取期末。债务含融资租赁，不含经营租赁。
A15: 股东权益（归母） | B15: =原始数据!E15 -> 2573 | C15: =B15 -> 2573 | D15: =原始数据!E37 -> 34533 | E15: =原始数据!E50 -> 127224 | F15: =原始数据!E65 -> 176768 | G15: =F15 -> 176768 | H15: 公式追溯至原始数据页；TTM流量求和/存量取期末。
A16: 总资产 | B16: =原始数据!E16 -> 92079 | C16: =B16 -> 92079 | D16: =原始数据!E38 -> 102094 | E16: =原始数据!E51 -> 192770 | F16: =原始数据!E66 -> 254045 | G16: =F16 -> 254045 | H16: 公式追溯至原始数据页；TTM流量求和/存量取期末。
A17: 总负债 | B17: =原始数据!E17 -> 50754 | C17: =B17 -> 50754 | D17: =原始数据!E39 -> 60512 | E17: =原始数据!E52 -> 65546 | F17: =原始数据!E67 -> 77277 | G17: =F17 -> 77277 | H17: 公式追溯至原始数据页；TTM流量求和/存量取期末。
A18: 净现金 | B18: =B13-B14 -> 1851 | C18: =C13-C14 -> 1851 | D18: =D13-D14 -> -6590 | E18: =E13-E14 -> 60645 | F18: =F13-F14 -> 51011 | G18: =G13-G14 -> 51011 | H18: 公式追溯至原始数据页；TTM流量求和/存量取期末。
A19: 经营利润率 | B19: =B7/B4 -> -0.13864196 | C19: =C7/C4 -> -0.27681452 | D19: =D7/D4 -> -0.41393268 | E19: =E7/E4 -> -0.018300486 | F19: =F7/F4 -> 0.19149228 | G19: =G7/G4 -> -0.020846987 | H19: 公式追溯至原始数据页；TTM流量求和/存量取期末。
A22: 每格公式批注标引用路径。SpaceX历史已含xAI/X共同控制追溯合并；Cursor仅自2026-08-14并入。Tesla主表净利润含非控股权益，归属股东净利润另列。
A24: 可赎回优先股（夹层） | B24: =原始数据!E18 -> 38752 | C24: =原始数据!E18 -> 38752 | D24: =原始数据!E40 -> 7049 | E24: =原始数据!E53 -> 0 | F24: =原始数据!E68 -> 0 | G24: =原始数据!E68 -> 0
A26: 可赎回优先股单列，2026Q2后为0。2025末权益2,573不含38,752夹层优先股；不能将IPO前后权益变化全部解释为经营盈利。

Sheet Tesla财务
A1: Tesla财务 | 单季、财年与TTM
A2: 单位：百万美元（股数为百万股；股价为美元/股），除非另有注明 | 取数：2026-10-22
A3: 项目 | B3: FY2025 | C3: 2025Q4 | D3: 2026Q1 | E3: 2026Q2 | F3: 2026Q3 | G3: TTM至26Q3 | H3: 口径 / 来源
A4: 营收 | B4: =原始数据!E121 -> 94827 | C4: =原始数据!E141 -> 24901 | D4: =原始数据!E160 -> 22387 | E4: =原始数据!E179 -> 28236 | F4: =原始数据!E198 -> 28046 | G4: =SUM(C4:F4) -> 103570 | H4: 公式追溯至原始数据页；TTM流量求和/存量取期末。
A5: 营业成本 | B5: =原始数据!E122 -> 77733 | C5: =原始数据!E142 -> 19892 | D5: =原始数据!E161 -> 17667 | E5: =原始数据!E180 -> 23485 | F5: =原始数据!E199 -> 22552 | G5: =SUM(C5:F5) -> 83596 | H5: 公式追溯至原始数据页；TTM流量求和/存量取期末。
A6: 毛利 | B6: =B4-B5 -> 17094 | C6: =C4-C5 -> 5009 | D6: =D4-D5 -> 4720 | E6: =E4-E5 -> 4751 | F6: =F4-F5 -> 5494 | G6: =G4-G5 -> 19974 | H6: 公式追溯至原始数据页；TTM流量求和/存量取期末。
A7: 经营利润 | B7: =原始数据!E123 -> 4355 | C7: =原始数据!E143 -> 1409 | D7: =原始数据!E162 -> 941 | E7: =原始数据!E181 -> 398 | F7: =原始数据!E200 -> 718 | G7: =SUM(C7:F7) -> 3466 | H7: 公式追溯至原始数据页；TTM流量求和/存量取期末。
A8: 合并净利润 | B8: =原始数据!E124 -> 3855 | C8: =原始数据!E144 -> 856 | D8: =原始数据!E163 -> 491 | E8: =原始数据!E182 -> 1128 | F8: =原始数据!E201 -> 804 | G8: =SUM(C8:F8) -> 3279 | H8: 公式追溯至原始数据页；TTM流量求和/存量取期末。
A9: 归属股东净利润 | B9: =原始数据!E125 -> 3794 | C9: =原始数据!E145 -> 840 | D9: =原始数据!E164 -> 477 | E9: =原始数据!E183 -> 1114 | F9: =原始数据!E202 -> 787 | G9: =SUM(C9:F9) -> 3218 | H9: 公式追溯至原始数据页；TTM流量求和/存量取期末。
A10: 经营现金流 | B10: =原始数据!E126 -> 14747 | C10: =原始数据!E146 -> 3813 | D10: =原始数据!E165 -> 3937 | E10: =原始数据!E184 -> 4697 | F10: =原始数据!E203 -> 6263 | G10: =SUM(C10:F10) -> 18710 | H10: 公式追溯至原始数据页；TTM流量求和/存量取期末。
A11: 资本开支（正数） | B11: =原始数据!E127 -> 8527 | C11: =原始数据!E147 -> 2393 | D11: =原始数据!E166 -> 2493 | E11: =原始数据!E185 -> 5789 | F11: =原始数据!E204 -> 4732 | G11: =SUM(C11:F11) -> 15407 | H11: 公式追溯至原始数据页；TTM流量求和/存量取期末。
A12: 自由现金流 | B12: =B10-B11 -> 6220 | C12: =C10-C11 -> 1420 | D12: =D10-D11 -> 1444 | E12: =E10-E11 -> -1092 | F12: =F10-F11 -> 1531 | G12: =G10-G11 -> 3303 | H12: 公式追溯至原始数据页；TTM流量求和/存量取期末。
A13: 现金及短期投资 | B13: =原始数据!E128+原始数据!E129 -> 44059 | C13: =原始数据!E148 -> 44059 | D13: =原始数据!E167 -> 44743 | E13: =原始数据!E186 -> 43524 | F13: =原始数据!E205 -> 45447 | G13: =原始数据!E205 -> 45447 | H13: 公式追溯至原始数据页；TTM流量求和/存量取期末。
A14: 有息负债含融资租赁 | B14: =原始数据!E130+原始数据!E131 -> 8376 | C14: =原始数据!E149+原始数据!E150 -> 8376 | D14: =原始数据!E168+原始数据!E169 -> 9229 | E14: =原始数据!E187+原始数据!E188 -> 9342 | F14: =原始数据!E206+原始数据!E207 -> 9523 | G14: =原始数据!E206+原始数据!E207 -> 9523 | H14: 公式追溯至原始数据页；TTM流量求和/存量取期末。债务含融资租赁，不含经营租赁。
A15: 股东权益（归母） | B15: =原始数据!E132 -> 82137 | C15: =原始数据!E151 -> 82137 | D15: =原始数据!E170 -> 84116 | E15: =原始数据!E189 -> 86858 | F15: =原始数据!E208 -> 89289 | G15: =F15 -> 89289 | H15: 公式追溯至原始数据页；TTM流量求和/存量取期末。
A16: 总资产 | B16: =原始数据!E133 -> 137806 | C16: =原始数据!E152 -> 137806 | D16: =原始数据!E171 -> 143724 | E16: =原始数据!E190 -> 148524 | F16: =原始数据!E209 -> 157517 | G16: =F16 -> 157517 | H16: 公式追溯至原始数据页；TTM流量求和/存量取期末。
A17: 总负债 | B17: =原始数据!E134 -> 54941 | C17: =原始数据!E153 -> 54941 | D17: =原始数据!E172 -> 58922 | E17: =原始数据!E191 -> 61005 | F17: =原始数据!E210 -> 67628 | G17: =F17 -> 67628 | H17: 公式追溯至原始数据页；TTM流量求和/存量取期末。
A18: 净现金 | B18: =B13-B14 -> 35683 | C18: =C13-C14 -> 35683 | D18: =D13-D14 -> 35514 | E18: =E13-E14 -> 34182 | F18: =F13-F14 -> 35924 | G18: =G13-G14 -> 35924 | H18: 公式追溯至原始数据页；TTM流量求和/存量取期末。
A19: 经营利润率 | B19: =B7/B4 -> 0.045925738 | C19: =C7/C4 -> 0.056584073 | D19: =D7/D4 -> 0.042033323 | E19: =E7/E4 -> 0.014095481 | F19: =F7/F4 -> 0.025600799 | G19: =G7/G4 -> 0.033465289 | H19: 公式追溯至原始数据页；TTM流量求和/存量取期末。
A22: 每格公式批注标引用路径。SpaceX历史已含xAI/X共同控制追溯合并；Cursor仅自2026-08-14并入。Tesla主表净利润含非控股权益，归属股东净利润另列。

Sheet 分部财务
A1: 正式披露分部与利润桥接
A2: 单位：百万美元（股数为百万股；股价为美元/股），除非另有注明 | 取数：2026-10-22
A3: 业务 / 指标 | B3: FY2025 | C3: 2025Q4 | D3: 2026Q1 | E3: 2026Q2 | F3: 2026Q3 | G3: TTM至26Q3 | H3: 利润口径 / 来源
A4: 航天 / 收入 | B4: =原始数据!E76 -> 4086 | C4: =原始数据!E76-原始数据!E85 -> 809 | D4: =原始数据!E94 -> 619 | E4: =原始数据!E103 -> 962 | F4: =原始数据!E112 -> 1767 | G4: =SUM(C4:F4) -> 4157 | H4: S1 Note19/18；S3 分部表；AI更名SI。
A5: 航天 / 成本 | B5: =原始数据!E77 -> 1352 | C5: =原始数据!E77-原始数据!E86 -> 248 | D5: =原始数据!E95 -> 281 | E5: =原始数据!E104 -> 329 | F5: =原始数据!E113 -> 435 | G5: =SUM(C5:F5) -> 1293 | H5: S1 Note19/18；S3 分部表；AI更名SI。
A6: 航天 / 毛利 | B6: =B4-B5 -> 2734 | C6: =C4-C5 -> 561 | D6: =D4-D5 -> 338 | E6: =E4-E5 -> 633 | F6: =F4-F5 -> 1332 | G6: =G4-G5 -> 2864 | H6: S1 Note19/18；S3 分部表；AI更名SI。
A7: 航天 / 经营利润 | B7: =原始数据!E78 -> -657 | C7: =原始数据!E78-原始数据!E87 -> -476 | D7: =原始数据!E96 -> -662 | E7: =原始数据!E105 -> -542 | F7: =原始数据!E114 -> -7 | G7: =SUM(C7:F7) -> -1687 | H7: S1 Note19/18；S3 分部表；AI更名SI。
A8: 连接 / 收入 | B8: =原始数据!E79 -> 11387 | C8: =原始数据!E79-原始数据!E88 -> 3228 | D8: =原始数据!E97 -> 3257 | E8: =原始数据!E106 -> 4291 | F8: =原始数据!E115 -> 5248 | G8: =SUM(C8:F8) -> 16024 | H8: S1 Note19/18；S3 分部表；AI更名SI。
A9: 连接 / 成本 | B9: =原始数据!E80 -> 5921 | C9: =原始数据!E80-原始数据!E89 -> 1650 | D9: =原始数据!E98 -> 1651 | E9: =原始数据!E107 -> 2060 | F9: =原始数据!E116 -> 2368 | G9: =SUM(C9:F9) -> 7729 | H9: S1 Note19/18；S3 分部表；AI更名SI。
A10: 连接 / 毛利 | B10: =B8-B9 -> 5466 | C10: =C8-C9 -> 1578 | D10: =D8-D9 -> 1606 | E10: =E8-E9 -> 2231 | F10: =F8-F9 -> 2880 | G10: =G8-G9 -> 8295 | H10: S1 Note19/18；S3 分部表；AI更名SI。
A11: 连接 / 经营利润 | B11: =原始数据!E81 -> 4423 | C11: =原始数据!E81-原始数据!E90 -> 1276 | D11: =原始数据!E99 -> 1188 | E11: =原始数据!E108 -> 1656 | F11: =原始数据!E117 -> 2367 | G11: =SUM(C11:F11) -> 6487 | H11: S1 Note19/18；S3 分部表；AI更名SI。
A12: 超级智能 SI / 收入 | B12: =原始数据!E82 -> 3201 | C12: =原始数据!E82-原始数据!E91 -> 923 | D12: =原始数据!E100 -> 818 | E12: =原始数据!E109 -> 2561 | F12: =原始数据!E118 -> 7560 | G12: =SUM(C12:F12) -> 11862 | H12: S1 Note19/18；S3 分部表；AI更名SI。
A13: 超级智能 SI / 成本 | B13: =原始数据!E83 -> 2178 | C13: =原始数据!E83-原始数据!E92 -> 604 | D13: =原始数据!E101 -> 456 | E13: =原始数据!E110 -> 1106 | F13: =原始数据!E119 -> 2675 | G13: =SUM(C13:F13) -> 4841 | H13: S1 Note19/18；S3 分部表；AI更名SI。
A14: 超级智能 SI / 毛利 | B14: =B12-B13 -> 1023 | C14: =C12-C13 -> 319 | D14: =D12-D13 -> 362 | E14: =E12-E13 -> 1455 | F14: =F12-F13 -> 4885 | G14: =G12-G13 -> 7021 | H14: S1 Note19/18；S3 分部表；AI更名SI。
A15: 超级智能 SI / 经营利润 | B15: =原始数据!E84 -> -6355 | C15: =原始数据!E84-原始数据!E93 -> -2173 | D15: =原始数据!E102 -> -2469 | E15: =原始数据!E111 -> -1257 | F15: =原始数据!E120 -> 431 | G15: =SUM(C15:F15) -> -5468 | H15: S1 Note19/18；S3 分部表；AI更名SI。
A16: 汽车（含服务及其他） / 收入 | B16: =原始数据!E135+原始数据!E136 -> 82056 | C16: =原始数据!E154+原始数据!E155 -> 21064 | D16: =原始数据!E173+原始数据!E174 -> 19979 | E16: =原始数据!E192+原始数据!E193 -> 25097 | F16: =原始数据!E211+原始数据!E212 -> 25165 | G16: =SUM(C16:F16) -> 91305 | H16: T1 Note16；T2 Note14；T3 p27。汽车含服务及其他，未披露分部经营利润。
A17: 汽车（含服务及其他） / 成本 | B17: =原始数据!E138+原始数据!E139 -> 68764 | C17: =原始数据!E157+原始数据!E158 -> 17153 | D17: =原始数据!E176+原始数据!E177 -> 16211 | E17: =原始数据!E195+原始数据!E196 -> 20986 | F17: =原始数据!E214+原始数据!E215 -> 20625 | G17: =SUM(C17:F17) -> 74975 | H17: T1 Note16；T2 Note14；T3 p27。汽车含服务及其他，未披露分部经营利润。
A18: 汽车（含服务及其他） / 毛利 | B18: =B16-B17 -> 13292 | C18: =C16-C17 -> 3911 | D18: =D16-D17 -> 3768 | E18: =E16-E17 -> 4111 | F18: =F16-F17 -> 4540 | G18: =G16-G17 -> 16330 | H18: T1 Note16；T2 Note14；T3 p27。汽车含服务及其他，未披露分部经营利润。
A19: 能源发电及储能 / 收入 | B19: =原始数据!E137 -> 12771 | C19: =原始数据!E156 -> 3837 | D19: =原始数据!E175 -> 2408 | E19: =原始数据!E194 -> 3139 | F19: =原始数据!E213 -> 2881 | G19: =SUM(C19:F19) -> 12265 | H19: T1 Note16；T2 Note14；T3 p27。汽车含服务及其他，未披露分部经营利润。
A20: 能源发电及储能 / 成本 | B20: =原始数据!E140 -> 8969 | C20: =原始数据!E159 -> 2739 | D20: =原始数据!E178 -> 1456 | E20: =原始数据!E197 -> 2499 | F20: =原始数据!E216 -> 1927 | G20: =SUM(C20:F20) -> 8621 | H20: T1 Note16；T2 Note14；T3 p27。汽车含服务及其他，未披露分部经营利润。
A21: 能源发电及储能 / 毛利 | B21: =B19-B20 -> 3802 | C21: =C19-C20 -> 1098 | D21: =D19-D20 -> 952 | E21: =E19-E20 -> 640 | F21: =F19-F20 -> 954 | G21: =G19-G20 -> 3644 | H21: T1 Note16；T2 Note14；T3 p27。汽车含服务及其他，未披露分部经营利润。
A22: Tesla经营费用（未分配到分部） | B22: =Tesla财务!B6-Tesla财务!B7 -> 12739 | C22: =Tesla财务!C6-Tesla财务!C7 -> 3600 | D22: =Tesla财务!D6-Tesla财务!D7 -> 3779 | E22: =Tesla财务!E6-Tesla财务!E7 -> 4353 | F22: =Tesla财务!F6-Tesla财务!F7 -> 4776 | G22: =Tesla财务!G6-Tesla财务!G7 -> 16508
A23: 合计经营利润（桥接后） | B23: =B7+B11+B15+B18+B21-B22 -> 1766 | C23: =C7+C11+C15+C18+C21-C22 -> 36 | D23: =D7+D11+D15+D18+D21-D22 -> -1002 | E23: =E7+E11+E15+E18+E21-E22 -> 255 | F23: =F7+F11+F15+F18+F21-F22 -> 3509 | G23: =G7+G11+G15+G18+G21-G22 -> 2798
A24: 营收勾稽差（应为0） | B24: =B4+B8+B12+B16+B19-SpaceX财务!B4-Tesla财务!B4 -> 0 | C24: =C4+C8+C12+C16+C19-SpaceX财务!C4-Tesla财务!C4 -> 0 | D24: =D4+D8+D12+D16+D19-SpaceX财务!D4-Tesla财务!D4 -> 0 | E24: =E4+E8+E12+E16+E19-SpaceX财务!E4-Tesla财务!E4 -> 0 | F24: =F4+F8+F12+F16+F19-SpaceX财务!F4-Tesla财务!F4 -> 0 | G24: =G4+G8+G12+G16+G19-SpaceX财务!G4-Tesla财务!G4 -> 0
A27: Tesla分部利润为毛利；SpaceX分部利润为经营利润。先扣Tesla未分配经营费用，再与SpaceX经营利润相加。不可将两种分部利润直接相加。

Sheet 市场数据
A1: 行情输入 | 只使用完整交易日
A2: 单位：百万美元（股数为百万股；股价为美元/股），除非另有注明 | 取数：2026-10-22
A3: 日期 | B3: SPCX收盘 | C3: SPCX成交量 | D3: TSLA收盘 | E3: TSLA成交量 | F3: SPCX收盘×量 | G3: TSLA收盘×量 | H3: 出处
A4: 2026-10-21 | B4: 159.31 | C4: 217419541 | D4: 386.47 | E4: 43161811 | F4: =B4*C4 -> 3.4637107e+10 | G4: =D4*E4 -> 1.6680745e+10 | H4: M1/M2：Stock Analysis历史行情；2026-10-22访问
A5: 2026-10-20 | B5: 147.79 | C5: 90413606 | D5: 373.71 | E5: 30590704 | F5: =B5*C5 -> 1.3362227e+10 | G5: =D5*E5 -> 1.1432052e+10 | H5: M1/M2：Stock Analysis历史行情；2026-10-22访问
A6: 2026-10-19 | B6: 147.96 | C6: 73858005 | D6: 368.06 | E6: 38756339 | F6: =B6*C6 -> 1.092803e+10 | G6: =D6*E6 -> 1.4264658e+10 | H6: M1/M2：Stock Analysis历史行情；2026-10-22访问
A7: 2026-10-16 | B7: 146.03 | C7: 88552887 | D7: 354.72 | E7: 62067344 | F7: =B7*C7 -> 1.2931378e+10 | G7: =D7*E7 -> 2.2016528e+10 | H7: M1/M2：Stock Analysis历史行情；2026-10-22访问
A8: 2026-10-15 | B8: 148.62 | C8: 101177143 | D8: 362.44 | E8: 26728314 | F8: =B8*C8 -> 1.5036947e+10 | G8: =D8*E8 -> 9.6874101e+09 | H8: M1/M2：Stock Analysis历史行情；2026-10-22访问
A9: 2026-10-14 | B9: 152.16 | C9: 68780976 | D9: 367.16 | E9: 31001421 | F9: =B9*C9 -> 1.0465713e+10 | G9: =D9*E9 -> 1.1382482e+10 | H9: M1/M2：Stock Analysis历史行情；2026-10-22访问
A10: 2026-10-13 | B10: 156.54 | C10: 69022484 | D10: 375.23 | E10: 18393043 | F10: =B10*C10 -> 1.080478e+10 | G10: =D10*E10 -> 6.9016215e+09 | H10: M1/M2：Stock Analysis历史行情；2026-10-22访问
A11: 2026-10-12 | B11: 163.42 | C11: 67434500 | D11: 378.03 | E11: 20244285 | F11: =B11*C11 -> 11020145990 | G11: =D11*E11 -> 7.6529471e+09 | H11: M1/M2：Stock Analysis历史行情；2026-10-22访问
A12: 2026-10-09 | B12: 162.57 | C12: 93042640 | D12: 382.7 | E12: 38952426 | F12: =B12*C12 -> 1.5125942e+10 | G12: =D12*E12 -> 1.4907093e+10 | H12: M1/M2：Stock Analysis历史行情；2026-10-22访问
A13: 2026-10-08 | B13: 160.57 | C13: 71897847 | D13: 375 | E13: 28394945 | F13: =B13*C13 -> 1.1544637e+10 | G13: =D13*E13 -> 10648104375 | H13: M1/M2：Stock Analysis历史行情；2026-10-22访问
A14: 2026-10-07 | B14: 167.6 | C14: 77473018 | D14: 377.81 | E14: 25594563 | F14: =B14*C14 -> 1.2984478e+10 | G14: =D14*E14 -> 9.6698818e+09 | H14: M1/M2：Stock Analysis历史行情；2026-10-22访问
A15: 2026-10-06 | B15: 171.92 | C15: 106952443 | D15: 380.68 | E15: 27735438 | F15: =B15*C15 -> 1.8387264e+10 | G15: =D15*E15 -> 1.0558327e+10 | H15: M1/M2：Stock Analysis历史行情；2026-10-22访问
... A23: 2026-09-24 | B23: 148.03 | C23: 72721441 | D23: 377.94 | E23: 26165727 | F23: =B23*C23 -> 1.0764955e+10 | G23: =D23*E23 -> 9.8890749e+09 | H23: M1/M2：Stock Analysis历史行情；2026-10-22访问
A25: 20日加权近似 | B25: =SUM(F4:F23)/SUM(C4:C23) -> 156.3372 | D25: =SUM(G4:G23)/SUM(E4:E23) -> 369.24077
A27: 近似值=Σ（日收盘价×日成交量）/Σ（日成交量）。不是逐笔VWAP；20日窗口2026-09-24至2026-10-21。若获交易所逐笔数据，应替换。

Sheet 关联交易
A1: 交易对账与抵销路线
A2: 单位：百万美元（股数为百万股；股价为美元/股），除非另有注明 | 取数：2026-10-22
A3: 交易 / 余额 | B3: 期间 | C3: 披露金额 | D3: 比较金额 | E3: 单位 | F3: 来源 | G3: 处理 | H3: 局限
A4: Megapack销售 / 成本 | B4: Q3 2026 | C4: =原始数据!E224 -> 221 | D4: =原始数据!E225 -> 171 | E4: 百万美元 | F4: T2 Note13 | G4: 抵销221收入、171成本，50内部毛利从资产及利润扣除 | H4: 设备在SpaceX资本化；并非冲收入又重复冲221费用
A5: Megapack销售 / 成本 | B5: 9M26 | C5: =原始数据!E227 -> 626 | D5: =原始数据!E228 -> 478 | E5: 百万美元 | F5: T2 Note13 | G5: 抵销626收入、478成本；内部毛利148 | H5: 未考虑折旧、税务回转和历史毛利，单列假设
A6: SpaceX关联资本采购现金流 | B6: 9M26 / 6M26 | C6: =原始数据!E230 -> 480 | D6: =原始数据!E237 -> 329 | E6: 百万美元 | F6: S3 p12；S2 Note17 | G6: 151为Q3差分；经营现金流与资本开支等额重分类 | H6: 9M现金480 vs Tesla收入626；需区分应计/现金、验收及预付
A7: 对SpaceX应收 / 未交货开票 | B7: 2026-09-30 | C7: =原始数据!E231 -> 729 | D7: =原始数据!E232 -> 588 | E7: 百万美元 | F7: T2 Note13 | G7: 729−588=141为已交货净核对起点；双边确认后抵销应收/应付 | H7: 不能将729全部视为已交货；也不能将141当已确认SpaceX应付
A8: 递延收入 / 未交货开票 | B8: 2026-09-30 | C8: =原始数据!E233 -> 648 | D8: =原始数据!E232 -> 588 | E8: 百万美元 | F8: T2 Note13 | G8: 648−588=60；按已收预付款与对方预付资产逐项核对 | H8: 当前516/长期132；60并不自动等于可抵销现金预付
A9: Tesla持有SpaceX投资 | B9: 2026-09-30 | C9: =原始数据!E236 -> 2865 | D9: — | E9: 百万美元 | F9: T2 Note2；S1 F61 | G9: 账面投资2,865与权益抵销；模型注销约19百万SpaceX股 | H9: 股数为拆股后估算；投资账面值不是用于定价的市值
A10: SpaceX股权重估收益 | B10: Q3 / 9M26 | C10: =原始数据!E226 -> -142 | D10: =原始数据!E229 -> 863 | E10: 百万美元 | F10: T2 Note2；T3 p30 | G10: 税前−142/863应剔除；实际税后−108/655用于净利润调整 | H10: 合并后不能确认自身权益工具价格变动收益
A11: Valor关联债务 | B11: 2026-09-30 | C11: =原始数据!E243 -> 2181 | D11: =原始数据!E244 -> 10716 | E11: 百万美元 | F11: S3 p11；S2 Note17 | G11: 保留：Valor不在合并范围；总12,897 | H11: Q3关联对手归属需以完整Q3季报再确认
A12: SpaceX关联利息 / 其他收益 | B12: Q3 2026 | C12: =原始数据!E245 -> 351 | D12: =原始数据!E246 -> 561 | E12: 百万美元 | F12: S3 p9 | G12: 351利息、561其他收益不可因“关联”二字全部抵销 | H12: Q3公告未充分标明561的对手与交易性质
A13: Megapack / Cybertruck采购 | B13: FY25 | C13: =原始数据!E248 -> 506 | D13: =原始数据!E249 -> 131 | E13: 百万美元 | F13: S1 Note18 F57 | G13: 追溯对账历史资产成本及未实现毛利 | H13: 与Tesla披露收入存在时点/分类差异，禁止直接硬配
A14: Tesla向SpaceX / xAI销售 | B14: FY25 | C14: =原始数据!E250 -> 143.3 | D14: =原始数据!E251 -> 430.1 | E14: 百万美元 | F14: T4 Related Person Transactions | G14: 历史收入需去重抵销；未进Q3/9M26本期金额 | H14: FY25收入573.4与637采购不一致；历史成本明细不足
A15: 商业支持支出：SpaceX / xAI | B15: FY25 | C15: =原始数据!E252 -> 11.4 | D15: =原始数据!E255 -> 4 | E15: 百万美元 | F15: T4 Related Person Transactions | G15: 合并范围内费用/收入成对抵销，核对重叠 | H15: 11.4与4.0可能与其他披露包含关系待核
A16: SpaceX飞机 / X广告 | B16: FY25 | C16: =原始数据!E253 -> 0.4 | D16: =原始数据!E254 -> 3.3 | E16: 百万美元 | F16: T4 Related Person Transactions | G16: 同在合并范围，核对后抵销费用与对方收入 | H16: 不在模型的2026已知抵销额中
A17: TBC / Musk安保公司支出 | B17: FY25 | C17: =原始数据!E257 -> 0.9 | D17: =原始数据!E258 -> 4.8 | E17: 百万美元 | F17: T4 Related Person Transactions | G17: 保留外部关联方交易；不合并这些企业 | H17: 关联交易定价与治理需独立审查
A18: Redwood支出 / 废料成本冲减 | B18: FY25 | C18: =原始数据!E259 -> 3.3 | D18: =原始数据!E260 -> 12.9 | E18: 百万美元 | F18: T4 Related Person Transactions | G18: 保留；Redwood不在范围内，属董事关联公司 | H18: 不属于Musk控制企业，单列治理事项
A19: Terafab合作 | B19: 2026 | C19: 未量化 | D19: — | E19: 百万美元 | F19: S1 F61 Tesla Collaboration | G19: 仅合作安排，不另添加一个独立收入分部 | H19: 项目投资分担、知识产权与资金承诺未量化

Sheet 合并备考
A1: 合并备考 | 已知抵销与未量化事项分开
A2: 单位：百万美元（股数为百万股；股价为美元/股），除非另有注明 | 取数：2026-10-22
A3: 项目 | B3: Tesla | C3: SpaceX | D3: 简单相加 | E3: 抵销 / 假设调整 | F3: 备考结果 | G3: 单位 | H3: 解释
A4: 2026Q3
A5: 营收 | B5: =Tesla财务!F4 -> 28046 | C5: =SpaceX财务!F4 -> 14575 | D5: =B5+C5 -> 42621 | E5: =-原始数据!E224 -> -221 | F5: =D5+E5 -> 42400 | G5: 百万美元 | H5: 含已知Megapack抵销；其他未量化关联交易尚待对账。
A6: 毛利 | B6: =Tesla财务!F6 -> 5494 | C6: =SpaceX财务!F6 -> 9097 | D6: =B6+C6 -> 14591 | E6: =-(原始数据!E224-原始数据!E225)+假设!B10 -> -50 | F6: =D6+E6 -> 14541 | G6: 百万美元 | H6: 含已知Megapack抵销；其他未量化关联交易尚待对账。
A7: 经营利润 | B7: =Tesla财务!F7 -> 718 | C7: =SpaceX财务!F7 -> 2791 | D7: =B7+C7 -> 3509 | E7: =-(原始数据!E224-原始数据!E225)+假设!B10+假设!B7-假设!B8 -> -50 | F7: =D7+E7 -> 3459 | G7: 百万美元 | H7: 内部资本化毛利未对外实现；折旧回转、协同与费用按假设。
A8: 合并净利润 | B8: =Tesla财务!F8 -> 804 | C8: =SpaceX财务!F8 -> 4404 | D8: =B8+C8 -> 5208 | E8: =(-(原始数据!E224-原始数据!E225)+假设!B10+假设!B7-假设!B8)*(1-假设!B9)-原始数据!E286 -> 58 | F8: =D8+E8 -> 5266 | G8: 百万美元 | H8: 剔除已披露税后投资重估损益；内部毛利及协同用假设税率。
A9: 经营现金流 | B9: =Tesla财务!F10 -> 6263 | C9: =SpaceX财务!F10 -> 9631 | D9: =B9+C9 -> 15894 | E9: =-假设!B12 -> -151 | F9: =D9+E9 -> 15743 | G9: 百万美元 | H9: 含已知Megapack抵销；其他未量化关联交易尚待对账。
A10: 资本开支 | B10: =Tesla财务!F11 -> 4732 | C10: =SpaceX财务!F11 -> 19593 | D10: =B10+C10 -> 24325 | E10: =-假设!B12 -> -151 | F10: =D10+E10 -> 24174 | G10: 百万美元 | H10: 含已知Megapack抵销；其他未量化关联交易尚待对账。
A11: 自由现金流 | B11: =Tesla财务!F12 -> 1531 | C11: =SpaceX财务!F12 -> -9962 | D11: =B11+C11 -> -8431 | E11: =E9-E10 -> 0 | F11: =D11+E11 -> -8431 | G11: 百万美元 | H11: 内部现金经营/投资重分类同时调整OCF和资本开支，FCF不因此改善。
A12: 2026前九月
A13: 营收 | B13: =原始数据!E217 -> 78669 | C13: =原始数据!E69 -> 27083 | D13: =B13+C13 -> 105752 | E13: =-原始数据!E227 -> -626 | F13: =D13+E13 -> 105126 | G13: 百万美元 | H13: 含已知Megapack抵销；其他未量化关联交易尚待对账。
A14: 毛利 | B14: =原始数据!E217-原始数据!E218 -> 14965 | C14: =原始数据!E69-原始数据!E70 -> 15722 | D14: =B14+C14 -> 30687 | E14: =-(原始数据!E227-原始数据!E228)+假设!B11 -> -148 | F14: =D14+E14 -> 30539 | G14: 百万美元 | H14: 含已知Megapack抵销；其他未量化关联交易尚待对账。
A15: 经营利润 | B15: =原始数据!E219 -> 2057 | C15: =原始数据!E71 -> 705 | D15: =B15+C15 -> 2762 | E15: =-(原始数据!E227-原始数据!E228)+假设!B11 -> -148 | F15: =D15+E15 -> 2614 | G15: 百万美元 | H15: 内部资本化毛利未对外实现；折旧回转、协同与费用按假设。
A16: 合并净利润 | B16: =原始数据!E220 -> 2423 | C16: =原始数据!E72 -> -413 | D16: =B16+C16 -> 2010 | E16: =(-(原始数据!E227-原始数据!E228)+假设!B11)*(1-假设!B9)-原始数据!E287 -> -803 | F16: =D16+E16 -> 1207 | G16: 百万美元 | H16: 剔除已披露税后投资重估损益；内部毛利及协同用假设税率。
A17: 经营现金流 | B17: =原始数据!E222 -> 14897 | C17: =原始数据!E74 -> 13097 | D17: =B17+C17 -> 27994 | E17: =-假设!B13 -> -480 | F17: =D17+E17 -> 27514 | G17: 百万美元 | H17: 含已知Megapack抵销；其他未量化关联交易尚待对账。
A18: 资本开支 | B18: =原始数据!E223 -> 13014 | C18: =原始数据!E75 -> 48069 | D18: =B18+C18 -> 61083 | E18: =-假设!B13 -> -480 | F18: =D18+E18 -> 60603 | G18: 百万美元 | H18: 含已知Megapack抵销；其他未量化关联交易尚待对账。
A19: 自由现金流 | B19: =原始数据!E222-原始数据!E223 -> 1883 | C19: =原始数据!E74-原始数据!E75 -> -34972 | D19: =B19+C19 -> -33089 | E19: =E17-E18 -> 0 | F19: =D19+E19 -> -33089 | G19: 百万美元 | H19: 内部现金经营/投资重分类同时调整OCF和资本开支，FCF不因此改善。
A20: TTM：仅简单相加
A21: 营收 | B21: =Tesla财务!G4 -> 103570 | C21: =SpaceX财务!G4 -> 32043 | D21: =B21+C21 -> 135613 | E21: 未完整抵销 | F21: =D21 -> 135613 | G21: 百万美元 | H21: Q4 2025内部毛利/交易缺少明细；本列仅展示加总，不代表完整合并TTM。
A22: 毛利 | B22: =Tesla财务!G6 -> 19974 | C22: =SpaceX财务!G6 -> 18180 | D22: =B22+C22 -> 38154 | E22: 未完整抵销 | F22: =D22 -> 38154 | G22: 百万美元 | H22: Q4 2025内部毛利/交易缺少明细；本列仅展示加总，不代表完整合并TTM。
A23: 经营利润 | B23: =Tesla财务!G7 -> 3466 | C23: =SpaceX财务!G7 -> -668 | D23: =B23+C23 -> 2798 | E23: 未完整抵销 | F23: =D23 -> 2798 | G23: 百万美元 | H23: Q4 2025内部毛利/交易缺少明细；本列仅展示加总，不代表完整合并TTM。
A24: 合并净利润 | B24: =Tesla财务!G8 -> 3279 | C24: =SpaceX财务!G8 -> -2760 | D24: =B24+C24 -> 519 | E24: 未完整抵销 | F24: =D24 -> 519 | G24: 百万美元 | H24: Q4 2025内部毛利/交易缺少明细；本列仅展示加总，不代表完整合并TTM。
A25: 经营现金流 | B25: =Tesla财务!G10 -> 18710 | C25: =SpaceX财务!G10 -> 15762 | D25: =B25+C25 -> 34472 | E25: 未完整抵销 | F25: =D25 -> 34472 | G25: 百万美元 | H25: Q4 2025内部毛利/交易缺少明细；本列仅展示加总，不代表完整合并TTM。
A26: 资本开支 | B26: =Tesla财务!G11 -> 15407 | C26: =SpaceX财务!G11 -> 54960 | D26: =B26+C26 -> 70367 | E26: 未完整抵销 | F26: =D26 -> 70367 | G26: 百万美元 | H26: Q4 2025内部毛利/交易缺少明细；本列仅展示加总，不代表完整合并TTM。
A27: 自由现金流 | B27: =Tesla财务!G12 -> 3303 | C27: =SpaceX财务!G12 -> -39198 | D27: =B27+C27 -> -35895 | E27: 未完整抵销 | F27: =D27 -> -35895 | G27: 百万美元 | H27: Q4 2025内部毛利/交易缺少明细；本列仅展示加总，不代表完整合并TTM。
A29: 2026-09-30资产负债表 | 账面基础，未做收购价分摊
A30: 现金及短期投资 | B30: =Tesla财务!F13 -> 45447 | C30: =SpaceX财务!F13 -> 89855 | D30: =B30+C30 -> 135302 | E30: =0 -> 0 | F30: =D30+E30 -> 135302 | H30: 资产负债暂不确认相关递延税；未核对往来默认不调整。股东权益不含非控股权益。
A31: 有息负债 | B31: =Tesla财务!F14 -> 9523 | C31: =SpaceX财务!F14 -> 38844 | D31: =B31+C31 -> 48367 | E31: =0 -> 0 | F31: =D31+E31 -> 48367 | H31: 资产负债暂不确认相关递延税；未核对往来默认不调整。股东权益不含非控股权益。
A32: 净现金 | B32: =Tesla财务!F18 -> 35924 | C32: =SpaceX财务!F18 -> 51011 | D32: =B32+C32 -> 86935 | E32: =0 -> 0 | F32: =D32+E32 -> 86935 | H32: 资产负债暂不确认相关递延税；未核对往来默认不调整。股东权益不含非控股权益。
A33: 总资产 | B33: =Tesla财务!F16 -> 157517 | C33: =SpaceX财务!F16 -> 254045 | D33: =B33+C33 -> 411562 | E33: =-原始数据!E236-(原始数据!E227-原始数据!E228)+假设!B11-假设!B16-假设!B14-假设!B15 -> -3013 | F33: =D33+E33 -> 408549 | H33: 资产负债暂不确认相关递延税；未核对往来默认不调整。股东权益不含非控股权益。
A34: 总负债 | B34: =Tesla财务!F17 -> 67628 | C34: =SpaceX财务!F17 -> 77277 | D34: =B34+C34 -> 144905 | E34: =-假设!B14-假设!B15 -> 0 | F34: =D34+E34 -> 144905 | H34: 资产负债暂不确认相关递延税；未核对往来默认不调整。股东权益不含非控股权益。
A35: 归母股东权益 | B35: =Tesla财务!F15 -> 89289 | C35: =SpaceX财务!F15 -> 176768 | D35: =B35+C35 -> 266057 | E35: =-原始数据!E236-(原始数据!E227-原始数据!E228)+假设!B11-假设!B16 -> -3013 | F35: =D35+E35 -> 263044 | H35: 资产负债暂不确认相关递延税；未核对往来默认不调整。股东权益不含非控股权益。
A37: Q3营收结构按已知221内部销售抵销后计；Tesla能源分部利润为毛利，SpaceX为经营利润。
A38: 汽车（含服务及其他） | B38: =分部财务!F16 -> 25165 | C38: =B38/F5 -> 0.59351415 | D38: =分部财务!F18 -> 4540 | H38: B列：外部营收；C列：营收占比；D列：毛利（不可直接与其他分部经营利润相加）
A39: 能源发电及储能 | B39: =分部财务!F19-原始数据!E224 -> 2660 | C39: =B39/F5 -> 0.062735849 | D39: =分部财务!F21-(原始数据!E224-原始数据!E225) -> 904 | H39: B列：外部营收；C列：营收占比；D列：毛利（不可直接与其他分部经营利润相加）
A40: 航天 | B40: =分部财务!F4 -> 1767 | C40: =B40/F5 -> 0.041674528 | D40: =分部财务!F7 -> -7 | H40: B列：外部营收；C列：营收占比；D列：经营利润
A41: 连接 | B41: =分部财务!F8 -> 5248 | C41: =B41/F5 -> 0.12377358 | D41: =分部财务!F11 -> 2367 | H41: B列：外部营收；C列：营收占比；D列：经营利润
A42: 超级智能 SI | B42: =分部财务!F12 -> 7560 | C42: =B42/F5 -> 0.17830189 | D42: =分部财务!F15 -> 431 | H42: B列：外部营收；C列：营收占比；D列：经营利润
...

Sheet 股本与持股
A1: 股本清洗 | 已发行、可行权与未达标奖励
A2: 单位：百万美元（股数为百万股；股价为美元/股），除非另有注明 | 取数：2026-10-22
A3: 项目 | B3: 数值 | C3: 单位 | D3: 来源 / 处理
A4: Tesla已发行股份 | B4: =原始数据!E261 -> 3952.6486 | C4: 百万股 | D4: T4 Ownership of Securities；2026-09-30；包含已发行未达标奖励
A5: SpaceX已发行A+B | B5: =原始数据!E274+原始数据!E275 -> 13579 | C5: 百万股 | D5: S3期末A8240+B5339；披露百万股四舍五入
A6: Tesla持有SpaceX股份（估计） | B6: =原始数据!E276*原始数据!E277 -> 19 | C6: 百万股 | D6: S1 F61：3.8百万股为拆股前，乘5得约19；假设无后续买卖
A7: SpaceX外部可获换股股份 | B7: =B5-B6 -> 13560 | C7: 百万股 | D7: 已发行总股数减Tesla自持，避免向自己发行
A8: Musk可支配Tesla已发行股份 | B8: =原始数据!E262 -> 699.58088 | C8: 百万股 | D8: T4含2018奖励已行权限制股；不含423.744未达标受不可撤销代理约束股份
A9: Musk可支配SpaceX已发行股份 | B9: =原始数据!E266+原始数据!E267-原始数据!E268+假设!B17 -> 6068.5475 | C9: 百万股 | D9: S1表内含350可行权期权，扣除以匹配已发行分母；含1302.072已发行绩效限制股，未必已归属
A10: Musk合并前Tesla股份占比 | B10: =B8/B4 -> 0.17699041 | C10: 比例 | D10: 统一已发行分母；与委托书19.8%口径不同
A11: Musk合并前SpaceX股份占比 | B11: =B9/B5 -> 0.44690681 | C11: 比例 | D11: 5月持股沿用至9月为假设；不是表决权
A12: Tesla委托书口径重算 | B12: =B8/(B4-原始数据!E263) -> 0.19824307 | C12: 比例 | D12: 对应披露约19.8%；从分母剔除未达标股份
A13: SpaceX招股书受益持股比例重算 | B13: =(原始数据!E266+原始数据!E267)/(原始数据!E270+原始数据!E271+原始数据!E272+原始数据!E268) -> 0.47754016 | C13: 比例 | D13: 招股书IPO后无超额配售分母；加入其350可行权期权；非当前期末比例
A14: SpaceX披露IPO后表决权 | B14: =原始数据!E273 -> 0.844 | C14: 比例 | D14: 仅引用事实；合并后股权类别与投票倍数未知，不能自动外推

Sheet 换股比例
A1: 三种定价方法 | 每1股SpaceX换取Tesla股数
A2: 单位：百万美元（股数为百万股；股价为美元/股），除非另有注明 | 取数：2026-10-22
A3: 项目 | B3: 10月21日收盘 | C3: 20日加权近似 | D3: 假设EV/营收 | E3: 口径说明
A4: SpaceX每股基础价值 | B4: =市场数据!B4 -> 159.31 | C4: =市场数据!B25 -> 156.3372 | D4: =(SpaceX财务!G4*假设!B5+SpaceX财务!F18+假设!B20)/股本与持股!B5 -> 32.073569
A5: Tesla每股基础价值 | B5: =市场数据!D4 -> 386.47 | C5: =市场数据!D25 -> 369.24077 | D5: =(Tesla财务!G4*假设!B6+Tesla财务!F18+股本与持股!B6*D4+假设!B21)/股本与持股!B4 -> 114.0535
A6: SpaceX基础股权价值 | B6: =B4*股本与持股!B5 -> 2163270.5 | C6: =C4*股本与持股!B5 -> 2122902.9 | D6: =D4*股本与持股!B5 -> 435527 | E6: 股权价值=每股价值×期末已发行股份；EV法加现金减债务。
A7: Tesla基础股权价值 | B7: =B5*股本与持股!B4 -> 1527580.1 | C7: =C5*股本与持股!B4 -> 1459479 | D7: =D5*股本与持股!B4 -> 450813.4 | E7: 倍数法Tesla另加其SpaceX股权的同法价值；市场法市值本已含其资产。
A8: 外部SpaceX股份交易对价 | B8: =B4*股本与持股!B7*(1+假设!B4) -> 2160243.6 | C8: =C4*股本与持股!B7*(1+假设!B4) -> 2119932.5 | D8: =D4*股本与持股!B7*(1+假设!B4) -> 434917.6
A9: 换股比例 r | B9: =B4*(1+假设!B4)/B5 -> 0.41221828 | C9: =C4*(1+假设!B4)/C5 -> 0.42340179 | D9: =D4*(1+假设!B4)/D5 -> 0.28121513 | E9: 法律发行主体假设Tesla；每1股外部SpaceX获r股Tesla。不是反向换股。
A10: 新发行Tesla股份 | B10: =B9*股本与持股!B7 -> 5589.6799 | C10: =C9*股本与持股!B7 -> 5741.3283 | D10: =D9*股本与持股!B7 -> 3813.2772
A11: 合并后股份 | B11: =B10+股本与持股!B4 -> 9542.3285 | C11: =C10+股本与持股!B4 -> 9693.9768 | D11: =D10+股本与持股!B4 -> 7765.9257
A12: 原SpaceX外部股东占比 | B12: =B10/B11 -> 0.58577735 | C12: =C10/C11 -> 0.59225727 | D12: =D10/D11 -> 0.49102674
A13: 原Tesla股东占比 | B13: =股本与持股!B4/B11 -> 0.41422265 | C13: =股本与持股!B4/C11 -> 0.40774273 | D13: =股本与持股!B4/D11 -> 0.50897326
A14: Musk合并后股份占比 | B14: =(股本与持股!B8+股本与持股!B9*B9)/B11 -> 0.33546813 | C14: =(股本与持股!B8+股本与持股!B9*C9)/C11 -> 0.33722123 | D14: =(股本与持股!B8+股本与持股!B9*D9)/D11 -> 0.30983406 | E14: 已发行/可支配股份口径，非投票权；持股不等于全部已归属经济利益。
A15: 较合并前Tesla变动（百分点） | B15: =(B14-股本与持股!B10)*100 -> 15.847772 | C15: =(C14-股本与持股!B10)*100 -> 16.023082 | D15: =(D14-股本与持股!B10)*100 -> 13.284365
A16: 较合并前SpaceX变动（百分点） | B16: =(B14-股本与持股!B11)*100 -> -11.143867 | C16: =(C14-股本与持股!B11)*100 -> -10.968558 | D16: =(D14-股本与持股!B11)*100 -> -13.707275
A17: 若SpaceX350百万期权全部行权 | B17: =(股本与持股!B8+(股本与持股!B9+原始数据!E268*假设!B18)*B9)/(B11+原始数据!E268*假设!B18*B9) -> 0.34536595 | C17: =(股本与持股!B8+(股本与持股!B9+原始数据!E268*假设!B18)*C9)/(C11+原始数据!E268*假设!B18*C9) -> 0.34720049 | D17: =(股本与持股!B8+(股本与持股!B9+原始数据!E268*假设!B18)*D9)/(D11+原始数据!E268*假设!B18*D9) -> 0.31847174 | E17: 固定r的股数示意，非完整稀释估值；未计行权所得现金和全部员工期权。
A18: 若Tesla未达标股全部转为可支配（上界） | B18: =(股本与持股!B8+原始数据!E263*假设!B19+股本与持股!B9*B9)/B11 -> 0.37987489 | C18: =(股本与持股!B8+原始数据!E263*假设!B19+股本与持股!B9*C9)/C11 -> 0.38093331 | D18: =(股本与持股!B8+原始数据!E263*假设!B19+股本与持股!B9*D9)/D11 -> 0.36439856 | E18: 既有股份转为可支配，不重复增加分母；未计334.09美元/股抵扣，不能视为合并自动兑现。
A22: 三种方法是交易数学情景，不是价格建议。市场法使用9月股本×10月21日价格，是近似市值而非当日股本核验；SpaceX分母为百万股取整。

Sheet 敏感性
A1: 溢价 × 定价方法 | 公式二维敏感性
A2: 单位：百万美元（股数为百万股；股价为美元/股），除非另有注明 | 取数：2026-10-22
A3: SpaceX溢价 | B3: 10月21日收盘 | C3: 20日加权近似 | D3: 假设EV/营收 | E3: 输出指标
A4: -0.2 | B4: =换股比例!B4*(1+$A4)/换股比例!B5 -> 0.32977463 | C4: =换股比例!C4*(1+$A4)/换股比例!C5 -> 0.33872143 | D4: =换股比例!D4*(1+$A4)/换股比例!D5 -> 0.2249721 | E4: 每1股SpaceX换取Tesla股数
A5: -0.1 | B5: =换股比例!B4*(1+$A5)/换股比例!B5 -> 0.37099646 | C5: =换股比例!C4*(1+$A5)/换股比例!C5 -> 0.38106161 | D5: =换股比例!D4*(1+$A5)/换股比例!D5 -> 0.25309362 | E5: 每1股SpaceX换取Tesla股数
A6: 0 | B6: =换股比例!B4*(1+$A6)/换股比例!B5 -> 0.41221828 | C6: =换股比例!C4*(1+$A6)/换股比例!C5 -> 0.42340179 | D6: =换股比例!D4*(1+$A6)/换股比例!D5 -> 0.28121513 | E6: 每1股SpaceX换取Tesla股数
A7: 0.1 | B7: =换股比例!B4*(1+$A7)/换股比例!B5 -> 0.45344011 | C7: =换股比例!C4*(1+$A7)/换股比例!C5 -> 0.46574197 | D7: =换股比例!D4*(1+$A7)/换股比例!D5 -> 0.30933664 | E7: 每1股SpaceX换取Tesla股数
A8: 0.2 | B8: =换股比例!B4*(1+$A8)/换股比例!B5 -> 0.49466194 | C8: =换股比例!C4*(1+$A8)/换股比例!C5 -> 0.50808215 | D8: =换股比例!D4*(1+$A8)/换股比例!D5 -> 0.33745816 | E8: 每1股SpaceX换取Tesla股数
A9: 0.3 | B9: =换股比例!B4*(1+$A9)/换股比例!B5 -> 0.53588377 | C9: =换股比例!C4*(1+$A9)/换股比例!C5 -> 0.55042233 | D9: =换股比例!D4*(1+$A9)/换股比例!D5 -> 0.36557967 | E9: 每1股SpaceX换取Tesla股数
A12: -0.2 | B12: =(换股比例!B4*(1+$A12)/换股比例!B5)*股本与持股!B7/(股本与持股!B4+(换股比例!B4*(1+$A12)/换股比例!B5)*股本与持股!B7) -> 0.53080907 | C12: =(换股比例!C4*(1+$A12)/换股比例!C5)*股本与持股!B7/(股本与持股!B4+(换股比例!C4*(1+$A12)/换股比例!C5)*股本与持股!B7) -> 0.53746991 | D12: =(换股比例!D4*(1+$A12)/换股比例!D5)*股本与持股!B7/(股本与持股!B4+(换股比例!D4*(1+$A12)/换股比例!D5)*股本与持股!B7) -> 0.4355996 | E12: 原SpaceX外部股东占比
A13: -0.1 | B13: =(换股比例!B4*(1+$A13)/换股比例!B5)*股本与持股!B7/(股本与持股!B4+(换股比例!B4*(1+$A13)/换股比例!B5)*股本与持股!B7) -> 0.56000335 | C13: =(换股比例!C4*(1+$A13)/换股比例!C5)*股本与持股!B7/(股本与持股!B4+(换股比例!C4*(1+$A13)/换股比例!C5)*股本与持股!B7) -> 0.56658814 | D13: =(换股比例!D4*(1+$A13)/换股比例!D5)*股本与持股!B7/(股本与持股!B4+(换股比例!D4*(1+$A13)/换股比例!D5)*股本与持股!B7) -> 0.46474425 | E13: 原SpaceX外部股东占比
A14: 0 | B14: =(换股比例!B4*(1+$A14)/换股比例!B5)*股本与持股!B7/(股本与持股!B4+(换股比例!B4*(1+$A14)/换股比例!B5)*股本与持股!B7) -> 0.58577735 | C14: =(换股比例!C4*(1+$A14)/换股比例!C5)*股本与持股!B7/(股本与持股!B4+(换股比例!C4*(1+$A14)/换股比例!C5)*股本与持股!B7) -> 0.59225727 | D14: =(换股比例!D4*(1+$A14)/换股比例!D5)*股本与持股!B7/(股本与持股!B4+(换股比例!D4*(1+$A14)/换股比例!D5)*股本与持股!B7) -> 0.49102674 | E14: 原SpaceX外部股东占比
A15: 0.1 | B15: =(换股比例!B4*(1+$A15)/换股比例!B5)*股本与持股!B7/(股本与持股!B4+(换股比例!B4*(1+$A15)/换股比例!B5)*股本与持股!B7) -> 0.60869889 | C15: =(换股比例!C4*(1+$A15)/换股比例!C5)*股本与持股!B7/(股本与持股!B4+(换股比例!C4*(1+$A15)/换股比例!C5)*股本与持股!B7) -> 0.61505587 | D15: =(换股比例!D4*(1+$A15)/换股比例!D5)*股本与持股!B7/(股本与持股!B4+(换股比例!D4*(1+$A15)/换股比例!D5)*股本与持股!B7) -> 0.51484895 | E15: 原SpaceX外部股东占比
A16: 0.2 | B16: =(换股比例!B4*(1+$A16)/换股比例!B5)*股本与持股!B7/(股本与持股!B4+(换股比例!B4*(1+$A16)/换股比例!B5)*股本与持股!B7) -> 0.62921665 | C16: =(换股比例!C4*(1+$A16)/换股比例!C5)*股本与持股!B7/(股本与持股!B4+(换股比例!C4*(1+$A16)/换股比例!C5)*股本与持股!B7) -> 0.63543994 | D16: =(换股比例!D4*(1+$A16)/换股比例!D5)*股本与持股!B7/(股本与持股!B4+(换股比例!D4*(1+$A16)/换股比例!D5)*股本与持股!B7) -> 0.5365409 | E16: 原SpaceX外部股东占比
A17: 0.3 | B17: =(换股比例!B4*(1+$A17)/换股比例!B5)*股本与持股!B7/(股本与持股!B4+(换股比例!B4*(1+$A17)/换股比例!B5)*股本与持股!B7) -> 0.64768993 | C17: =(换股比例!C4*(1+$A17)/换股比例!C5)*股本与持股!B7/(股本与持股!B4+(换股比例!C4*(1+$A17)/换股比例!C5)*股本与持股!B7) -> 0.65377377 | D17: =(换股比例!D4*(1+$A17)/换股比例!D5)*股本与持股!B7/(股本与持股!B4+(换股比例!D4*(1+$A17)/换股比例!D5)*股本与持股!B7) -> 0.5563761 | E17: 原SpaceX外部股东占比
A20: -0.2 | B20: =(股本与持股!B8+(换股比例!B4*(1+$A20)/换股比例!B5)*股本与持股!B9)/(股本与持股!B4+(换股比例!B4*(1+$A20)/换股比例!B5)*股本与持股!B7) -> 0.32059687 | C20: =(股本与持股!B8+(换股比例!C4*(1+$A20)/换股比例!C5)*股本与持股!B9)/(股本与持股!B4+(换股比例!C4*(1+$A20)/换股比例!C5)*股本与持股!B7) -> 0.32239891 | D20: =(股本与持股!B8+(换股比例!D4*(1+$A20)/换股比例!D5)*股本与持股!B9)/(股本与持股!B4+(换股比例!D4*(1+$A20)/换股比例!D5)*股本与持股!B7) -> 0.29483865 | E20: Musk合并后股份占比
A21: -0.1 | B21: =(股本与持股!B8+(换股比例!B4*(1+$A21)/换股比例!B5)*股本与持股!B9)/(股本与持股!B4+(换股比例!B4*(1+$A21)/换股比例!B5)*股本与持股!B7) -> 0.32849517 | C21: =(股本与持股!B8+(换股比例!C4*(1+$A21)/换股比例!C5)*股本与持股!B9)/(股本与持股!B4+(换股比例!C4*(1+$A21)/换股比例!C5)*股本与持股!B7) -> 0.33027663 | D21: =(股本与持股!B8+(换股比例!D4*(1+$A21)/换股比例!D5)*股本与持股!B9)/(股本与持股!B4+(换股比例!D4*(1+$A21)/换股比例!D5)*股本与持股!B7) -> 0.30272352 | E21: Musk合并后股份占比
A22: 0 | B22: =(股本与持股!B8+(换股比例!B4*(1+$A22)/换股比例!B5)*股本与持股!B9)/(股本与持股!B4+(换股比例!B4*(1+$A22)/换股比例!B5)*股本与持股!B7) -> 0.33546813 | C22: =(股本与持股!B8+(换股比例!C4*(1+$A22)/换股比例!C5)*股本与持股!B9)/(股本与持股!B4+(换股比例!C4*(1+$A22)/换股比例!C5)*股本与持股!B7) -> 0.33722123 | D22: =(股本与持股!B8+(换股比例!D4*(1+$A22)/换股比例!D5)*股本与持股!B9)/(股本与持股!B4+(换股比例!D4*(1+$A22)/换股比例!D5)*股本与持股!B7) -> 0.30983406 | E22: Musk合并后股份占比
A23: 0.1 | B23: =(股本与持股!B8+(换股比例!B4*(1+$A23)/换股比例!B5)*股本与持股!B9)/(股本与持股!B4+(换股比例!B4*(1+$A23)/换股比例!B5)*股本与持股!B7) -> 0.34166938 | C23: =(股本与持股!B8+(换股比例!C4*(1+$A23)/换股比例!C5)*股本与持股!B9)/(股本与持股!B4+(换股比例!C4*(1+$A23)/换股比例!C5)*股本与持股!B7) -> 0.34338922 | D23: =(股本与持股!B8+(换股比例!D4*(1+$A23)/换股比例!D5)*股本与持股!B9)/(股本与持股!B4+(换股比例!D4*(1+$A23)/换股比例!D5)*股本与持股!B7) -> 0.31627898 | E23: Musk合并后股份占比
A24: 0.2 | B24: =(股本与持股!B8+(换股比例!B4*(1+$A24)/换股比例!B5)*股本与持股!B9)/(股本与持股!B4+(换股比例!B4*(1+$A24)/换股比例!B5)*股本与持股!B7) -> 0.34722031 | C24: =(股本与持股!B8+(换股比例!C4*(1+$A24)/换股比例!C5)*股本与持股!B9)/(股本与持股!B4+(换股比例!C4*(1+$A24)/换股比例!C5)*股本与持股!B7) -> 0.34890398 | D24: =(股本与持股!B8+(换股比例!D4*(1+$A24)/换股比例!D5)*股本与持股!B9)/(股本与持股!B4+(换股比例!D4*(1+$A24)/换股比例!D5)*股本与持股!B7) -> 0.32214757 | E24: Musk合并后股份占比
A25: 0.3 | B25: =(股本与持股!B8+(换股比例!B4*(1+$A25)/换股比例!B5)*股本与持股!B9)/(股本与持股!B4+(换股比例!B4*(1+$A25)/换股比例!B5)*股本与持股!B7) -> 0.35221812 | C25: =(股本与持股!B8+(换股比例!C4*(1+$A25)/换股比例!C5)*股本与持股!B9)/(股本与持股!B4+(换股比例!C4*(1+$A25)/换股比例!C5)*股本与持股!B7) -> 0.35386406 | D25: =(股本与持股!B8+(换股比例!D4*(1+$A25)/换股比例!D5)*股本与持股!B9)/(股本与持股!B4+(换股比例!D4*(1+$A25)/换股比例!D5)*股本与持股!B7) -> 0.32751384 | E25: Musk合并后股份占比
A28: 溢价为相对各方法SpaceX基础价值的加成，Tesla端不加溢价。全部单元格为明确公式，兼容无需Excel数据表重算引擎的阅读器。

Sheet 校验
A1: 模型勾稽 | 所有差额应为0
A2: 单位：百万美元（股数为百万股；股价为美元/股），除非另有注明 | 取数：2026-10-22
A3: 校验项目 | B3: 差额 | C3: 说明
A4: Tesla B 分部收入勾稽 | B4: =分部财务!B16+分部财务!B19-Tesla财务!B4 -> 0 | C4: 本公司正式分部收入总和−公司收入
A5: Tesla C 分部收入勾稽 | B5: =分部财务!C16+分部财务!C19-Tesla财务!C4 -> 0 | C5: 本公司正式分部收入总和−公司收入
A6: Tesla D 分部收入勾稽 | B6: =分部财务!D16+分部财务!D19-Tesla财务!D4 -> 0 | C6: 本公司正式分部收入总和−公司收入
A7: Tesla E 分部收入勾稽 | B7: =分部财务!E16+分部财务!E19-Tesla财务!E4 -> 0 | C7: 本公司正式分部收入总和−公司收入
A8: Tesla F 分部收入勾稽 | B8: =分部财务!F16+分部财务!F19-Tesla财务!F4 -> 0 | C8: 本公司正式分部收入总和−公司收入
A9: Tesla G 分部收入勾稽 | B9: =分部财务!G16+分部财务!G19-Tesla财务!G4 -> 0 | C9: 本公司正式分部收入总和−公司收入
A10: SpaceX B 分部收入勾稽 | B10: =分部财务!B4+分部财务!B8+分部财务!B12-SpaceX财务!B4 -> 0 | C10: 本公司正式分部收入总和−公司收入
A11: SpaceX C 分部收入勾稽 | B11: =分部财务!C4+分部财务!C8+分部财务!C12-SpaceX财务!C4 -> 0 | C11: 本公司正式分部收入总和−公司收入
A12: SpaceX D 分部收入勾稽 | B12: =分部财务!D4+分部财务!D8+分部财务!D12-SpaceX财务!D4 -> 0 | C12: 本公司正式分部收入总和−公司收入
A13: SpaceX E 分部收入勾稽 | B13: =分部财务!E4+分部财务!E8+分部财务!E12-SpaceX财务!E4 -> 0 | C13: 本公司正式分部收入总和−公司收入
A14: SpaceX F 分部收入勾稽 | B14: =分部财务!F4+分部财务!F8+分部财务!F12-SpaceX财务!F4 -> 0 | C14: 本公司正式分部收入总和−公司收入
A15: SpaceX G 分部收入勾稽 | B15: =分部财务!G4+分部财务!G8+分部财务!G12-SpaceX财务!G4 -> 0 | C15: 本公司正式分部收入总和−公司收入
A16: 换股股东占比合计 B | B16: =换股比例!B12+换股比例!B13-1 -> 0 | C16: 原Tesla+外部SpaceX=100%
A17: 换股股东占比合计 C | B17: =换股比例!C12+换股比例!C13-1 -> 0 | C17: 原Tesla+外部SpaceX=100%
A18: 换股股东占比合计 D | B18: =换股比例!D12+换股比例!D13-1 -> 0 | C18: 原Tesla+外部SpaceX=100%
A19: Q3备考分部收入一致 | B19: =SUM(合并备考!B38:B42)-合并备考!F5 -> 0 | C19: 抵销后业务结构与备考营收一致
A20: Q3 FCF重分类无虚增 | B20: =合并备考!F11-合并备考!D11 -> 0 | C20: 同额抵销经营收款和内部资本采购
A21: 9M26 FCF重分类无虚增 | B21: =合并备考!F19-合并备考!D19 -> 0 | C21: 同上
A22: 备考资产负债勾稽 | B22: =合并备考!F33-合并备考!F34-合并备考!F35-合并备考!F44 -> 0 | C22: 总资产=总负债+归母权益+非控股权益及可赎回非控股权益
